<sdf version='1.6'>
  <model name='ICub'>
    <link name='base_link'>
      <pose frame=''>0 0 0 0 -0 0</pose>
      <inertial>
        <pose frame=''>0.011682 -0.051355 -0.000577 0 -0 0</pose>
        <mass>1.221</mass>
        <inertia>
          <ixx>1.23288</ixx>
          <ixy>0.000161724</ixy>
          <ixz>-4.09406e-06</ixz>
          <iyy>1.2322</iyy>
          <iyz>-5.17611e-06</iyz>
          <izz>1.23276</izz>
        </inertia>
      </inertial>
      <visual name='base_link_fixed_joint_lump__left_palm_visual'>
        <pose frame=''>0.016 -0.0625 -0 1.5708 -0 1.5708</pose>
        <geometry>
          <mesh>
            <scale>1 1 1</scale>
            <uri>model://icub_with_hands/meshes/left_palm.dae</uri>
          </mesh>
        </geometry>
      </visual>
      <visual name='base_link_fixed_joint_lump__lindexbase_visual_1'>
        <pose frame=''>0.01225 -0.0643 -0.027 -1.4749 -0.072507 -1.57079</pose>
        <geometry>
          <mesh>
            <scale>1 1 1</scale>
            <uri>model://icub_with_hands/meshes/lindexbase.dae</uri>
          </mesh>
        </geometry>
      </visual>
      <visual name='base_link_fixed_joint_lump__lail0_visual_2'>
        <pose frame=''>0.01225 -0.075498 -0.027259 0.0959 0.017493 -1.57079</pose>
        <geometry>
          <mesh>
            <scale>1 1 1</scale>
            <uri>model://icub_with_hands/meshes/lail0.dae</uri>
          </mesh>
        </geometry>
      </visual>
      <visual name='base_link_fixed_joint_lump__llittlebase_visual_3'>
        <pose frame=''>0.0135 -0.06225 0.02475 -1.6581 -0.017493 -1.57079</pose>
        <geometry>
          <mesh>
            <scale>1 1 1</scale>
            <uri>model://icub_with_hands/meshes/llittlebase.dae</uri>
          </mesh>
        </geometry>
      </visual>
      <visual name='base_link_fixed_joint_lump__llil0_visual_4'>
        <pose frame=''>0.0135 -0.077048 0.025009 -0.0873 -0.017493 -1.57079</pose>
        <geometry>
          <mesh>
            <scale>1 1 1</scale>
            <uri>model://icub_with_hands/meshes/llil0.dae</uri>
          </mesh>
        </geometry>
      </visual>
      <visual name='base_link_fixed_joint_lump__lmiddlebase_visual_5'>
        <pose frame=''>0.011 -0.0653 -0.01 -1.5708 7e-06 -1.57079</pose>
        <geometry>
          <mesh>
            <scale>1 1 1</scale>
            <uri>model://icub_with_hands/meshes/lmiddlebase.dae</uri>
          </mesh>
        </geometry>
      </visual>
      <visual name='base_link_fixed_joint_lump__lml0_visual_6'>
        <pose frame=''>0.011 -0.0803 -0.01 -0 7e-06 -1.57079</pose>
        <geometry>
          <mesh>
            <scale>1 1 1</scale>
            <uri>model://icub_with_hands/meshes/lml0.dae</uri>
          </mesh>
        </geometry>
      </visual>
      <visual name='base_link_fixed_joint_lump__lringbase_visual_7'>
        <pose frame=''>0.01175 -0.06415 0.0059 -1.6581 -0.008693 -1.57079</pose>
        <geometry>
          <mesh>
            <scale>1 1 1</scale>
            <uri>model://icub_with_hands/meshes/lringbase.dae</uri>
          </mesh>
        </geometry>
      </visual>
      <visual name='base_link_fixed_joint_lump__lril0_visual_8'>
        <pose frame=''>0.01175 -0.078949 0.006029 -0.0873 -0.008693 -1.57079</pose>
        <geometry>
          <mesh>
            <scale>1 1 1</scale>
            <uri>model://icub_with_hands/meshes/lril0.dae</uri>
          </mesh>
        </geometry>
      </visual>
    </link>
    <link name='lail1'>
      <pose frame=''>0.01225 -0.075498 -0.027259 0.0959 0.017493 -1.57079</pose>
      <inertial>
        <pose frame=''>0 0 0 0 -0 0</pose>
        <mass>0.111</mass>
        <inertia>
          <ixx>0.112</ixx>
          <ixy>0</ixy>
          <ixz>0</ixz>
          <iyy>0.112</iyy>
          <iyz>0</iyz>
          <izz>0.112</izz>
        </inertia>
      </inertial>
      <visual name='lail1_visual'>
        <pose frame=''>0.0259 0 0 0 -0 0</pose>
        <geometry>
          <mesh>
            <scale>1 1 1</scale>
            <uri>model://icub_with_hands/meshes/lail1.dae</uri>
          </mesh>
        </geometry>
      </visual>
    </link>
    <joint name='laij3' type='revolute'>
      <child>lail1</child>
      <parent>base_link</parent>
      <axis>
        <xyz>-0.095753 -0.017412 0.995253</xyz>
        <limit>
          <lower>0</lower>
          <upper>1.5708</upper>
          <effort>1000</effort>
          <velocity>0.5</velocity>
        </limit>
        <dynamics>
          <spring_reference>0</spring_reference>
          <spring_stiffness>0</spring_stiffness>
        </dynamics>
        <use_parent_model_frame>1</use_parent_model_frame>
      </axis>
    </joint>
    <link name='lail2'>
      <pose frame=''>0.01225 -0.101394 -0.027712 0.0959 0.017493 -1.57079</pose>
      <inertial>
        <pose frame=''>0 0 0 0 -0 0</pose>
        <mass>0.111</mass>
        <inertia>
          <ixx>0.112</ixx>
          <ixy>0</ixy>
          <ixz>0</ixz>
          <iyy>0.112</iyy>
          <iyz>0</iyz>
          <izz>0.112</izz>
        </inertia>
      </inertial>
      <visual name='lail2_visual'>
        <pose frame=''>0.022 0 0 0 -0 0</pose>
        <geometry>
          <mesh>
            <scale>1 1 1</scale>
            <uri>model://icub_with_hands/meshes/lail2.dae</uri>
          </mesh>
        </geometry>
      </visual>
    </link>
    <joint name='laij4' type='revolute'>
      <child>lail2</child>
      <parent>lail1</parent>
      <axis>
        <xyz>-0.095753 -0.017412 0.995253</xyz>
        <limit>
          <lower>0</lower>
          <upper>1.5708</upper>
          <effort>1000</effort>
          <velocity>0.5</velocity>
        </limit>
        <dynamics>
          <spring_reference>0</spring_reference>
          <spring_stiffness>0</spring_stiffness>
        </dynamics>
        <use_parent_model_frame>1</use_parent_model_frame>
      </axis>
    </joint>
    <link name='lail3'>
      <pose frame=''>0.01225 -0.12339 -0.028097 0.0959 0.017493 -1.57079</pose>
      <inertial>
        <pose frame=''>0 0 0 0 -0 0</pose>
        <mass>0.111</mass>
        <inertia>
          <ixx>0.112</ixx>
          <ixy>0</ixy>
          <ixz>0</ixz>
          <iyy>0.112</iyy>
          <iyz>0</iyz>
          <izz>0.112</izz>
        </inertia>
      </inertial>
      <visual name='lail3_visual'>
        <pose frame=''>0.0168 0 0 -1.5708 0 0</pose>
        <geometry>
          <mesh>
            <scale>1 1 1</scale>
            <uri>model://icub_with_hands/meshes/lail3.dae</uri>
          </mesh>
        </geometry>
      </visual>
    </link>
    <joint name='laij5' type='revolute'>
      <child>lail3</child>
      <parent>lail2</parent>
      <axis>
        <xyz>-0.095753 -0.017412 0.995253</xyz>
        <limit>
          <lower>0</lower>
          <upper>1.5708</upper>
          <effort>1000</effort>
          <velocity>0.5</velocity>
        </limit>
        <dynamics>
          <spring_reference>0</spring_reference>
          <spring_stiffness>0</spring_stiffness>
        </dynamics>
        <use_parent_model_frame>1</use_parent_model_frame>
      </axis>
    </joint>
    <link name='llil1'>
      <pose frame=''>0.0135 -0.077048 0.025009 -0.0873 -0.017493 -1.57079</pose>
      <inertial>
        <pose frame=''>0 0 0 0 -0 0</pose>
        <mass>0.111</mass>
        <inertia>
          <ixx>0.112</ixx>
          <ixy>0</ixy>
          <ixz>0</ixz>
          <iyy>0.112</iyy>
          <iyz>0</iyz>
          <izz>0.112</izz>
        </inertia>
      </inertial>
      <visual name='llil1_visual'>
        <pose frame=''>0.0218 0 0 0 -0 0</pose>
        <geometry>
          <mesh>
            <scale>1 1 1</scale>
            <uri>model://icub_with_hands/meshes/llil1.dae</uri>
          </mesh>
        </geometry>
      </visual>
    </link>
    <joint name='llij3' type='revolute'>
      <child>llil1</child>
      <parent>base_link</parent>
      <axis>
        <xyz>0.087189 0.017426 0.996039</xyz>
        <limit>
          <lower>0</lower>
          <upper>1.5708</upper>
          <effort>1000</effort>
          <velocity>0.5</velocity>
        </limit>
        <dynamics>
          <spring_reference>0</spring_reference>
          <spring_stiffness>0</spring_stiffness>
        </dynamics>
        <use_parent_model_frame>1</use_parent_model_frame>
      </axis>
    </joint>
    <link name='llil2'>
      <pose frame=''>0.013501 -0.098844 0.02539 -0.0873 -0.017493 -1.57079</pose>
      <inertial>
        <pose frame=''>0 0 0 0 -0 0</pose>
        <mass>0.111</mass>
        <inertia>
          <ixx>0.112</ixx>
          <ixy>0</ixy>
          <ixz>0</ixz>
          <iyy>0.112</iyy>
          <iyz>0</iyz>
          <izz>0.112</izz>
        </inertia>
      </inertial>
      <visual name='llil2_visual'>
        <pose frame=''>0.019 0 0 0 -0 0</pose>
        <geometry>
          <mesh>
            <scale>1 1 1</scale>
            <uri>model://icub_with_hands/meshes/llil2.dae</uri>
          </mesh>
        </geometry>
      </visual>
    </link>
    <joint name='llij4' type='revolute'>
      <child>llil2</child>
      <parent>llil1</parent>
      <axis>
        <xyz>0.087189 0.017426 0.996039</xyz>
        <limit>
          <lower>0</lower>
          <upper>1.5708</upper>
          <effort>1000</effort>
          <velocity>0.5</velocity>
        </limit>
        <dynamics>
          <spring_reference>0</spring_reference>
          <spring_stiffness>0</spring_stiffness>
        </dynamics>
        <use_parent_model_frame>1</use_parent_model_frame>
      </axis>
    </joint>
    <link name='llil3'>
      <pose frame=''>0.013501 -0.117841 0.025723 -0.0873 -0.017493 -1.57079</pose>
      <inertial>
        <pose frame=''>0 0 0 0 -0 0</pose>
        <mass>0.111</mass>
        <inertia>
          <ixx>0.112</ixx>
          <ixy>0</ixy>
          <ixz>0</ixz>
          <iyy>0.112</iyy>
          <iyz>0</iyz>
          <izz>0.112</izz>
        </inertia>
      </inertial>
      <visual name='llil3_visual'>
        <pose frame=''>0.0168 0 0 -1.5708 0 0</pose>
        <geometry>
          <mesh>
            <scale>1 1 1</scale>
            <uri>model://icub_with_hands/meshes/llil3.dae</uri>
          </mesh>
        </geometry>
      </visual>
    </link>
    <joint name='llij5' type='revolute'>
      <child>llil3</child>
      <parent>llil2</parent>
      <axis>
        <xyz>0.087189 0.017426 0.996039</xyz>
        <limit>
          <lower>0</lower>
          <upper>1.5708</upper>
          <effort>1000</effort>
          <velocity>0.5</velocity>
        </limit>
        <dynamics>
          <spring_reference>0</spring_reference>
          <spring_stiffness>0</spring_stiffness>
        </dynamics>
        <use_parent_model_frame>1</use_parent_model_frame>
      </axis>
    </joint>
    <link name='lml1'>
      <pose frame=''>0.011 -0.0803 -0.01 -0 7e-06 -1.57079</pose>
      <inertial>
        <pose frame=''>0 0 0 0 -0 0</pose>
        <mass>0.111</mass>
        <inertia>
          <ixx>0.112</ixx>
          <ixy>0</ixy>
          <ixz>0</ixz>
          <iyy>0.112</iyy>
          <iyz>0</iyz>
          <izz>0.112</izz>
        </inertia>
      </inertial>
      <visual name='lml1_visual'>
        <pose frame=''>0.0285 0 0 0 -0 0</pose>
        <geometry>
          <mesh>
            <scale>1 1 1</scale>
            <uri>model://icub_with_hands/meshes/lml1.dae</uri>
          </mesh>
        </geometry>
      </visual>
    </link>
    <joint name='lmj3' type='revolute'>
      <child>lml1</child>
      <parent>base_link</parent>
      <axis>
        <xyz>0 -7e-06 1</xyz>
        <limit>
          <lower>0</lower>
          <upper>1.5708</upper>
          <effort>1000</effort>
          <velocity>0.5</velocity>
        </limit>
        <dynamics>
          <spring_reference>0</spring_reference>
          <spring_stiffness>0</spring_stiffness>
        </dynamics>
        <use_parent_model_frame>1</use_parent_model_frame>
      </axis>
    </joint>
    <link name='lml2'>
      <pose frame=''>0.011 -0.1088 -0.01 -0 7e-06 -1.57079</pose>
      <inertial>
        <pose frame=''>0 0 0 0 -0 0</pose>
        <mass>0.111</mass>
        <inertia>
          <ixx>0.112</ixx>
          <ixy>0</ixy>
          <ixz>0</ixz>
          <iyy>0.112</iyy>
          <iyz>0</iyz>
          <izz>0.112</izz>
        </inertia>
      </inertial>
      <visual name='lml2_visual'>
        <pose frame=''>0.024 0 0 0 -0 0</pose>
        <geometry>
          <mesh>
            <scale>1 1 1</scale>
            <uri>model://icub_with_hands/meshes/lml2.dae</uri>
          </mesh>
        </geometry>
      </visual>
    </link>
    <joint name='lmj4' type='revolute'>
      <child>lml2</child>
      <parent>lml1</parent>
      <axis>
        <xyz>0 -7e-06 1</xyz>
        <limit>
          <lower>0</lower>
          <upper>1.5708</upper>
          <effort>1000</effort>
          <velocity>0.5</velocity>
        </limit>
        <dynamics>
          <spring_reference>0</spring_reference>
          <spring_stiffness>0</spring_stiffness>
        </dynamics>
        <use_parent_model_frame>1</use_parent_model_frame>
      </axis>
    </joint>
    <link name='lml3'>
      <pose frame=''>0.011001 -0.1328 -0.010001 -0 7e-06 -1.57079</pose>
      <inertial>
        <pose frame=''>0 0 0 0 -0 0</pose>
        <mass>0.111</mass>
        <inertia>
          <ixx>0.112</ixx>
          <ixy>0</ixy>
          <ixz>0</ixz>
          <iyy>0.112</iyy>
          <iyz>0</iyz>
          <izz>0.112</izz>
        </inertia>
      </inertial>
      <visual name='lml3_visual'>
        <pose frame=''>0.0168 0 0 -1.5708 0 0</pose>
        <geometry>
          <mesh>
            <scale>1 1 1</scale>
            <uri>model://icub_with_hands/meshes/lml3.dae</uri>
          </mesh>
        </geometry>
      </visual>
    </link>
    <joint name='lmj5' type='revolute'>
      <child>lml3</child>
      <parent>lml2</parent>
      <axis>
        <xyz>0 -7e-06 1</xyz>
        <limit>
          <lower>0</lower>
          <upper>1.5708</upper>
          <effort>1000</effort>
          <velocity>0.5</velocity>
        </limit>
        <dynamics>
          <spring_reference>0</spring_reference>
          <spring_stiffness>0</spring_stiffness>
        </dynamics>
        <use_parent_model_frame>1</use_parent_model_frame>
      </axis>
    </joint>
    <link name='lril1'>
      <pose frame=''>0.01175 -0.078949 0.006029 -0.0873 -0.008693 -1.57079</pose>
      <inertial>
        <pose frame=''>0 0 0 0 -0 0</pose>
        <mass>0.111</mass>
        <inertia>
          <ixx>0.112</ixx>
          <ixy>0</ixy>
          <ixz>0</ixz>
          <iyy>0.112</iyy>
          <iyz>0</iyz>
          <izz>0.112</izz>
        </inertia>
      </inertial>
      <visual name='lril1_visual'>
        <pose frame=''>0.0259 0 0 0 -0 0</pose>
        <geometry>
          <mesh>
            <scale>1 1 1</scale>
            <uri>model://icub_with_hands/meshes/lril1.dae</uri>
          </mesh>
        </geometry>
      </visual>
    </link>
    <joint name='lrij3' type='revolute'>
      <child>lril1</child>
      <parent>base_link</parent>
      <axis>
        <xyz>0.087189 0.00866 0.996154</xyz>
        <limit>
          <lower>0</lower>
          <upper>1.5708</upper>
          <effort>1000</effort>
          <velocity>0.5</velocity>
        </limit>
        <dynamics>
          <spring_reference>0</spring_reference>
          <spring_stiffness>0</spring_stiffness>
        </dynamics>
        <use_parent_model_frame>1</use_parent_model_frame>
      </axis>
    </joint>
    <link name='lril2'>
      <pose frame=''>0.01175 -0.104848 0.006254 -0.0873 -0.008693 -1.57079</pose>
      <inertial>
        <pose frame=''>0 0 0 0 -0 0</pose>
        <mass>0.111</mass>
        <inertia>
          <ixx>0.112</ixx>
          <ixy>0</ixy>
          <ixz>0</ixz>
          <iyy>0.112</iyy>
          <iyz>0</iyz>
          <izz>0.112</izz>
        </inertia>
      </inertial>
      <visual name='lril2_visual'>
        <pose frame=''>0.022 0 0 0 -0 0</pose>
        <geometry>
          <mesh>
            <scale>1 1 1</scale>
            <uri>model://icub_with_hands/meshes/lril2.dae</uri>
          </mesh>
        </geometry>
      </visual>
    </link>
    <joint name='lrij4' type='revolute'>
      <child>lril2</child>
      <parent>lril1</parent>
      <axis>
        <xyz>0.087189 0.00866 0.996154</xyz>
        <limit>
          <lower>0</lower>
          <upper>1.5708</upper>
          <effort>1000</effort>
          <velocity>0.5</velocity>
        </limit>
        <dynamics>
          <spring_reference>0</spring_reference>
          <spring_stiffness>0</spring_stiffness>
        </dynamics>
        <use_parent_model_frame>1</use_parent_model_frame>
      </axis>
    </joint>
    <link name='lril3'>
      <pose frame=''>0.011751 -0.126848 0.006445 -0.0873 -0.008693 -1.57079</pose>
      <inertial>
        <pose frame=''>0 0 0 0 -0 0</pose>
        <mass>0.111</mass>
        <inertia>
          <ixx>0.112</ixx>
          <ixy>0</ixy>
          <ixz>0</ixz>
          <iyy>0.112</iyy>
          <iyz>0</iyz>
          <izz>0.112</izz>
        </inertia>
      </inertial>
      <visual name='lril3_visual'>
        <pose frame=''>0.0168 0 0 -1.5708 0 0</pose>
        <geometry>
          <mesh>
            <scale>1 1 1</scale>
            <uri>model://icub_with_hands/meshes/lril3.dae</uri>
          </mesh>
        </geometry>
      </visual>
    </link>
    <joint name='lrij5' type='revolute'>
      <child>lril3</child>
      <parent>lril2</parent>
      <axis>
        <xyz>0.087189 0.00866 0.996154</xyz>
        <limit>
          <lower>0</lower>
          <upper>1.5708</upper>
          <effort>1000</effort>
          <velocity>0.5</velocity>
        </limit>
        <dynamics>
          <spring_reference>0</spring_reference>
          <spring_stiffness>0</spring_stiffness>
        </dynamics>
        <use_parent_model_frame>1</use_parent_model_frame>
      </axis>
    </joint>
    <link name='ltl0'>
      <pose frame=''>0.021 -0.0386 -0.01235 -3.063 1.07329 -1.5708</pose>
      <inertial>
        <pose frame=''>0 0 0 0 -0 0</pose>
        <mass>0.222</mass>
        <inertia>
          <ixx>0.224</ixx>
          <ixy>0</ixy>
          <ixz>0</ixz>
          <iyy>0.224</iyy>
          <iyz>5.29396e-23</iyz>
          <izz>0.224</izz>
        </inertia>
      </inertial>
      <visual name='ltl0_visual'>
        <pose frame=''>0 0 0 -1.5708 0 0</pose>
        <geometry>
          <mesh>
            <scale>1 1 1</scale>
            <uri>model://icub_with_hands/meshes/ltl0.dae</uri>
          </mesh>
        </geometry>
      </visual>
      <visual name='ltl0_fixed_joint_lump__ltl1_visual_1'>
        <pose frame=''>0.021 -0.0056 0 -1.5708 0 0</pose>
        <geometry>
          <mesh>
            <scale>1 1 1</scale>
            <uri>model://icub_with_hands/meshes/ltl1.dae</uri>
          </mesh>
        </geometry>
      </visual>
    </link>
    <joint name='ltj2' type='revolute'>
      <child>ltl0</child>
      <parent>base_link</parent>
      <axis>
        <xyz>-0.078511 -0.876064 0.47576</xyz>
        <limit>
          <lower>0</lower>
          <upper>1.5708</upper>
          <effort>1000</effort>
          <velocity>0.5</velocity>
        </limit>
        <dynamics>
          <spring_reference>0</spring_reference>
          <spring_stiffness>0</spring_stiffness>
        </dynamics>
        <use_parent_model_frame>1</use_parent_model_frame>
      </axis>
    </joint>
    <link name='ltl2'>
      <pose frame=''>0.026583 -0.049008 -0.030595 1.64938 1.07329 -1.5708</pose>
      <inertial>
        <pose frame=''>0 0 0 0 -0 0</pose>
        <mass>0.111</mass>
        <inertia>
          <ixx>0.112</ixx>
          <ixy>0</ixy>
          <ixz>0</ixz>
          <iyy>0.112</iyy>
          <iyz>0</iyz>
          <izz>0.112</izz>
        </inertia>
      </inertial>
      <visual name='ltl2_visual'>
        <pose frame=''>0.026 0 0 0 -0 0</pose>
        <geometry>
          <mesh>
            <scale>1 1 1</scale>
            <uri>model://icub_with_hands/meshes/ltl2.dae</uri>
          </mesh>
        </geometry>
      </visual>
    </link>
    <joint name='ltj4' type='revolute'>
      <child>ltl2</child>
      <parent>ltl0</parent>
      <axis>
        <xyz>-0.996914 0.068991 -0.037465</xyz>
        <limit>
          <lower>0</lower>
          <upper>1.5708</upper>
          <effort>1000</effort>
          <velocity>0.5</velocity>
        </limit>
        <dynamics>
          <spring_reference>0</spring_reference>
          <spring_stiffness>0</spring_stiffness>
        </dynamics>
        <use_parent_model_frame>1</use_parent_model_frame>
      </axis>
    </joint>
    <link name='ltl3'>
      <pose frame=''>0.026583 -0.061416 -0.053443 1.64938 1.07329 -1.5708</pose>
      <inertial>
        <pose frame=''>0 0 0 0 -0 0</pose>
        <mass>0.111</mass>
        <inertia>
          <ixx>0.112</ixx>
          <ixy>0</ixy>
          <ixz>0</ixz>
          <iyy>0.112</iyy>
          <iyz>0</iyz>
          <izz>0.112</izz>
        </inertia>
      </inertial>
      <visual name='ltl3_visual'>
        <pose frame=''>0.022 0 0 0 -0 0</pose>
        <geometry>
          <mesh>
            <scale>1 1 1</scale>
            <uri>model://icub_with_hands/meshes/ltl3.dae</uri>
          </mesh>
        </geometry>
      </visual>
    </link>
    <joint name='ltj5' type='revolute'>
      <child>ltl3</child>
      <parent>ltl2</parent>
      <axis>
        <xyz>-0.996914 0.068991 -0.037465</xyz>
        <limit>
          <lower>0</lower>
          <upper>1.5708</upper>
          <effort>1000</effort>
          <velocity>0.5</velocity>
        </limit>
        <dynamics>
          <spring_reference>0</spring_reference>
          <spring_stiffness>0</spring_stiffness>
        </dynamics>
        <use_parent_model_frame>1</use_parent_model_frame>
      </axis>
    </joint>
    <link name='ltl4'>
      <pose frame=''>0.026583 -0.071915 -0.072776 1.64938 1.07329 -1.5708</pose>
      <inertial>
        <pose frame=''>0 0 0 0 -0 0</pose>
        <mass>0.111</mass>
        <inertia>
          <ixx>0.112</ixx>
          <ixy>0</ixy>
          <ixz>0</ixz>
          <iyy>0.112</iyy>
          <iyz>0</iyz>
          <izz>0.112</izz>
        </inertia>
      </inertial>
      <visual name='ltl4_visual'>
        <pose frame=''>0.0168 0 0 0 -0 0</pose>
        <geometry>
          <mesh>
            <scale>1 1 1</scale>
            <uri>model://icub_with_hands/meshes/ltl4.dae</uri>
          </mesh>
        </geometry>
      </visual>
    </link>
    <joint name='ltj6' type='revolute'>
      <child>ltl4</child>
      <parent>ltl3</parent>
      <axis>
        <xyz>-0.996914 0.068991 -0.037465</xyz>
        <limit>
          <lower>0</lower>
          <upper>1.5708</upper>
          <effort>1000</effort>
          <velocity>0.5</velocity>
        </limit>
        <dynamics>
          <spring_reference>0</spring_reference>
          <spring_stiffness>0</spring_stiffness>
        </dynamics>
        <use_parent_model_frame>1</use_parent_model_frame>
      </axis>
    </joint>
  </model>
</sdf>
