<?xml version="1.0"?>
<robot name="ICub">


   <link name="base_link">
      <origin rpy="0 0 0" xyz="0 0 0"/>
    <inertial>
      <origin xyz="0 0 0" rpy="0 0 0"/>
      <mass value="0.111"/>
      <inertia
        ixx="0.112" ixy="0.0" ixz="0.0"
        iyy="0.112" iyz="0.0"
        izz="0.112"/>
    </inertial>
   </link>


<!-- RIGHT HAND -->

   <link name="right_palm">
      <visual>
      <origin rpy="0 0 3.1416" xyz="-0.0625 0 0.016"/>
         <geometry>
	    <mesh filename="package://icub_with_hands/meshes/right_palm.dae"/>
         </geometry>
      </visual>
    <inertial>
      <origin xyz="0 0 0" rpy="0 0 0"/>
      <mass value="0.111"/>
      <inertia
        ixx="0.112" ixy="0.0" ixz="0.0"
        iyy="0.112" iyz="0.0"
        izz="0.112"/>
    </inertial>
   </link>

   <link name="thumbbase">
    <inertial>
      <origin xyz="0 0 0" rpy="0 0 0"/>
      <mass value="0.111"/>
      <inertia
        ixx="0.112" ixy="0.0" ixz="0.0"
        iyy="0.112" iyz="0.0"
        izz="0.112"/>
    </inertial>
   </link>

   <link name="tl0">
      <visual>
      <origin rpy="-1.5708 0 0" xyz="0 0 0"/>
         <geometry>
	    <mesh filename="package://icub_with_hands/meshes/tl0.dae"/>
         </geometry>
      </visual>
    <inertial>
      <origin xyz="0 0 0" rpy="0 0 0"/>
      <mass value="0.111"/>
      <inertia
        ixx="0.112" ixy="0.0" ixz="0.0"
        iyy="0.112" iyz="0.0"
        izz="0.112"/>
    </inertial>
   </link>

   <link name="tl1">
      <visual>
      <origin rpy="0 0 0" xyz="0.021 0 0.0056"/>
         <geometry>
	    <mesh filename="package://icub_with_hands/meshes/tl1.dae"/>
         </geometry>
      </visual>
    <inertial>
      <origin xyz="0 0 0" rpy="0 0 0"/>
      <mass value="0.111"/>
      <inertia
        ixx="0.112" ixy="0.0" ixz="0.0"
        iyy="0.112" iyz="0.0"
        izz="0.112"/>
    </inertial>
   </link>

   <link name="tl2">
      <visual>
      <origin rpy="0 0 0" xyz="0.026 0 0"/>
         <geometry>
	    <mesh filename="package://icub_with_hands/meshes/tl2.dae"/>
         </geometry>
      </visual>
    <inertial>
      <origin xyz="0 0 0" rpy="0 0 0"/>
      <mass value="0.111"/>
      <inertia
        ixx="0.112" ixy="0.0" ixz="0.0"
        iyy="0.112" iyz="0.0"
        izz="0.112"/>
    </inertial>
   </link>

   <link name="tl3">
      <visual>
      <origin rpy="0 0 0" xyz="0.022 0 0"/>
         <geometry>
	    <mesh filename="package://icub_with_hands/meshes/tl3.dae"/>
         </geometry>
      </visual>
    <inertial>
      <origin xyz="0 0 0" rpy="0 0 0"/>
      <mass value="0.111"/>
      <inertia
        ixx="0.112" ixy="0.0" ixz="0.0"
        iyy="0.112" iyz="0.0"
        izz="0.112"/>
    </inertial>
   </link>

   <link name="tl4">
      <visual>
      <origin rpy="0 0 0" xyz="0.0168 0 0"/>
         <geometry>
	    <mesh filename="package://icub_with_hands/meshes/tl4.dae"/>
         </geometry>
      </visual>
    <inertial>
      <origin xyz="0 0 0" rpy="0 0 0"/>
      <mass value="0.111"/>
      <inertia
        ixx="0.112" ixy="0.0" ixz="0.0"
        iyy="0.112" iyz="0.0"
        izz="0.112"/>
    </inertial>
   </link>

   <link name="indexbase">
      <visual>
      <origin rpy="0.0959 0 0.0175" xyz="0.0018 -0.027 -0.00375"/>
         <geometry>
	    <mesh filename="package://icub_with_hands/meshes/indexbase.dae"/>
         </geometry>
      </visual>
    <inertial>
      <origin xyz="0 0 0" rpy="0 0 0"/>
      <mass value="0.111"/>
      <inertia
        ixx="0.112" ixy="0.0" ixz="0.0"
        iyy="0.112" iyz="0.0"
        izz="0.112"/>
    </inertial>
   </link>

   <link name="il0">
      <visual>
      <origin rpy="1.5708 0 0" xyz="0.0148 0 0"/>
         <geometry>
	    <mesh filename="package://icub_with_hands/meshes/il0.dae"/>
         </geometry>
      </visual>
    <inertial>
      <origin xyz="0 0 0" rpy="0 0 0"/>
      <mass value="0.111"/>
      <inertia
        ixx="0.112" ixy="0.0" ixz="0.0"
        iyy="0.112" iyz="0.0"
        izz="0.112"/>
    </inertial>
   </link>

   <link name="il1">
      <visual>
      <origin rpy="0 0 0" xyz="0.0259 0 0"/>
         <geometry>
	    <mesh filename="package://icub_with_hands/meshes/il1.dae"/>
         </geometry>
      </visual>
    <inertial>
      <origin xyz="0 0 0" rpy="0 0 0"/>
      <mass value="0.111"/>
      <inertia
        ixx="0.112" ixy="0.0" ixz="0.0"
        iyy="0.112" iyz="0.0"
        izz="0.112"/>
    </inertial>
   </link>

   <link name="il2">
      <visual>
      <origin rpy="0 0 0" xyz="0.022 0 0"/>
         <geometry>
	    <mesh filename="package://icub_with_hands/meshes/il2.dae"/>
         </geometry>
      </visual>
    <inertial>
      <origin xyz="0 0 0" rpy="0 0 0"/>
      <mass value="0.111"/>
      <inertia
        ixx="0.112" ixy="0.0" ixz="0.0"
        iyy="0.112" iyz="0.0"
        izz="0.112"/>
    </inertial>
   </link>

   <link name="il3">
      <visual>
      <origin rpy="-1.5708 0 0" xyz="0.0168 0 0"/>
         <geometry>
	    <mesh filename="package://icub_with_hands/meshes/il3.dae"/>
         </geometry>
      </visual>
    <inertial>
      <origin xyz="0 0 0" rpy="0 0 0"/>
      <mass value="0.111"/>
      <inertia
        ixx="0.112" ixy="0.0" ixz="0.0"
        iyy="0.112" iyz="0.0"
        izz="0.112"/>
    </inertial>
   </link>

   <link name="middlebase">
      <visual>
      <origin rpy="0 0 0" xyz="0.0028 -0.01 -0.005"/>
         <geometry>
	    <mesh filename="package://icub_with_hands/meshes/middlebase.dae"/>
         </geometry>
      </visual>
    <inertial>
      <origin xyz="0 0 0" rpy="0 0 0"/>
      <mass value="0.111"/>
      <inertia
        ixx="0.112" ixy="0.0" ixz="0.0"
        iyy="0.112" iyz="0.0"
        izz="0.112"/>
    </inertial>
   </link>

   <link name="ml0">
      <visual>
      <origin rpy="1.5708 0 0" xyz="0.015 0 0"/>
         <geometry>
	    <mesh filename="package://icub_with_hands/meshes/ml0.dae"/>
         </geometry>
      </visual>
    <inertial>
      <origin xyz="0 0 0" rpy="0 0 0"/>
      <mass value="0.111"/>
      <inertia
        ixx="0.112" ixy="0.0" ixz="0.0"
        iyy="0.112" iyz="0.0"
        izz="0.112"/>
    </inertial>
   </link>

   <link name="ml1">
      <visual>
      <origin rpy="0 0 0" xyz="0.0285 0 0"/>
         <geometry>
	    <mesh filename="package://icub_with_hands/meshes/ml1.dae"/>
         </geometry>
      </visual>
    <inertial>
      <origin xyz="0 0 0" rpy="0 0 0"/>
      <mass value="0.111"/>
      <inertia
        ixx="0.112" ixy="0.0" ixz="0.0"
        iyy="0.112" iyz="0.0"
        izz="0.112"/>
    </inertial>
   </link>

   <link name="ml2">
      <visual>
      <origin rpy="0 0 0" xyz="0.0240 0 0"/>
         <geometry>
	    <mesh filename="package://icub_with_hands/meshes/ml2.dae"/>
         </geometry>
      </visual>
    <inertial>
      <origin xyz="0 0 0" rpy="0 0 0"/>
      <mass value="0.111"/>
      <inertia
        ixx="0.112" ixy="0.0" ixz="0.0"
        iyy="0.112" iyz="0.0"
        izz="0.112"/>
    </inertial>
   </link>

   <link name="ml3">
      <visual>
      <origin rpy="-1.5708 0 0" xyz="0.0168 0 0"/>
         <geometry>
	    <mesh filename="package://icub_with_hands/meshes/ml3.dae"/>
         </geometry>
      </visual>
    <inertial>
      <origin xyz="0 0 0" rpy="0 0 0"/>
      <mass value="0.111"/>
      <inertia
        ixx="0.112" ixy="0.0" ixz="0.0"
        iyy="0.112" iyz="0.0"
        izz="0.112"/>
    </inertial>
   </link>

   <link name="ringbase">
      <visual>
      <origin rpy="0.0873 0 0.0087" xyz="0.00165 0.0059 -0.00425"/>
         <geometry>
	    <mesh filename="package://icub_with_hands/meshes/ringbase.dae"/>
         </geometry>
      </visual>
    <inertial>
      <origin xyz="0 0 0" rpy="0 0 0"/>
      <mass value="0.111"/>
      <inertia
        ixx="0.112" ixy="0.0" ixz="0.0"
        iyy="0.112" iyz="0.0"
        izz="0.112"/>
    </inertial>
   </link>

   <link name="ril0">
      <visual>
      <origin rpy="1.5708 0 0" xyz="0.0148 0 0"/>
         <geometry>
	    <mesh filename="package://icub_with_hands/meshes/ril0.dae"/>
         </geometry>
      </visual>
    <inertial>
      <origin xyz="0 0 0" rpy="0 0 0"/>
      <mass value="0.111"/>
      <inertia
        ixx="0.112" ixy="0.0" ixz="0.0"
        iyy="0.112" iyz="0.0"
        izz="0.112"/>
    </inertial>
   </link>

   <link name="ril1">
      <visual>
      <origin rpy="0 0 0" xyz="0.0259 0 0"/>
         <geometry>
	    <mesh filename="package://icub_with_hands/meshes/ril1.dae"/>
         </geometry>
      </visual>
    <inertial>
      <origin xyz="0 0 0" rpy="0 0 0"/>
      <mass value="0.111"/>
      <inertia
        ixx="0.112" ixy="0.0" ixz="0.0"
        iyy="0.112" iyz="0.0"
        izz="0.112"/>
    </inertial>
   </link>

   <link name="ril2">
      <visual>
      <origin rpy="0 0 0" xyz="0.022 0 0"/>
         <geometry>
	    <mesh filename="package://icub_with_hands/meshes/ril2.dae"/>
         </geometry>
      </visual>
    <inertial>
      <origin xyz="0 0 0" rpy="0 0 0"/>
      <mass value="0.111"/>
      <inertia
        ixx="0.112" ixy="0.0" ixz="0.0"
        iyy="0.112" iyz="0.0"
        izz="0.112"/>
    </inertial>
   </link>

   <link name="ril3">
      <visual>
      <origin rpy="-1.5708 0 0" xyz="0.0168 0 0"/>
         <geometry>
	    <mesh filename="package://icub_with_hands/meshes/ril3.dae"/>
         </geometry>
      </visual>
    <inertial>
      <origin xyz="0 0 0" rpy="0 0 0"/>
      <mass value="0.111"/>
      <inertia
        ixx="0.112" ixy="0.0" ixz="0.0"
        iyy="0.112" iyz="0.0"
        izz="0.112"/>
    </inertial>
   </link>

   <link name="littlebase">
      <visual>
      <origin rpy="0.0873 0 0.0175" xyz="-0.00025 0.02475 -0.0025"/>
         <geometry>
	    <mesh filename="package://icub_with_hands/meshes/littlebase.dae"/>
         </geometry>
      </visual>
    <inertial>
      <origin xyz="0 0 0" rpy="0 0 0"/>
      <mass value="0.111"/>
      <inertia
        ixx="0.112" ixy="0.0" ixz="0.0"
        iyy="0.112" iyz="0.0"
        izz="0.112"/>
    </inertial>
   </link>

   <link name="lil0">
      <visual>
      <origin rpy="1.5708 0 0" xyz="0.0148 0 0"/>
         <geometry>
	    <mesh filename="package://icub_with_hands/meshes/lil0.dae"/>
         </geometry>
      </visual>
    <inertial>
      <origin xyz="0 0 0" rpy="0 0 0"/>
      <mass value="0.111"/>
      <inertia
        ixx="0.112" ixy="0.0" ixz="0.0"
        iyy="0.112" iyz="0.0"
        izz="0.112"/>
    </inertial>
   </link>

   <link name="lil1">
      <visual>
      <origin rpy="0 0 0" xyz="0.0218 0 0"/>
         <geometry>
	    <mesh filename="package://icub_with_hands/meshes/lil1.dae"/>
         </geometry>
      </visual>
    <inertial>
      <origin xyz="0 0 0" rpy="0 0 0"/>
      <mass value="0.111"/>
      <inertia
        ixx="0.112" ixy="0.0" ixz="0.0"
        iyy="0.112" iyz="0.0"
        izz="0.112"/>
    </inertial>
   </link>

   <link name="lil2">
      <visual>
      <origin rpy="0 0 0" xyz="0.019 0 0"/>
         <geometry>
	    <mesh filename="package://icub_with_hands/meshes/lil2.dae"/>
         </geometry>
      </visual>
    <inertial>
      <origin xyz="0 0 0" rpy="0 0 0"/>
      <mass value="0.111"/>
      <inertia
        ixx="0.112" ixy="0.0" ixz="0.0"
        iyy="0.112" iyz="0.0"
        izz="0.112"/>
    </inertial>
   </link>

   <link name="lil3">
      <visual>
      <origin rpy="-1.5708 0 0" xyz="0.0168 0 0"/>
         <geometry>
	    <mesh filename="package://icub_with_hands/meshes/lil3.dae"/>
         </geometry>
      </visual>
    <inertial>
      <origin xyz="0 0 0" rpy="0 0 0"/>
      <mass value="0.111"/>
      <inertia
        ixx="0.112" ixy="0.0" ixz="0.0"
        iyy="0.112" iyz="0.0"
        izz="0.112"/>
    </inertial>
   </link>

	
<!-- ########################################################## JOINTS #########################################################
##################################################################################################################
##################################################################################################################
##################################################################################################################
##################################################################################################################
##################################################################################################################
################################################################################################################## -->

<!-- RIGHT HAND -->

   <joint name="right_wrist_yaw" type="fixed">
      <axis xyz="0 0 1"/>
      <limit effort="1000.0" lower="-0.3491" upper="0.6981" velocity="0.5"/>
      <parent link="base_link"/>
      <child link="right_palm"/>
      <origin rpy="1.5708 0 1.5708" xyz="0 0 0"/>
   </joint>

   <joint name="tj1" type="fixed">
      <parent link="right_palm"/>
      <child link="thumbbase"/>
      <origin rpy="0 0 3.1416" xyz="-0.0625 0 0.016"/>
   </joint>

   <joint name="tj2" type="revolute">
      <axis xyz="0 0 1"/>
      <limit effort="1000.0" lower="0" upper="1.5708" velocity="0.5"/>
      <parent link="thumbbase"/>
      <child link="tl0"/>
      <origin rpy="1.4922 0 -1.0733" xyz="-0.0239 -0.01235 0.005"/>
   </joint>

   <joint name="tj3" type="fixed">
      <parent link="tl0"/>
      <child link="tl1"/>
      <origin rpy="-1.5708 0 0" xyz="0 0 0"/>
   </joint>

   <joint name="tj4" type="revolute">
      <axis xyz="0 0 1"/>
      <limit effort="1000.0" lower="0" upper="1.5708" velocity="0.5"/>
      <parent link="tl1"/>
      <child link="tl2"/>
      <origin rpy="0 0 0" xyz="0.021 0 0.0056"/>
   </joint>

   <joint name="tj5" type="revolute">
      <axis xyz="0 0 1"/>
      <limit effort="1000.0" lower="0" upper="1.5708" velocity="0.5"/>
      <parent link="tl2"/>
      <child link="tl3"/>
      <origin rpy="0 0 0" xyz="0.026 0 0"/>
   </joint>

   <joint name="tj6" type="revolute">
      <axis xyz="0 0 1"/>
      <limit effort="1000.0" lower="0" upper="1.5708" velocity="0.5"/>
      <parent link="tl3"/>
      <child link="tl4"/>
      <origin rpy="0 0 0" xyz="0.022 0 0"/>
   </joint>

   <joint name="ij1" type="fixed">
      <parent link="right_palm"/>
      <child link="indexbase"/>
      <origin rpy="0 0 3.1416" xyz="-0.0625 0 0.016"/>
   </joint>

   <joint name="ij2" type="fixed">
      <parent link="indexbase"/>
      <child link="il0"/>
      <origin rpy="0.0959 0 0.0175" xyz="0.0018 -0.027 -0.00375"/>
   </joint>

   <joint name="ij3" type="revolute">
      <axis xyz="0 0 1"/>
      <limit effort="1000.0" lower="0" upper="1.5708" velocity="0.5"/>
      <parent link="il0"/>
      <child link="il1"/>
      <origin rpy="1.5708 0 0" xyz="0.0148 0 0"/>
   </joint>

   <joint name="ij4" type="revolute">
      <axis xyz="0 0 1"/>
      <limit effort="1000.0" lower="0" upper="1.5708" velocity="0.5"/>
      <parent link="il1"/>
      <child link="il2"/>
      <origin rpy="0 0 0" xyz="0.0259 0 0"/>
   </joint>

   <joint name="ij5" type="revolute">
      <axis xyz="0 0 1"/>
      <limit effort="1000.0" lower="0" upper="1.5708" velocity="0.5"/>
      <parent link="il2"/>
      <child link="il3"/>
      <origin rpy="0 0 0" xyz="0.022 0 0"/>
   </joint>

   <joint name="mj1" type="fixed">
      <parent link="right_palm"/>
      <child link="middlebase"/>
      <origin rpy="0 0 3.1416" xyz="-0.0625 0 0.016"/>
   </joint>

   <joint name="mj2" type="fixed">
      <parent link="middlebase"/>
      <child link="ml0"/>
      <origin rpy="0 0 0" xyz="0.0028 -0.01 -0.005"/>
   </joint>

   <joint name="mj3" type="revolute">
      <axis xyz="0 0 1"/>
      <limit effort="1000.0" lower="0" upper="1.5708" velocity="0.5"/>
      <parent link="ml0"/>
      <child link="ml1"/>
      <origin rpy="1.5708 0 0" xyz="0.015 0 0"/>
   </joint>

   <joint name="mj4" type="revolute">
      <axis xyz="0 0 1"/>
      <limit effort="1000.0" lower="0" upper="1.5708" velocity="0.5"/>
      <parent link="ml1"/>
      <child link="ml2"/>
      <origin rpy="0 0 0" xyz="0.0285 0 0"/>
   </joint>

   <joint name="mj5" type="revolute">
      <axis xyz="0 0 1"/>
      <limit effort="1000.0" lower="0" upper="1.5708" velocity="0.5"/>
      <parent link="ml2"/>
      <child link="ml3"/>
      <origin rpy="0 0 0" xyz="0.0240 0 0"/>
   </joint>

   <joint name="rij1" type="fixed">
      <parent link="right_palm"/>
      <child link="ringbase"/>
      <origin rpy="0 0 3.1416" xyz="-0.0625 0 0.016"/>
   </joint>

   <joint name="rij2" type="fixed">
      <parent link="ringbase"/>
      <child link="ril0"/>
      <origin rpy="0.0873 0 0.0087" xyz="0.00165 0.0059 -0.00425"/>
   </joint>

   <joint name="rij3" type="revolute">
      <axis xyz="0 0 1"/>
      <limit effort="1000.0" lower="0" upper="1.5708" velocity="0.5"/>
      <parent link="ril0"/>
      <child link="ril1"/>
      <origin rpy="1.5708 0 0" xyz="0.0148 0 0"/>
   </joint>

   <joint name="rij4" type="revolute">
      <axis xyz="0 0 1"/>
      <limit effort="1000.0" lower="0" upper="1.5708" velocity="0.5"/>
      <parent link="ril1"/>
      <child link="ril2"/>
      <origin rpy="0 0 0" xyz="0.0259 0 0"/>
   </joint>

   <joint name="rij5" type="revolute">
      <axis xyz="0 0 1"/>
      <limit effort="1000.0" lower="0" upper="1.5708" velocity="0.5"/>
      <parent link="ril2"/>
      <child link="ril3"/>
      <origin rpy="0 0 0" xyz="0.022 0 0"/>
   </joint>

   <joint name="lij1" type="fixed">
      <parent link="right_palm"/>
      <child link="littlebase"/>
      <origin rpy="0 0 3.1416" xyz="-0.0625 0 0.016"/>
   </joint>

   <joint name="lij2" type="fixed">
      <parent link="littlebase"/>
      <child link="lil0"/>
      <origin rpy="0.0873 0 0.0175" xyz="-0.00025 0.02475 -0.0025"/>
   </joint>

   <joint name="lij3" type="revolute">
      <axis xyz="0 0 1"/>
      <limit effort="1000.0" lower="0" upper="1.5708" velocity="0.5"/>
      <parent link="lil0"/>
      <child link="lil1"/>
      <origin rpy="1.5708 0 0" xyz="0.0148 0 0"/>
   </joint>

   <joint name="lij4" type="revolute">
      <axis xyz="0 0 1"/>
      <limit effort="1000.0" lower="0" upper="1.5708" velocity="0.5"/>
      <parent link="lil1"/>
      <child link="lil2"/>
      <origin rpy="0 0 0" xyz="0.0218 0 0"/>
   </joint>

   <joint name="lij5" type="revolute">
      <axis xyz="0 0 1"/>
      <limit effort="1000.0" lower="0" upper="1.5708" velocity="0.5"/>
      <parent link="lil2"/>
      <child link="lil3"/>
      <origin rpy="0 0 0" xyz="0.019 0 0"/>
   </joint>

</robot>
