<?xml version="1.0"?>
<robot name="ICub">


   <link name="base_link">
      <origin rpy="0 0 0" xyz="0 0 0"/>
    <inertial>
      <origin xyz="0 0 0" rpy="0 0 0"/>
      <mass value="0.111"/>
      <inertia
        ixx="0.112" ixy="0.0" ixz="0.0"
        iyy="0.112" iyz="0.0"
        izz="0.112"/>
    </inertial>
   </link>

<!-- LEFT HAND -->

   <link name="left_palm">
      <visual>
      <origin rpy="0 0 0" xyz="-0.0625 0 0.016"/>
         <geometry>
	    <mesh filename="package://icub_with_hands/meshes/left_palm.dae"/>
         </geometry>
      </visual>
    <inertial>
      <origin xyz="0 0 0" rpy="0 0 0"/>
      <mass value="0.111"/>
      <inertia
        ixx="0.112" ixy="0.0" ixz="0.0"
        iyy="0.112" iyz="0.0"
        izz="0.112"/>
    </inertial>
   </link>

   <link name="lthumbbase">
    <inertial>
      <origin xyz="0 0 0" rpy="0 0 0"/>
      <mass value="0.111"/>
      <inertia
        ixx="0.112" ixy="0.0" ixz="0.0"
        iyy="0.112" iyz="0.0"
        izz="0.112"/>
    </inertial>
   </link>

   <link name="ltl0">
      <visual>
      <origin rpy="-1.5708 0 0" xyz="0 0 0"/>
         <geometry>
	    <mesh filename="package://icub_with_hands/meshes/ltl0.dae"/>
         </geometry>
      </visual>
    <inertial>
      <origin xyz="0 0 0" rpy="0 0 0"/>
      <mass value="0.111"/>
      <inertia
        ixx="0.112" ixy="0.0" ixz="0.0"
        iyy="0.112" iyz="0.0"
        izz="0.112"/>
    </inertial>
   </link>

   <link name="ltl1">
      <visual>
      <origin rpy="0 0 0" xyz="0.021 0 -0.0056"/>
         <geometry>
	    <mesh filename="package://icub_with_hands/meshes/ltl1.dae"/>
         </geometry>
      </visual>
    <inertial>
      <origin xyz="0 0 0" rpy="0 0 0"/>
      <mass value="0.111"/>
      <inertia
        ixx="0.112" ixy="0.0" ixz="0.0"
        iyy="0.112" iyz="0.0"
        izz="0.112"/>
    </inertial>
   </link>

   <link name="ltl2">
      <visual>
      <origin rpy="0 0 0" xyz="0.026 0 0"/>
         <geometry>
	    <mesh filename="package://icub_with_hands/meshes/ltl2.dae"/>
         </geometry>
      </visual>
    <inertial>
      <origin xyz="0 0 0" rpy="0 0 0"/>
      <mass value="0.111"/>
      <inertia
        ixx="0.112" ixy="0.0" ixz="0.0"
        iyy="0.112" iyz="0.0"
        izz="0.112"/>
    </inertial>
   </link>

   <link name="ltl3">
      <visual>
      <origin rpy="0 0 0" xyz="0.022 0 0"/>
         <geometry>
	    <mesh filename="package://icub_with_hands/meshes/ltl3.dae"/>
         </geometry>
      </visual>
    <inertial>
      <origin xyz="0 0 0" rpy="0 0 0"/>
      <mass value="0.111"/>
      <inertia
        ixx="0.112" ixy="0.0" ixz="0.0"
        iyy="0.112" iyz="0.0"
        izz="0.112"/>
    </inertial>
   </link>

   <link name="ltl4">
      <visual>
      <origin rpy="0 0 0" xyz="0.0168 0 0"/>
         <geometry>
	    <mesh filename="package://icub_with_hands/meshes/ltl4.dae"/>
         </geometry>
      </visual>
    <inertial>
      <origin xyz="0 0 0" rpy="0 0 0"/>
      <mass value="0.111"/>
      <inertia
        ixx="0.112" ixy="0.0" ixz="0.0"
        iyy="0.112" iyz="0.0"
        izz="0.112"/>
    </inertial>
   </link>

   <link name="lindexbase">
      <visual>
      <origin rpy="0.0959 0 -3.2141" xyz="-0.0018 -0.027 -0.00375"/>
         <geometry>
	    <mesh filename="package://icub_with_hands/meshes/lindexbase.dae"/>
         </geometry>
      </visual>
    <inertial>
      <origin xyz="0 0 0" rpy="0 0 0"/>
      <mass value="0.111"/>
      <inertia
        ixx="0.112" ixy="0.0" ixz="0.0"
        iyy="0.112" iyz="0.0"
        izz="0.112"/>
    </inertial>
   </link>

   <link name="lail0">
      <visual>
      <origin rpy="1.5708 0 0" xyz="0.0148 0 0"/>
         <geometry>
	    <mesh filename="package://icub_with_hands/meshes/lail0.dae"/>
         </geometry>
      </visual>
    <inertial>
      <origin xyz="0 0 0" rpy="0 0 0"/>
      <mass value="0.111"/>
      <inertia
        ixx="0.112" ixy="0.0" ixz="0.0"
        iyy="0.112" iyz="0.0"
        izz="0.112"/>
    </inertial>
   </link>

   <link name="lail1">

      <visual>
      <origin rpy="0 0 0" xyz="0.0259 0 0"/>
         <geometry>
	    <mesh filename="package://icub_with_hands/meshes/lail1.dae"/>
         </geometry>
      </visual>
    <inertial>
      <origin xyz="0 0 0" rpy="0 0 0"/>
      <mass value="0.111"/>
      <inertia
        ixx="0.112" ixy="0.0" ixz="0.0"
        iyy="0.112" iyz="0.0"
        izz="0.112"/>
    </inertial>
   </link>

   <link name="lail2">

      <visual>
      <origin rpy="0 0 0" xyz="0.022 0 0"/>
         <geometry>
	    <mesh filename="package://icub_with_hands/meshes/lail2.dae"/>
         </geometry>
      </visual>
    <inertial>
      <origin xyz="0 0 0" rpy="0 0 0"/>
      <mass value="0.111"/>
      <inertia
        ixx="0.112" ixy="0.0" ixz="0.0"
        iyy="0.112" iyz="0.0"
        izz="0.112"/>
    </inertial>
   </link>

   <link name="lail3">

      <visual>
      <origin rpy="-1.5708 0 0" xyz="0.0168 0 0"/>
         <geometry>
	    <mesh filename="package://icub_with_hands/meshes/lail3.dae"/>
         </geometry>
      </visual>
    <inertial>
      <origin xyz="0 0 0" rpy="0 0 0"/>
      <mass value="0.111"/>
      <inertia
        ixx="0.112" ixy="0.0" ixz="0.0"
        iyy="0.112" iyz="0.0"
        izz="0.112"/>
    </inertial>
   </link>

   <link name="lmiddlebase">

      <visual>
      <origin rpy="0 0 3.1416" xyz="-0.0028 -0.01 -0.005"/>
         <geometry>
	    <mesh filename="package://icub_with_hands/meshes/lmiddlebase.dae"/>
         </geometry>
      </visual>
    <inertial>
      <origin xyz="0 0 0" rpy="0 0 0"/>
      <mass value="0.111"/>
      <inertia
        ixx="0.112" ixy="0.0" ixz="0.0"
        iyy="0.112" iyz="0.0"
        izz="0.112"/>
    </inertial>
   </link>

   <link name="lml0">

      <visual>
      <origin rpy="1.5708 0 0" xyz="0.015 0 0"/>
         <geometry>
	    <mesh filename="package://icub_with_hands/meshes/lml0.dae"/>
         </geometry>
      </visual>
    <inertial>
      <origin xyz="0 0 0" rpy="0 0 0"/>
      <mass value="0.111"/>
      <inertia
        ixx="0.112" ixy="0.0" ixz="0.0"
        iyy="0.112" iyz="0.0"
        izz="0.112"/>
    </inertial>
   </link>

   <link name="lml1">

      <visual>
      <origin rpy="0 0 0" xyz="0.0285 0 0"/>
         <geometry>
	    <mesh filename="package://icub_with_hands/meshes/lml1.dae"/>
         </geometry>
      </visual>
    <inertial>
      <origin xyz="0 0 0" rpy="0 0 0"/>
      <mass value="0.111"/>
      <inertia
        ixx="0.112" ixy="0.0" ixz="0.0"
        iyy="0.112" iyz="0.0"
        izz="0.112"/>
    </inertial>
   </link>

   <link name="lml2">

      <visual>
      <origin rpy="0 0 0" xyz="0.0240 0 0"/>
         <geometry>
	    <mesh filename="package://icub_with_hands/meshes/lml2.dae"/>
         </geometry>
      </visual>
    <inertial>
      <origin xyz="0 0 0" rpy="0 0 0"/>
      <mass value="0.111"/>
      <inertia
        ixx="0.112" ixy="0.0" ixz="0.0"
        iyy="0.112" iyz="0.0"
        izz="0.112"/>
    </inertial>
   </link>

   <link name="lml3">

      <visual>
      <origin rpy="-1.5708 0 0" xyz="0.0168 0 0"/>
         <geometry>
	    <mesh filename="package://icub_with_hands/meshes/lml3.dae"/>
         </geometry>
      </visual>
    <inertial>
      <origin xyz="0 0 0" rpy="0 0 0"/>
      <mass value="0.111"/>
      <inertia
        ixx="0.112" ixy="0.0" ixz="0.0"
        iyy="0.112" iyz="0.0"
        izz="0.112"/>
    </inertial>
   </link>

   <link name="lringbase">

      <visual>
      <origin rpy="-0.0873 0 3.1329" xyz="-0.00165 0.0059 -0.00425"/>
         <geometry>
	    <mesh filename="package://icub_with_hands/meshes/lringbase.dae"/>
         </geometry>
      </visual>
    <inertial>
      <origin xyz="0 0 0" rpy="0 0 0"/>
      <mass value="0.111"/>
      <inertia
        ixx="0.112" ixy="0.0" ixz="0.0"
        iyy="0.112" iyz="0.0"
        izz="0.112"/>
    </inertial>
   </link>

   <link name="lril0">

      <visual>
      <origin rpy="1.5708 0 0" xyz="0.0148 0 0"/>
         <geometry>
	    <mesh filename="package://icub_with_hands/meshes/lril0.dae"/>
         </geometry>
      </visual>
    <inertial>
      <origin xyz="0 0 0" rpy="0 0 0"/>
      <mass value="0.111"/>
      <inertia
        ixx="0.112" ixy="0.0" ixz="0.0"
        iyy="0.112" iyz="0.0"
        izz="0.112"/>
    </inertial>
   </link>

   <link name="lril1">

      <visual>
      <origin rpy="0 0 0" xyz="0.0259 0 0"/>
         <geometry>
	    <mesh filename="package://icub_with_hands/meshes/lril1.dae"/>
         </geometry>
      </visual>
    <inertial>
      <origin xyz="0 0 0" rpy="0 0 0"/>
      <mass value="0.111"/>
      <inertia
        ixx="0.112" ixy="0.0" ixz="0.0"
        iyy="0.112" iyz="0.0"
        izz="0.112"/>
    </inertial>
   </link>

   <link name="lril2">

      <visual>
      <origin rpy="0 0 0" xyz="0.022 0 0"/>
         <geometry>
	    <mesh filename="package://icub_with_hands/meshes/lril2.dae"/>
         </geometry>
      </visual>
    <inertial>
      <origin xyz="0 0 0" rpy="0 0 0"/>
      <mass value="0.111"/>
      <inertia
        ixx="0.112" ixy="0.0" ixz="0.0"
        iyy="0.112" iyz="0.0"
        izz="0.112"/>
    </inertial>
   </link>

   <link name="lril3">

      <visual>
      <origin rpy="-1.5708 0 0" xyz="0.0168 0 0"/>
         <geometry>
	    <mesh filename="package://icub_with_hands/meshes/lril3.dae"/>
         </geometry>
      </visual>
    <inertial>
      <origin xyz="0 0 0" rpy="0 0 0"/>
      <mass value="0.111"/>
      <inertia
        ixx="0.112" ixy="0.0" ixz="0.0"
        iyy="0.112" iyz="0.0"
        izz="0.112"/>
    </inertial>
   </link>

   <link name="llittlebase">

      <visual>
      <origin rpy="-0.0873 0 3.1241" xyz="0.00025 0.02475 -0.0025"/>
         <geometry>
	    <mesh filename="package://icub_with_hands/meshes/llittlebase.dae"/>
         </geometry>
      </visual>
    <inertial>
      <origin xyz="0 0 0" rpy="0 0 0"/>
      <mass value="0.111"/>
      <inertia
        ixx="0.112" ixy="0.0" ixz="0.0"
        iyy="0.112" iyz="0.0"
        izz="0.112"/>
    </inertial>
   </link>

   <link name="llil0">

      <visual>
      <origin rpy="1.5708 0 0" xyz="0.0148 0 0"/>
         <geometry>
	    <mesh filename="package://icub_with_hands/meshes/llil0.dae"/>
         </geometry>
      </visual>
    <inertial>
      <origin xyz="0 0 0" rpy="0 0 0"/>
      <mass value="0.111"/>
      <inertia
        ixx="0.112" ixy="0.0" ixz="0.0"
        iyy="0.112" iyz="0.0"
        izz="0.112"/>
    </inertial>
   </link>

   <link name="llil1">

      <visual>
      <origin rpy="0 0 0" xyz="0.0218 0 0"/>
         <geometry>
	    <mesh filename="package://icub_with_hands/meshes/llil1.dae"/>
         </geometry>
      </visual>
    <inertial>
      <origin xyz="0 0 0" rpy="0 0 0"/>
      <mass value="0.111"/>
      <inertia
        ixx="0.112" ixy="0.0" ixz="0.0"
        iyy="0.112" iyz="0.0"
        izz="0.112"/>
    </inertial>
   </link>

   <link name="llil2">

      <visual>
      <origin rpy="0 0 0" xyz="0.019 0 0"/>
         <geometry>
	    <mesh filename="package://icub_with_hands/meshes/llil2.dae"/>
         </geometry>
      </visual>
    <inertial>
      <origin xyz="0 0 0" rpy="0 0 0"/>
      <mass value="0.111"/>
      <inertia
        ixx="0.112" ixy="0.0" ixz="0.0"
        iyy="0.112" iyz="0.0"
        izz="0.112"/>
    </inertial>
   </link>

   <link name="llil3">

      <visual>
      <origin rpy="-1.5708 0 0" xyz="0.0168 0 0"/>
         <geometry>
	    <mesh filename="package://icub_with_hands/meshes/llil3.dae"/>
         </geometry>
      </visual>
    <inertial>
      <origin xyz="0 0 0" rpy="0 0 0"/>
      <mass value="0.111"/>
      <inertia
        ixx="0.112" ixy="0.0" ixz="0.0"
        iyy="0.112" iyz="0.0"
        izz="0.112"/>
    </inertial>
   </link>



	
<!-- ########################################################## JOINTS #########################################################
##################################################################################################################
##################################################################################################################
##################################################################################################################
##################################################################################################################
##################################################################################################################
################################################################################################################## -->



<!-- LEFT HAND -->

   <joint name="left_wrist_yaw" type="fixed">
      <axis xyz="0 0 1"/>
      <limit effort="1000.0" lower="-0.3491" upper="0.6981" velocity="0.5"/>
      <parent link="base_link"/>
      <child link="left_palm"/>
      <origin rpy="1.5708 0 1.5708" xyz="0 0 0"/>
   </joint>

   <joint name="ltj1" type="fixed">
      <parent link="left_palm"/>
      <child link="lthumbbase"/>
      <origin rpy="0 0 0" xyz="-0.0625 0 0.016"/>
   </joint>

   <joint name="ltj2" type="revolute">
      <axis xyz="0 0 -1"/>
      <limit effort="1000.0" lower="0" upper="1.5708" velocity="0.5"/>
      <parent link="lthumbbase"/>
      <child link="ltl0"/>
      <origin rpy="-1.4922 0 -2.0683" xyz="0.0239 -0.01235 0.005"/>
   </joint>

   <joint name="ltj3" type="fixed">
      <parent link="ltl0"/>
      <child link="ltl1"/>
      <origin rpy="-1.5708 0 0" xyz="0 0 0"/>
   </joint>

   <joint name="ltj4" type="revolute">
      <axis xyz="0 0 1"/>
      <limit effort="1000.0" lower="0" upper="1.5708" velocity="0.5"/>
      <parent link="ltl1"/>
      <child link="ltl2"/>
      <origin rpy="0 0 0" xyz="0.021 0 -0.0056"/>
   </joint>

   <joint name="ltj5" type="revolute">
      <axis xyz="0 0 1"/>
      <limit effort="1000.0" lower="0" upper="1.5708" velocity="0.5"/>
      <parent link="ltl2"/>
      <child link="ltl3"/>
      <origin rpy="0 0 0" xyz="0.026 0 0"/>
   </joint>

   <joint name="ltj6" type="revolute">
      <axis xyz="0 0 1"/>
      <limit effort="1000.0" lower="0" upper="1.5708" velocity="0.5"/>
      <parent link="ltl3"/>
      <child link="ltl4"/>
      <origin rpy="0 0 0" xyz="0.022 0 0"/>
   </joint>

   <joint name="laij1" type="fixed">
      <parent link="left_palm"/>
      <child link="lindexbase"/>
      <origin rpy="0 0 0" xyz="-0.0625 0 0.016"/>
   </joint>

   <joint name="laij2" type="fixed">
      <parent link="lindexbase"/>
      <child link="lail0"/>
      <origin rpy="0.0959 0 -3.1241" xyz="0.0018 -0.027 -0.00375"/>
   </joint>

   <joint name="laij3" type="revolute">
      <axis xyz="0 0 1"/>
      <limit effort="1000.0" lower="0" upper="1.5708" velocity="0.5"/>
      <parent link="lail0"/>
      <child link="lail1"/>
      <origin rpy="1.5708 0 0" xyz="0.0148 0 0"/>
   </joint>

   <joint name="laij4" type="revolute">
      <axis xyz="0 0 1"/>
      <limit effort="1000.0" lower="0" upper="1.5708" velocity="0.5"/>
      <parent link="lail1"/>
      <child link="lail2"/>
      <origin rpy="0 0 0" xyz="0.0259 0 0"/>
   </joint>

   <joint name="laij5" type="revolute">
      <axis xyz="0 0 1"/>
      <limit effort="1000.0" lower="0" upper="1.5708" velocity="0.5"/>
      <parent link="lail2"/>
      <child link="lail3"/>
      <origin rpy="0 0 0" xyz="0.022 0 0"/>
   </joint>

   <joint name="lmj1" type="fixed">
      <parent link="left_palm"/>
      <child link="lmiddlebase"/>
      <origin rpy="0 0 0" xyz="-0.0625 0 0.016"/>
   </joint>

   <joint name="lmj2" type="fixed">
      <parent link="lmiddlebase"/>
      <child link="lml0"/>
      <origin rpy="0 0 3.1416" xyz="-0.0028 -0.01 -0.005"/>
   </joint>

   <joint name="lmj3" type="revolute">
      <axis xyz="0 0 1"/>
      <limit effort="1000.0" lower="0" upper="1.5708" velocity="0.5"/>
      <parent link="lml0"/>
      <child link="lml1"/>
      <origin rpy="1.5708 0 0" xyz="0.015 0 0"/>
   </joint>

   <joint name="lmj4" type="revolute">
      <axis xyz="0 0 1"/>
      <limit effort="1000.0" lower="0" upper="1.5708" velocity="0.5"/>
      <parent link="lml1"/>
      <child link="lml2"/>
      <origin rpy="0 0 0" xyz="0.0285 0 0"/>
   </joint>

   <joint name="lmj5" type="revolute">
      <axis xyz="0 0 1"/>
      <limit effort="1000.0" lower="0" upper="1.5708" velocity="0.5"/>
      <parent link="lml2"/>
      <child link="lml3"/>
      <origin rpy="0 0 0" xyz="0.0240 0 0"/>
   </joint>

   <joint name="lrij1" type="fixed">
      <parent link="left_palm"/>
      <child link="lringbase"/>
      <origin rpy="0 0 0" xyz="-0.0625 0 0.016"/>
   </joint>

   <joint name="lrij2" type="fixed">
      <parent link="lringbase"/>
      <child link="lril0"/>
      <origin rpy="-0.0873 0 3.1329" xyz="-0.00165 0.0059 -0.00425"/>
   </joint>

   <joint name="lrij3" type="revolute">
      <axis xyz="0 0 1"/>
      <limit effort="1000.0" lower="0" upper="1.5708" velocity="0.5"/>
      <parent link="lril0"/>
      <child link="lril1"/>
      <origin rpy="1.5708 0 0" xyz="0.0148 0 0"/>
   </joint>

   <joint name="lrij4" type="revolute">
      <axis xyz="0 0 1"/>
      <limit effort="1000.0" lower="0" upper="1.5708" velocity="0.5"/>
      <parent link="lril1"/>
      <child link="lril2"/>
      <origin rpy="0 0 0" xyz="0.0259 0 0"/>
   </joint>

   <joint name="lrij5" type="revolute">
      <axis xyz="0 0 1"/>
      <limit effort="1000.0" lower="0" upper="1.5708" velocity="0.5"/>
      <parent link="lril2"/>
      <child link="lril3"/>
      <origin rpy="0 0 0" xyz="0.022 0 0"/>
   </joint>

   <joint name="llij1" type="fixed">
      <parent link="left_palm"/>
      <child link="llittlebase"/>
      <origin rpy="0 0 0" xyz="-0.0625 0 0.016"/>
   </joint>

   <joint name="llij2" type="fixed">
      <parent link="llittlebase"/>
      <child link="llil0"/>
      <origin rpy="-0.0873 0 3.1241" xyz="0.00025 0.02475 -0.0025"/>
   </joint>

   <joint name="llij3" type="revolute">
      <axis xyz="0 0 1"/>
      <limit effort="1000.0" lower="0" upper="1.5708" velocity="0.5"/>
      <parent link="llil0"/>
      <child link="llil1"/>
      <origin rpy="1.5708 0 0" xyz="0.0148 0 0"/>
   </joint>

   <joint name="llij4" type="revolute">
      <axis xyz="0 0 1"/>
      <limit effort="1000.0" lower="0" upper="1.5708" velocity="0.5"/>
      <parent link="llil1"/>
      <child link="llil2"/>
      <origin rpy="0 0 0" xyz="0.0218 0 0"/>
   </joint>

   <joint name="llij5" type="revolute">
      <axis xyz="0 0 1"/>
      <limit effort="1000.0" lower="0" upper="1.5708" velocity="0.5"/>
      <parent link="llil2"/>
      <child link="llil3"/>
      <origin rpy="0 0 0" xyz="0.019 0 0"/>
   </joint>


</robot>
