<sdf version='1.5'>
  <model name='iCubGenova02'>
    <link name='root_link'>
      <pose>0 0 0 0 -0 0</pose>
      <inertial>
        <pose>0.024882 0.000104 -0.044081 1.5708 -0 -1.5708</pose>
        <mass>5.09143</mass>
        <inertia>
          <ixx>0.0139679</ixx>
          <ixy>-5.93488e-06</ixy>
          <ixz>-1.55458e-05</ixz>
          <iyy>0.0202112</iyy>
          <iyz>-0.00170968</iyz>
          <izz>0.0249124</izz>
        </inertia>
      </inertial>
      <collision name='root_link_collision'>
        <pose>-0.0364 0 0.032 1.5708 -0 -1.5708</pose>
        <geometry>
          <mesh>
            <scale>0.001 0.001 0.001</scale>
            <uri>model://iCubGenova02/meshes/dae/root.dae</uri>
          </mesh>
        </geometry>
      </collision>
      <visual name='root_link_visual'>
        <pose>-0.0364 0 0.032 1.5708 -0 -1.5708</pose>
        <geometry>
          <mesh>
            <scale>0.001 0.001 0.001</scale>
            <uri>model://iCubGenova02/meshes/dae/root.dae</uri>
          </mesh>
        </geometry>
      </visual>
    </link>
    <link name='l_hip_1'>
      <pose>0.006452 -0.022386 -0.119913 1.5708 -0 -1.5708</pose>
      <inertial>
        <pose>0.041678 -6.3e-05 -0.000401 0 -0 0</pose>
        <mass>0.915608</mass>
        <inertia>
          <ixx>0.000402555</ixx>
          <ixy>1.07708e-06</ixy>
          <ixz>-1.569e-06</ixz>
          <iyy>0.000570806</iyy>
          <iyz>-6.5378e-07</iyz>
          <izz>0.00057937</izz>
        </inertia>
      </inertial>
      <collision name='l_hip_1_collision'>
        <pose>-0.022386 0.151913 0.042852 0 -0 0</pose>
        <geometry>
          <mesh>
            <scale>0.001 0.001 0.001</scale>
            <uri>model://iCubGenova02/meshes/dae/l_hip_1.dae</uri>
          </mesh>
        </geometry>
      </collision>
      <visual name='l_hip_1_visual'>
        <pose>-0.022386 0.151913 0.042852 0 -0 0</pose>
        <geometry>
          <mesh>
            <scale>0.001 0.001 0.001</scale>
            <uri>model://iCubGenova02/meshes/dae/l_hip_1.dae</uri>
          </mesh>
        </geometry>
      </visual>
    </link>
    <joint name='l_hip_pitch' type='revolute'>
      <child>l_hip_1</child>
      <parent>root_link</parent>
      <axis>
        <xyz>-0 1 0</xyz>
        <limit>
          <lower>-0.523599</lower>
          <upper>1.48353</upper>
          <effort>50000</effort>
          <velocity>50000</velocity>
        </limit>
        <dynamics>
          <damping>0.223</damping>
          <friction>0</friction>
          <spring_reference>0</spring_reference>
          <spring_stiffness>0</spring_stiffness>
        </dynamics>
        <use_parent_model_frame>1</use_parent_model_frame>
      </axis>
    </joint>
    <link name='l_hip_2'>
      <pose>0.031992 -0.0701 -0.119913 1.5708 -0 -1.5708</pose>
      <inertial>
        <pose>-1.9e-05 -0.044047 0.023959 0 -0 0</pose>
        <mass>0.421161</mass>
        <inertia>
          <ixx>0.000494475</ixx>
          <ixy>1.54783e-07</ixy>
          <ixz>-1.86267e-07</ixz>
          <iyy>0.000288821</iyy>
          <iyz>1.53903e-05</iyz>
          <izz>0.000319114</izz>
        </inertia>
      </inertial>
      <collision name='l_hip_2_collision'>
        <pose>-0.0701 0.151913 0.068392 0 -0 0</pose>
        <geometry>
          <mesh>
            <scale>0.001 0.001 0.001</scale>
            <uri>model://iCubGenova02/meshes/dae/l_hip_2.dae</uri>
          </mesh>
        </geometry>
      </collision>
      <visual name='l_hip_2_visual'>
        <pose>-0.0701 0.151913 0.068392 0 -0 0</pose>
        <geometry>
          <mesh>
            <scale>0.001 0.001 0.001</scale>
            <uri>model://iCubGenova02/meshes/dae/l_hip_2.dae</uri>
          </mesh>
        </geometry>
      </visual>
    </link>
    <joint name='l_hip_roll' type='revolute'>
      <child>l_hip_2</child>
      <parent>l_hip_1</parent>
      <axis>
        <xyz>-1 -0 0</xyz>
        <limit>
          <lower>0</lower>
          <upper>1.5708</upper>
          <effort>50000</effort>
          <velocity>50000</velocity>
        </limit>
        <dynamics>
          <damping>0.223</damping>
          <friction>0</friction>
          <spring_reference>0</spring_reference>
          <spring_stiffness>0</spring_stiffness>
        </dynamics>
        <use_parent_model_frame>1</use_parent_model_frame>
      </axis>
    </joint>
    <link name='l_hip_3'>
      <pose>0.007309 -0.0701 -0.194213 3.14159 -0 -3.14159</pose>
      <inertial>
        <pose>0.000282 -0.000123 0.008718 -1.5708 0 0</pose>
        <mass>0.126212</mass>
        <inertia>
          <ixx>3.27938e-05</ixx>
          <ixy>2.67901e-07</ixy>
          <ixz>-4.41463e-09</ixz>
          <iyy>5.69957e-05</iyy>
          <iyz>3.32338e-08</iyz>
          <izz>3.26449e-05</izz>
        </inertia>
      </inertial>
      <collision name='l_hip_3_collision'>
        <pose>-0.0701 0.043409 -0.226213 -1.5708 0 0</pose>
        <geometry>
          <mesh>
            <scale>0.001 0.001 0.001</scale>
            <uri>model://iCubGenova02/meshes/dae/l_hip_3.dae</uri>
          </mesh>
        </geometry>
      </collision>
      <visual name='l_hip_3_visual'>
        <pose>-0.0701 0.043409 -0.226213 -1.5708 0 0</pose>
        <geometry>
          <mesh>
            <scale>0.001 0.001 0.001</scale>
            <uri>model://iCubGenova02/meshes/dae/l_hip_3.dae</uri>
          </mesh>
        </geometry>
      </visual>
    </link>
    <joint name='l_leg_ft_sensor' type='revolute'>
      <child>l_hip_3</child>
      <parent>l_hip_2</parent>
      <axis>
        <limit>
          <lower>0</lower>
          <upper>0</upper>
        </limit>
        <dynamics>
          <damping>0</damping>
          <friction>0</friction>
          <spring_reference>0</spring_reference>
          <spring_stiffness>0</spring_stiffness>
        </dynamics>
        <use_parent_model_frame>1</use_parent_model_frame>
        <xyz>0 0 1</xyz>
      </axis>
      <physics>
        <ode>
          <limit>
            <cfm>0</cfm>
            <erp>0.2</erp>
          </limit>
        </ode>
      </physics>
      <sensor name='l_leg_ft_sensor' type='force_torque'>
        <always_on>1</always_on>
        <update_rate>100</update_rate>
        <force_torque>
          <frame>child</frame>
          <measure_direction>child_to_parent</measure_direction>
        </force_torque>
      </sensor>
    </joint>
    <link name='l_upper_leg'>
      <pose>0.007309 -0.0701 -0.208813 1.5708 0 -1.5708</pose>
      <inertial>
        <pose>0.000116 -0.078858 0.003309 0 -0 0</pose>
        <mass>1.8084</mass>
        <inertia>
          <ixx>0.00648406</ixx>
          <ixy>-0.000115201</ixy>
          <ixz>-3.80294e-06</ixz>
          <iyy>0.00144872</iyy>
          <iyz>-0.000137046</iyz>
          <izz>0.00647804</izz>
        </inertia>
      </inertial>
      <collision name='l_upper_leg_collision'>
        <pose>-0.0701 0.241013 0.043409 0 -0 0</pose>
        <geometry>
          <mesh>
            <scale>0.001 0.001 0.001</scale>
            <uri>model://iCubGenova02/meshes/dae/l_upper_leg.dae</uri>
          </mesh>
        </geometry>
        <surface>
          <contact>
            <ode/>
          </contact>
          <friction>
            <ode/>
          </friction>
        </surface>
        <surface>
          <contact>
            <ode/>
          </contact>
          <friction>
            <ode/>
          </friction>
        </surface>
        <surface>
          <contact>
            <ode/>
          </contact>
          <friction>
            <ode/>
          </friction>
        </surface>
        <surface>
          <contact>
            <ode/>
          </contact>
          <friction>
            <ode/>
          </friction>
        </surface>
        <surface>
          <contact>
            <ode/>
          </contact>
          <friction>
            <ode/>
          </friction>
        </surface>
        <surface>
          <contact>
            <ode/>
          </contact>
          <friction>
            <ode/>
          </friction>
        </surface>
        <surface>
          <contact>
            <ode/>
          </contact>
          <friction>
            <ode/>
          </friction>
        </surface>
      </collision>
      <visual name='l_upper_leg_visual'>
        <pose>-0.0701 0.241013 0.043409 0 -0 0</pose>
        <geometry>
          <mesh>
            <scale>0.001 0.001 0.001</scale>
            <uri>model://iCubGenova02/meshes/dae/l_upper_leg.dae</uri>
          </mesh>
        </geometry>
      </visual>
      <velocity_decay/>
      <sensor name='l_upper_leg_mtb_acc_10b1' type='imu'>
        <always_on>1</always_on>
        <update_rate>100</update_rate>
        <pose>0.031565 0.049332 0.042002 0.837758 -8.6e-05 1.57087</pose>
        <plugin name='iCub_yarp_gazebo_plugin_ACC' filename='libgazebo_yarp_inertialmtb.so'/>
      </sensor>
      <velocity_decay/>
      <sensor name='l_upper_leg_mtb_acc_10b2' type='imu'>
        <always_on>1</always_on>
        <update_rate>100</update_rate>
        <pose>0.008384 0.039452 0.053355 0.837758 -8.6e-05 1.57087</pose>
        <plugin name='iCub_yarp_gazebo_plugin_ACC' filename='libgazebo_yarp_inertialmtb.so'/>
      </sensor>
      <velocity_decay/>
      <sensor name='l_upper_leg_mtb_acc_10b3' type='imu'>
        <always_on>1</always_on>
        <update_rate>100</update_rate>
        <pose>0.015071 0.004382 0.053785 0 -0 1.5708</pose>
        <plugin name='iCub_yarp_gazebo_plugin_ACC' filename='libgazebo_yarp_inertialmtb.so'/>
      </sensor>
      <velocity_decay/>
      <sensor name='l_upper_leg_mtb_acc_10b4' type='imu'>
        <always_on>1</always_on>
        <update_rate>100</update_rate>
        <pose>-0.014429 0.004382 0.053785 0 -0 1.5708</pose>
        <plugin name='iCub_yarp_gazebo_plugin_ACC' filename='libgazebo_yarp_inertialmtb.so'/>
      </sensor>
      <velocity_decay/>
      <sensor name='l_upper_leg_mtb_acc_10b5' type='imu'>
        <always_on>1</always_on>
        <update_rate>100</update_rate>
        <pose>-0.0415 -0.004658 0.034129 -1.18682 -0 1.5708</pose>
        <plugin name='iCub_yarp_gazebo_plugin_ACC' filename='libgazebo_yarp_inertialmtb.so'/>
      </sensor>
      <velocity_decay/>
      <sensor name='l_upper_leg_mtb_acc_10b6' type='imu'>
        <always_on>1</always_on>
        <update_rate>100</update_rate>
        <pose>0.017809 -0.026212 -0.043785 -3.14159 -0 -1.57091</pose>
        <plugin name='iCub_yarp_gazebo_plugin_ACC' filename='libgazebo_yarp_inertialmtb.so'/>
      </sensor>
      <gravity>1</gravity>
      <velocity_decay/>
      <self_collide>0</self_collide>
      <sensor name='l_upper_leg_mtb_acc_10b7' type='imu'>
        <always_on>1</always_on>
        <update_rate>100</update_rate>
        <pose>-0.014192 -0.026211 -0.043785 -3.14159 0 -1.57095</pose>
        <plugin name='iCub_yarp_gazebo_plugin_ACC' filename='libgazebo_yarp_inertialmtb.so'/>
      </sensor>
    </link>
    <joint name='l_hip_yaw' type='revolute'>
      <child>l_upper_leg</child>
      <parent>l_hip_3</parent>
      <axis>
        <xyz>0 -0 1</xyz>
        <limit>
          <lower>-1.22173</lower>
          <upper>1.22173</upper>
          <effort>50000</effort>
          <velocity>50000</velocity>
        </limit>
        <dynamics>
          <damping>0.223</damping>
          <friction>0</friction>
          <spring_reference>0</spring_reference>
          <spring_stiffness>0</spring_stiffness>
        </dynamics>
        <use_parent_model_frame>1</use_parent_model_frame>
      </axis>
    </joint>
    <link name='l_lower_leg'>
      <pose>0.007309 -0.046317 -0.354438 1.5708 0 -1.5708</pose>
      <inertial>
        <pose>0.027377 -0.088559 0.000854 0 -0 0</pose>
        <mass>1.4724</mass>
        <inertia>
          <ixx>0.00424976</ixx>
          <ixy>-0.000240559</ixy>
          <ixz>6.75117e-05</ixz>
          <iyy>0.00151575</iyy>
          <iyz>-0.000230535</iyz>
          <izz>0.00458657</izz>
        </inertia>
      </inertial>
      <collision name='l_lower_leg_collision'>
        <pose>-0.046317 0.386638 0.043409 0 -0 0</pose>
        <geometry>
          <mesh>
            <scale>0.001 0.001 0.001</scale>
            <uri>model://iCubGenova02/meshes/dae/l_lower_leg.dae</uri>
          </mesh>
        </geometry>
        <surface>
          <contact>
            <ode/>
          </contact>
          <friction>
            <ode/>
          </friction>
        </surface>
        <surface>
          <contact>
            <ode/>
          </contact>
          <friction>
            <ode/>
          </friction>
        </surface>
        <surface>
          <contact>
            <ode/>
          </contact>
          <friction>
            <ode/>
          </friction>
        </surface>
        <surface>
          <contact>
            <ode/>
          </contact>
          <friction>
            <ode/>
          </friction>
        </surface>
      </collision>
      <visual name='l_lower_leg_visual'>
        <pose>-0.046317 0.386638 0.043409 0 -0 0</pose>
        <geometry>
          <mesh>
            <scale>0.001 0.001 0.001</scale>
            <uri>model://iCubGenova02/meshes/dae/l_lower_leg.dae</uri>
          </mesh>
        </geometry>
      </visual>
      <velocity_decay/>
      <sensor name='l_lower_leg_mtb_acc_10b8' type='imu'>
        <always_on>1</always_on>
        <update_rate>100</update_rate>
        <pose>0.009984 -0.004318 0.054452 -0.349066 4e-05 1.5709</pose>
        <plugin name='iCub_yarp_gazebo_plugin_ACC' filename='libgazebo_yarp_inertialmtb.so'/>
      </sensor>
      <velocity_decay/>
      <sensor name='l_lower_leg_mtb_acc_10b9' type='imu'>
        <always_on>1</always_on>
        <update_rate>100</update_rate>
        <pose>0.066527 -0.043468 0.025915 1.309 -0.000112 1.57083</pose>
        <plugin name='iCub_yarp_gazebo_plugin_ACC' filename='libgazebo_yarp_inertialmtb.so'/>
      </sensor>
      <velocity_decay/>
      <sensor name='l_lower_leg_mtb_acc_10b10' type='imu'>
        <always_on>1</always_on>
        <update_rate>100</update_rate>
        <pose>0.030989 -0.011037 0.052381 -1.32645 -0 1.5708</pose>
        <plugin name='iCub_yarp_gazebo_plugin_ACC' filename='libgazebo_yarp_inertialmtb.so'/>
      </sensor>
      <gravity>1</gravity>
      <velocity_decay/>
      <self_collide>0</self_collide>
      <sensor name='l_lower_leg_mtb_acc_10b11' type='imu'>
        <always_on>1</always_on>
        <update_rate>100</update_rate>
        <pose>-0.017936 -0.092958 0.018459 -1.309 -2.5e-05 1.57079</pose>
        <plugin name='iCub_yarp_gazebo_plugin_ACC' filename='libgazebo_yarp_inertialmtb.so'/>
      </sensor>
    </link>
    <joint name='l_knee' type='revolute'>
      <child>l_lower_leg</child>
      <parent>l_upper_leg</parent>
      <axis>
        <xyz>-0 1 0</xyz>
        <limit>
          <lower>-1.74533</lower>
          <upper>0</upper>
          <effort>50000</effort>
          <velocity>50000</velocity>
        </limit>
        <dynamics>
          <damping>0.223</damping>
          <friction>0</friction>
          <spring_reference>0</spring_reference>
          <spring_stiffness>0</spring_stiffness>
        </dynamics>
        <use_parent_model_frame>1</use_parent_model_frame>
      </axis>
    </joint>
    <link name='l_ankle_1'>
      <pose>0.007309 -0.1056 -0.555438 1.5708 0 -1.5708</pose>
      <inertial>
        <pose>-0.034594 6.3e-05 0.015261 0 -0 0</pose>
        <mass>0.6798</mass>
        <inertia>
          <ixx>0.000405061</ixx>
          <ixy>-1.12515e-06</ixy>
          <ixz>3.06764e-05</ixz>
          <iyy>0.000448346</iyy>
          <iyz>2.88993e-06</iyz>
          <izz>0.000309416</izz>
        </inertia>
      </inertial>
      <collision name='l_ankle_1_collision'>
        <pose>-0.1056 0.587138 0.043409 0 -0 0</pose>
        <geometry>
          <mesh>
            <scale>0.001 0.001 0.001</scale>
            <uri>model://iCubGenova02/meshes/dae/l_ankle_1.dae</uri>
          </mesh>
        </geometry>
      </collision>
      <visual name='l_ankle_1_visual'>
        <pose>-0.1056 0.587138 0.043409 0 -0 0</pose>
        <geometry>
          <mesh>
            <scale>0.001 0.001 0.001</scale>
            <uri>model://iCubGenova02/meshes/dae/l_ankle_1.dae</uri>
          </mesh>
        </geometry>
      </visual>
    </link>
    <joint name='l_ankle_pitch' type='revolute'>
      <child>l_ankle_1</child>
      <parent>l_lower_leg</parent>
      <axis>
        <xyz>0 -1 -0</xyz>
        <limit>
          <lower>-0.349066</lower>
          <upper>0.523599</upper>
          <effort>50000</effort>
          <velocity>50000</velocity>
        </limit>
        <dynamics>
          <damping>0.223</damping>
          <friction>0</friction>
          <spring_reference>0</spring_reference>
          <spring_stiffness>0</spring_stiffness>
        </dynamics>
        <use_parent_model_frame>1</use_parent_model_frame>
      </axis>
    </joint>
    <link name='l_ankle_2'>
      <pose>-0.040779 -0.0701 -0.555438 1.5708 0 -1.5708</pose>
      <inertial>
        <pose>-8e-06 -0.038202 -0.04732 0 -0 0</pose>
        <mass>0.267485</mass>
        <inertia>
          <ixx>0.000335682</ixx>
          <ixy>-7.53335e-08</ixy>
          <ixz>2.93681e-08</ixz>
          <iyy>0.00025387</iyy>
          <iyz>-4.26218e-07</iyz>
          <izz>0.000154833</izz>
        </inertia>
      </inertial>
      <collision name='l_ankle_2_collision'>
        <pose>-0.0701 0.587138 -0.004679 0 -0 0</pose>
        <geometry>
          <mesh>
            <scale>0.001 0.001 0.001</scale>
            <uri>model://iCubGenova02/meshes/dae/l_ankle_2.dae</uri>
          </mesh>
        </geometry>
      </collision>
      <visual name='l_ankle_2_visual'>
        <pose>-0.0701 0.587138 -0.004679 0 -0 0</pose>
        <geometry>
          <mesh>
            <scale>0.001 0.001 0.001</scale>
            <uri>model://iCubGenova02/meshes/dae/l_ankle_2.dae</uri>
          </mesh>
        </geometry>
      </visual>
    </link>
    <joint name='l_ankle_roll' type='revolute'>
      <child>l_ankle_2</child>
      <parent>l_ankle_1</parent>
      <axis>
        <xyz>-1 -0 0</xyz>
        <limit>
          <lower>-0.349066</lower>
          <upper>0.349066</upper>
          <effort>50000</effort>
          <velocity>50000</velocity>
        </limit>
        <dynamics>
          <damping>0.223</damping>
          <friction>0</friction>
          <spring_reference>0</spring_reference>
          <spring_stiffness>0</spring_stiffness>
        </dynamics>
        <use_parent_model_frame>1</use_parent_model_frame>
      </axis>
    </joint>
    <link name='l_foot'>
      <pose>0.010809 -0.0701 -0.615738 3.14159 0 -3.14159</pose>
      <inertial>
        <pose>0.033691 -0.005366 -0.001154 -1.5708 -0 -1.5708</pose>
        <mass>0.382372</mass>
        <inertia>
          <ixx>0.00121061</ixx>
          <ixy>-3.65345e-07</ixy>
          <ixz>5.78649e-05</ixz>
          <iyy>0.00141515</iyy>
          <iyz>-7.67241e-06</iyz>
          <izz>0.000273665</izz>
        </inertia>
      </inertial>
      <collision name='l_foot_collision'>
        <pose>0.047209 0.0701 -0.647438 -1.5708 -0 -1.5708</pose>
        <geometry>
          <mesh>
            <scale>0.001 0.001 0.001</scale>
            <uri>model://iCubGenova02/meshes/dae/l_foot.dae</uri>
          </mesh>
        </geometry>
        <surface>
          <contact>
            <ode/>
          </contact>
          <friction>
            <ode/>
          </friction>
        </surface>
        <surface>
          <contact>
            <ode/>
          </contact>
          <friction>
            <ode/>
          </friction>
        </surface>
      </collision>
      <visual name='l_foot_visual'>
        <pose>0.047209 0.0701 -0.647438 -1.5708 -0 -1.5708</pose>
        <geometry>
          <mesh>
            <scale>0.001 0.001 0.001</scale>
            <uri>model://iCubGenova02/meshes/dae/l_foot.dae</uri>
          </mesh>
        </geometry>
      </visual>
      <velocity_decay/>
      <sensor name='l_foot_mtb_acc_10b12' type='imu'>
        <always_on>1</always_on>
        <update_rate>100</update_rate>
        <pose>0.105522 0.000807 -0.001215 0 -0 1.5708</pose>
        <plugin name='iCub_yarp_gazebo_plugin_ACC' filename='libgazebo_yarp_inertialmtb.so'/>
      </sensor>
      <gravity>1</gravity>
      <velocity_decay/>
      <self_collide>0</self_collide>
      <sensor name='l_foot_mtb_acc_10b13' type='imu'>
        <always_on>1</always_on>
        <update_rate>100</update_rate>
        <pose>0.080522 0.011807 -0.001215 0 -0 1.5708</pose>
        <plugin name='iCub_yarp_gazebo_plugin_ACC' filename='libgazebo_yarp_inertialmtb.so'/>
      </sensor>
    </link>
    <joint name='l_foot_ft_sensor' type='revolute'>
      <child>l_foot</child>
      <parent>l_ankle_2</parent>
      <axis>
        <limit>
          <lower>0</lower>
          <upper>0</upper>
        </limit>
        <dynamics>
          <damping>0</damping>
          <friction>0</friction>
          <spring_reference>0</spring_reference>
          <spring_stiffness>0</spring_stiffness>
        </dynamics>
        <use_parent_model_frame>1</use_parent_model_frame>
        <xyz>0 0 1</xyz>
      </axis>
      <physics>
        <ode>
          <limit>
            <cfm>0</cfm>
            <erp>0.2</erp>
          </limit>
        </ode>
      </physics>
      <sensor name='l_foot_ft_sensor' type='force_torque'>
        <always_on>1</always_on>
        <update_rate>100</update_rate>
        <force_torque>
          <frame>child</frame>
          <measure_direction>child_to_parent</measure_direction>
        </force_torque>
      </sensor>
    </joint>
    <link name='r_hip_1'>
      <pose>0.006452 0.023366 -0.119913 1.5708 -0 -1.5708</pose>
      <inertial>
        <pose>-0.040711 -5.9e-05 -0.000523 0 -0 0</pose>
        <mass>0.920354</mass>
        <inertia>
          <ixx>0.000404796</ixx>
          <ixy>-1.20388e-06</ixy>
          <ixz>1.0611e-06</ixz>
          <iyy>0.000575006</iyy>
          <iyz>-5.32287e-07</iyz>
          <izz>0.000580444</izz>
        </inertia>
      </inertial>
      <collision name='r_hip_1_collision'>
        <pose>0.023366 0.151913 0.042852 0 -0 0</pose>
        <geometry>
          <mesh>
            <scale>0.001 0.001 0.001</scale>
            <uri>model://iCubGenova02/meshes/dae/r_hip_1.dae</uri>
          </mesh>
        </geometry>
      </collision>
      <visual name='r_hip_1_visual'>
        <pose>0.023366 0.151913 0.042852 0 -0 0</pose>
        <geometry>
          <mesh>
            <scale>0.001 0.001 0.001</scale>
            <uri>model://iCubGenova02/meshes/dae/r_hip_1.dae</uri>
          </mesh>
        </geometry>
      </visual>
    </link>
    <joint name='r_hip_pitch' type='revolute'>
      <child>r_hip_1</child>
      <parent>root_link</parent>
      <axis>
        <xyz>-0 1 0</xyz>
        <limit>
          <lower>-0.523599</lower>
          <upper>1.48353</upper>
          <effort>50000</effort>
          <velocity>50000</velocity>
        </limit>
        <dynamics>
          <damping>0.223</damping>
          <friction>0</friction>
          <spring_reference>0</spring_reference>
          <spring_stiffness>0</spring_stiffness>
        </dynamics>
        <use_parent_model_frame>1</use_parent_model_frame>
      </axis>
    </joint>
    <link name='r_hip_2'>
      <pose>0.032796 0.0701 -0.119913 1.5708 -0 -1.5708</pose>
      <inertial>
        <pose>4e-06 -0.044233 0.024898 0 -0 0</pose>
        <mass>0.4194</mass>
        <inertia>
          <ixx>0.00048916</ixx>
          <ixy>-2.70159e-07</ixy>
          <ixz>1.85233e-07</ixz>
          <iyy>0.00028697</iyy>
          <iyz>1.28773e-05</iyz>
          <izz>0.000315599</izz>
        </inertia>
      </inertial>
      <collision name='r_hip_2_collision'>
        <pose>0.0701 0.151913 0.069196 0 -0 0</pose>
        <geometry>
          <mesh>
            <scale>0.001 0.001 0.001</scale>
            <uri>model://iCubGenova02/meshes/dae/r_hip_2.dae</uri>
          </mesh>
        </geometry>
      </collision>
      <visual name='r_hip_2_visual'>
        <pose>0.0701 0.151913 0.069196 0 -0 0</pose>
        <geometry>
          <mesh>
            <scale>0.001 0.001 0.001</scale>
            <uri>model://iCubGenova02/meshes/dae/r_hip_2.dae</uri>
          </mesh>
        </geometry>
      </visual>
    </link>
    <joint name='r_hip_roll' type='revolute'>
      <child>r_hip_2</child>
      <parent>r_hip_1</parent>
      <axis>
        <xyz>1 0 -0</xyz>
        <limit>
          <lower>0</lower>
          <upper>1.5708</upper>
          <effort>50000</effort>
          <velocity>50000</velocity>
        </limit>
        <dynamics>
          <damping>0.223</damping>
          <friction>0</friction>
          <spring_reference>0</spring_reference>
          <spring_stiffness>0</spring_stiffness>
        </dynamics>
        <use_parent_model_frame>1</use_parent_model_frame>
      </axis>
    </joint>
    <link name='r_hip_3'>
      <pose>0.007309 0.0701 -0.194213 3.14159 -0 -3.14159</pose>
      <inertial>
        <pose>-0.000123 -0.000282 0.008718 -1.5708 -0 -1.5708</pose>
        <mass>0.126212</mass>
        <inertia>
          <ixx>3.27938e-05</ixx>
          <ixy>2.67901e-07</ixy>
          <ixz>-4.41463e-09</ixz>
          <iyy>5.69957e-05</iyy>
          <iyz>3.32338e-08</iyz>
          <izz>3.26449e-05</izz>
        </inertia>
      </inertial>
      <collision name='r_hip_3_collision'>
        <pose>0.043709 -0.0701 -0.226213 -1.5708 -0 -1.5708</pose>
        <geometry>
          <mesh>
            <scale>0.001 0.001 0.001</scale>
            <uri>model://iCubGenova02/meshes/dae/r_hip_3.dae</uri>
          </mesh>
        </geometry>
      </collision>
      <visual name='r_hip_3_visual'>
        <pose>0.043709 -0.0701 -0.226213 -1.5708 -0 -1.5708</pose>
        <geometry>
          <mesh>
            <scale>0.001 0.001 0.001</scale>
            <uri>model://iCubGenova02/meshes/dae/r_hip_3.dae</uri>
          </mesh>
        </geometry>
      </visual>
    </link>
    <joint name='r_leg_ft_sensor' type='revolute'>
      <child>r_hip_3</child>
      <parent>r_hip_2</parent>
      <axis>
        <limit>
          <lower>0</lower>
          <upper>0</upper>
        </limit>
        <dynamics>
          <damping>0</damping>
          <friction>0</friction>
          <spring_reference>0</spring_reference>
          <spring_stiffness>0</spring_stiffness>
        </dynamics>
        <use_parent_model_frame>1</use_parent_model_frame>
        <xyz>0 0 1</xyz>
      </axis>
      <physics>
        <ode>
          <limit>
            <cfm>0</cfm>
            <erp>0.2</erp>
          </limit>
        </ode>
      </physics>
      <sensor name='r_leg_ft_sensor' type='force_torque'>
        <always_on>1</always_on>
        <update_rate>100</update_rate>
        <force_torque>
          <frame>child</frame>
          <measure_direction>child_to_parent</measure_direction>
        </force_torque>
      </sensor>
    </joint>
    <link name='r_upper_leg'>
      <pose>0.007309 0.0701 -0.208813 1.5708 0 -1.5708</pose>
      <inertial>
        <pose>-3.9e-05 -0.078897 0.003322 0 -0 0</pose>
        <mass>1.8035</mass>
        <inertia>
          <ixx>0.00647659</ixx>
          <ixy>0.000120497</ixy>
          <ixz>5.1676e-06</ixz>
          <iyy>0.00144565</iyy>
          <iyz>-0.000136871</iyz>
          <izz>0.00646915</izz>
        </inertia>
      </inertial>
      <collision name='r_upper_leg_collision'>
        <pose>0.0701 0.241013 0.043709 0 -0 0</pose>
        <geometry>
          <mesh>
            <scale>0.001 0.001 0.001</scale>
            <uri>model://iCubGenova02/meshes/dae/r_upper_leg.dae</uri>
          </mesh>
        </geometry>
      </collision>
      <visual name='r_upper_leg_visual'>
        <pose>0.0701 0.241013 0.043709 0 -0 0</pose>
        <geometry>
          <mesh>
            <scale>0.001 0.001 0.001</scale>
            <uri>model://iCubGenova02/meshes/dae/r_upper_leg.dae</uri>
          </mesh>
        </geometry>
      </visual>
    </link>
    <joint name='r_hip_yaw' type='revolute'>
      <child>r_upper_leg</child>
      <parent>r_hip_3</parent>
      <axis>
        <xyz>0 0 -1</xyz>
        <limit>
          <lower>-1.22173</lower>
          <upper>1.22173</upper>
          <effort>50000</effort>
          <velocity>50000</velocity>
        </limit>
        <dynamics>
          <damping>0.223</damping>
          <friction>0</friction>
          <spring_reference>0</spring_reference>
          <spring_stiffness>0</spring_stiffness>
        </dynamics>
        <use_parent_model_frame>1</use_parent_model_frame>
      </axis>
    </joint>
    <link name='r_lower_leg'>
      <pose>0.007309 0.046296 -0.354438 1.5708 0 -1.5708</pose>
      <inertial>
        <pose>-0.027417 -0.088787 0.001091 0 -0 0</pose>
        <mass>1.472</mass>
        <inertia>
          <ixx>0.00425264</ixx>
          <ixy>0.000230005</ixy>
          <ixz>-5.52978e-05</ixz>
          <iyy>0.00151456</iyy>
          <iyz>-0.0002616</iyz>
          <izz>0.00459004</izz>
        </inertia>
      </inertial>
      <collision name='r_lower_leg_collision'>
        <pose>0.046296 0.386638 0.043709 0 -0 0</pose>
        <geometry>
          <mesh>
            <scale>0.001 0.001 0.001</scale>
            <uri>model://iCubGenova02/meshes/dae/r_lower_leg.dae</uri>
          </mesh>
        </geometry>
      </collision>
      <visual name='r_lower_leg_visual'>
        <pose>0.046296 0.386638 0.043709 0 -0 0</pose>
        <geometry>
          <mesh>
            <scale>0.001 0.001 0.001</scale>
            <uri>model://iCubGenova02/meshes/dae/r_lower_leg.dae</uri>
          </mesh>
        </geometry>
      </visual>
    </link>
    <joint name='r_knee' type='revolute'>
      <child>r_lower_leg</child>
      <parent>r_upper_leg</parent>
      <axis>
        <xyz>-0 1 0</xyz>
        <limit>
          <lower>-1.74533</lower>
          <upper>0</upper>
          <effort>50000</effort>
          <velocity>50000</velocity>
        </limit>
        <dynamics>
          <damping>0.223</damping>
          <friction>0</friction>
          <spring_reference>0</spring_reference>
          <spring_stiffness>0</spring_stiffness>
        </dynamics>
        <use_parent_model_frame>1</use_parent_model_frame>
      </axis>
    </joint>
    <link name='r_ankle_1'>
      <pose>0.007309 0.1056 -0.555438 1.5708 0 -1.5708</pose>
      <inertial>
        <pose>0.034628 6.3e-05 0.015251 0 -0 0</pose>
        <mass>0.6803</mass>
        <inertia>
          <ixx>0.000405201</ixx>
          <ixy>7.40602e-07</ixy>
          <ixz>-3.03315e-05</ixz>
          <iyy>0.000449108</iyy>
          <iyz>2.88976e-06</iyz>
          <izz>0.000310063</izz>
        </inertia>
      </inertial>
      <collision name='r_ankle_1_collision'>
        <pose>0.1056 0.587138 0.043709 0 -0 0</pose>
        <geometry>
          <mesh>
            <scale>0.001 0.001 0.001</scale>
            <uri>model://iCubGenova02/meshes/dae/r_ankle_1.dae</uri>
          </mesh>
        </geometry>
      </collision>
      <visual name='r_ankle_1_visual'>
        <pose>0.1056 0.587138 0.043709 0 -0 0</pose>
        <geometry>
          <mesh>
            <scale>0.001 0.001 0.001</scale>
            <uri>model://iCubGenova02/meshes/dae/r_ankle_1.dae</uri>
          </mesh>
        </geometry>
      </visual>
    </link>
    <joint name='r_ankle_pitch' type='revolute'>
      <child>r_ankle_1</child>
      <parent>r_lower_leg</parent>
      <axis>
        <xyz>0 -1 -0</xyz>
        <limit>
          <lower>-0.349066</lower>
          <upper>0.523599</upper>
          <effort>50000</effort>
          <velocity>50000</velocity>
        </limit>
        <dynamics>
          <damping>0.223</damping>
          <friction>0</friction>
          <spring_reference>0</spring_reference>
          <spring_stiffness>0</spring_stiffness>
        </dynamics>
        <use_parent_model_frame>1</use_parent_model_frame>
      </axis>
    </joint>
    <link name='r_ankle_2'>
      <pose>0.025809 0.0701 -0.555438 1.5708 0 -1.5708</pose>
      <inertial>
        <pose>-8e-06 -0.038202 0.019267 0 -0 0</pose>
        <mass>0.267485</mass>
        <inertia>
          <ixx>0.000335682</ixx>
          <ixy>-7.53335e-08</ixy>
          <ixz>2.93681e-08</ixz>
          <iyy>0.00025387</iyy>
          <iyz>-4.26218e-07</iyz>
          <izz>0.000154833</izz>
        </inertia>
      </inertial>
      <collision name='r_ankle_2_collision'>
        <pose>0.0701 0.587138 0.062209 0 -0 0</pose>
        <geometry>
          <mesh>
            <scale>0.001 0.001 0.001</scale>
            <uri>model://iCubGenova02/meshes/dae/r_ankle_2.dae</uri>
          </mesh>
        </geometry>
      </collision>
      <visual name='r_ankle_2_visual'>
        <pose>0.0701 0.587138 0.062209 0 -0 0</pose>
        <geometry>
          <mesh>
            <scale>0.001 0.001 0.001</scale>
            <uri>model://iCubGenova02/meshes/dae/r_ankle_2.dae</uri>
          </mesh>
        </geometry>
      </visual>
    </link>
    <joint name='r_ankle_roll' type='revolute'>
      <child>r_ankle_2</child>
      <parent>r_ankle_1</parent>
      <axis>
        <xyz>1 0 0</xyz>
        <limit>
          <lower>-0.349066</lower>
          <upper>0.349066</upper>
          <effort>50000</effort>
          <velocity>50000</velocity>
        </limit>
        <dynamics>
          <damping>0.223</damping>
          <friction>0</friction>
          <spring_reference>0</spring_reference>
          <spring_stiffness>0</spring_stiffness>
        </dynamics>
        <use_parent_model_frame>1</use_parent_model_frame>
      </axis>
    </joint>
    <link name='r_foot'>
      <pose>0.010809 0.0701 -0.615738 3.14159 0 -3.14159</pose>
      <inertial>
        <pose>0.033624 0.005365 -0.001138 -1.5708 -0 -1.5708</pose>
        <mass>0.38227</mass>
        <inertia>
          <ixx>0.00120765</ixx>
          <ixy>3.70545e-07</ixy>
          <ixz>-5.78137e-05</ixz>
          <iyy>0.00141242</iyy>
          <iyz>-7.82502e-06</iyz>
          <izz>0.000273419</izz>
        </inertia>
      </inertial>
      <collision name='r_foot_collision'>
        <pose>0.047209 -0.0701 -0.647438 -1.5708 -0 -1.5708</pose>
        <geometry>
          <mesh>
            <scale>0.001 0.001 0.001</scale>
            <uri>model://iCubGenova02/meshes/dae/r_foot.dae</uri>
          </mesh>
        </geometry>
      </collision>
      <visual name='r_foot_visual'>
        <pose>0.047209 -0.0701 -0.647438 -1.5708 -0 -1.5708</pose>
        <geometry>
          <mesh>
            <scale>0.001 0.001 0.001</scale>
            <uri>model://iCubGenova02/meshes/dae/r_foot.dae</uri>
          </mesh>
        </geometry>
      </visual>
    </link>
    <joint name='r_foot_ft_sensor' type='revolute'>
      <child>r_foot</child>
      <parent>r_ankle_2</parent>
      <axis>
        <limit>
          <lower>0</lower>
          <upper>0</upper>
        </limit>
        <dynamics>
          <damping>0</damping>
          <friction>0</friction>
          <spring_reference>0</spring_reference>
          <spring_stiffness>0</spring_stiffness>
        </dynamics>
        <use_parent_model_frame>1</use_parent_model_frame>
        <xyz>0 0 1</xyz>
      </axis>
      <physics>
        <ode>
          <limit>
            <cfm>0</cfm>
            <erp>0.2</erp>
          </limit>
        </ode>
      </physics>
      <sensor name='r_foot_ft_sensor' type='force_torque'>
        <always_on>1</always_on>
        <update_rate>100</update_rate>
        <force_torque>
          <frame>child</frame>
          <measure_direction>child_to_parent</measure_direction>
        </force_torque>
      </sensor>
    </joint>
    <link name='torso_1'>
      <pose>0 0.027046 0 1.5708 -0 -1.5708</pose>
      <inertial>
        <pose>0.027092 0.029148 -0.00044 0 -0 0</pose>
        <mass>0.67144</mass>
        <inertia>
          <ixx>0.00040911</ixx>
          <ixy>-1.04522e-06</ixy>
          <ixz>-1.02516e-06</ixz>
          <iyy>0.000384141</iyy>
          <iyz>6.50708e-06</iyz>
          <izz>0.000299445</izz>
        </inertia>
      </inertial>
      <collision name='torso_1_collision'>
        <pose>0.027046 0.032 0.0364 0 -0 0</pose>
        <geometry>
          <mesh>
            <scale>0.001 0.001 0.001</scale>
            <uri>model://iCubGenova02/meshes/dae/torso_1.dae</uri>
          </mesh>
        </geometry>
      </collision>
      <visual name='torso_1_visual'>
        <pose>0.027046 0.032 0.0364 0 -0 0</pose>
        <geometry>
          <mesh>
            <scale>0.001 0.001 0.001</scale>
            <uri>model://iCubGenova02/meshes/dae/torso_1.dae</uri>
          </mesh>
        </geometry>
      </visual>
    </link>
    <joint name='torso_pitch' type='revolute'>
      <child>torso_1</child>
      <parent>root_link</parent>
      <axis>
        <xyz>0 -1 -0</xyz>
        <limit>
          <lower>-0.349066</lower>
          <upper>1.22173</upper>
          <effort>50000</effort>
          <velocity>50000</velocity>
        </limit>
        <dynamics>
          <damping>0.06</damping>
          <friction>0</friction>
          <spring_reference>0</spring_reference>
          <spring_stiffness>0</spring_stiffness>
        </dynamics>
        <use_parent_model_frame>1</use_parent_model_frame>
      </axis>
    </joint>
    <link name='torso_2'>
      <pose>0.057691 0 0.032 1.5708 -0 -1.5708</pose>
      <inertial>
        <pose>-0.000113 0.036182 0.057661 0 -0 0</pose>
        <mass>0.428161</mass>
        <inertia>
          <ixx>0.000833014</ixx>
          <ixy>2.2275e-08</ixy>
          <ixz>8.1931e-08</ixz>
          <iyy>0.000440576</iyy>
          <iyz>-6.00823e-07</iyz>
          <izz>0.000605488</izz>
        </inertia>
      </inertial>
      <collision name='torso_2_collision'>
        <pose>0 0.1433 0.038998 0 -0 0</pose>
        <geometry>
          <mesh>
            <scale>0.001 0.001 0.001</scale>
            <uri>model://iCubGenova02/meshes/dae/torso_2.dae</uri>
          </mesh>
        </geometry>
      </collision>
      <visual name='torso_2_visual'>
        <pose>0 0.1433 0.038998 0 -0 0</pose>
        <geometry>
          <mesh>
            <scale>0.001 0.001 0.001</scale>
            <uri>model://iCubGenova02/meshes/dae/torso_2.dae</uri>
          </mesh>
        </geometry>
      </visual>
    </link>
    <joint name='torso_roll' type='revolute'>
      <child>torso_2</child>
      <parent>torso_1</parent>
      <axis>
        <xyz>-1 -0 0</xyz>
        <limit>
          <lower>-0.523599</lower>
          <upper>0.523599</upper>
          <effort>50000</effort>
          <velocity>50000</velocity>
        </limit>
        <dynamics>
          <damping>0.06</damping>
          <friction>0</friction>
          <spring_reference>0</spring_reference>
          <spring_stiffness>0</spring_stiffness>
        </dynamics>
        <use_parent_model_frame>1</use_parent_model_frame>
      </axis>
    </joint>
    <link name='chest'>
      <pose>-0.005497 0 0.082 1.5708 -0 -1.5708</pose>
      <inertial>
        <pose>0.000189 0.073091 -0.047238 0 -0 0</pose>
        <mass>7.638</mass>
        <inertia>
          <ixx>0.0430325</ixx>
          <ixy>2.91075e-05</ixy>
          <ixz>0.000181985</ixz>
          <iyy>0.0440836</iyy>
          <iyz>-0.000429106</iyz>
          <izz>0.0260563</izz>
        </inertia>
      </inertial>
      <collision name='chest_collision'>
        <pose>0 0.0928 -0.024189 0 -0 0</pose>
        <geometry>
          <mesh>
            <scale>0.001 0.001 0.001</scale>
            <uri>model://iCubGenova02/meshes/dae/bb_chest.dae</uri>
          </mesh>
        </geometry>
      </collision>
      <visual name='chest_visual'>
        <pose>0 0.0928 -0.024189 0 -0 0</pose>
        <geometry>
          <mesh>
            <scale>0.001 0.001 0.001</scale>
            <uri>model://iCubGenova02/meshes/dae/bb_chest.dae</uri>
          </mesh>
        </geometry>
      </visual>
    </link>
    <joint name='torso_yaw' type='revolute'>
      <child>chest</child>
      <parent>torso_2</parent>
      <axis>
        <xyz>-0 0 -1</xyz>
        <limit>
          <lower>-0.872665</lower>
          <upper>0.872665</upper>
          <effort>50000</effort>
          <velocity>50000</velocity>
        </limit>
        <dynamics>
          <damping>0.06</damping>
          <friction>0</friction>
          <spring_reference>0</spring_reference>
          <spring_stiffness>0</spring_stiffness>
        </dynamics>
        <use_parent_model_frame>1</use_parent_model_frame>
      </axis>
    </joint>
    <link name='l_shoulder_1'>
      <pose>-0.013466 -0.120016 0.1748 1.5708 -0 -1.5708</pose>
      <inertial>
        <pose>-0.008985 -3.3e-05 -0.0089 0 -0 0</pose>
        <mass>0.114882</mass>
        <inertia>
          <ixx>2.24676e-05</ixx>
          <ixy>-1.77064e-08</ixy>
          <ixz>3.55951e-06</ixz>
          <iyy>2.29712e-05</iyy>
          <iyz>6.57597e-08</iyz>
          <izz>1.00139e-05</izz>
        </inertia>
      </inertial>
      <collision name='l_shoulder_1_collision'>
        <pose>-0.120257 0 -0.032223 0 -0 0</pose>
        <geometry>
          <mesh>
            <scale>0.001 0.001 0.001</scale>
            <uri>model://iCubGenova02/meshes/dae/l_shoulder_1.dae</uri>
          </mesh>
        </geometry>
      </collision>
      <visual name='l_shoulder_1_visual'>
        <pose>-0.120257 0 -0.032223 0 -0 0</pose>
        <geometry>
          <mesh>
            <scale>0.001 0.001 0.001</scale>
            <uri>model://iCubGenova02/meshes/dae/l_shoulder_1.dae</uri>
          </mesh>
        </geometry>
      </visual>
    </link>
    <joint name='l_shoulder_pitch' type='revolute'>
      <child>l_shoulder_1</child>
      <parent>chest</parent>
      <axis>
        <xyz>-0.258819 -0.965926 0</xyz>
        <limit>
          <lower>-1.66679</lower>
          <upper>0.174533</upper>
          <effort>50000</effort>
          <velocity>50000</velocity>
        </limit>
        <dynamics>
          <damping>0.06</damping>
          <friction>0</friction>
          <spring_reference>0</spring_reference>
          <spring_stiffness>0</spring_stiffness>
        </dynamics>
        <use_parent_model_frame>1</use_parent_model_frame>
      </axis>
    </joint>
    <link name='l_shoulder_2'>
      <pose>-0.021986 -0.106345 0.1748 -3.14159 1.309 -0.261799</pose>
      <inertial>
        <pose>0.021475 0.000269 -0.019411 0 -0 0</pose>
        <mass>0.239074</mass>
        <inertia>
          <ixx>0.000159206</ixx>
          <ixy>1.51033e-07</ixy>
          <ixz>-1.04783e-05</ixz>
          <iyy>0.000207209</iyy>
          <iyz>1.20634e-06</iyz>
          <izz>0.000105106</izz>
        </inertia>
      </inertial>
      <collision name='l_shoulder_2_collision'>
        <pose>-0.106587 0 -0.040743 0 -0 0</pose>
        <geometry>
          <mesh>
            <scale>0.001 0.001 0.001</scale>
            <uri>model://iCubGenova02/meshes/dae/l_shoulder_2.dae</uri>
          </mesh>
        </geometry>
      </collision>
      <visual name='l_shoulder_2_visual'>
        <pose>-0.106587 0 -0.040743 0 -0 0</pose>
        <geometry>
          <mesh>
            <scale>0.001 0.001 0.001</scale>
            <uri>model://iCubGenova02/meshes/dae/l_shoulder_2.dae</uri>
          </mesh>
        </geometry>
      </visual>
    </link>
    <joint name='l_shoulder_roll' type='revolute'>
      <child>l_shoulder_2</child>
      <parent>l_shoulder_1</parent>
      <axis>
        <xyz>-0.965926 0.258819 0</xyz>
        <limit>
          <lower>0</lower>
          <upper>2.80649</upper>
          <effort>50000</effort>
          <velocity>50000</velocity>
        </limit>
        <dynamics>
          <damping>0.06</damping>
          <friction>0</friction>
          <spring_reference>0</spring_reference>
          <spring_stiffness>0</spring_stiffness>
        </dynamics>
        <use_parent_model_frame>1</use_parent_model_frame>
      </axis>
    </joint>
    <link name='l_shoulder_3'>
      <pose>-0.010619 -0.109391 0.151746 -3.14159 1.309 0</pose>
      <inertial>
        <pose>0.026798 -1.6e-05 0.014696 0 -0 0</pose>
        <mass>0.35913</mass>
        <inertia>
          <ixx>0.00014245</ixx>
          <ixy>-2.22441e-07</ixy>
          <ixz>-4.95846e-05</ixz>
          <iyy>0.000197807</iyy>
          <iyz>1.07538e-07</iyz>
          <izz>0.000151706</izz>
        </inertia>
      </inertial>
      <collision name='l_shoulder_3_collision'>
        <pose>-0.131901 0 -0.035343 0 -0 0</pose>
        <geometry>
          <mesh>
            <scale>0.001 0.001 0.001</scale>
            <uri>model://iCubGenova02/meshes/dae/l_shoulder_3.dae</uri>
          </mesh>
        </geometry>
      </collision>
      <visual name='l_shoulder_3_visual'>
        <pose>-0.131901 0 -0.035343 0 -0 0</pose>
        <geometry>
          <mesh>
            <scale>0.001 0.001 0.001</scale>
            <uri>model://iCubGenova02/meshes/dae/l_shoulder_3.dae</uri>
          </mesh>
        </geometry>
      </visual>
    </link>
    <joint name='l_shoulder_yaw' type='revolute'>
      <child>l_shoulder_3</child>
      <parent>l_shoulder_2</parent>
      <axis>
        <xyz>-0 0 -1</xyz>
        <limit>
          <lower>-0.645772</lower>
          <upper>1.39626</upper>
          <effort>50000</effort>
          <velocity>50000</velocity>
        </limit>
        <dynamics>
          <damping>0.06</damping>
          <friction>0</friction>
          <spring_reference>0</spring_reference>
          <spring_stiffness>0</spring_stiffness>
        </dynamics>
        <use_parent_model_frame>1</use_parent_model_frame>
      </axis>
    </joint>
    <link name='l_upper_arm'>
      <pose>-0.025619 -0.109391 0.095 3.14159 -0 -3.14159</pose>
      <inertial>
        <pose>-0.006121 -0.000189 0.029368 0 -1.309 3.14159</pose>
        <mass>0.746799</mass>
        <inertia>
          <ixx>0.000509731</ixx>
          <ixy>-6.90767e-07</ixy>
          <ixz>1.20048e-05</ixz>
          <iyy>0.00067086</iyy>
          <iyz>3.11833e-06</iyz>
          <izz>0.000601202</izz>
        </inertia>
      </inertial>
      <collision name='l_upper_arm_collision'>
        <pose>-0.015 0 -0.1933 0 -1.309 3.14159</pose>
        <geometry>
          <mesh>
            <scale>0.001 0.001 0.001</scale>
            <uri>model://iCubGenova02/meshes/dae/l_upper_arm.dae</uri>
          </mesh>
        </geometry>
      </collision>
      <visual name='l_upper_arm_visual'>
        <pose>-0.015 0 -0.1933 0 -1.309 3.14159</pose>
        <geometry>
          <mesh>
            <scale>0.001 0.001 0.001</scale>
            <uri>model://iCubGenova02/meshes/dae/l_upper_arm.dae</uri>
          </mesh>
        </geometry>
      </visual>
    </link>
    <joint name='l_arm_ft_sensor' type='revolute'>
      <child>l_upper_arm</child>
      <parent>l_shoulder_3</parent>
      <axis>
        <limit>
          <lower>0</lower>
          <upper>0</upper>
        </limit>
        <dynamics>
          <damping>0</damping>
          <friction>0</friction>
          <spring_reference>0</spring_reference>
          <spring_stiffness>0</spring_stiffness>
        </dynamics>
        <use_parent_model_frame>1</use_parent_model_frame>
        <xyz>0 0 1</xyz>
      </axis>
      <physics>
        <ode>
          <limit>
            <cfm>0</cfm>
            <erp>0.2</erp>
          </limit>
        </ode>
      </physics>
      <sensor name='l_arm_ft_sensor' type='force_torque'>
        <always_on>1</always_on>
        <update_rate>100</update_rate>
        <force_torque>
          <frame>child</frame>
          <measure_direction>child_to_parent</measure_direction>
        </force_torque>
      </sensor>
    </joint>
    <link name='l_elbow_1'>
      <pose>-0.025619 -0.075391 0.01574 -3.14159 1.309 0</pose>
      <inertial>
        <pose>0.090439 0.02985 0.009215 0 -0 0</pose>
        <mass>1.17718</mass>
        <inertia>
          <ixx>0.00107783</ixx>
          <ixy>0.000310534</ixy>
          <ixz>-0.00156091</ixz>
          <iyy>0.00689571</iyy>
          <iyz>0.000135264</iyz>
          <izz>0.00628941</izz>
        </inertia>
      </inertial>
      <collision name='l_elbow_1_collision'>
        <pose>-0.25939 0.034 -0.085033 0 -0 0</pose>
        <geometry>
          <mesh>
            <scale>0.001 0.001 0.001</scale>
            <uri>model://iCubGenova02/meshes/dae/l_elbow_1.dae</uri>
          </mesh>
        </geometry>
      </collision>
      <visual name='l_elbow_1_visual'>
        <pose>-0.25939 0.034 -0.085033 0 -0 0</pose>
        <geometry>
          <mesh>
            <scale>0.001 0.001 0.001</scale>
            <uri>model://iCubGenova02/meshes/dae/l_elbow_1.dae</uri>
          </mesh>
        </geometry>
      </visual>
    </link>
    <joint name='l_elbow' type='revolute'>
      <child>l_elbow_1</child>
      <parent>l_upper_arm</parent>
      <axis>
        <xyz>-0 1 0</xyz>
        <limit>
          <lower>0.261799</lower>
          <upper>1.85005</upper>
          <effort>50000</effort>
          <velocity>50000</velocity>
        </limit>
        <dynamics>
          <damping>0.06</damping>
          <friction>0</friction>
          <spring_reference>0</spring_reference>
          <spring_stiffness>0</spring_stiffness>
        </dynamics>
        <use_parent_model_frame>1</use_parent_model_frame>
      </axis>
    </joint>
    <link name='neck_1'>
      <pose>-0.010808 0.0143 0.254797 1.5708 -0 -1.5708</pose>
      <inertial>
        <pose>0.014371 0.006567 -0.006384 0 -0 0</pose>
        <mass>0.125793</mass>
        <inertia>
          <ixx>4.0647e-05</ixx>
          <ixy>8.09156e-08</ixy>
          <ixz>-3.74998e-08</ixz>
          <iyy>3.881e-05</iyy>
          <iyz>9.39717e-06</iyz>
          <izz>4.7535e-05</izz>
        </inertia>
      </inertial>
      <collision name='neck_1_collision'>
        <pose>0.0143 -0.079997 -0.029501 0 -0 0</pose>
        <geometry>
          <mesh>
            <scale>0.001 0.001 0.001</scale>
            <uri>model://iCubGenova02/meshes/dae/neck_1.dae</uri>
          </mesh>
        </geometry>
      </collision>
      <visual name='neck_1_visual'>
        <pose>0.0143 -0.079997 -0.029501 0 -0 0</pose>
        <geometry>
          <mesh>
            <scale>0.001 0.001 0.001</scale>
            <uri>model://iCubGenova02/meshes/dae/neck_1.dae</uri>
          </mesh>
        </geometry>
      </visual>
    </link>
    <joint name='neck_pitch' type='revolute'>
      <child>neck_1</child>
      <parent>chest</parent>
      <axis>
        <xyz>-0 1 0</xyz>
        <limit>
          <lower>-0.698132</lower>
          <upper>0.383972</upper>
          <effort>50000</effort>
          <velocity>50000</velocity>
        </limit>
        <dynamics>
          <damping>0.06</damping>
          <friction>0</friction>
          <spring_reference>0</spring_reference>
          <spring_stiffness>0</spring_stiffness>
        </dynamics>
        <use_parent_model_frame>1</use_parent_model_frame>
      </axis>
    </joint>
    <link name='neck_2'>
      <pose>-0.031608 0 0.264297 1.5708 -0 -1.5708</pose>
      <inertial>
        <pose>-8.9e-05 0.035225 -0.019545 0 -0 0</pose>
        <mass>0.177087</mass>
        <inertia>
          <ixx>0.000117943</ixx>
          <ixy>-5.25591e-07</ixy>
          <ixz>4.68307e-07</ixz>
          <iyy>4.04013e-05</iyy>
          <iyz>9.81476e-06</iyz>
          <izz>0.000105186</izz>
        </inertia>
      </inertial>
      <collision name='neck_2_collision'>
        <pose>0 -0.089497 -0.050301 0 -0 0</pose>
        <geometry>
          <mesh>
            <scale>0.001 0.001 0.001</scale>
            <uri>model://iCubGenova02/meshes/dae/neck_2.dae</uri>
          </mesh>
        </geometry>
      </collision>
      <visual name='neck_2_visual'>
        <pose>0 -0.089497 -0.050301 0 -0 0</pose>
        <geometry>
          <mesh>
            <scale>0.001 0.001 0.001</scale>
            <uri>model://iCubGenova02/meshes/dae/neck_2.dae</uri>
          </mesh>
        </geometry>
      </visual>
    </link>
    <joint name='neck_roll' type='revolute'>
      <child>neck_2</child>
      <parent>neck_1</parent>
      <axis>
        <xyz>-1 -0 0</xyz>
        <limit>
          <lower>-0.349066</lower>
          <upper>0.349066</upper>
          <effort>50000</effort>
          <velocity>50000</velocity>
        </limit>
        <dynamics>
          <damping>0.06</damping>
          <friction>0</friction>
          <spring_reference>0</spring_reference>
          <spring_stiffness>0</spring_stiffness>
        </dynamics>
        <use_parent_model_frame>1</use_parent_model_frame>
      </axis>
    </joint>
    <link name='head'>
      <pose>-0.010808 0 0.241953 1.5708 -0 -1.5708</pose>
      <inertial>
        <pose>-0.000574 0.113511 -0.007539 0 -0 0</pose>
        <mass>1.50691</mass>
        <inertia>
          <ixx>0.00680478</ixx>
          <ixy>-1.60267e-05</ixy>
          <ixz>7.28166e-05</ixz>
          <iyy>0.00634736</iyy>
          <iyz>0.000292091</iyz>
          <izz>0.00478116</izz>
        </inertia>
      </inertial>
      <collision name='head_collision'>
        <pose>0 -0.067153 -0.029501 0 -0 0</pose>
        <geometry>
          <mesh>
            <scale>0.001 0.001 0.001</scale>
            <uri>model://iCubGenova02/meshes/dae/head.dae</uri>
          </mesh>
        </geometry>
        <surface>
          <contact>
            <ode/>
          </contact>
          <friction>
            <ode/>
          </friction>
        </surface>
      </collision>
      <visual name='head_visual'>
        <pose>0 -0.067153 -0.029501 0 -0 0</pose>
        <geometry>
          <mesh>
            <scale>0.001 0.001 0.001</scale>
            <uri>model://iCubGenova02/meshes/dae/head.dae</uri>
          </mesh>
        </geometry>
      </visual>
      <gravity>1</gravity>
      <velocity_decay/>
      <self_collide>0</self_collide>
      <sensor name='imu_frame' type='imu'>
        <always_on>1</always_on>
        <update_rate>100</update_rate>
        <pose>0.0095 0.133444 0.0093 -1.57081 1.5708 -1.1e-05</pose>
        <plugin name='iCub_yarp_gazebo_plugin_IMU' filename='libgazebo_yarp_imu.so'>
          <yarpConfigurationFile>model://iCubGenova02/conf/inertial.ini</yarpConfigurationFile>
        </plugin>
      </sensor>
    </link>
    <joint name='neck_yaw' type='revolute'>
      <child>head</child>
      <parent>neck_2</parent>
      <axis>
        <xyz>0 -0 1</xyz>
        <limit>
          <lower>-0.872665</lower>
          <upper>0.872665</upper>
          <effort>50000</effort>
          <velocity>50000</velocity>
        </limit>
        <dynamics>
          <damping>0.06</damping>
          <friction>0</friction>
          <spring_reference>0</spring_reference>
          <spring_stiffness>0</spring_stiffness>
        </dynamics>
        <use_parent_model_frame>1</use_parent_model_frame>
      </axis>
    </joint>
    <link name='r_shoulder_1'>
      <pose>-0.013466 0.120016 0.1748 -1.5708 -0 2.0944</pose>
      <inertial>
        <pose>-0.012266 3.2e-05 -0.003211 0 -0 0</pose>
        <mass>0.114862</mass>
        <inertia>
          <ixx>2.24541e-05</ixx>
          <ixy>-1.65173e-08</ixy>
          <ixz>-3.55626e-06</ixz>
          <iyy>2.29582e-05</iyy>
          <iyz>-6.13337e-08</iyz>
          <izz>1.00116e-05</izz>
        </inertia>
      </inertial>
      <collision name='r_shoulder_1_collision'>
        <pose>0.099008 0 -0.026529 0 -0 0</pose>
        <geometry>
          <mesh>
            <scale>0.001 0.001 0.001</scale>
            <uri>model://iCubGenova02/meshes/dae/r_shoulder_1.dae</uri>
          </mesh>
        </geometry>
      </collision>
      <visual name='r_shoulder_1_visual'>
        <pose>0.099008 0 -0.026529 0 -0 0</pose>
        <geometry>
          <mesh>
            <scale>0.001 0.001 0.001</scale>
            <uri>model://iCubGenova02/meshes/dae/r_shoulder_1.dae</uri>
          </mesh>
        </geometry>
      </visual>
    </link>
    <joint name='r_shoulder_pitch' type='revolute'>
      <child>r_shoulder_1</child>
      <parent>chest</parent>
      <axis>
        <xyz>0.258819 -0.965926 -0</xyz>
        <limit>
          <lower>-1.66679</lower>
          <upper>0.174533</upper>
          <effort>50000</effort>
          <velocity>50000</velocity>
        </limit>
        <dynamics>
          <damping>0.06</damping>
          <friction>0</friction>
          <spring_reference>0</spring_reference>
          <spring_stiffness>0</spring_stiffness>
        </dynamics>
        <use_parent_model_frame>1</use_parent_model_frame>
      </axis>
    </joint>
    <link name='r_shoulder_2'>
      <pose>-0.021982 0.106346 0.1748 -3.14159 -1.309 -2.87979</pose>
      <inertial>
        <pose>-0.021414 0.000272 -0.01944 0 -0 0</pose>
        <mass>0.238162</mass>
        <inertia>
          <ixx>0.000158626</ixx>
          <ixy>-1.12091e-07</ixy>
          <ixz>1.02574e-05</ixz>
          <iyy>0.000206526</iyy>
          <iyz>1.19785e-06</iyz>
          <izz>0.000104956</izz>
        </inertia>
      </inertial>
      <collision name='r_shoulder_2_collision'>
        <pose>0.106588 0 -0.040739 0 -0 0</pose>
        <geometry>
          <mesh>
            <scale>0.001 0.001 0.001</scale>
            <uri>model://iCubGenova02/meshes/dae/r_shoulder_2.dae</uri>
          </mesh>
        </geometry>
      </collision>
      <visual name='r_shoulder_2_visual'>
        <pose>0.106588 0 -0.040739 0 -0 0</pose>
        <geometry>
          <mesh>
            <scale>0.001 0.001 0.001</scale>
            <uri>model://iCubGenova02/meshes/dae/r_shoulder_2.dae</uri>
          </mesh>
        </geometry>
      </visual>
    </link>
    <joint name='r_shoulder_roll' type='revolute'>
      <child>r_shoulder_2</child>
      <parent>r_shoulder_1</parent>
      <axis>
        <xyz>0.965926 0.258819 -0</xyz>
        <limit>
          <lower>0</lower>
          <upper>2.80649</upper>
          <effort>50000</effort>
          <velocity>50000</velocity>
        </limit>
        <dynamics>
          <damping>0.06</damping>
          <friction>0</friction>
          <spring_reference>0</spring_reference>
          <spring_stiffness>0</spring_stiffness>
        </dynamics>
        <use_parent_model_frame>1</use_parent_model_frame>
      </axis>
    </joint>
    <link name='r_shoulder_3'>
      <pose>-0.010619 0.109391 0.151712 -3.14159 -1.309 -3.14159</pose>
      <inertial>
        <pose>-0.026762 -7e-06 0.0147 0 -0 0</pose>
        <mass>0.35913</mass>
        <inertia>
          <ixx>0.000142333</ixx>
          <ixy>3.60361e-07</ixy>
          <ixz>4.94445e-05</ixz>
          <iyy>0.000197746</iyy>
          <iyz>2.65919e-07</iyz>
          <izz>0.000151821</izz>
        </inertia>
      </inertial>
      <collision name='r_shoulder_3_collision'>
        <pose>0.131934 0 -0.035352 0 -0 0</pose>
        <geometry>
          <mesh>
            <scale>0.001 0.001 0.001</scale>
            <uri>model://iCubGenova02/meshes/dae/r_shoulder_3.dae</uri>
          </mesh>
        </geometry>
      </collision>
      <visual name='r_shoulder_3_visual'>
        <pose>0.131934 0 -0.035352 0 -0 0</pose>
        <geometry>
          <mesh>
            <scale>0.001 0.001 0.001</scale>
            <uri>model://iCubGenova02/meshes/dae/r_shoulder_3.dae</uri>
          </mesh>
        </geometry>
      </visual>
    </link>
    <joint name='r_shoulder_yaw' type='revolute'>
      <child>r_shoulder_3</child>
      <parent>r_shoulder_2</parent>
      <axis>
        <xyz>0 0 1</xyz>
        <limit>
          <lower>-0.645772</lower>
          <upper>1.39626</upper>
          <effort>50000</effort>
          <velocity>50000</velocity>
        </limit>
        <dynamics>
          <damping>0.06</damping>
          <friction>0</friction>
          <spring_reference>0</spring_reference>
          <spring_stiffness>0</spring_stiffness>
        </dynamics>
        <use_parent_model_frame>1</use_parent_model_frame>
      </axis>
    </joint>
    <link name='r_upper_arm'>
      <pose>-0.025619 0.109391 0.095 -3.14159 -0 -3.14159</pose>
      <inertial>
        <pose>-0.006087 0.000126 0.029312 0 1.309 0</pose>
        <mass>0.745104</mass>
        <inertia>
          <ixx>0.000509527</ixx>
          <ixy>1.19292e-06</ixy>
          <ixz>-1.17426e-05</ixz>
          <iyy>0.000668487</iyy>
          <iyz>1.13363e-06</iyz>
          <izz>0.000599254</izz>
        </inertia>
      </inertial>
      <collision name='r_upper_arm_collision'>
        <pose>-0.015 0 -0.1933 0 1.309 0</pose>
        <geometry>
          <mesh>
            <scale>0.001 0.001 0.001</scale>
            <uri>model://iCubGenova02/meshes/dae/r_upper_arm.dae</uri>
          </mesh>
        </geometry>
      </collision>
      <visual name='r_upper_arm_visual'>
        <pose>-0.015 0 -0.1933 0 1.309 0</pose>
        <geometry>
          <mesh>
            <scale>0.001 0.001 0.001</scale>
            <uri>model://iCubGenova02/meshes/dae/r_upper_arm.dae</uri>
          </mesh>
        </geometry>
      </visual>
    </link>
    <joint name='r_arm_ft_sensor' type='revolute'>
      <child>r_upper_arm</child>
      <parent>r_shoulder_3</parent>
      <axis>
        <limit>
          <lower>0</lower>
          <upper>0</upper>
        </limit>
        <dynamics>
          <damping>0</damping>
          <friction>0</friction>
          <spring_reference>0</spring_reference>
          <spring_stiffness>0</spring_stiffness>
        </dynamics>
        <use_parent_model_frame>1</use_parent_model_frame>
        <xyz>0 0 1</xyz>
      </axis>
      <physics>
        <ode>
          <limit>
            <cfm>0</cfm>
            <erp>0.2</erp>
          </limit>
        </ode>
      </physics>
      <sensor name='r_arm_ft_sensor' type='force_torque'>
        <always_on>1</always_on>
        <update_rate>100</update_rate>
        <force_torque>
          <frame>child</frame>
          <measure_direction>child_to_parent</measure_direction>
        </force_torque>
      </sensor>
    </joint>
    <link name='r_elbow_1'>
      <pose>-0.025619 0.086891 0.01574 -3.14159 -1.309 -3.14159</pose>
      <inertial>
        <pose>-0.0905 0.01842 0.009185 0 -0 0</pose>
        <mass>1.17637</mass>
        <inertia>
          <ixx>0.00107282</ixx>
          <ixy>-0.000311989</ixy>
          <ixz>0.00155336</ixz>
          <iyy>0.00689615</iyy>
          <iyz>0.000137135</iyz>
          <izz>0.00629364</izz>
        </inertia>
      </inertial>
      <collision name='r_elbow_1_collision'>
        <pose>0.25939 0.0225 -0.085033 0 -0 0</pose>
        <geometry>
          <mesh>
            <scale>0.001 0.001 0.001</scale>
            <uri>model://iCubGenova02/meshes/dae/r_elbow_1.dae</uri>
          </mesh>
        </geometry>
      </collision>
      <visual name='r_elbow_1_visual'>
        <pose>0.25939 0.0225 -0.085033 0 -0 0</pose>
        <geometry>
          <mesh>
            <scale>0.001 0.001 0.001</scale>
            <uri>model://iCubGenova02/meshes/dae/r_elbow_1.dae</uri>
          </mesh>
        </geometry>
      </visual>
    </link>
    <joint name='r_elbow' type='revolute'>
      <child>r_elbow_1</child>
      <parent>r_upper_arm</parent>
      <axis>
        <xyz>-0 1 -0</xyz>
        <limit>
          <lower>0.261799</lower>
          <upper>1.85005</upper>
          <effort>50000</effort>
          <velocity>50000</velocity>
        </limit>
        <dynamics>
          <damping>0.06</damping>
          <friction>0</friction>
          <spring_reference>0</spring_reference>
          <spring_stiffness>0</spring_stiffness>
        </dynamics>
        <use_parent_model_frame>1</use_parent_model_frame>
      </axis>
    </joint>
    <static>0</static>
    <plugin name='iCub_yarp_gazebo_plugin_ACCpart' filename='libgazebo_yarp_inertialmtbPart.so'>
      <yarpConfigurationFile>model://iCubGenova02/conf/MTB/gazebo-left_leg-mtb.ini</yarpConfigurationFile>
    </plugin>
    <plugin name='controlboard_torso' filename='libgazebo_yarp_controlboard.so'>
      <yarpConfigurationFile>model://iCubGenova02/conf/gazebo_iCubGenova02_torso.ini</yarpConfigurationFile>
    </plugin>
    <plugin name='controlboard_head' filename='libgazebo_yarp_controlboard.so'>
      <yarpConfigurationFile>model://iCubGenova02/conf/gazebo_iCubGenova02_head.ini</yarpConfigurationFile>
    </plugin>
    <plugin name='controlboard_left_arm' filename='libgazebo_yarp_controlboard.so'>
      <yarpConfigurationFile>model://iCubGenova02/conf/gazebo_iCubGenova02_left_arm.ini</yarpConfigurationFile>
      <initialConfiguration>-0.52 0.52 0 0.785 0 0 0.698</initialConfiguration>
    </plugin>
    <plugin name='controlboard_right_arm' filename='libgazebo_yarp_controlboard.so'>
      <yarpConfigurationFile>model://iCubGenova02/conf/gazebo_iCubGenova02_right_arm.ini</yarpConfigurationFile>
      <initialConfiguration>-0.52 0.52 0 0.785 0 0 0.698</initialConfiguration>
    </plugin>
    <plugin name='controlboard_right_leg' filename='libgazebo_yarp_controlboard.so'>
      <yarpConfigurationFile>model://iCubGenova02/conf/gazebo_iCubGenova02_right_leg.ini</yarpConfigurationFile>
    </plugin>
    <plugin name='controlboard_left_leg' filename='libgazebo_yarp_controlboard.so'>
      <yarpConfigurationFile>model://iCubGenova02/conf/gazebo_iCubGenova02_left_leg.ini</yarpConfigurationFile>
    </plugin>
    <plugin name='apply_external_wrench' filename='libgazebo_yarp_externalwrench.so'>
      <robotNamefromConfigFile>model://iCubGenova02/conf/gazebo_iCubGenova02_robotname.ini</robotNamefromConfigFile>
    </plugin>
    <pose> 0 0 0.62 0 0 0 </pose>
  </model>
</sdf>
