<robot name="iCub">
    <link name="chest">
        <inertial>
            <mass value="4.81" />
            <origin xyz="0.00222898 0.075 -1.18362e-17" rpy="0 -0 0" />
            <inertia ixx="0.07472" ixy="-3.6e-06" ixz="-4.705e-05" iyy="0.08145" iyz="0.004567" izz="0.01306" />
        </inertial>
        <visual>
            <origin xyz="-0.0055 -6.93889e-18 -3.55271e-18" rpy="2.03442 -1.5708 -0.463617" />
            <geometry>
                <mesh filename="model://icub/meshes/visual/icub_chest.dae" scale="1 1 1" />
            </geometry>
            <material name="material.metal">
                <texture />
                <color rgba="0 0 0 1" />
            </material>
        </visual>
        <collision>
            <origin xyz="-0.0055 -6.93889e-18 -3.55271e-18" rpy="2.03442 -1.5708 -0.463617" />
            <geometry>
                <mesh filename="model://icub/meshes/collision/icub_simple_collision_chest.dae" scale="1 1 1" />
            </geometry>
        </collision>
    </link>
    <link name="chest_skin_frame">
        <inertial>
            <mass value="0" />
            <origin xyz="0 0 0" rpy="0 -0 0" />
            <inertia ixx="0" ixy="0" ixz="0" iyy="0" iyz="0" izz="0" />
        </inertial>
    </link>
    <!-- LINKS FOR ICUB BALANCING ON A CHAIR -->
    <link name="l_upper_leg_contact">
        <inertial>
            <mass value="0" />
            <origin xyz="0 0 0" rpy="0 -0 0" />
            <inertia ixx="0" ixy="0" ixz="0" iyy="0" iyz="0" izz="0" />
        </inertial>
    </link>
    <link name="r_upper_leg_contact">
        <inertial>
            <mass value="0" />
            <origin xyz="0 0 0" rpy="0 -0 0" />
            <inertia ixx="0" ixy="0" ixz="0" iyy="0" iyz="0" izz="0" />
        </inertial>
    </link>
    <!-- *********************************** -->
    <link name="codyco_balancing_world">
        <inertial>
            <mass value="0" />
            <origin xyz="0 0 0" rpy="0 -0 0" />
            <inertia ixx="0" ixy="0" ixz="0" iyy="0" iyz="0" izz="0" />
        </inertial>
    </link>
    <link name="head">
        <inertial>
            <mass value="3" />
            <origin xyz="0.0185 -0.1108 6.78454e-18" rpy="0 -0 0" />
            <inertia ixx="0.01" ixy="0" ixz="0" iyy="0.01" iyz="0" izz="0.01" />
        </inertial>
        <visual>
            <origin xyz="0.0045 -0.0235 9.42472e-13" rpy="1.81577 1.5708 0.244969" />
            <geometry>
                <mesh filename="model://icub/meshes/visual/icub_head.dae" scale="1 1 1" />
            </geometry>
            <material name="material.metal">
                <texture />
                <color rgba="0 0 0 1" />
            </material>
        </visual>
        <collision>
            <origin xyz="0.0045 -0.0235 9.42472e-13" rpy="1.81577 1.5708 0.244969" />
            <geometry>
                <mesh filename="model://icub/meshes/collision/icub_simple_collision_head.dae" scale="1 1 1" />
            </geometry>
        </collision>
    </link>
    <link name="imu_frame">
        <inertial>
            <mass value="0" />
            <origin xyz="0 0 0" rpy="0 -0 0" />
            <inertia ixx="0" ixy="0" ixz="0" iyy="0" iyz="0" izz="0" />
        </inertial>
    </link>
    <link name="l_ankle_1">
        <inertial>
            <mass value="0.746" />
            <origin xyz="-0.0054 0.00163 0.0172" rpy="0 -0 0" />
            <inertia ixx="0.01" ixy="-7.081e-06" ixz="4.1421e-05" iyy="0.01" iyz="2.0817e-05" izz="0.01" />
        </inertial>
        <visual>
            <origin xyz="1.11022e-16 -5.54343e-12 4.45647e-12" rpy="1.5708 1.53106e-11 1.53105e-11" />
            <geometry>
                <mesh filename="model://icub/meshes/visual/icub_l_ankle_1.dae" scale="1 1 1" />
            </geometry>
            <material name="material.metal">
                <texture />
                <color rgba="0 0 0 1" />
            </material>
        </visual>
        <collision>
            <origin xyz="1.11022e-16 -5.54343e-12 4.45647e-12" rpy="1.5708 1.53106e-11 1.53105e-11" />
            <geometry>
                <mesh filename="model://icub/meshes/collision/icub_simple_collision_l_ankle_1.dae" scale="1 1 1" />
            </geometry>
        </collision>
    </link>
    <link name="l_ankle_2">
        <inertial>
            <mass value="0.2675" />
            <origin xyz="0 0 0.037" rpy="0 -0 0" />
            <inertia ixx="0.01" ixy="0" ixz="0" iyy="0.01" iyz="0" izz="0.01" />
        </inertial>
    </link>
    <link name="l_elbow_1">
        <inertial>
            <mass value="0.1" />
            <origin xyz="-0.0013 0.00371 -0.00105" rpy="0 -0 0" />
            <inertia ixx="0.01" ixy="-5.15e-07" ixz="-4.08e-07" iyy="0.01" iyz="-3.71e-07" izz="0.01" />
        </inertial>
    </link>
    <link name="l_foot">
        <inertial>
            <mass value="0.5935" />
            <origin xyz="0.024069 -0.000613931 -0.0284154" rpy="0 -0 0" />
            <inertia ixx="0.01" ixy="-4.51893e-06" ixz="0.000567785" iyy="0.01" iyz="-6.62361e-07" izz="0.01" />
        </inertial>
        <visual>
            <origin xyz="4.45647e-12 -5.54343e-12 -0.037" rpy="2.35619 1.5708 2.35619" />
            <geometry>
                <mesh filename="model://icub/meshes/visual/icub_l_foot.dae" scale="1 1 1" />
            </geometry>
            <material name="material.metal">
                <texture />
                <color rgba="0 0 0 1" />
            </material>
        </visual>
        <collision>
            <origin xyz="4.45647e-12 -5.54343e-12 -0.037" rpy="2.35619 1.5708 2.35619" />
            <geometry>
                <mesh filename="model://icub/meshes/collision/icub_simple_collision_l_foot.dae" scale="1 1 1" />
            </geometry>
        </collision>
    </link>
    <link name="l_foot_dh_frame">
        <inertial>
            <mass value="0" />
            <origin xyz="0 0 0" rpy="0 -0 0" />
            <inertia ixx="0" ixy="0" ixz="0" iyy="0" iyz="0" izz="0" />
        </inertial>
    </link>
    <link name="l_forearm">
        <inertial>
            <mass value="0.525" />
            <origin xyz="0.000347 0.066 0.00476" rpy="0 -0 0" />
            <inertia ixx="0.01" ixy="4.337e-06" ixz="2.39e-07" iyy="0.01" iyz="1.9381e-05" izz="0.01" />
        </inertial>
        <visual>
            <origin xyz="-0.000143922 -1.25974e-12 0.0204334" rpy="0.477647 1.5708 2.04844" />
            <geometry>
                <mesh filename="model://icub/meshes/visual/icub_l_forearm.dae" scale="1 1 1" />
            </geometry>
            <material name="material.metal">
                <texture />
                <color rgba="0 0 0 1" />
            </material>
        </visual>
        <collision>
            <origin xyz="-0.000143922 -1.25974e-12 0.0204334" rpy="0.477647 1.5708 2.04844" />
            <geometry>
                <mesh filename="model://icub/meshes/collision/icub_simple_collision_l_forearm.dae" scale="1 1 1" />
            </geometry>
        </collision>
    </link>
    <link name="l_forearm_dh_frame">
        <inertial>
            <mass value="0" />
            <origin xyz="0 0 0" rpy="0 -0 0" />
            <inertia ixx="0" ixy="0" ixz="0" iyy="0" iyz="0" izz="0" />
        </inertial>
    </link>
    <link name="l_gripper">
        <inertial>
            <mass value="0" />
            <origin xyz="0 0 0" rpy="0 -0 0" />
            <inertia ixx="0" ixy="0" ixz="0" iyy="0" iyz="0" izz="0" />
        </inertial>
    </link>
    <link name="l_hand">
        <inertial>
            <mass value="0.213" />
            <origin xyz="0.07023 -0.00805 -0.007" rpy="0 -0 0" />
            <inertia ixx="0.01" ixy="1.278e-05" ixz="4.823e-06" iyy="0.01" iyz="-1.8188e-05" izz="0.01" />
        </inertial>
        <visual>
            <origin xyz="-1.25973e-12 0.0204334 -0.000143922" rpy="5.10271e-12 -2.64186e-12 1.49622e-11" />
            <geometry>
                <mesh filename="model://icub/meshes/visual/icub_l_hand.dae" scale="1 1 1" />
            </geometry>
            <material name="material.metal">
                <texture />
                <color rgba="0 0 0 1" />
            </material>
        </visual>
        <collision>
            <origin xyz="-1.25973e-12 0.0204334 -0.000143922" rpy="5.10271e-12 -2.64186e-12 1.49622e-11" />
            <geometry>
                <mesh filename="model://icub/meshes/collision/icub_simple_collision_l_hand.dae" scale="1 1 1" />
            </geometry>
        </collision>
    </link>
    <link name="l_hand_dh_frame">
        <inertial>
            <mass value="0" />
            <origin xyz="0 0 0" rpy="0 -0 0" />
            <inertia ixx="0" ixy="0" ixz="0" iyy="0" iyz="0" izz="0" />
        </inertial>
    </link>
    <link name="l_hip_1">
        <inertial>
            <mass value="0.754" />
            <origin xyz="0 -0.0782 0" rpy="0 -0 0" />
            <inertia ixx="0.01" ixy="2.059e-06" ixz="1.451e-06" iyy="0.01" iyz="1.545e-06" izz="0.01" />
        </inertial>
        <visual>
            <origin xyz="0 0 0" rpy="2.35619 1.5708 0.785398" />
            <geometry>
                <mesh filename="model://icub/meshes/visual/icub_l_hip_1.dae" scale="1 1 1" />
            </geometry>
            <material name="material.metal">
                <texture />
                <color rgba="0 0 0 1" />
            </material>
        </visual>
        <collision>
            <origin xyz="0 0 0" rpy="2.35619 1.5708 0.785398" />
            <geometry>
                <mesh filename="model://icub/meshes/collision/icub_simple_collision_l_hip_1.dae" scale="1 1 1" />
            </geometry>
        </collision>
    </link>
    <link name="l_hip_2">
        <inertial>
            <mass value="0.526" />
            <origin xyz="0 0 0.03045" rpy="0 -0 0" />
            <inertia ixx="0.01" ixy="-7.4e-08" ixz="1.0835e-05" iyy="0.01" iyz="-6.2e-08" izz="0.01" />
        </inertial>
        <visual>
            <origin xyz="0 0 0" rpy="-2.35623 -1.5708 -0.785361" />
            <geometry>
                <mesh filename="model://icub/meshes/visual/icub_l_hip_2.dae" scale="1 1 1" />
            </geometry>
            <material name="material.metal">
                <texture />
                <color rgba="0 0 0 1" />
            </material>
        </visual>
        <collision>
            <origin xyz="0 0 0" rpy="-2.35623 -1.5708 -0.785361" />
            <geometry>
                <mesh filename="model://icub/meshes/collision/icub_simple_collision_l_hip_2.dae" scale="1 1 1" />
            </geometry>
        </collision>
    </link>
    <link name="l_hip_3">
        <inertial>
            <mass value="0.1" />
            <origin xyz="0 0 0" rpy="0 -0 0" />
            <inertia ixx="0.01" ixy="0" ixz="0" iyy="0.01" iyz="0" izz="0.01" />
        </inertial>
    </link>
    <link name="l_lower_leg">
        <inertial>
            <mass value="1.264" />
            <origin xyz="-0.1071 0.00182 0.00211" rpy="0 -0 0" />
            <inertia ixx="0.01" ixy="-0.000185699" ixz="-6.3147e-05" iyy="0.01" iyz="7.86e-07" izz="0.01" />
        </inertial>
        <visual>
            <origin xyz="5.55112e-17 2.28232e-12 2.2823e-12" rpy="-3.14159 -2.33487e-16 1.5708" />
            <geometry>
                <mesh filename="model://icub/meshes/visual/icub_l_shank.dae" scale="1 1 1" />
            </geometry>
            <material name="material.metal">
                <texture />
                <color rgba="0 0 0 1" />
            </material>
        </visual>
        <collision>
            <origin xyz="5.55112e-17 2.28232e-12 2.2823e-12" rpy="-3.14159 -2.33487e-16 1.5708" />
            <geometry>
                <mesh filename="model://icub/meshes/collision/icub_simple_collision_l_shank.dae" scale="1 1 1" />
            </geometry>
        </collision>
    </link>
    <link name="l_shoulder_1">
        <inertial>
            <mass value="0.189" />
            <origin xyz="-5e-06 0.0187 -0.00119" rpy="0 -0 0" />
            <inertia ixx="0.01" ixy="9e-09" ixz="0" iyy="0.01" iyz="-1.7e-08" izz="0.01" />
        </inertial>
        <visual>
            <origin xyz="3.08642e-14 0.109285 -0.00521101" rpy="2.84053 1.5708 1.26973" />
            <geometry>
                <mesh filename="model://icub/meshes/visual/icub_l_shoulder_1.dae" scale="1 1 1" />
            </geometry>
            <material name="material.metal">
                <texture />
                <color rgba="0 0 0 1" />
            </material>
        </visual>
        <collision>
            <origin xyz="3.08642e-14 0.109285 -0.00521101" rpy="2.84053 1.5708 1.26973" />
            <geometry>
                <mesh filename="model://icub/meshes/collision/icub_simple_collision_l_shoulder_1.dae" scale="1 1 1" />
            </geometry>
        </collision>
    </link>
    <link name="l_shoulder_2">
        <inertial>
            <mass value="0.179" />
            <origin xyz="9.4e-05 -0.00627 0.0166" rpy="0 -0 0" />
            <inertia ixx="0.01" ixy="4.66e-07" ixz="3.65e-07" iyy="0.01" iyz="-2.0524e-05" izz="0.01" />
        </inertial>
        <visual>
            <origin xyz="-0.00154529 -0.00521101 -1.11181e-12" rpy="1.00126 1.5708 2.57206" />
            <geometry>
                <mesh filename="model://icub/meshes/visual/icub_l_shoulder_2.dae" scale="1 1 1" />
            </geometry>
            <material name="material.metal">
                <texture />
                <color rgba="0 0 0 1" />
            </material>
        </visual>
        <collision>
            <origin xyz="-0.00154529 -0.00521101 -1.11181e-12" rpy="1.00126 1.5708 2.57206" />
            <geometry>
                <mesh filename="model://icub/meshes/collision/icub_simple_collision_l_shoulder_2.dae" scale="1 1 1" />
            </geometry>
        </collision>
    </link>
    <link name="l_shoulder_3">
        <inertial>
            <mass value="0.156157" />
            <origin xyz="0.00559398 9.77357e-05 0.0501346" rpy="0 -0 0" />
            <inertia ixx="0.01" ixy="-5.662e-08" ixz="-4.3618e-06" iyy="0.01" iyz="-7.42844e-07" izz="0.01" />
        </inertial>
    </link>
    <link name="l_sole">
        <inertial>
            <mass value="0" />
            <origin xyz="0 0 0" rpy="0 -0 0" />
            <inertia ixx="0" ixy="0" ixz="0" iyy="0" iyz="0" izz="0" />
        </inertial>
    </link>
    <link name="l_upper_arm">
        <inertial>
            <mass value="0.727843" />
            <origin xyz="-0.000156 -9.87e-05 0.0298" rpy="0 -0 0" />
            <inertia ixx="0.01" ixy="-1.08e-06" ixz="-2.29e-06" iyy="0.01" iyz="3.57e-06" izz="0.01" />
        </inertial>
        <visual>
            <origin xyz="-0.0204334 0.000143922 -0.068" rpy="1.15274e-11 4.92958e-12 -1.309" />
            <geometry>
                <mesh filename="model://icub/meshes/visual/icub_l_arm.dae" scale="1 1 1" />
            </geometry>
            <material name="material.metal">
                <texture />
                <color rgba="0 0 0 1" />
            </material>
        </visual>
        <collision>
            <origin xyz="-0.0204334 0.000143922 -0.068" rpy="1.15274e-11 4.92958e-12 -1.309" />
            <geometry>
                <mesh filename="model://icub/meshes/collision/icub_simple_collision_l_arm.dae" scale="1 1 1" />
            </geometry>
        </collision>
    </link>
    <link name="l_upper_arm_dh_frame">
        <inertial>
            <mass value="0" />
            <origin xyz="0 0 0" rpy="0 -0 0" />
            <inertia ixx="0" ixy="0" ixz="0" iyy="0" iyz="0" izz="0" />
        </inertial>
    </link>
    <link name="l_upper_leg">
        <inertial>
            <mass value="2.175" />
            <origin xyz="0.00144 -0.15943 -0.00039" rpy="0 -0 0" />
            <inertia ixx="0.01" ixy="-6.726e-05" ixz="2.267e-06" iyy="0.01" iyz="3.63726e-05" izz="0.01" />
        </inertial>
        <visual>
            <origin xyz="0 0 0" rpy="0.463626 1.5708 2.03443" />
            <geometry>
                <mesh filename="model://icub/meshes/visual/icub_l_thigh.dae" scale="1 1 1" />
            </geometry>
            <material name="material.metal">
                <texture />
                <color rgba="0 0 0 1" />
            </material>
        </visual>
        <collision>
            <origin xyz="0 0 0" rpy="0.463626 1.5708 2.03443" />
            <geometry>
                <mesh filename="model://icub/meshes/collision/icub_simple_collision_l_thigh.dae" scale="1 1 1" />
            </geometry>
        </collision>
    </link>
    <link name="l_wrist_1">
        <inertial>
            <mass value="0.1" />
            <origin xyz="0 0 0" rpy="0 -0 0" />
            <inertia ixx="0.01" ixy="0" ixz="0" iyy="0.01" iyz="0" izz="0.01" />
        </inertial>
    </link>
    <link name="neck_1">
        <inertial>
            <mass value="0.1" />
            <origin xyz="0 0 0" rpy="0 -0 0" />
            <inertia ixx="0.01" ixy="0" ixz="0" iyy="0.01" iyz="0" izz="0.01" />
        </inertial>
        <visual>
            <origin xyz="-5.55112e-17 9.62889e-13 -0.0055" rpy="-7.25153e-06 -1.5708 -1.57079" />
            <geometry>
                <mesh filename="model://icub/meshes/visual/icub_neck_1.dae" scale="1 1 1" />
            </geometry>
            <material name="material.metal">
                <texture />
                <color rgba="0 0 0 1" />
            </material>
        </visual>
        <collision>
            <origin xyz="-5.55112e-17 9.62889e-13 -0.0055" rpy="-7.25153e-06 -1.5708 -1.57079" />
            <geometry>
                <mesh filename="model://icub/meshes/collision/icub_simple_collision_neck_1.dae" scale="1 1 1" />
            </geometry>
        </collision>
    </link>
    <link name="neck_2">
        <inertial>
            <mass value="0.1" />
            <origin xyz="0 0 0" rpy="0 -0 0" />
            <inertia ixx="0.01" ixy="0" ixz="0" iyy="0.01" iyz="0" izz="0.01" />
        </inertial>
        <visual>
            <origin xyz="-9.62885e-13 0.0055 0.0235" rpy="2.17538e-05 -1.5708 1.57077" />
            <geometry>
                <mesh filename="model://icub/meshes/visual/icub_neck_2.dae" scale="1 1 1" />
            </geometry>
            <material name="material.metal">
                <texture />
                <color rgba="0 0 0 1" />
            </material>
        </visual>
        <collision>
            <origin xyz="-9.62885e-13 0.0055 0.0235" rpy="2.17538e-05 -1.5708 1.57077" />
            <geometry>
                <mesh filename="model://icub/meshes/collision/icub_simple_collision_neck_2.dae" scale="1 1 1" />
            </geometry>
        </collision>
    </link>
    <link name="r_ankle_1">
        <inertial>
            <mass value="0.746" />
            <origin xyz="-0.0054 0.00163 -0.0172" rpy="0 -0 0" />
            <inertia ixx="0.01" ixy="-1.69407e-21" ixz="1.35525e-20" iyy="0.01" iyz="3.38813e-21" izz="0.01" />
        </inertial>
        <visual>
            <origin xyz="1.11022e-16 -1.08717e-12 -4.45647e-12" rpy="-1.5708 -1.53106e-11 5.10376e-12" />
            <geometry>
                <mesh filename="model://icub/meshes/visual/icub_r_ankle_1.dae" scale="1 1 1" />
            </geometry>
            <material name="material.metal">
                <texture />
                <color rgba="0 0 0 1" />
            </material>
        </visual>
        <collision>
            <origin xyz="1.11022e-16 -1.08717e-12 -4.45647e-12" rpy="-1.5708 -1.53106e-11 5.10376e-12" />
            <geometry>
                <mesh filename="model://icub/meshes/collision/icub_simple_collision_r_ankle_1.dae" scale="1 1 1" />
            </geometry>
        </collision>
    </link>
    <link name="r_ankle_2">
        <inertial>
            <mass value="0.2675" />
            <origin xyz="0 0 0.037" rpy="0 -0 0" />
            <inertia ixx="0.01" ixy="0" ixz="0" iyy="0.01" iyz="0" izz="0.01" />
        </inertial>
    </link>
    <link name="r_elbow_1">
        <inertial>
            <mass value="0.1" />
            <origin xyz="0.0013 -0.00371 0.00105" rpy="0 -0 0" />
            <inertia ixx="0.01" ixy="-5.02e-07" ixz="-3.99e-07" iyy="0.01" iyz="-3.71e-07" izz="0.01" />
        </inertial>
    </link>
    <link name="r_foot">
        <inertial>
            <mass value="0.5935" />
            <origin xyz="0.024069 0.000613931 -0.0284154" rpy="0 -0 0" />
            <inertia ixx="0.01" ixy="4.51893e-06" ixz="0.000567784" iyy="0.01" iyz="6.62535e-07" izz="0.01" />
        </inertial>
        <visual>
            <origin xyz="4.45647e-12 1.08717e-12 -0.037" rpy="0.321762 1.5708 -2.81983" />
            <geometry>
                <mesh filename="model://icub/meshes/visual/icub_r_foot.dae" scale="1 1 1" />
            </geometry>
            <material name="material.metal">
                <texture />
                <color rgba="0 0 0 1" />
            </material>
        </visual>
        <collision>
            <origin xyz="4.45647e-12 1.08717e-12 -0.037" rpy="0.321762 1.5708 -2.81983" />
            <geometry>
                <mesh filename="model://icub/meshes/collision/icub_simple_collision_r_foot.dae" scale="1 1 1" />
            </geometry>
        </collision>
    </link>
    <link name="r_foot_dh_frame">
        <inertial>
            <mass value="0" />
            <origin xyz="0 0 0" rpy="0 -0 0" />
            <inertia ixx="0" ixy="0" ixz="0" iyy="0" iyz="0" izz="0" />
        </inertial>
    </link>
    <link name="r_forearm">
        <inertial>
            <mass value="0.525" />
            <origin xyz="-0.000347 -0.066 -0.00476" rpy="0 -0 0" />
            <inertia ixx="0.01" ixy="5.66e-06" ixz="1.4e-06" iyy="0.01" iyz="1.82e-05" izz="0.01" />
        </inertial>
        <visual>
            <origin xyz="0.000143922 -1.07214e-12 -0.0204334" rpy="1.39994 1.5708 2.97073" />
            <geometry>
                <mesh filename="model://icub/meshes/visual/icub_r_forearm.dae" scale="1 1 1" />
            </geometry>
            <material name="material.metal">
                <texture />
                <color rgba="0 0 0 1" />
            </material>
        </visual>
        <collision>
            <origin xyz="0.000143922 -1.07214e-12 -0.0204334" rpy="1.39994 1.5708 2.97073" />
            <geometry>
                <mesh filename="model://icub/meshes/collision/icub_simple_collision_r_forearm.dae" scale="1 1 1" />
            </geometry>
        </collision>
    </link>
    <link name="r_forearm_dh_frame">
        <inertial>
            <mass value="0" />
            <origin xyz="0 0 0" rpy="0 -0 0" />
            <inertia ixx="0" ixy="0" ixz="0" iyy="0" iyz="0" izz="0" />
        </inertial>
    </link>
    <link name="r_gripper">
        <inertial>
            <mass value="0" />
            <origin xyz="0 0 0" rpy="0 -0 0" />
            <inertia ixx="0" ixy="0" ixz="0" iyy="0" iyz="0" izz="0" />
        </inertial>
    </link>
    <link name="r_hand">
        <inertial>
            <mass value="0.213" />
            <origin xyz="0.07023 -0.00805 0.007" rpy="0 -0 0" />
            <inertia ixx="0.01" ixy="1.26e-05" ixz="-6.08e-06" iyy="0.01" iyz="1.76e-05" izz="0.01" />
        </inertial>
        <visual>
            <origin xyz="1.0721e-12 0.0204334 0.000143922" rpy="1.53098e-11 2.00656e-11 -3.14159" />
            <geometry>
                <mesh filename="model://icub/meshes/visual/icub_r_hand.dae" scale="1 1 1" />
            </geometry>
            <material name="material.metal">
                <texture />
                <color rgba="0 0 0 1" />
            </material>
        </visual>
        <collision>
            <origin xyz="1.0721e-12 0.0204334 0.000143922" rpy="1.53098e-11 2.00656e-11 -3.14159" />
            <geometry>
                <mesh filename="model://icub/meshes/collision/icub_simple_collision_r_hand.dae" scale="1 1 1" />
            </geometry>
        </collision>
    </link>
    <link name="r_hand_dh_frame">
        <inertial>
            <mass value="0" />
            <origin xyz="0 0 0" rpy="0 -0 0" />
            <inertia ixx="0" ixy="0" ixz="0" iyy="0" iyz="0" izz="0" />
        </inertial>
    </link>
    <link name="r_hip_1">
        <inertial>
            <mass value="0.754" />
            <origin xyz="0 -0.0782 0" rpy="0 -0 0" />
            <inertia ixx="0.01" ixy="0" ixz="0" iyy="0.01" iyz="0" izz="0.01" />
        </inertial>
        <visual>
            <origin xyz="0 0 0" rpy="-1.3734 -1.5708 -0.380506" />
            <geometry>
                <mesh filename="model://icub/meshes/visual/icub_r_hip_1.dae" scale="1 1 1" />
            </geometry>
            <material name="material.metal">
                <texture />
                <color rgba="0 0 0 1" />
            </material>
        </visual>
        <collision>
            <origin xyz="0 0 0" rpy="-1.3734 -1.5708 -0.380506" />
            <geometry>
                <mesh filename="model://icub/meshes/collision/icub_simple_collision_r_hip_1.dae" scale="1 1 1" />
            </geometry>
        </collision>
    </link>
    <link name="r_hip_2">
        <inertial>
            <mass value="0.526" />
            <origin xyz="0 0 0.03045" rpy="0 -0 0" />
            <inertia ixx="0.01" ixy="0" ixz="0" iyy="0.01" iyz="0" izz="0.01" />
        </inertial>
        <visual>
            <origin xyz="0 0 0" rpy="0.785327 -1.5708 -0.785327" />
            <geometry>
                <mesh filename="model://icub/meshes/visual/icub_r_hip_2.dae" scale="1 1 1" />
            </geometry>
            <material name="material.metal">
                <texture />
                <color rgba="0 0 0 1" />
            </material>
        </visual>
        <collision>
            <origin xyz="0 0 0" rpy="0.785327 -1.5708 -0.785327" />
            <geometry>
                <mesh filename="model://icub/meshes/collision/icub_simple_collision_r_hip_2.dae" scale="1 1 1" />
            </geometry>
        </collision>
    </link>
    <link name="r_hip_3">
        <inertial>
            <mass value="0.1" />
            <origin xyz="0 0 0" rpy="0 -0 0" />
            <inertia ixx="0.01" ixy="0" ixz="0" iyy="0.01" iyz="0" izz="0.01" />
        </inertial>
    </link>
    <link name="r_lower_leg">
        <inertial>
            <mass value="1.264" />
            <origin xyz="-0.1071 0.00182 -0.00211" rpy="0 -0 0" />
            <inertia ixx="0.01" ixy="5.42101e-20" ixz="-5.42101e-20" iyy="0.01" iyz="8.47033e-22" izz="0.01" />
        </inertial>
        <visual>
            <origin xyz="5.55112e-17 2.28232e-12 -8.32667e-17" rpy="3.14159 -1.14424e-17 1.5708" />
            <geometry>
                <mesh filename="model://icub/meshes/visual/icub_r_shank.dae" scale="1 1 1" />
            </geometry>
            <material name="material.metal">
                <texture />
                <color rgba="0 0 0 1" />
            </material>
        </visual>
        <collision>
            <origin xyz="5.55112e-17 2.28232e-12 -8.32667e-17" rpy="3.14159 -1.14424e-17 1.5708" />
            <geometry>
                <mesh filename="model://icub/meshes/collision/icub_simple_collision_r_shank.dae" scale="1 1 1" />
            </geometry>
        </collision>
    </link>
    <link name="r_shoulder_1">
        <inertial>
            <mass value="0.189" />
            <origin xyz="5e-06 0.0187 0.00119" rpy="0 -0 0" />
            <inertia ixx="0.01" ixy="2.1e-08" ixz="-1e-09" iyy="0.01" iyz="4.22e-06" izz="0.01" />
        </inertial>
        <visual>
            <origin xyz="-3.08642e-14 0.109285 0.00521101" rpy="-0.0815582 1.5708 1.48924" />
            <geometry>
                <mesh filename="model://icub/meshes/visual/icub_r_shoulder_1.dae" scale="1 1 1" />
            </geometry>
            <material name="material.metal">
                <texture />
                <color rgba="0 0 0 1" />
            </material>
        </visual>
        <collision>
            <origin xyz="-3.08642e-14 0.109285 0.00521101" rpy="-0.0815582 1.5708 1.48924" />
            <geometry>
                <mesh filename="model://icub/meshes/collision/icub_simple_collision_r_shoulder_1.dae" scale="1 1 1" />
            </geometry>
        </collision>
    </link>
    <link name="r_shoulder_2">
        <inertial>
            <mass value="0.179" />
            <origin xyz="-9.4e-05 -0.00627 -0.0166" rpy="0 -0 0" />
            <inertia ixx="0.01" ixy="-4.53e-07" ixz="2.03e-07" iyy="0.01" iyz="2.07e-05" izz="0.01" />
        </inertial>
        <visual>
            <origin xyz="-0.00154529 -0.00521101 -1.11181e-12" rpy="2.14034 -1.5708 -0.56954" />
            <geometry>
                <mesh filename="model://icub/meshes/visual/icub_r_shoulder_2.dae" scale="1 1 1" />
            </geometry>
            <material name="material.metal">
                <texture />
                <color rgba="0 0 0 1" />
            </material>
        </visual>
        <collision>
            <origin xyz="-0.00154529 -0.00521101 -1.11181e-12" rpy="2.14034 -1.5708 -0.56954" />
            <geometry>
                <mesh filename="model://icub/meshes/collision/icub_simple_collision_r_shoulder_2.dae" scale="1 1 1" />
            </geometry>
        </collision>
    </link>
    <link name="r_shoulder_3">
        <inertial>
            <mass value="0.155" />
            <origin xyz="0.00553932 -2.47652e-05 0.0493895" rpy="0 -0 0" />
            <inertia ixx="0.01" ixy="3.56977e-07" ixz="-3.95372e-06" iyy="0.01" iyz="-6.5128e-06" izz="0.01" />
        </inertial>
    </link>
    <link name="r_sole">
        <inertial>
            <mass value="0" />
            <origin xyz="0 0 0" rpy="0 -0 0" />
            <inertia ixx="0" ixy="0" ixz="0" iyy="0" iyz="0" izz="0" />
        </inertial>
    </link>
    <link name="r_upper_arm">
        <inertial>
            <mass value="0.729" />
            <origin xyz="-0.00015906 8.28733e-05 0.0298828" rpy="0 -0 0" />
            <inertia ixx="0.01" ixy="-1.08e-06" ixz="-2.29e-06" iyy="0.01" iyz="3.57e-06" izz="0.01" />
        </inertial>
        <visual>
            <origin xyz="-0.0204334 -0.000143922 -0.068" rpy="-3.14159 -1.51363e-11 1.309" />
            <geometry>
                <mesh filename="model://icub/meshes/visual/icub_r_arm.dae" scale="1 1 1" />
            </geometry>
            <material name="material.metal">
                <texture />
                <color rgba="0 0 0 1" />
            </material>
        </visual>
        <collision>
            <origin xyz="-0.0204334 -0.000143922 -0.068" rpy="-3.14159 -1.51363e-11 1.309" />
            <geometry>
                <mesh filename="model://icub/meshes/collision/icub_simple_collision_r_arm.dae" scale="1 1 1" />
            </geometry>
        </collision>
    </link>
    <link name="r_upper_arm_dh_frame">
        <inertial>
            <mass value="0" />
            <origin xyz="0 0 0" rpy="0 -0 0" />
            <inertia ixx="0" ixy="0" ixz="0" iyy="0" iyz="0" izz="0" />
        </inertial>
    </link>
    <link name="r_upper_leg">
        <inertial>
            <mass value="2.175" />
            <origin xyz="0.00144 -0.15943 0.00039" rpy="0 -0 0" />
            <inertia ixx="0.01" ixy="0" ixz="0" iyy="0.01" iyz="-2.71051e-20" izz="0.01" />
        </inertial>
        <visual>
            <origin xyz="0 0 0" rpy="-1.57072 -1.5708 3.14152" />
            <geometry>
                <mesh filename="model://icub/meshes/visual/icub_r_thigh.dae" scale="1 1 1" />
            </geometry>
            <material name="material.metal">
                <texture />
                <color rgba="0 0 0 1" />
            </material>
        </visual>
        <collision>
            <origin xyz="0 0 0" rpy="-1.57072 -1.5708 3.14152" />
            <geometry>
                <mesh filename="model://icub/meshes/collision/icub_simple_collision_r_thigh.dae" scale="1 1 1" />
            </geometry>
        </collision>
    </link>
    <link name="r_wrist_1">
        <inertial>
            <mass value="0.1" />
            <origin xyz="0 0 0" rpy="0 -0 0" />
            <inertia ixx="0.01" ixy="0" ixz="0" iyy="0.01" iyz="0" izz="0.01" />
        </inertial>
    </link>
    <link name="root_link">
        <inertial>
            <mass value="4.72" />
            <origin xyz="0 0 0" rpy="0 -0 0" />
            <inertia ixx="0.01" ixy="0" ixz="0" iyy="0.01" iyz="0" izz="0.01" />
        </inertial>
        <visual>
            <origin xyz="0 0 0" rpy="0 -0 0" />
            <geometry>
                <mesh filename="model://icub/meshes/visual/icub_root_link.dae" scale="1 1 1" />
            </geometry>
            <material name="material.metal">
                <texture />
                <color rgba="0 0 0 1" />
            </material>
        </visual>
        <collision>
            <origin xyz="0 0 0" rpy="0 -0 0" />
            <geometry>
                <mesh filename="model://icub/meshes/collision/icub_simple_collision_root_link.dae" scale="1 1 1" />
            </geometry>
        </collision>
    </link>
    <link name="torso">
        <inertial>
            <mass value="0" />
            <origin xyz="0 0 0" rpy="0 -0 0" />
            <inertia ixx="0" ixy="0" ixz="0" iyy="0" iyz="0" izz="0" />
        </inertial>
    </link>
    <link name="torso_1">
        <inertial>
            <mass value="0.1" />
            <origin xyz="0 0 0" rpy="0 -0 0" />
            <inertia ixx="0.01" ixy="-4.263e-05" ixz="-3.889e-08" iyy="0.01" iyz="0" izz="0.01" />
        </inertial>
        <visual>
            <origin xyz="0 0 0" rpy="-1.5708 5.10314e-12 1.11022e-16" />
            <geometry>
                <mesh filename="model://icub/meshes/visual/icub_lap_belt_1.dae" scale="1 1 1" />
            </geometry>
            <material name="material.metal">
                <texture />
                <color rgba="0 0 0 1" />
            </material>
        </visual>
        <collision>
            <origin xyz="0 0 0" rpy="-1.5708 5.10314e-12 1.11022e-16" />
            <geometry>
                <mesh filename="model://icub/meshes/collision/icub_simple_collision_lap_belt_1.dae" scale="1 1 1" />
            </geometry>
        </collision>
    </link>
    <link name="torso_2">
        <inertial>
            <mass value="0.1" />
            <origin xyz="0 0 0" rpy="0 -0 0" />
            <inertia ixx="0.01" ixy="-1.923e-06" ixz="5.095e-05" iyy="0.01" iyz="-3.849e-07" izz="0.01" />
        </inertial>
    </link>
    <joint name="torso_yaw" type="revolute">
        <origin xyz="-7.46298e-34 -0.0055 0" rpy="-1.5708 -0 -1.5708" />
        <axis xyz="0 -1 6.12323e-17" />
        <parent link="torso_2" />
        <child link="chest" />
        <dynamics damping="1" friction="0" />
        <limit effort="80" velocity="100" lower="-1.02974" upper="1.02974" />
    </joint>
    <joint name="chest_skin_frame_fixed_joint" type="fixed">
        <origin xyz="0.00231 0.1933 -1.18362e-17" rpy="-1.8747e-33 5.77686e-66 6.16298e-33" />
        <axis xyz="0 0 0" />
        <parent link="chest" />
        <child link="chest_skin_frame" />
    </joint>
    <!-- JOINTS FOR ICUB BALANCING ON A CHAIR -->
    <joint name="l_upper_leg_frame_fixed_joint" type="fixed">
        <origin xyz="-0.0596 -0.0700 -0.0009" rpy="-1.5810 -0.2157 -1.5231" />
        <axis xyz="0 0 0" />
        <parent link="l_upper_leg" />
        <child link="l_upper_leg_contact" />
    </joint>
    <joint name="r_upper_leg_frame_fixed_joint" type="fixed">
        <origin xyz="-0.0596 -0.0694 -0.0008" rpy="-1.5606 0.2124 -1.5229" />
        <axis xyz="0 0 0" />
        <parent link="r_upper_leg" />
        <child link="r_upper_leg_contact" />
    </joint>
    <!-- ************************************ -->
    <joint name="codyco_balancing_world_fixed_joint" type="fixed">
        <origin xyz="-1.24246e-32 -2.65687e-65 0.004" rpy="3.14159 -0 0" />
        <axis xyz="0 0 0" />
        <parent link="l_foot" />
        <child link="codyco_balancing_world" />
    </joint>
    <joint name="neck_yaw" type="revolute">
        <origin xyz="-5.77779e-34 0 0" rpy="-1.5708 -0 1.5708" />
        <axis xyz="0 -1 6.12323e-17" />
        <parent link="neck_2" />
        <child link="head" />
        <dynamics damping="1" friction="0" />
        <limit effort="20" velocity="100" lower="-0.959931" upper="0.959931" />
    </joint>
    <joint name="imu_frame_fixed_joint" type="fixed">
        <origin xyz="0.0185 -0.1108 0.0066" rpy="1.5708 -0 0" />
        <axis xyz="0 0 0" />
        <parent link="head" />
        <child link="imu_frame" />
    </joint>
    <joint name="l_ankle_pitch" type="revolute">
        <origin xyz="-0.213 0 0" rpy="-1.5708 0 0" />
        <axis xyz="0 -1 6.12323e-17" />
        <parent link="l_lower_leg" />
        <child link="l_ankle_1" />
        <dynamics damping="1" friction="0" />
        <limit effort="24" velocity="100" lower="-0.733038" upper="0.366519" />
    </joint>
    <joint name="l_ankle_roll" type="revolute">
        <origin xyz="0 0 0" rpy="0 -1.5708 0" />
        <axis xyz="1 0 0" />
        <parent link="l_ankle_1" />
        <child link="l_ankle_2" />
        <dynamics damping="1" friction="0" />
        <limit effort="11" velocity="100" lower="-0.418879" upper="0.418879" />
    </joint>
    <joint name="l_elbow" type="revolute">
        <origin xyz="0 0 0.08428" rpy="-6.12323e-17 0 0" />
        <axis xyz="0 1 6.12323e-17" />
        <parent link="l_upper_arm" />
        <child link="l_elbow_1" />
        <dynamics damping="1" friction="0" />
        <limit effort="20" velocity="100" lower="0.0959931" upper="1.85005" />
    </joint>
    <joint name="l_foot_ft_sensor" type="fixed">
        <origin xyz="0 0 0.037" rpy="0 -0 0" />
        <axis xyz="0 0 0" />
        <parent link="l_ankle_2" />
        <child link="l_foot" />
    </joint>
    <joint name="l_foot_dh_frame_fixed_joint" type="fixed">
        <origin xyz="0 0 0.004" rpy="0 1.5708 0" />
        <axis xyz="0 0 0" />
        <parent link="l_foot" />
        <child link="l_foot_dh_frame" />
    </joint>
    <joint name="l_wrist_prosup" type="revolute">
        <origin xyz="-0.015 0 0" rpy="1.5708 -0 -1.5708" />
        <axis xyz="0 1 6.12323e-17" />
        <parent link="l_elbow_1" />
        <child link="l_forearm" />
        <dynamics damping="1" friction="0" />
        <limit effort="0.45" velocity="100" lower="-0.872665" upper="0.872665" />
    </joint>
    <joint name="l_forearm_dh_frame_fixed_joint" type="fixed">
        <origin xyz="0 0.1373 8.4072e-18" rpy="0 -0 0" />
        <axis xyz="0 0 0" />
        <parent link="l_forearm" />
        <child link="l_forearm_dh_frame" />
    </joint>
    <joint name="l_gripper_joint" type="fixed">
        <origin xyz="0.0625 0 -0.016" rpy="0 -0 0" />
        <axis xyz="0 0 0" />
        <parent link="l_hand" />
        <child link="l_gripper" />
    </joint>
    <joint name="l_wrist_yaw" type="revolute">
        <origin xyz="0 0 0" rpy="0 -0 0" />
        <axis xyz="0 0 1" />
        <parent link="l_wrist_1" />
        <child link="l_hand" />
        <dynamics damping="1" friction="0" />
        <limit effort="0.65" velocity="100" lower="-0.436332" upper="0.436332" />
    </joint>
    <joint name="l_hand_dh_frame_fixed_joint" type="fixed">
        <origin xyz="0.0625 0 -0.016" rpy="0 -0 0" />
        <axis xyz="0 0 0" />
        <parent link="l_hand" />
        <child link="l_hand_dh_frame" />
    </joint>
    <joint name="l_hip_pitch" type="revolute">
        <origin xyz="0 -0.0681 -0.1199" rpy="-3.14159 1.5708 -2.77556e-17" />
        <axis xyz="0 -1 6.12323e-17" />
        <parent link="root_link" />
        <child link="l_hip_1" />
        <dynamics damping="1" friction="0" />
        <limit effort="84" velocity="100" lower="-0.767945" upper="2.30383" />
    </joint>
    <joint name="l_hip_roll" type="revolute">
        <origin xyz="0 0 0" rpy="3.14159 -1.5708 -2.77556e-17" />
        <axis xyz="1 0 -6.12323e-17" />
        <parent link="l_hip_1" />
        <child link="l_hip_2" />
        <dynamics damping="1" friction="0" />
        <limit effort="84" velocity="100" lower="-2.07694" upper="0.296706" />
    </joint>
    <joint name="l_leg_ft_sensor" type="fixed">
        <origin xyz="0 0 0.0665" rpy="0 -0 0" />
        <axis xyz="0 0 0" />
        <parent link="l_hip_2" />
        <child link="l_hip_3" />
    </joint>
    <joint name="l_knee" type="revolute">
        <origin xyz="0 -0.2236 -1.36916e-17" rpy="3.14159 -1.2326e-32 1.5708" />
        <axis xyz="0 1.22465e-16 -1" />
        <parent link="l_upper_leg" />
        <child link="l_lower_leg" />
        <dynamics damping="1" friction="0" />
        <limit effort="30" velocity="100" lower="-2.18166" upper="0.401426" />
    </joint>
    <joint name="l_shoulder_pitch" type="revolute">
        <origin xyz="0.00525 0.1433 -0.11026" rpy="1.309 5.55112e-17 1.5708" />
        <axis xyz="0 -1 5.55112e-17" />
        <parent link="chest" />
        <child link="l_shoulder_1" />
        <dynamics damping="1" friction="0" />
        <limit effort="84" velocity="100" lower="-1.65806" upper="0.0872665" />
    </joint>
    <joint name="l_shoulder_roll" type="revolute">
        <origin xyz="0 0 0" rpy="1.5708 -0 -1.5708" />
        <axis xyz="0 1 6.12323e-17" />
        <parent link="l_shoulder_1" />
        <child link="l_shoulder_2" />
        <dynamics damping="1" friction="0" />
        <limit effort="84" velocity="100" lower="0" upper="2.80649" />
    </joint>
    <joint name="l_shoulder_yaw" type="revolute">
        <origin xyz="4.33681e-19 1.73472e-18 0" rpy="6.12323e-17 -0 1.309" />
        <axis xyz="0 6.12323e-17 1" />
        <parent link="l_shoulder_2" />
        <child link="l_shoulder_3" />
        <dynamics damping="1" friction="0" />
        <limit effort="34" velocity="100" lower="-0.645772" upper="1.74533" />
    </joint>
    <joint name="l_sole_fixed_joint" type="fixed">
        <origin xyz="-1.24246e-32 -2.65687e-65 0.004" rpy="3.14159 -0 0" />
        <axis xyz="0 0 0" />
        <parent link="l_foot" />
        <child link="l_sole" />
    </joint>
    <joint name="l_arm_ft_sensor" type="fixed">
        <origin xyz="0.015 9.36797e-18 0.068" rpy="0 -0 0" />
        <axis xyz="0 0 0" />
        <parent link="l_shoulder_3" />
        <child link="l_upper_arm" />
    </joint>
    <joint name="l_upper_arm_dh_frame_fixed_joint" type="fixed">
        <origin xyz="0 0 0.08428" rpy="-1.5708 0 0" />
        <axis xyz="0 0 0" />
        <parent link="l_upper_arm" />
        <child link="l_upper_arm_dh_frame" />
    </joint>
    <joint name="l_hip_yaw" type="revolute">
        <origin xyz="0 0 -0.0665" rpy="-1.5708 -6.16298e-33 -6.12323e-17" />
        <axis xyz="0 1 6.12323e-17" />
        <parent link="l_hip_3" />
        <child link="l_upper_leg" />
        <dynamics damping="1" friction="0" />
        <limit effort="40" velocity="100" lower="-1.37881" upper="1.37881" />
    </joint>
    <joint name="l_wrist_pitch" type="revolute">
        <origin xyz="0 0.1373 8.4072e-18" rpy="1.5708 -0 1.5708" />
        <axis xyz="0 1 6.12323e-17" />
        <parent link="l_forearm" />
        <child link="l_wrist_1" />
        <dynamics damping="1" friction="0" />
        <limit effort="0.65" velocity="100" lower="-1.13446" upper="0.174533" />
    </joint>
    <joint name="neck_pitch" type="revolute">
        <origin xyz="0.00231 0.1933 -1.18362e-17" rpy="1.5708 -0 1.5708" />
        <axis xyz="0 1 6.12323e-17" />
        <parent link="chest" />
        <child link="neck_1" />
        <dynamics damping="1" friction="0" />
        <limit effort="20" velocity="100" lower="-0.698132" upper="0.523599" />
    </joint>
    <joint name="neck_roll" type="revolute">
        <origin xyz="0.0095 0 0" rpy="-1.5708 -0 -1.5708" />
        <axis xyz="0 -1 6.12323e-17" />
        <parent link="neck_1" />
        <child link="neck_2" />
        <dynamics damping="1" friction="0" />
        <limit effort="20" velocity="100" lower="-1.22173" upper="1.0472" />
    </joint>
    <joint name="r_ankle_pitch" type="revolute">
        <origin xyz="-0.213 0 0" rpy="1.5708 -0 0" />
        <axis xyz="0 1 6.12323e-17" />
        <parent link="r_lower_leg" />
        <child link="r_ankle_1" />
        <dynamics damping="1" friction="0" />
        <limit effort="24" velocity="100" lower="-0.733038" upper="0.366519" />
    </joint>
    <joint name="r_ankle_roll" type="revolute">
        <origin xyz="0 0 0" rpy="0.504019 1.5708 -2.63757" />
        <axis xyz="-1 1.22465e-16 0" />
        <parent link="r_ankle_1" />
        <child link="r_ankle_2" />
        <dynamics damping="1" friction="0" />
        <limit effort="11" velocity="100" lower="-0.418879" upper="0.418879" />
    </joint>
    <joint name="r_elbow" type="revolute">
        <origin xyz="0 0 0.08428" rpy="3.14159 -0 3.14159" />
        <axis xyz="0 1 6.12323e-17" />
        <parent link="r_upper_arm" />
        <child link="r_elbow_1" />
        <dynamics damping="1" friction="0" />
        <limit effort="20" velocity="100" lower="0.0959931" upper="1.85005" />
    </joint>
    <joint name="r_foot_ft_sensor" type="fixed">
        <origin xyz="0 0 0.037" rpy="0 -0 0" />
        <axis xyz="0 0 0" />
        <parent link="r_ankle_2" />
        <child link="r_foot" />
    </joint>
    <joint name="r_foot_dh_frame_fixed_joint" type="fixed">
        <origin xyz="0 0 0.004" rpy="0 1.5708 0" />
        <axis xyz="0 0 0" />
        <parent link="r_foot" />
        <child link="r_foot_dh_frame" />
    </joint>
    <joint name="r_wrist_prosup" type="revolute">
        <origin xyz="0.015 0 0" rpy="1.5708 -0 -1.5708" />
        <axis xyz="0 1 6.12323e-17" />
        <parent link="r_elbow_1" />
        <child link="r_forearm" />
        <dynamics damping="1" friction="0" />
        <limit effort="0.45" velocity="100" lower="-0.872665" upper="0.872665" />
    </joint>
    <joint name="r_forearm_dh_frame_fixed_joint" type="fixed">
        <origin xyz="0 -0.1373 -8.4072e-18" rpy="0 -0 0" />
        <axis xyz="0 0 0" />
        <parent link="r_forearm" />
        <child link="r_forearm_dh_frame" />
    </joint>
    <joint name="r_gripper_joint" type="fixed">
        <origin xyz="0.0625 0 0.016" rpy="0 -0 0" />
        <axis xyz="0 0 0" />
        <parent link="r_hand" />
        <child link="r_gripper" />
    </joint>
    <joint name="r_wrist_yaw" type="revolute">
        <origin xyz="0 0 0" rpy="0 -0 3.14159" />
        <axis xyz="0 0 1" />
        <parent link="r_wrist_1" />
        <child link="r_hand" />
        <dynamics damping="1" friction="0" />
        <limit effort="0.65" velocity="100" lower="-0.436332" upper="0.436332" />
    </joint>
    <joint name="r_hand_dh_frame_fixed_joint" type="fixed">
        <origin xyz="0.0625 0 0.016" rpy="0 -0 0" />
        <axis xyz="0 0 0" />
        <parent link="r_hand" />
        <child link="r_hand_dh_frame" />
    </joint>
    <joint name="r_hip_pitch" type="revolute">
        <origin xyz="0 0.0681 -0.1199" rpy="-2.77556e-17 1.5708 2.77556e-17" />
        <axis xyz="0 1 6.12323e-17" />
        <parent link="root_link" />
        <child link="r_hip_1" />
        <dynamics damping="1" friction="0" />
        <limit effort="84" velocity="100" lower="-0.767945" upper="2.30383" />
    </joint>
    <joint name="r_hip_roll" type="revolute">
        <origin xyz="0 0 0" rpy="2.77556e-17 1.5708 -2.77556e-17" />
        <axis xyz="-1 0 6.12323e-17" />
        <parent link="r_hip_1" />
        <child link="r_hip_2" />
        <dynamics damping="1" friction="0" />
        <limit effort="84" velocity="100" lower="-2.07694" upper="0.296706" />
    </joint>
    <joint name="r_leg_ft_sensor" type="fixed">
        <origin xyz="0 0 0.0665" rpy="0 -0 0" />
        <axis xyz="0 0 0" />
        <parent link="r_hip_2" />
        <child link="r_hip_3" />
    </joint>
    <joint name="r_knee" type="revolute">
        <origin xyz="0 -0.2236 1.36916e-17" rpy="3.14159 -1.2326e-32 1.5708" />
        <axis xyz="0 1.22465e-16 -1" />
        <parent link="r_upper_leg" />
        <child link="r_lower_leg" />
        <dynamics damping="1" friction="0" />
        <limit effort="30" velocity="100" lower="-2.18166" upper="0.401426" />
    </joint>
    <joint name="r_shoulder_pitch" type="revolute">
        <origin xyz="0.00525 0.1433 0.11026" rpy="-1.309 -0 1.5708" />
        <axis xyz="0 1 5.55112e-17" />
        <parent link="chest" />
        <child link="r_shoulder_1" />
        <dynamics damping="1" friction="0" />
        <limit effort="84" velocity="100" lower="-1.65806" upper="0.0872665" />
    </joint>
    <joint name="r_shoulder_roll" type="revolute">
        <origin xyz="0 0 0" rpy="-1.5708 -0 -1.5708" />
        <axis xyz="0 -1 6.12323e-17" />
        <parent link="r_shoulder_1" />
        <child link="r_shoulder_2" />
        <dynamics damping="1" friction="0" />
        <limit effort="84" velocity="100" lower="0" upper="2.80649" />
    </joint>
    <joint name="r_shoulder_yaw" type="revolute">
        <origin xyz="-4.33681e-19 0 0" rpy="3.14159 -0 1.309" />
        <axis xyz="0 6.12323e-17 -1" />
        <parent link="r_shoulder_2" />
        <child link="r_shoulder_3" />
        <dynamics damping="1" friction="0" />
        <limit effort="34" velocity="100" lower="-0.645772" upper="1.74533" />
    </joint>
    <joint name="r_sole_fixed_joint" type="fixed">
        <origin xyz="-1.24246e-32 -9.86076e-35 0.004" rpy="3.14159 -0 0" />
        <axis xyz="0 0 0" />
        <parent link="r_foot" />
        <child link="r_sole" />
    </joint>
    <joint name="r_arm_ft_sensor" type="fixed">
        <origin xyz="0.015 -8.93429e-18 0.068" rpy="0 -0 0" />
        <axis xyz="0 0 0" />
        <parent link="r_shoulder_3" />
        <child link="r_upper_arm" />
    </joint>
    <joint name="r_upper_arm_dh_frame_fixed_joint" type="fixed">
        <origin xyz="0 0 0.08428" rpy="1.5708 -0 3.14159" />
        <axis xyz="0 0 0" />
        <parent link="r_upper_arm" />
        <child link="r_upper_arm_dh_frame" />
    </joint>
    <joint name="r_hip_yaw" type="revolute">
        <origin xyz="0 0 -0.0665" rpy="-1.5708 -6.16298e-33 6.12323e-17" />
        <axis xyz="0 -1 6.12323e-17" />
        <parent link="r_hip_3" />
        <child link="r_upper_leg" />
        <dynamics damping="1" friction="0" />
        <limit effort="40" velocity="100" lower="-1.37881" upper="1.37881" />
    </joint>
    <joint name="r_wrist_pitch" type="revolute">
        <origin xyz="0 -0.1373 -8.4072e-18" rpy="1.5708 -0 1.5708" />
        <axis xyz="0 1 6.12323e-17" />
        <parent link="r_forearm" />
        <child link="r_wrist_1" />
        <dynamics damping="1" friction="0" />
        <limit effort="0.65" velocity="100" lower="-1.13446" upper="0.174533" />
    </joint>
    <joint name="torso_joint" type="fixed">
        <origin xyz="0.00231 0.1933 -1.18362e-17" rpy="0 -0 0" />
        <axis xyz="0 0 0" />
        <parent link="chest" />
        <child link="torso" />
    </joint>
    <joint name="torso_pitch" type="revolute">
        <origin xyz="0 0 0" rpy="-2.77556e-17 -1.5708 3.14159" />
        <axis xyz="0 1 6.12323e-17" />
        <parent link="root_link" />
        <child link="torso_1" />
        <dynamics damping="1" friction="0" />
        <limit effort="36" velocity="100" lower="-0.383972" upper="1.46608" />
    </joint>
    <joint name="torso_roll" type="revolute">
        <origin xyz="0.032 -2.67276e-51 0" rpy="1.5708 -0 -1.5708" />
        <axis xyz="0 1 6.12323e-17" />
        <parent link="torso_1" />
        <child link="torso_2" />
        <dynamics damping="1" friction="0" />
        <limit effort="80" velocity="100" lower="-0.680678" upper="0.680678" />
    </joint>
  <gazebo reference="l_leg_ft_sensor">
    <sensor name="l_leg_ft_sensor" type="force_torque">
      <always_on>1</always_on>
      <update_rate>100</update_rate>
      <force_torque>
        <frame>child</frame>
        <measure_direction>child_to_parent</measure_direction>
      </force_torque>
    </sensor>
  </gazebo>
  <sensor name="l_leg_ft_sensor" type="force_torque">
    <parent joint="l_leg_ft_sensor"/>
    <force_torque>
      <frame>child</frame>
      <measure_direction>child_to_parent</measure_direction>
    </force_torque>
  </sensor>
  <gazebo reference="r_leg_ft_sensor">
    <sensor name="r_leg_ft_sensor" type="force_torque">
      <always_on>1</always_on>
      <update_rate>100</update_rate>
      <force_torque>
        <frame>child</frame>
        <measure_direction>child_to_parent</measure_direction>
      </force_torque>
    </sensor>
  </gazebo>
  <sensor name="r_leg_ft_sensor" type="force_torque">
    <parent joint="r_leg_ft_sensor"/>
    <force_torque>
      <frame>child</frame>
      <measure_direction>child_to_parent</measure_direction>
    </force_torque>
  </sensor>
  <gazebo reference="l_foot_ft_sensor">
    <sensor name="l_foot_ft_sensor" type="force_torque">
      <always_on>1</always_on>
      <update_rate>100</update_rate>
      <force_torque>
        <frame>child</frame>
        <measure_direction>child_to_parent</measure_direction>
      </force_torque>
    </sensor>
  </gazebo>
  <sensor name="l_foot_ft_sensor" type="force_torque">
    <parent joint="l_foot_ft_sensor"/>
    <force_torque>
      <frame>child</frame>
      <measure_direction>child_to_parent</measure_direction>
    </force_torque>
  </sensor>
  <gazebo reference="r_foot_ft_sensor">
    <sensor name="r_foot_ft_sensor" type="force_torque">
      <always_on>1</always_on>
      <update_rate>100</update_rate>
      <force_torque>
        <frame>child</frame>
        <measure_direction>child_to_parent</measure_direction>
      </force_torque>
    </sensor>
  </gazebo>
  <sensor name="r_foot_ft_sensor" type="force_torque">
    <parent joint="r_foot_ft_sensor"/>
    <force_torque>
      <frame>child</frame>
      <measure_direction>child_to_parent</measure_direction>
    </force_torque>
  </sensor>
  <gazebo reference="l_arm_ft_sensor">
    <sensor name="l_arm_ft_sensor" type="force_torque">
      <always_on>1</always_on>
      <update_rate>100</update_rate>
      <force_torque>
        <frame>child</frame>
        <measure_direction>child_to_parent</measure_direction>
      </force_torque>
    </sensor>
  </gazebo>
  <sensor name="l_arm_ft_sensor" type="force_torque">
    <parent joint="l_arm_ft_sensor"/>
    <force_torque>
      <frame>child</frame>
      <measure_direction>child_to_parent</measure_direction>
    </force_torque>
  </sensor>
  <gazebo reference="r_arm_ft_sensor">
    <sensor name="r_arm_ft_sensor" type="force_torque">
      <always_on>1</always_on>
      <update_rate>100</update_rate>
      <force_torque>
        <frame>child</frame>
        <measure_direction>child_to_parent</measure_direction>
      </force_torque>
    </sensor>
  </gazebo>
  <sensor name="r_arm_ft_sensor" type="force_torque">
    <parent joint="r_arm_ft_sensor"/>
    <force_torque>
      <frame>child</frame>
      <measure_direction>child_to_parent</measure_direction>
    </force_torque>
</sensor>
  <gazebo reference="root_link">
    <sensor name="root_link_ems_acc_eb5" type="imu">
      <always_on>1</always_on>
      <update_rate>100</update_rate>
      <pose>0.0493308 -0.0125771 -0.115691 -3.14159265359 1.29154404503 3.14159265359</pose>
      <plugin name="iCub_yarp_gazebo_plugin_ACC" filename="libgazebo_yarp_inertialmtb.so"/>
    </sensor>
  </gazebo>
  <sensor name="root_link_ems_acc_eb5" type="accelerometer">
    <parent link="root_link"/>
    <origin rpy="-3.14159265359 1.29154404503 3.14159265359" xyz="0.0493308 -0.0125771 -0.115691"/>
  </sensor>
  <gazebo reference="root_link">
    <sensor name="root_link_ems_gyro_eb5" type="imu">
      <always_on>1</always_on>
      <update_rate>100</update_rate>
      <pose>0.0493308 -0.0125771 -0.115691 -3.14159265359 1.29154404503 3.14159265359</pose>
    </sensor>
  </gazebo>
  <sensor name="root_link_ems_gyro_eb5" type="gyroscope">
    <parent link="root_link"/>
    <origin rpy="-3.14159265359 1.29154404503 3.14159265359" xyz="0.0493308 -0.0125771 -0.115691"/>
  </sensor>
  <gazebo reference="chest">
    <sensor name="chest_ems_acc_eb1" type="imu">
      <always_on>1</always_on>
      <update_rate>100</update_rate>
      <pose>0.0647855001907 0.064043 -0.064709 3.1415169123 -0.261799309122 0.000292641880255</pose>
      <plugin name="iCub_yarp_gazebo_plugin_ACC" filename="libgazebo_yarp_inertialmtb.so"/>
    </sensor>
  </gazebo>
  <sensor name="chest_ems_acc_eb1" type="accelerometer">
    <parent link="chest"/>
    <origin rpy="3.1415169123 -0.261799309122 0.000292641880255" xyz="0.0647855001907 0.064043 -0.064709"/>
  </sensor>
  <gazebo reference="chest">
    <sensor name="chest_ems_gyro_eb1" type="imu">
      <always_on>1</always_on>
      <update_rate>100</update_rate>
      <pose>0.0692016001907 0.064548 -0.0635257 3.1415169123 -0.261799309122 0.000292641880255</pose>
    </sensor>
  </gazebo>
  <sensor name="chest_ems_gyro_eb1" type="gyroscope">
    <parent link="chest"/>
    <origin rpy="3.1415169123 -0.261799309122 0.000292641880255" xyz="0.0692016001907 0.064548 -0.0635257"/>
  </sensor>
  <gazebo reference="chest">
    <sensor name="chest_ems_acc_eb2" type="imu">
      <always_on>1</always_on>
      <update_rate>100</update_rate>
      <pose>0.0204533001907 0.088063 -0.0641645 3.14159050104 0.261799319819 3.14158433678</pose>
      <plugin name="iCub_yarp_gazebo_plugin_ACC" filename="libgazebo_yarp_inertialmtb.so"/>
    </sensor>
  </gazebo>
  <sensor name="chest_ems_acc_eb2" type="accelerometer">
    <parent link="chest"/>
    <origin rpy="3.14159050104 0.261799319819 3.14158433678" xyz="0.0204533001907 0.088063 -0.0641645"/>
  </sensor>
  <gazebo reference="chest">
    <sensor name="chest_ems_gyro_eb2" type="imu">
      <always_on>1</always_on>
      <update_rate>100</update_rate>
      <pose>0.0160371001907 0.087559 -0.0653478 3.14159050104 0.261799319819 3.14158433678</pose>
    </sensor>
  </gazebo>
  <sensor name="chest_ems_gyro_eb2" type="gyroscope">
    <parent link="chest"/>
    <origin rpy="3.14159050104 0.261799319819 3.14158433678" xyz="0.0160371001907 0.087559 -0.0653478"/>
  </sensor>
  <gazebo reference="chest">
    <sensor name="chest_ems_acc_eb3" type="imu">
      <always_on>1</always_on>
      <update_rate>100</update_rate>
      <pose>-0.0230587998093 0.064019 -0.0758985 3.14110916203 0.261100516471 -0.000309071462555</pose>
      <plugin name="iCub_yarp_gazebo_plugin_ACC" filename="libgazebo_yarp_inertialmtb.so"/>
    </sensor>
  </gazebo>
  <sensor name="chest_ems_acc_eb3" type="accelerometer">
    <parent link="chest"/>
    <origin rpy="3.14110916203 0.261100516471 -0.000309071462555" xyz="-0.0230587998093 0.064019 -0.0758985"/>
  </sensor>
  <gazebo reference="chest">
    <sensor name="chest_ems_gyro_eb3" type="imu">
      <always_on>1</always_on>
      <update_rate>100</update_rate>
      <pose>-0.0186416998093 0.064521 -0.0770785 3.14110916203 0.261100516471 -0.000309071462555</pose>
    </sensor>
  </gazebo>
  <sensor name="chest_ems_gyro_eb3" type="gyroscope">
    <parent link="chest"/>
    <origin rpy="3.14110916203 0.261100516471 -0.000309071462555" xyz="-0.0186416998093 0.064521 -0.0770785"/>
  </sensor>
  <gazebo reference="chest">
    <sensor name="chest_ems_acc_eb4" type="imu">
      <always_on>1</always_on>
      <update_rate>100</update_rate>
      <pose>-0.0621620998093 0.088063 -0.0529886 -3.14159050476 -0.261799319819 3.14158433987</pose>
      <plugin name="iCub_yarp_gazebo_plugin_ACC" filename="libgazebo_yarp_inertialmtb.so"/>
    </sensor>
  </gazebo>
  <sensor name="chest_ems_acc_eb4" type="accelerometer">
    <parent link="chest"/>
    <origin rpy="-3.14159050476 -0.261799319819 3.14158433987" xyz="-0.0621620998093 0.088063 -0.0529886"/>
  </sensor>
  <gazebo reference="chest">
    <sensor name="chest_ems_gyro_eb4" type="imu">
      <always_on>1</always_on>
      <update_rate>100</update_rate>
      <pose>-0.0665783998093 0.087559 -0.0518053 -3.14159050476 -0.261799319819 3.14158433987</pose>
    </sensor>
  </gazebo>
  <sensor name="chest_ems_gyro_eb4" type="gyroscope">
    <parent link="chest"/>
    <origin rpy="-3.14159050476 -0.261799319819 3.14158433987" xyz="-0.0665783998093 0.087559 -0.0518053"/>
  </sensor>
  <gazebo reference="chest">
    <sensor name="chest_mtb_acc_0b7" type="imu">
      <always_on>1</always_on>
      <update_rate>100</update_rate>
      <pose>-0.0607539998093 -0.0017836 0.0442342 0.875167771492 0.116363734392 -1.48597350247</pose>
      <plugin name="iCub_yarp_gazebo_plugin_ACC" filename="libgazebo_yarp_inertialmtb.so"/>
    </sensor>
  </gazebo>
  <sensor name="chest_mtb_acc_0b7" type="accelerometer">
    <parent link="chest"/>
    <origin rpy="0.875167771492 0.116363734392 -1.48597350247" xyz="-0.0607539998093 -0.0017836 0.0442342"/>
  </sensor>
  <gazebo reference="chest">
    <sensor name="chest_mtb_acc_0b8" type="imu">
      <always_on>1</always_on>
      <update_rate>100</update_rate>
      <pose>-0.0457046998093 -0.001846 0.0567427 0.500960084689 0.107313688983 -1.4778325291</pose>
      <plugin name="iCub_yarp_gazebo_plugin_ACC" filename="libgazebo_yarp_inertialmtb.so"/>
    </sensor>
  </gazebo>
  <sensor name="chest_mtb_acc_0b8" type="accelerometer">
    <parent link="chest"/>
    <origin rpy="0.500960084689 0.107313688983 -1.4778325291" xyz="-0.0457046998093 -0.001846 0.0567427"/>
  </sensor>
  <gazebo reference="chest">
    <sensor name="chest_mtb_acc_0b9" type="imu">
      <always_on>1</always_on>
      <update_rate>100</update_rate>
      <pose>0.0439036001907 -0.0017841 0.0577221 -0.500959928973 0.107315404248 -1.66376017469</pose>
      <plugin name="iCub_yarp_gazebo_plugin_ACC" filename="libgazebo_yarp_inertialmtb.so"/>
    </sensor>
  </gazebo>
  <sensor name="chest_mtb_acc_0b9" type="accelerometer">
    <parent link="chest"/>
    <origin rpy="-0.500959928973 0.107315404248 -1.66376017469" xyz="0.0439036001907 -0.0017841 0.0577221"/>
  </sensor>
  <gazebo reference="chest">
    <sensor name="chest_mtb_acc_0b10" type="imu">
      <always_on>1</always_on>
      <update_rate>100</update_rate>
      <pose>0.0594286001907 -0.0018543 0.0457982 -0.875168153475 0.116362025479 -1.65561807505</pose>
      <plugin name="iCub_yarp_gazebo_plugin_ACC" filename="libgazebo_yarp_inertialmtb.so"/>
    </sensor>
  </gazebo>
  <sensor name="chest_mtb_acc_0b10" type="accelerometer">
    <parent link="chest"/>
    <origin rpy="-0.875168153475 0.116362025479 -1.65561807505" xyz="0.0594286001907 -0.0018543 0.0457982"/>
  </sensor>
  <gazebo reference="r_upper_arm">
    <sensor name="r_upper_arm_mtb_acc_2b10" type="imu">
      <always_on>1</always_on>
      <update_rate>100</update_rate>
      <pose>-0.0412195 0.029588 0.0295279 1.57079546365 1.57078381225 -2.68257161165</pose>
      <plugin name="iCub_yarp_gazebo_plugin_ACC" filename="libgazebo_yarp_inertialmtb.so"/>
    </sensor>
  </gazebo>
  <sensor name="r_upper_arm_mtb_acc_2b10" type="accelerometer">
    <parent link="r_upper_arm"/>
    <origin rpy="1.57079546365 1.57078381225 -2.68257161165" xyz="-0.0412195 0.029588 0.0295279"/>
  </sensor>
  <gazebo reference="r_upper_arm">
    <sensor name="r_upper_arm_mtb_acc_2b11" type="imu">
      <always_on>1</always_on>
      <update_rate>100</update_rate>
      <pose>-0.0430568 0.02868 0.0760604 -1.57079614695 -1.57050350741 0.459021725219</pose>
      <plugin name="iCub_yarp_gazebo_plugin_ACC" filename="libgazebo_yarp_inertialmtb.so"/>
    </sensor>
  </gazebo>
  <sensor name="r_upper_arm_mtb_acc_2b11" type="accelerometer">
    <parent link="r_upper_arm"/>
    <origin rpy="-1.57079614695 -1.57050350741 0.459021725219" xyz="-0.0430568 0.02868 0.0760604"/>
  </sensor>
  <gazebo reference="r_upper_arm">
    <sensor name="r_upper_arm_mtb_acc_2b12" type="imu">
      <always_on>1</always_on>
      <update_rate>100</update_rate>
      <pose>-0.0430555 0.028681 0.0049922 -1.11177442168 -1.57079632679 0.0</pose>
      <plugin name="iCub_yarp_gazebo_plugin_ACC" filename="libgazebo_yarp_inertialmtb.so"/>
    </sensor>
  </gazebo>
  <sensor name="r_upper_arm_mtb_acc_2b12" type="accelerometer">
    <parent link="r_upper_arm"/>
    <origin rpy="-1.11177442168 -1.57079632679 0.0" xyz="-0.0430555 0.028681 0.0049922"/>
  </sensor>
  <gazebo reference="r_upper_arm">
    <sensor name="r_upper_arm_mtb_acc_2b13" type="imu">
      <always_on>1</always_on>
      <update_rate>100</update_rate>
      <pose>0.010593184 0.02835 -0.010738 1.57079632702 -0.000214520362041 2.47803674451</pose>
      <plugin name="iCub_yarp_gazebo_plugin_ACC" filename="libgazebo_yarp_inertialmtb.so"/>
    </sensor>
  </gazebo>
  <sensor name="r_upper_arm_mtb_acc_2b13" type="accelerometer">
    <parent link="r_upper_arm"/>
    <origin rpy="1.57079632702 -0.000214520362041 2.47803674451" xyz="0.010593184 0.02835 -0.010738"/>
  </sensor>
  <gazebo reference="r_forearm">
    <sensor name="r_forearm_mtb_acc_2b7" type="imu">
      <always_on>1</always_on>
      <update_rate>100</update_rate>
      <pose>-0.0768728106161 0.005497 -0.0110480091994 0.26179949998 0.000370413042328 1.57125816863</pose>
      <plugin name="iCub_yarp_gazebo_plugin_ACC" filename="libgazebo_yarp_inertialmtb.so"/>
    </sensor>
  </gazebo>
  <sensor name="r_forearm_mtb_acc_2b7" type="accelerometer">
    <parent link="r_forearm"/>
    <origin rpy="0.26179949998 0.000370413042328 1.57125816863" xyz="-0.0768728106161 0.005497 -0.0110480091994"/>
  </sensor>
  <gazebo reference="r_forearm">
    <sensor name="r_forearm_mtb_acc_2b8" type="imu">
      <always_on>1</always_on>
      <update_rate>100</update_rate>
      <pose>-0.0514186285381 0.015786 0.0407521034996 -0.661143946092 0.147825248461 0.092070114703</pose>
      <plugin name="iCub_yarp_gazebo_plugin_ACC" filename="libgazebo_yarp_inertialmtb.so"/>
    </sensor>
  </gazebo>
  <sensor name="r_forearm_mtb_acc_2b8" type="accelerometer">
    <parent link="r_forearm"/>
    <origin rpy="-0.661143946092 0.147825248461 0.092070114703" xyz="-0.0514186285381 0.015786 0.0407521034996"/>
  </sensor>
  <gazebo reference="r_forearm">
    <sensor name="r_forearm_mtb_acc_2b9" type="imu">
      <always_on>1</always_on>
      <update_rate>100</update_rate>
      <pose>-0.0216380215578 0.027924 -0.0132491219944 -1.76682626732 0.261191225646 0.054048344372</pose>
      <plugin name="iCub_yarp_gazebo_plugin_ACC" filename="libgazebo_yarp_inertialmtb.so"/>
    </sensor>
  </gazebo>
  <sensor name="r_forearm_mtb_acc_2b9" type="accelerometer">
    <parent link="r_forearm"/>
    <origin rpy="-1.76682626732 0.261191225646 0.054048344372" xyz="-0.0216380215578 0.027924 -0.0132491219944"/>
  </sensor>
  <gazebo reference="l_upper_arm">
    <sensor name="l_upper_arm_mtb_acc_1b10" type="imu">
      <always_on>1</always_on>
      <update_rate>100</update_rate>
      <pose>-0.0430554 -0.028681 0.0295279 -1.57079650664 -1.57050350741 2.68257092837</pose>
      <plugin name="iCub_yarp_gazebo_plugin_ACC" filename="libgazebo_yarp_inertialmtb.so"/>
    </sensor>
  </gazebo>
  <sensor name="l_upper_arm_mtb_acc_1b10" type="accelerometer">
    <parent link="l_upper_arm"/>
    <origin rpy="-1.57079650664 -1.57050350741 2.68257092837" xyz="-0.0430554 -0.028681 0.0295279"/>
  </sensor>
  <gazebo reference="l_upper_arm">
    <sensor name="l_upper_arm_mtb_acc_1b11" type="imu">
      <always_on>1</always_on>
      <update_rate>100</update_rate>
      <pose>-0.0412181 -0.029589 0.0760604 -1.57079650664 -1.57050350741 2.68257092837</pose>
      <plugin name="iCub_yarp_gazebo_plugin_ACC" filename="libgazebo_yarp_inertialmtb.so"/>
    </sensor>
  </gazebo>
  <sensor name="l_upper_arm_mtb_acc_1b11" type="accelerometer">
    <parent link="l_upper_arm"/>
    <origin rpy="-1.57079650664 -1.57050350741 2.68257092837" xyz="-0.0412181 -0.029589 0.0760604"/>
  </sensor>
  <gazebo reference="l_upper_arm">
    <sensor name="l_upper_arm_mtb_acc_1b12" type="imu">
      <always_on>1</always_on>
      <update_rate>100</update_rate>
      <pose>-0.0412195 -0.029588 0.0049921 -1.5707971899 -1.57078381225 2.68257161159</pose>
      <plugin name="iCub_yarp_gazebo_plugin_ACC" filename="libgazebo_yarp_inertialmtb.so"/>
    </sensor>
  </gazebo>
  <sensor name="l_upper_arm_mtb_acc_1b12" type="accelerometer">
    <parent link="l_upper_arm"/>
    <origin rpy="-1.5707971899 -1.57078381225 2.68257161159" xyz="-0.0412195 -0.029588 0.0049921"/>
  </sensor>
  <gazebo reference="l_upper_arm">
    <sensor name="l_upper_arm_mtb_acc_1b13" type="imu">
      <always_on>1</always_on>
      <update_rate>100</update_rate>
      <pose>0.010592657 -0.028351 -0.0086914 -1.57079632657 0.000214520362042 -2.47803674451</pose>
      <plugin name="iCub_yarp_gazebo_plugin_ACC" filename="libgazebo_yarp_inertialmtb.so"/>
    </sensor>
  </gazebo>
  <sensor name="l_upper_arm_mtb_acc_1b13" type="accelerometer">
    <parent link="l_upper_arm"/>
    <origin rpy="-1.57079632657 0.000214520362042 -2.47803674451" xyz="0.010592657 -0.028351 -0.0086914"/>
  </sensor>
  <gazebo reference="l_forearm">
    <sensor name="l_forearm_mtb_acc_1b7" type="imu">
      <always_on>1</always_on>
      <update_rate>100</update_rate>
      <pose>0.0768728106161 -0.005483 -0.0110480091994 0.26179949998 0.000370413042328 -1.57033448496</pose>
      <plugin name="iCub_yarp_gazebo_plugin_ACC" filename="libgazebo_yarp_inertialmtb.so"/>
    </sensor>
  </gazebo>
  <sensor name="l_forearm_mtb_acc_1b7" type="accelerometer">
    <parent link="l_forearm"/>
    <origin rpy="0.26179949998 0.000370413042328 -1.57033448496" xyz="0.0768728106161 -0.005483 -0.0110480091994"/>
  </sensor>
  <gazebo reference="l_forearm">
    <sensor name="l_forearm_mtb_acc_1b8" type="imu">
      <always_on>1</always_on>
      <update_rate>100</update_rate>
      <pose>0.0514241875192 -0.0180279 0.0407506756155 -0.661143946092 0.147825248461 -3.04952253889</pose>
      <plugin name="iCub_yarp_gazebo_plugin_ACC" filename="libgazebo_yarp_inertialmtb.so"/>
    </sensor>
  </gazebo>
  <sensor name="l_forearm_mtb_acc_1b8" type="accelerometer">
    <parent link="l_forearm"/>
    <origin rpy="-0.661143946092 0.147825248461 -3.04952253889" xyz="0.0514241875192 -0.0180279 0.0407506756155"/>
  </sensor>
  <gazebo reference="l_forearm">
    <sensor name="l_forearm_mtb_acc_1b9" type="imu">
      <always_on>1</always_on>
      <update_rate>100</update_rate>
      <pose>0.0220992133815 0.025657 -0.0151175209138 1.76682134218 0.261099829847 3.08752548202</pose>
      <plugin name="iCub_yarp_gazebo_plugin_ACC" filename="libgazebo_yarp_inertialmtb.so"/>
    </sensor>
  </gazebo>
  <sensor name="l_forearm_mtb_acc_1b9" type="accelerometer">
    <parent link="l_forearm"/>
    <origin rpy="1.76682134218 0.261099829847 3.08752548202" xyz="0.0220992133815 0.025657 -0.0151175209138"/>
  </sensor>
  <gazebo reference="r_upper_leg">
    <sensor name="r_upper_leg_ems_acc_eb8" type="imu">
      <always_on>1</always_on>
      <update_rate>100</update_rate>
      <pose>0.0404072 -0.040027 -0.0125751 1.57079632679 -0.0 -1.57079632679</pose>
      <plugin name="iCub_yarp_gazebo_plugin_ACC" filename="libgazebo_yarp_inertialmtb.so"/>
    </sensor>
  </gazebo>
  <sensor name="r_upper_leg_ems_acc_eb8" type="accelerometer">
    <parent link="r_upper_leg"/>
    <origin rpy="1.57079632679 -0.0 -1.57079632679" xyz="0.0404072 -0.040027 -0.0125751"/>
  </sensor>
  <gazebo reference="r_upper_leg">
    <sensor name="r_upper_leg_ems_acc_eb11" type="imu">
      <always_on>1</always_on>
      <update_rate>100</update_rate>
      <pose>-0.040407 -0.083207 -0.0125771 1.57079632679 -0.0 -1.57079632679</pose>
      <plugin name="iCub_yarp_gazebo_plugin_ACC" filename="libgazebo_yarp_inertialmtb.so"/>
    </sensor>
  </gazebo>
  <sensor name="r_upper_leg_ems_acc_eb11" type="accelerometer">
    <parent link="r_upper_leg"/>
    <origin rpy="1.57079632679 -0.0 -1.57079632679" xyz="-0.040407 -0.083207 -0.0125771"/>
  </sensor>
  <gazebo reference="r_upper_leg">
    <sensor name="r_upper_leg_ems_gyro_eb8" type="imu">
      <always_on>1</always_on>
      <update_rate>100</update_rate>
      <pose>0.0404072 -0.035455 -0.013079 1.57079632679 -0.0 -1.57079632679</pose>
    </sensor>
  </gazebo>
  <sensor name="r_upper_leg_ems_gyro_eb8" type="gyroscope">
    <parent link="r_upper_leg"/>
    <origin rpy="1.57079632679 -0.0 -1.57079632679" xyz="0.0404072 -0.035455 -0.013079"/>
  </sensor>
  <gazebo reference="r_upper_leg">
    <sensor name="r_upper_leg_ems_gyro_eb11" type="imu">
      <always_on>1</always_on>
      <update_rate>100</update_rate>
      <pose>-0.040407 -0.087779 -0.013081 1.57079632679 -0.0 -1.57079632679</pose>
    </sensor>
  </gazebo>
  <sensor name="r_upper_leg_ems_gyro_eb11" type="gyroscope">
    <parent link="r_upper_leg"/>
    <origin rpy="1.57079632679 -0.0 -1.57079632679" xyz="-0.040407 -0.087779 -0.013081"/>
  </sensor>
  <gazebo reference="r_upper_leg">
    <sensor name="r_upper_leg_mtb_acc_11b1" type="imu">
      <always_on>1</always_on>
      <update_rate>100</update_rate>
      <pose>-0.030195 0.04914 0.043588612 -0.837758053858 -0.000342790749344 1.57087401652</pose>
      <plugin name="iCub_yarp_gazebo_plugin_ACC" filename="libgazebo_yarp_inertialmtb.so"/>
    </sensor>
  </gazebo>
  <sensor name="r_upper_leg_mtb_acc_11b1" type="accelerometer">
    <parent link="r_upper_leg"/>
    <origin rpy="-0.837758053858 -0.000342790749344 1.57087401652" xyz="-0.030195 0.04914 0.043588612"/>
  </sensor>
  <gazebo reference="r_upper_leg">
    <sensor name="r_upper_leg_mtb_acc_11b2" type="imu">
      <always_on>1</always_on>
      <update_rate>100</update_rate>
      <pose>-0.0064065 0.039256 0.0539467 -0.261799341927 -0.000399050135154 1.57090848318</pose>
      <plugin name="iCub_yarp_gazebo_plugin_ACC" filename="libgazebo_yarp_inertialmtb.so"/>
    </sensor>
  </gazebo>
  <sensor name="r_upper_leg_mtb_acc_11b2" type="accelerometer">
    <parent link="r_upper_leg"/>
    <origin rpy="-0.261799341927 -0.000399050135154 1.57090848318" xyz="-0.0064065 0.039256 0.0539467"/>
  </sensor>
  <gazebo reference="r_upper_leg">
    <sensor name="r_upper_leg_mtb_acc_11b3" type="imu">
      <always_on>1</always_on>
      <update_rate>100</update_rate>
      <pose>-0.0130214 0.004186 0.0538313 -4.98244646387e-08 -0.000429089990594 1.57091244355</pose>
      <plugin name="iCub_yarp_gazebo_plugin_ACC" filename="libgazebo_yarp_inertialmtb.so"/>
    </sensor>
  </gazebo>
  <sensor name="r_upper_leg_mtb_acc_11b3" type="accelerometer">
    <parent link="r_upper_leg"/>
    <origin rpy="-4.98244646387e-08 -0.000429089990594 1.57091244355" xyz="-0.0130214 0.004186 0.0538313"/>
  </sensor>
  <gazebo reference="r_upper_leg">
    <sensor name="r_upper_leg_mtb_acc_11b4" type="imu">
      <always_on>1</always_on>
      <update_rate>100</update_rate>
      <pose>0.0422675 -0.004845 0.0322719 1.18682375086 -0.000536853726193 1.57083983106</pose>
      <plugin name="iCub_yarp_gazebo_plugin_ACC" filename="libgazebo_yarp_inertialmtb.so"/>
    </sensor>
  </gazebo>
  <sensor name="r_upper_leg_mtb_acc_11b4" type="accelerometer">
    <parent link="r_upper_leg"/>
    <origin rpy="1.18682375086 -0.000536853726193 1.57083983106" xyz="0.0422675 -0.004845 0.0322719"/>
  </sensor>
  <gazebo reference="r_upper_leg">
    <sensor name="r_upper_leg_mtb_acc_11b5" type="imu">
      <always_on>1</always_on>
      <update_rate>100</update_rate>
      <pose>0.0164786 0.004186 0.0538313 -4.98244646387e-08 -0.000429089990594 1.57091244355</pose>
      <plugin name="iCub_yarp_gazebo_plugin_ACC" filename="libgazebo_yarp_inertialmtb.so"/>
    </sensor>
  </gazebo>
  <sensor name="r_upper_leg_mtb_acc_11b5" type="accelerometer">
    <parent link="r_upper_leg"/>
    <origin rpy="-4.98244646387e-08 -0.000429089990594 1.57091244355" xyz="0.0164786 0.004186 0.0538313"/>
  </sensor>
  <gazebo reference="r_upper_leg">
    <sensor name="r_upper_leg_mtb_acc_11b6" type="imu">
      <always_on>1</always_on>
      <update_rate>100</update_rate>
      <pose>-0.0157594 -0.026365 -0.0437518 3.14159265359 0.000429089993416 -1.57079632679</pose>
      <plugin name="iCub_yarp_gazebo_plugin_ACC" filename="libgazebo_yarp_inertialmtb.so"/>
    </sensor>
  </gazebo>
  <sensor name="r_upper_leg_mtb_acc_11b6" type="accelerometer">
    <parent link="r_upper_leg"/>
    <origin rpy="3.14159265359 0.000429089993416 -1.57079632679" xyz="-0.0157594 -0.026365 -0.0437518"/>
  </sensor>
  <gazebo reference="r_upper_leg">
    <sensor name="r_upper_leg_mtb_acc_11b7" type="imu">
      <always_on>1</always_on>
      <update_rate>100</update_rate>
      <pose>0.0162386 -0.026366 -0.0437518 3.14159260377 0.000429089990404 -1.57091243007</pose>
      <plugin name="iCub_yarp_gazebo_plugin_ACC" filename="libgazebo_yarp_inertialmtb.so"/>
    </sensor>
  </gazebo>
  <sensor name="r_upper_leg_mtb_acc_11b7" type="accelerometer">
    <parent link="r_upper_leg"/>
    <origin rpy="3.14159260377 0.000429089990404 -1.57091243007" xyz="0.0162386 -0.026366 -0.0437518"/>
  </sensor>
  <gazebo reference="r_lower_leg">
    <sensor name="r_lower_leg_ems_acc_eb9" type="imu">
      <always_on>1</always_on>
      <update_rate>100</update_rate>
      <pose>0.0235071 -0.092765 0.04351373 -4.26442049238e-17 -0.218166543341 1.57079632679</pose>
      <plugin name="iCub_yarp_gazebo_plugin_ACC" filename="libgazebo_yarp_inertialmtb.so"/>
    </sensor>
  </gazebo>
  <sensor name="r_lower_leg_ems_acc_eb9" type="accelerometer">
    <parent link="r_lower_leg"/>
    <origin rpy="-4.26442049238e-17 -0.218166543341 1.57079632679" xyz="0.0235071 -0.092765 0.04351373"/>
  </sensor>
  <gazebo reference="r_lower_leg">
    <sensor name="r_lower_leg_ems_gyro_eb9" type="imu">
      <always_on>1</always_on>
      <update_rate>100</update_rate>
      <pose>0.024011 -0.088301 0.044503292 -4.26442049238e-17 -0.218166543341 1.57079632679</pose>
    </sensor>
  </gazebo>
  <sensor name="r_lower_leg_ems_gyro_eb9" type="gyroscope">
    <parent link="r_lower_leg"/>
    <origin rpy="-4.26442049238e-17 -0.218166543341 1.57079632679" xyz="0.024011 -0.088301 0.044503292"/>
  </sensor>
  <gazebo reference="r_lower_leg">
    <sensor name="r_lower_leg_mtb_acc_11b8" type="imu">
      <always_on>1</always_on>
      <update_rate>100</update_rate>
      <pose>-0.0055283 -0.004318 0.05362922 -0.244346164565 2.80911040963e-05 1.57090899435</pose>
      <plugin name="iCub_yarp_gazebo_plugin_ACC" filename="libgazebo_yarp_inertialmtb.so"/>
    </sensor>
  </gazebo>
  <sensor name="r_lower_leg_mtb_acc_11b8" type="accelerometer">
    <parent link="r_lower_leg"/>
    <origin rpy="-0.244346164565 2.80911040963e-05 1.57090899435" xyz="-0.0055283 -0.004318 0.05362922"/>
  </sensor>
  <gazebo reference="r_lower_leg">
    <sensor name="r_lower_leg_mtb_acc_11b9" type="imu">
      <always_on>1</always_on>
      <update_rate>100</update_rate>
      <pose>0.0253904 -0.004318 0.0537517 0.349065638045 -3.97141037841e-05 1.57090544048</pose>
      <plugin name="iCub_yarp_gazebo_plugin_ACC" filename="libgazebo_yarp_inertialmtb.so"/>
    </sensor>
  </gazebo>
  <sensor name="r_lower_leg_mtb_acc_11b9" type="accelerometer">
    <parent link="r_lower_leg"/>
    <origin rpy="0.349065638045 -3.97141037841e-05 1.57090544048" xyz="0.0253904 -0.004318 0.0537517"/>
  </sensor>
  <gazebo reference="r_lower_leg">
    <sensor name="r_lower_leg_mtb_acc_11b10" type="imu">
      <always_on>1</always_on>
      <update_rate>100</update_rate>
      <pose>-0.0325465 -0.043468 0.0278945 -1.30899714732 4.4408920985e-16 1.57079632679</pose>
      <plugin name="iCub_yarp_gazebo_plugin_ACC" filename="libgazebo_yarp_inertialmtb.so"/>
    </sensor>
  </gazebo>
  <sensor name="r_lower_leg_mtb_acc_11b10" type="accelerometer">
    <parent link="r_lower_leg"/>
    <origin rpy="-1.30899714732 4.4408920985e-16 1.57079632679" xyz="-0.0325465 -0.043468 0.0278945"/>
  </sensor>
  <gazebo reference="r_lower_leg">
    <sensor name="r_lower_leg_mtb_acc_11b11" type="imu">
      <always_on>1</always_on>
      <update_rate>100</update_rate>
      <pose>0.0519165 -0.092958 0.0164801 1.30899714594 -0.000112159802878 1.57082638021</pose>
      <plugin name="iCub_yarp_gazebo_plugin_ACC" filename="libgazebo_yarp_inertialmtb.so"/>
    </sensor>
  </gazebo>
  <sensor name="r_lower_leg_mtb_acc_11b11" type="accelerometer">
    <parent link="r_lower_leg"/>
    <origin rpy="1.30899714594 -0.000112159802878 1.57082638021" xyz="0.0519165 -0.092958 0.0164801"/>
  </sensor>
  <gazebo reference="r_foot">
    <sensor name="r_foot_mtb_acc_11b12" type="imu">
      <always_on>1</always_on>
      <update_rate>100</update_rate>
      <pose>0.1034744 -0.000807 -0.001215 2.22044604925e-16 2.22044604925e-16 -1.57079632679</pose>
      <plugin name="iCub_yarp_gazebo_plugin_ACC" filename="libgazebo_yarp_inertialmtb.so"/>
    </sensor>
  </gazebo>
  <sensor name="r_foot_mtb_acc_11b12" type="accelerometer">
    <parent link="r_foot"/>
    <origin rpy="2.22044604925e-16 2.22044604925e-16 -1.57079632679" xyz="0.1034744 -0.000807 -0.001215"/>
  </sensor>
  <gazebo reference="r_foot">
    <sensor name="r_foot_mtb_acc_11b13" type="imu">
      <always_on>1</always_on>
      <update_rate>100</update_rate>
      <pose>0.0784744 -0.0118072 -0.001215 2.22044604925e-16 2.22044604925e-16 -1.57079632679</pose>
      <plugin name="iCub_yarp_gazebo_plugin_ACC" filename="libgazebo_yarp_inertialmtb.so"/>
    </sensor>
  </gazebo>
  <sensor name="r_foot_mtb_acc_11b13" type="accelerometer">
    <parent link="r_foot"/>
    <origin rpy="2.22044604925e-16 2.22044604925e-16 -1.57079632679" xyz="0.0784744 -0.0118072 -0.001215"/>
  </sensor>
  <gazebo reference="l_upper_leg">
    <sensor name="l_upper_leg_ems_acc_eb6" type="imu">
      <always_on>1</always_on>
      <update_rate>100</update_rate>
      <pose>-0.0404072 -0.083207 -0.0125771 1.57079632679 -0.0 -1.57079632679</pose>
      <plugin name="iCub_yarp_gazebo_plugin_ACC" filename="libgazebo_yarp_inertialmtb.so"/>
    </sensor>
  </gazebo>
  <sensor name="l_upper_leg_ems_acc_eb6" type="accelerometer">
    <parent link="l_upper_leg"/>
    <origin rpy="1.57079632679 -0.0 -1.57079632679" xyz="-0.0404072 -0.083207 -0.0125771"/>
  </sensor>
  <gazebo reference="l_upper_leg">
    <sensor name="l_upper_leg_ems_acc_eb10" type="imu">
      <always_on>1</always_on>
      <update_rate>100</update_rate>
      <pose>0.040407 -0.040027 -0.0125751 1.57079632679 -0.0 1.57079632679</pose>
      <plugin name="iCub_yarp_gazebo_plugin_ACC" filename="libgazebo_yarp_inertialmtb.so"/>
    </sensor>
  </gazebo>
  <sensor name="l_upper_leg_ems_acc_eb10" type="accelerometer">
    <parent link="l_upper_leg"/>
    <origin rpy="1.57079632679 -0.0 1.57079632679" xyz="0.040407 -0.040027 -0.0125751"/>
  </sensor>
  <gazebo reference="l_upper_leg">
    <sensor name="l_upper_leg_ems_gyro_eb6" type="imu">
      <always_on>1</always_on>
      <update_rate>100</update_rate>
      <pose>-0.0404072 -0.087779 -0.013081 1.57079632679 -0.0 -1.57079632679</pose>
    </sensor>
  </gazebo>
  <sensor name="l_upper_leg_ems_gyro_eb6" type="gyroscope">
    <parent link="l_upper_leg"/>
    <origin rpy="1.57079632679 -0.0 -1.57079632679" xyz="-0.0404072 -0.087779 -0.013081"/>
  </sensor>
  <gazebo reference="l_upper_leg">
    <sensor name="l_upper_leg_ems_gyro_eb10" type="imu">
      <always_on>1</always_on>
      <update_rate>100</update_rate>
      <pose>0.040407 -0.035455 -0.013079 1.57079632679 -0.0 1.57079632679</pose>
    </sensor>
  </gazebo>
  <sensor name="l_upper_leg_ems_gyro_eb10" type="gyroscope">
    <parent link="l_upper_leg"/>
    <origin rpy="1.57079632679 -0.0 1.57079632679" xyz="0.040407 -0.035455 -0.013079"/>
  </sensor>
  <gazebo reference="l_upper_leg">
    <sensor name="l_upper_leg_mtb_acc_10b1" type="imu">
      <always_on>1</always_on>
      <update_rate>100</update_rate>
      <pose>0.031565 0.049332 0.04200163 0.837758036961 -8.62912829653e-05 1.57087402394</pose>
      <plugin name="iCub_yarp_gazebo_plugin_ACC" filename="libgazebo_yarp_inertialmtb.so"/>
    </sensor>
  </gazebo>
  <sensor name="l_upper_leg_mtb_acc_10b1" type="accelerometer">
    <parent link="l_upper_leg"/>
    <origin rpy="0.837758036961 -8.62912829653e-05 1.57087402394" xyz="0.031565 0.049332 0.04200163"/>
  </sensor>
  <gazebo reference="l_upper_leg">
    <sensor name="l_upper_leg_mtb_acc_10b2" type="imu">
      <always_on>1</always_on>
      <update_rate>100</update_rate>
      <pose>0.0083839 0.039452 0.05335544 0.261799318135 -3.00531353284e-05 1.57090848663</pose>
      <plugin name="iCub_yarp_gazebo_plugin_ACC" filename="libgazebo_yarp_inertialmtb.so"/>
    </sensor>
  </gazebo>
  <sensor name="l_upper_leg_mtb_acc_10b2" type="accelerometer">
    <parent link="l_upper_leg"/>
    <origin rpy="0.261799318135 -3.00531353284e-05 1.57090848663" xyz="0.0083839 0.039452 0.05335544"/>
  </sensor>
  <gazebo reference="l_upper_leg">
    <sensor name="l_upper_leg_mtb_acc_10b3" type="imu">
      <always_on>1</always_on>
      <update_rate>100</update_rate>
      <pose>0.0150706 0.004382 0.053785 0.0 -0.0 1.57079632679</pose>
      <plugin name="iCub_yarp_gazebo_plugin_ACC" filename="libgazebo_yarp_inertialmtb.so"/>
    </sensor>
  </gazebo>
  <sensor name="l_upper_leg_mtb_acc_10b3" type="accelerometer">
    <parent link="l_upper_leg"/>
    <origin rpy="0.0 -0.0 1.57079632679" xyz="0.0150706 0.004382 0.053785"/>
  </sensor>
  <gazebo reference="l_upper_leg">
    <sensor name="l_upper_leg_mtb_acc_10b4" type="imu">
      <always_on>1</always_on>
      <update_rate>100</update_rate>
      <pose>-0.0144294 0.004382 0.053785 0.0 -0.0 1.57079632679</pose>
      <plugin name="iCub_yarp_gazebo_plugin_ACC" filename="libgazebo_yarp_inertialmtb.so"/>
    </sensor>
  </gazebo>
  <sensor name="l_upper_leg_mtb_acc_10b4" type="accelerometer">
    <parent link="l_upper_leg"/>
    <origin rpy="0.0 -0.0 1.57079632679" xyz="-0.0144294 0.004382 0.053785"/>
  </sensor>
  <gazebo reference="l_upper_leg">
    <sensor name="l_upper_leg_mtb_acc_10b5" type="imu">
      <always_on>1</always_on>
      <update_rate>100</update_rate>
      <pose>-0.0414999 -0.004658 0.03412949 -1.18682376254 -0.0 1.57079632679</pose>
      <plugin name="iCub_yarp_gazebo_plugin_ACC" filename="libgazebo_yarp_inertialmtb.so"/>
    </sensor>
  </gazebo>
  <sensor name="l_upper_leg_mtb_acc_10b5" type="accelerometer">
    <parent link="l_upper_leg"/>
    <origin rpy="-1.18682376254 -0.0 1.57079632679" xyz="-0.0414999 -0.004658 0.03412949"/>
  </sensor>
  <gazebo reference="l_upper_leg">
    <sensor name="l_upper_leg_mtb_acc_10b6" type="imu">
      <always_on>1</always_on>
      <update_rate>100</update_rate>
      <pose>0.0178086 -0.026212 -0.043785 3.14159265359 0.0 -1.57091243005</pose>
      <plugin name="iCub_yarp_gazebo_plugin_ACC" filename="libgazebo_yarp_inertialmtb.so"/>
    </sensor>
  </gazebo>
  <sensor name="l_upper_leg_mtb_acc_10b6" type="accelerometer">
    <parent link="l_upper_leg"/>
    <origin rpy="3.14159265359 0.0 -1.57091243005" xyz="0.0178086 -0.026212 -0.043785"/>
  </sensor>
  <gazebo reference="l_upper_leg">
    <sensor name="l_upper_leg_mtb_acc_10b7" type="imu">
      <always_on>1</always_on>
      <update_rate>100</update_rate>
      <pose>-0.0141918 -0.026211 -0.043785 3.14159265359 0.0 -1.5709453147</pose>
      <plugin name="iCub_yarp_gazebo_plugin_ACC" filename="libgazebo_yarp_inertialmtb.so"/>
    </sensor>
  </gazebo>
  <sensor name="l_upper_leg_mtb_acc_10b7" type="accelerometer">
    <parent link="l_upper_leg"/>
    <origin rpy="3.14159265359 0.0 -1.5709453147" xyz="-0.0141918 -0.026211 -0.043785"/>
  </sensor>
  <gazebo reference="l_lower_leg">
    <sensor name="l_lower_leg_ems_acc_eb7" type="imu">
      <always_on>1</always_on>
      <update_rate>100</update_rate>
      <pose>0.0249001 -0.092765 0.04351373 -4.26442049238e-17 -0.218166543341 1.57079632679</pose>
      <plugin name="iCub_yarp_gazebo_plugin_ACC" filename="libgazebo_yarp_inertialmtb.so"/>
    </sensor>
  </gazebo>
  <sensor name="l_lower_leg_ems_acc_eb7" type="accelerometer">
    <parent link="l_lower_leg"/>
    <origin rpy="-4.26442049238e-17 -0.218166543341 1.57079632679" xyz="0.0249001 -0.092765 0.04351373"/>
  </sensor>
  <gazebo reference="l_lower_leg">
    <sensor name="l_lower_leg_ems_gyro_eb7" type="imu">
      <always_on>1</always_on>
      <update_rate>100</update_rate>
      <pose>0.025404 -0.088301 0.044503292 -4.26442049238e-17 -0.218166543341 1.57079632679</pose>
    </sensor>
  </gazebo>
  <sensor name="l_lower_leg_ems_gyro_eb7" type="gyroscope">
    <parent link="l_lower_leg"/>
    <origin rpy="-4.26442049238e-17 -0.218166543341 1.57079632679" xyz="0.025404 -0.088301 0.044503292"/>
  </sensor>
  <gazebo reference="l_lower_leg">
    <sensor name="l_lower_leg_mtb_acc_10b8" type="imu">
      <always_on>1</always_on>
      <update_rate>100</update_rate>
      <pose>0.0307696 -0.004318 0.05313347 0.24434616607 -0.0 1.57079632679</pose>
      <plugin name="iCub_yarp_gazebo_plugin_ACC" filename="libgazebo_yarp_inertialmtb.so"/>
    </sensor>
  </gazebo>
  <sensor name="l_lower_leg_mtb_acc_10b8" type="accelerometer">
    <parent link="l_lower_leg"/>
    <origin rpy="0.24434616607 -0.0 1.57079632679" xyz="0.0307696 -0.004318 0.05313347"/>
  </sensor>
  <gazebo reference="l_lower_leg">
    <sensor name="l_lower_leg_mtb_acc_10b9" type="imu">
      <always_on>1</always_on>
      <update_rate>100</update_rate>
      <pose>-0.0002136 -0.004318 0.0544518 -0.349065638045 3.97141037841e-05 1.57090544048</pose>
      <plugin name="iCub_yarp_gazebo_plugin_ACC" filename="libgazebo_yarp_inertialmtb.so"/>
    </sensor>
  </gazebo>
  <sensor name="l_lower_leg_mtb_acc_10b9" type="accelerometer">
    <parent link="l_lower_leg"/>
    <origin rpy="-0.349065638045 3.97141037841e-05 1.57090544048" xyz="-0.0002136 -0.004318 0.0544518"/>
  </sensor>
  <gazebo reference="l_lower_leg">
    <sensor name="l_lower_leg_mtb_acc_10b10" type="imu">
      <always_on>1</always_on>
      <update_rate>100</update_rate>
      <pose>0.0563295 -0.043468 0.0259151 1.30899714594 -0.000112159802878 1.57082638021</pose>
      <plugin name="iCub_yarp_gazebo_plugin_ACC" filename="libgazebo_yarp_inertialmtb.so"/>
    </sensor>
  </gazebo>
  <sensor name="l_lower_leg_mtb_acc_10b10" type="accelerometer">
    <parent link="l_lower_leg"/>
    <origin rpy="1.30899714594 -0.000112159802878 1.57082638021" xyz="0.0563295 -0.043468 0.0259151"/>
  </sensor>
  <gazebo reference="l_lower_leg">
    <sensor name="l_lower_leg_mtb_acc_10b11" type="imu">
      <always_on>1</always_on>
      <update_rate>100</update_rate>
      <pose>-0.0281332 -0.092958 0.0184593 -1.3089971472 -2.54317885712e-05 1.57078951235</pose>
      <plugin name="iCub_yarp_gazebo_plugin_ACC" filename="libgazebo_yarp_inertialmtb.so"/>
    </sensor>
  </gazebo>
  <sensor name="l_lower_leg_mtb_acc_10b11" type="accelerometer">
    <parent link="l_lower_leg"/>
    <origin rpy="-1.3089971472 -2.54317885712e-05 1.57078951235" xyz="-0.0281332 -0.092958 0.0184593"/>
  </sensor>
  <gazebo reference="l_foot">
    <sensor name="l_foot_mtb_acc_10b12" type="imu">
      <always_on>1</always_on>
      <update_rate>100</update_rate>
      <pose>0.1055224 0.0008072 -0.001215 0.0 -0.0 1.57079632679</pose>
      <plugin name="iCub_yarp_gazebo_plugin_ACC" filename="libgazebo_yarp_inertialmtb.so"/>
    </sensor>
  </gazebo>
  <sensor name="l_foot_mtb_acc_10b12" type="accelerometer">
    <parent link="l_foot"/>
    <origin rpy="0.0 -0.0 1.57079632679" xyz="0.1055224 0.0008072 -0.001215"/>
  </sensor>
  <gazebo reference="l_foot">
    <sensor name="l_foot_mtb_acc_10b13" type="imu">
      <always_on>1</always_on>
      <update_rate>100</update_rate>
      <pose>0.0805224 0.0118072 -0.001215 0.0 -0.0 1.57079632679</pose>
      <plugin name="iCub_yarp_gazebo_plugin_ACC" filename="libgazebo_yarp_inertialmtb.so"/>
    </sensor>
  </gazebo>
  <sensor name="l_foot_mtb_acc_10b13" type="accelerometer">
    <parent link="l_foot"/>
    <origin rpy="0.0 -0.0 1.57079632679" xyz="0.0805224 0.0118072 -0.001215"/>
  </sensor>
  <gazebo reference="r_arm_ft_sensor">
  <disableFixedJointLumping>true</disableFixedJointLumping>
</gazebo>
  <gazebo reference="r_arm_ft_sensor">
  <disableFixedJointLumping>true</disableFixedJointLumping>
</gazebo>
  <gazebo reference="l_arm_ft_sensor">
  <disableFixedJointLumping>true</disableFixedJointLumping>
</gazebo>
  <gazebo reference="r_leg_ft_sensor">
  <disableFixedJointLumping>true</disableFixedJointLumping>
</gazebo>
  <gazebo reference="l_leg_ft_sensor">
  <disableFixedJointLumping>true</disableFixedJointLumping>
</gazebo>
  <gazebo reference="r_foot_ft_sensor">
  <disableFixedJointLumping>true</disableFixedJointLumping>
</gazebo>
  <gazebo reference="l_foot_ft_sensor">
  <disableFixedJointLumping>true</disableFixedJointLumping>
</gazebo>
<gazebo>
<plugin name="iCub_yarp_gazebo_plugin_ACCpart" filename="libgazebo_yarp_inertialmtbPart.so">
  <yarpConfigurationFile>model://icub/conf/MTB/gazebo_icub_left_leg_mtb.ini</yarpConfigurationFile>
</plugin>
<plugin name="iCub_yarp_gazebo_plugin_ACCpart" filename="libgazebo_yarp_inertialmtbPart.so">
  <yarpConfigurationFile>model://icub/conf/MTB/gazebo_icub_right_leg_mtb.ini</yarpConfigurationFile>
</plugin>
<plugin name="controlboard_torso" filename="libgazebo_yarp_controlboard.so">
    <yarpConfigurationFile>model://icub/conf/gazebo_icub_torso.ini</yarpConfigurationFile>
</plugin>
<plugin name="controlboard_head" filename="libgazebo_yarp_controlboard.so">
    <yarpConfigurationFile>model://icub/conf/gazebo_icub_head_without_eyes.ini</yarpConfigurationFile>
</plugin>
<plugin name="controlboard_left_arm" filename="libgazebo_yarp_controlboard.so">
    <yarpConfigurationFile>model://icub/conf/gazebo_icub_left_arm_no_hand_for_no_hand_model.ini</yarpConfigurationFile>
    <initialConfiguration>-0.52 0.52 0 0.785 0 0 0.698</initialConfiguration>
</plugin>
<plugin name="controlboard_right_arm" filename="libgazebo_yarp_controlboard.so">
    <yarpConfigurationFile>model://icub/conf/gazebo_icub_right_arm_no_hand_for_no_hand_model.ini</yarpConfigurationFile>
    <initialConfiguration>-0.52 0.52 0 0.785 0 0 0.698</initialConfiguration>
</plugin>
<plugin name="controlboard_right_leg" filename="libgazebo_yarp_controlboard.so">
    <yarpConfigurationFile>model://icub/conf/gazebo_icub_right_leg.ini</yarpConfigurationFile>
</plugin>
<plugin name="controlboard_left_leg" filename="libgazebo_yarp_controlboard.so">
    <yarpConfigurationFile>model://icub/conf/gazebo_icub_left_leg.ini</yarpConfigurationFile>
</plugin>
<plugin name="apply_external_wrench" filename="libgazebo_yarp_externalwrench.so">
     <robotNamefromConfigFile>model://icub/conf/gazebo_icub_robotname.ini</robotNamefromConfigFile>
</plugin>
</gazebo>
</robot>
