<sdf version='1.4'>
  <model name='iCub'>
    <link name='root_link'>
      <pose>0 0 0 0 -0 0</pose>
      <inertial>
        <pose>0 0 0 0 -0 0</pose>
        <mass>1.2</mass>
        <inertia>
          <ixx>0.01</ixx>
          <ixy>0</ixy>
          <ixz>0</ixz>
          <iyy>0.01</iyy>
          <iyz>0</iyz>
          <izz>0.01</izz>
        </inertia>
      </inertial>
      <collision name='root_link_collision'>
        <pose>0 0 0 0 -0 0</pose>
        <geometry>
          <mesh>
            <scale>1 1 1</scale>
            <uri>model://icub/meshes/collision/icub_simple_collision_root_link.dae</uri>
          </mesh>
        </geometry>
      </collision>
      <visual name='root_link_visual'>
        <pose>0 0 0 0 -0 0</pose>
        <geometry>
          <mesh>
            <scale>1 1 1</scale>
            <uri>model://icub/meshes/visual/icub_root_link.dae</uri>
          </mesh>
        </geometry>
      </visual>
      <velocity_decay>
        <linear>0</linear>
        <angular>0</angular>
      </velocity_decay>
    </link>
    <link name='l_hip_1'>
      <pose>0 -0.0681 -0.1199 2.65359e-06 1.57079 3.14159</pose>
      <inertial>
        <pose>0 -0.0782 0 0 -0 0</pose>
        <mass>0.754</mass>
        <inertia>
          <ixx>0.01</ixx>
          <ixy>2.059e-06</ixy>
          <ixz>1.451e-06</ixz>
          <iyy>0.01</iyy>
          <iyz>1.545e-06</iyz>
          <izz>0.01</izz>
        </inertia>
      </inertial>
      <collision name='l_hip_1_collision'>
        <pose>0 0 0 -0.945183 1.57079 -2.51598</pose>
        <geometry>
          <mesh>
            <scale>1 1 1</scale>
            <uri>model://icub/meshes/collision/icub_simple_collision_l_hip_1.dae</uri>
          </mesh>
        </geometry>
      </collision>
      <visual name='l_hip_1_visual'>
        <pose>0 0 0 -0.945183 1.57079 -2.51598</pose>
        <geometry>
          <mesh>
            <scale>1 1 1</scale>
            <uri>model://icub/meshes/visual/icub_l_hip_1.dae</uri>
          </mesh>
        </geometry>
      </visual>
      <velocity_decay>
        <linear>0</linear>
        <angular>0</angular>
      </velocity_decay>
    </link>
    <joint name='l_hip_pitch' type='revolute'>
      <child>l_hip_1</child>
      <parent>root_link</parent>
      <axis>
        <xyz>5.30718e-06 1 -1.67887e-11</xyz>
        <limit>
          <lower>-0.5235987756</lower>
          <upper>1.5707963268</upper>
          <effort>84</effort>
          <velocity>100</velocity>
        </limit>
        <dynamics>
		<damping>0.48</damping>
	</dynamics>
      </axis>
    </joint>
    <link name='l_hip_2'>
      <pose>0 -0.0681 -0.1199 3.14159 -1.26536e-05 3.14159</pose>
      <inertial>
        <pose>0 0 0.03045 0 -0 0</pose>
        <mass>0.526</mass>
        <inertia>
          <ixx>0.01</ixx>
          <ixy>-7.4e-08</ixy>
          <ixz>1.0835e-05</ixz>
          <iyy>0.01</iyy>
          <iyz>-6.2e-08</iyz>
          <izz>0.01</izz>
        </inertia>
      </inertial>
      <collision name='l_hip_2_collision'>
        <pose>0 0 0 -0.346628 -1.57079 -2.79497</pose>
        <geometry>
          <mesh>
            <scale>1 1 1</scale>
            <uri>model://icub/meshes/collision/icub_simple_collision_l_hip_2.dae</uri>
          </mesh>
        </geometry>
      </collision>
      <visual name='l_hip_2_visual'>
        <pose>0 0 0 -0.346628 -1.57079 -2.79497</pose>
        <geometry>
          <mesh>
            <scale>1 1 1</scale>
            <uri>model://icub/meshes/visual/icub_l_hip_2.dae</uri>
          </mesh>
        </geometry>
      </visual>
      <velocity_decay>
        <linear>0</linear>
        <angular>0</angular>
      </velocity_decay>
    </link>
    <joint name='l_hip_roll' type='revolute'>
      <child>l_hip_2</child>
      <parent>l_hip_1</parent>
      <axis>
        <xyz>-1 5.30716e-06 1.26536e-05</xyz>
        <limit>
            <lower>0</lower>
            <upper>1.5707963268</upper>
          <effort>84</effort>
          <velocity>100</velocity>
        </limit>
        <dynamics/>
      </axis>
    </joint>
    <link name='l_hip_3'>
      <pose>0 -0.0681 -0.1199 -1.53072e-05 5.30721e-06 -1.5708</pose>
      <inertial>
        <pose>0 0 0 0 -0 0</pose>
        <mass>0.1</mass>
        <inertia>
          <ixx>0.01</ixx>
          <ixy>0</ixy>
          <ixz>0</ixz>
          <iyy>0.01</iyy>
          <iyz>0</iyz>
          <izz>0.01</izz>
        </inertia>
      </inertial>
      <velocity_decay>
        <linear>0</linear>
        <angular>0</angular>
      </velocity_decay>
    </link>
    <joint name='l_leg_ft_sensor' type='revolute'>
      <child>l_hip_3</child>
      <parent>l_hip_2</parent>
      <axis>
        <xyz>0 0 0</xyz>
        <limit>
          <lower>0</lower>
          <upper>0</upper>
          <effort>0</effort>
          <velocity>0</velocity>
        </limit>
        <dynamics/>
      </axis>
      <!-- check pose of the wrench returned by the simulated sensor -->
      <sensor name="left_leg_ft" type="force_torque">
        <always_on>true</always_on>
        <visualize>true</visualize>
        <update_rate>100</update_rate>
        <pose>0 0 0 0 0 0</pose>
        <plugin filename="libgazebo_yarp_forcetorque.so" name="left_leg_ft_plugin">
          <yarpConfigurationFile>model://icub/conf/FT/gazebo_icub_left_leg_ft.ini</yarpConfigurationFile>
        </plugin>
      </sensor>
    </joint>
    <link name='l_thigh'>
      <pose>0 -0.0681 -0.1199 1.57079 -1.53072e-05 3.14159</pose>
      <inertial>
        <pose>0.00144 -0.15943 -0.00039 0 -0 0</pose>
        <mass>2.175</mass>
        <inertia>
          <ixx>0.01</ixx>
          <ixy>-6.726e-05</ixy>
          <ixz>2.267e-06</ixz>
          <iyy>0.01</iyy>
          <iyz>3.63726e-05</iyz>
          <izz>0.01</izz>
        </inertia>
      </inertial>
      <collision name='l_thigh_collision'>
        <pose>0 0 0 1.93765 1.57079 -2.77475</pose>
        <geometry>
          <mesh>
            <scale>1 1 1</scale>
            <uri>model://icub/meshes/collision/icub_simple_collision_l_thigh.dae</uri>
          </mesh>
        </geometry>
      </collision>
      <visual name='l_thigh_visual'>
        <pose>0 0 0 1.93765 1.57079 -2.77475</pose>
        <geometry>
          <mesh>
            <scale>1 1 1</scale>
            <uri>model://icub/meshes/visual/icub_l_thigh.dae</uri>
          </mesh>
        </geometry>
      </visual>
      <velocity_decay>
        <linear>0</linear>
        <angular>0</angular>
      </velocity_decay>
    </link>
    <joint name='l_hip_yaw' type='revolute'>
      <child>l_thigh</child>
      <parent>l_hip_3</parent>
      <axis>
        <xyz>1.53072e-05 -1.63403e-06 1</xyz>
        <limit>
          <lower>-1.3962634016</lower>
          <upper>1.3613568166</upper>
          <effort>40</effort>
          <velocity>100</velocity>
        </limit>
        <dynamics/>
      </axis>
    </joint>
    <link name='l_shank'>
      <pose>-3.42268e-06 -0.0680996 -0.3435 1.65667 -1.57078 -0.0858797</pose>
      <inertial>
        <pose>-0.1071 0.00182 0.00211 0 -0 0</pose>
        <mass>1.264</mass>
        <inertia>
          <ixx>0.01</ixx>
          <ixy>-0.000185699</ixy>
          <ixz>-6.3147e-05</ixz>
          <iyy>0.01</iyy>
          <iyz>7.86e-07</iyz>
          <izz>0.01</izz>
        </inertia>
      </inertial>
      <collision name='l_shank_collision'>
        <pose>1.95097e-11 -2.236e-06 -2.27994e-07 3.14159 -5.30752e-06 1.57081</pose>
        <geometry>
          <mesh>
            <scale>1 1 1</scale>
            <uri>model://icub/meshes/collision/icub_simple_collision_l_shank.dae</uri>
          </mesh>
        </geometry>
      </collision>
      <visual name='l_shank_visual'>
        <pose>1.95097e-11 -2.236e-06 -2.27994e-07 3.14159 -5.30752e-06 1.57081</pose>
        <geometry>
          <mesh>
            <scale>1 1 1</scale>
            <uri>model://icub/meshes/visual/icub_l_shank.dae</uri>
          </mesh>
        </geometry>
      </visual>
      <velocity_decay>
        <linear>0</linear>
        <angular>0</angular>
      </velocity_decay>
    </link>
    <joint name='l_knee' type='revolute'>
      <child>l_shank</child>
      <parent>l_thigh</parent>
      <axis>
        <xyz>7.96076e-06 1 1.6339e-06</xyz>
        <limit>
            <lower>-2.181661565</lower>
            <upper>0.2617993878</upper>
          <effort>30</effort>
          <velocity>100</velocity>
        </limit>
        <dynamics>
		<damping>0.29</damping>
	</dynamics>
      </axis>
    </joint>
    <link name='l_ankle_1'>
      <pose>-7.4655e-06 -0.0680993 -0.5565 0.0858681 -1.57078 -0.0858797</pose>
      <inertial>
        <pose>-0.0054 0.00163 0.0172 0 -0 0</pose>
        <mass>0.746</mass>
        <inertia>
          <ixx>0.01</ixx>
          <ixy>-7.081e-06</ixy>
          <ixz>4.1421e-05</ixz>
          <iyy>0.01</iyy>
          <iyz>2.0817e-05</iyz>
          <izz>0.01</izz>
        </inertia>
      </inertial>
      <collision name='l_ankle_1_collision'>
        <pose>3.95315e-11 4.452e-07 -5.14839e-06 1.57081 -1.36732e-05 -1.01971e-06</pose>
        <geometry>
          <mesh>
            <scale>1 1 1</scale>
            <uri>model://icub/meshes/collision/icub_simple_collision_l_ankle_1.dae</uri>
          </mesh>
        </geometry>
      </collision>
      <visual name='l_ankle_1_visual'>
        <pose>3.95315e-11 4.452e-07 -5.14839e-06 1.57081 -1.36732e-05 -1.01971e-06</pose>
        <geometry>
          <mesh>
            <scale>1 1 1</scale>
            <uri>model://icub/meshes/visual/icub_l_ankle_1.dae</uri>
          </mesh>
        </geometry>
      </visual>
      <velocity_decay>
        <linear>0</linear>
        <angular>0</angular>
      </velocity_decay>
    </link>
    <joint name='l_ankle_pitch' type='revolute'>
      <child>l_ankle_1</child>
      <parent>l_shank</parent>
      <axis>
        <xyz>-1.1634e-05 -1 -1.63383e-06</xyz>
        <limit>
          <lower>-0.3490658504</lower>
          <upper>0.7679448709</upper>
          <effort>24</effort>
          <velocity>100</velocity>
        </limit>
        <dynamics/>
      </axis>
    </joint>
    <link name='l_foot'>
      <pose>-7.4655e-06 -0.0680993 -0.5565 0.0858681 -1.57078 -0.0858797</pose>
      <inertial>
        <pose>-0.041 0 0 0 -0 0</pose>
        <mass>0.1</mass>
        <inertia>
          <ixx>0.01</ixx>
          <ixy>0</ixy>
          <ixz>0</ixz>
          <iyy>0.01</iyy>
          <iyz>0</iyz>
          <izz>0.01</izz>
        </inertia>
      </inertial>
      <collision name='l_foot_collision'>
        <pose>3.95315e-11 4.452e-07 -5.14839e-06 8.98039e-06 -1.36732e-05 -1.01971e-06</pose>
        <geometry>
          <mesh>
            <scale>1 1 1</scale>
            <uri>model://icub/meshes/collision/icub_simple_collision_l_foot.dae</uri>
          </mesh>
        </geometry>
    	<surface>
     	<contact>
      	<ode>
	<soft_erp>
		0.5
	</soft_erp>
       <kp>
        1e+05
       </kp>
       <kd>
        10000
       </kd>
       <max_vel>
        1
       </max_vel>
       <min_depth>
        0
       </min_depth>
      </ode>
     </contact>
     <friction>
      <ode>
       <mu>
        1
       </mu>
       <mu2>
        1
       </mu2>
       <fdir1>
        1 0 0
       </fdir1>
      </ode>
     </friction>
    </surface>
      </collision>
      <visual name='l_foot_visual'>
        <pose>3.95315e-11 4.452e-07 -5.14839e-06 8.98039e-06 -1.36732e-05 -1.01971e-06</pose>
        <geometry>
          <mesh>
            <scale>1 1 1</scale>
            <uri>model://icub/meshes/visual/icub_l_foot.dae</uri>
          </mesh>
        </geometry>
      </visual>
      <velocity_decay>
        <linear>0</linear>
        <angular>0</angular>
      </velocity_decay>
    </link>
    <joint name='l_ankle_roll' type='revolute'>
      <child>l_foot</child>
      <parent>l_ankle_1</parent>
      <axis>
        <xyz>-1 1.16339e-05 1.89804e-05</xyz>
        <limit>
          <lower>-0.418879</lower>
          <upper>0.418879</upper>
          <effort>11</effort>
          <velocity>100</velocity>
        </limit>
        <dynamics/>
      </axis>
    </joint>
    <link name='r_hip_1'>
      <pose>0 0.0681 -0.1199 3.14159 1.57079 -3.14159</pose>
      <inertial>
        <pose>0 -0.0782 0 0 -0 0</pose>
        <mass>0.754</mass>
        <inertia>
          <ixx>0.01</ixx>
          <ixy>0</ixy>
          <ixz>0</ixz>
          <iyy>0.01</iyy>
          <iyz>0</iyz>
          <izz>0.01</izz>
        </inertia>
      </inertial>
      <collision name='r_hip_1_collision'>
        <pose>0 0 0 1.5708 -1.57079 3.14159</pose>
        <geometry>
          <mesh>
            <scale>1 1 1</scale>
            <uri>model://icub/meshes/collision/icub_simple_collision_r_hip_1.dae</uri>
          </mesh>
        </geometry>
      </collision>
      <visual name='r_hip_1_visual'>
        <pose>0 0 0 1.5708 -1.57079 3.14159</pose>
        <geometry>
          <mesh>
            <scale>1 1 1</scale>
            <uri>model://icub/meshes/visual/icub_r_hip_1.dae</uri>
          </mesh>
        </geometry>
      </visual>
      <velocity_decay>
        <linear>0</linear>
        <angular>0</angular>
      </velocity_decay>
    </link>
    <joint name='r_hip_pitch' type='revolute'>
      <child>r_hip_1</child>
      <parent>root_link</parent>
      <axis>
        <xyz>-5.30718e-06 1 1.67887e-11</xyz>
        <limit>
            <lower>-0.5235987756</lower>
            <upper>1.5707963268</upper>
          <effort>84</effort>
          <velocity>100</velocity>
        </limit>
        <dynamics>
		<damping>0.49</damping>
	</dynamics>
      </axis>
    </joint>
    <link name='r_hip_2'>
      <pose>0 0.0681 -0.1199 -3.14159 -1.26536e-05 -3.14159</pose>
      <inertial>
        <pose>0 0 0.03045 0 -0 0</pose>
        <mass>0.526</mass>
        <inertia>
          <ixx>0.01</ixx>
          <ixy>0</ixy>
          <ixz>0</ixz>
          <iyy>0.01</iyy>
          <iyz>0</iyz>
          <izz>0.01</izz>
        </inertia>
      </inertial>
      <collision name='r_hip_2_collision'>
        <pose>0 0 0 3.14159 -1.57079 -3.14159</pose>
        <geometry>
          <mesh>
            <scale>1 1 1</scale>
            <uri>model://icub/meshes/collision/icub_simple_collision_r_hip_2.dae</uri>
          </mesh>
        </geometry>
      </collision>
      <visual name='r_hip_2_visual'>
        <pose>0 0 0 3.14159 -1.57079 -3.14159</pose>
        <geometry>
          <mesh>
            <scale>1 1 1</scale>
            <uri>model://icub/meshes/visual/icub_r_hip_2.dae</uri>
          </mesh>
        </geometry>
      </visual>
      <velocity_decay>
        <linear>0</linear>
        <angular>0</angular>
      </velocity_decay>
    </link>
    <joint name='r_hip_roll' type='revolute'>
      <child>r_hip_2</child>
      <parent>r_hip_1</parent>
      <axis>
        <xyz>1 5.30716e-06 -1.26536e-05</xyz>
        <limit>
          <lower>0</lower>
          <upper>1.5707963268</upper>
          <effort>84</effort>
          <velocity>100</velocity>
        </limit>
        <dynamics/>
      </axis>
    </joint>
    <link name='r_hip_3'>
      <pose>0 0.0681 -0.1199 -3.14158 5.30721e-06 1.5708</pose>
      <inertial>
        <pose>0 0 0 0 -0 0</pose>
        <mass>0.1</mass>
        <inertia>
          <ixx>0.01</ixx>
          <ixy>0</ixy>
          <ixz>0</ixz>
          <iyy>0.01</iyy>
          <iyz>0</iyz>
          <izz>0.01</izz>
        </inertia>
      </inertial>
      <velocity_decay>
        <linear>0</linear>
        <angular>0</angular>
      </velocity_decay>
    </link>
    <joint name='r_leg_ft_sensor' type='revolute'>
      <child>r_hip_3</child>
      <parent>r_hip_2</parent>
      <axis>
        <xyz>0 0 -0</xyz>
        <limit>
          <lower>0</lower>
          <upper>0</upper>
          <effort>0</effort>
          <velocity>0</velocity>
        </limit>
        <dynamics/>
      </axis>
      <!-- check pose of the wrench returned by the simulated sensor -->
      <sensor name="right_leg_ft" type="force_torque">
        <always_on>true</always_on>
        <visualize>true</visualize>
        <update_rate>100</update_rate>
        <pose>0 0 0 0 0 0</pose>
        <plugin filename="libgazebo_yarp_forcetorque.so" name="right_leg_ft_plugin">
          <yarpConfigurationFile>model://icub/conf/FT/gazebo_icub_right_leg_ft.ini</yarpConfigurationFile>
        </plugin>
      </sensor>
    </joint>
    <link name='r_thigh'>
      <pose>0 0.0681 -0.1199 1.5708 -1.26536e-05 -3.14159</pose>
      <inertial>
        <pose>0.00144 -0.15943 0.00039 0 -0 0</pose>
        <mass>2.175</mass>
        <inertia>
          <ixx>0.01</ixx>
          <ixy>0</ixy>
          <ixz>0</ixz>
          <iyy>0.01</iyy>
          <iyz>-2.71051e-20</iyz>
          <izz>0.01</izz>
        </inertia>
      </inertial>
      <collision name='r_thigh_collision'>
        <pose>0 0 0 3.14159 -1.57079 -1.5708</pose>
        <geometry>
          <mesh>
            <scale>1 1 1</scale>
            <uri>model://icub/meshes/collision/icub_simple_collision_r_thigh.dae</uri>
          </mesh>
        </geometry>
      </collision>
      <visual name='r_thigh_visual'>
        <pose>0 0 0 3.14159 -1.57079 -1.5708</pose>
        <geometry>
          <mesh>
            <scale>1 1 1</scale>
            <uri>model://icub/meshes/visual/icub_r_thigh.dae</uri>
          </mesh>
        </geometry>
      </visual>
      <velocity_decay>
        <linear>0</linear>
        <angular>0</angular>
      </velocity_decay>
    </link>
    <joint name='r_hip_yaw' type='revolute'>
      <child>r_thigh</child>
      <parent>r_hip_3</parent>
      <axis>
        <xyz>-1.26536e-05 -1.63402e-06 -1</xyz>
        <limit>
            <lower>-1.3962634016</lower>
            <upper>1.3613568166</upper>
          <effort>40</effort>
          <velocity>100</velocity>
        </limit>
        <dynamics/>
      </axis>
    </joint>
    <link name='r_shank'>
      <pose>-2.82934e-06 0.0680996 -0.3435 1.47105 -1.57078 0.0997515</pose>
      <inertial>
        <pose>-0.1071 0.00182 -0.00211 0 -0 0</pose>
        <mass>1.264</mass>
        <inertia>
          <ixx>0.01</ixx>
          <ixy>5.42101e-20</ixy>
          <ixz>-5.42101e-20</ixz>
          <iyy>0.01</iyy>
          <iyz>8.47033e-22</iyz>
          <izz>0.01</izz>
        </inertia>
      </inertial>
      <collision name='r_shank_collision'>
        <pose>1.35762e-11 -1.64266e-06 8.21324e-07 -3.14159 -2.65363e-06 1.57081</pose>
        <geometry>
          <mesh>
            <scale>1 1 1</scale>
            <uri>model://icub/meshes/collision/icub_simple_collision_r_shank.dae</uri>
          </mesh>
        </geometry>
      </collision>
      <visual name='r_shank_visual'>
        <pose>1.35762e-11 -1.64266e-06 8.21324e-07 -3.14159 -2.65363e-06 1.57081</pose>
        <geometry>
          <mesh>
            <scale>1 1 1</scale>
            <uri>model://icub/meshes/visual/icub_r_shank.dae</uri>
          </mesh>
        </geometry>
      </visual>
      <velocity_decay>
        <linear>0</linear>
        <angular>0</angular>
      </velocity_decay>
    </link>
    <joint name='r_knee' type='revolute'>
      <child>r_shank</child>
      <parent>r_thigh</parent>
      <axis>
        <xyz>-2.65359e-06 1 -1.634e-06</xyz>
        <limit>
          <lower>-2.181661565</lower>
          <upper>0.2617993878</upper>
          <effort>30</effort>
          <velocity>100</velocity>
        </limit>
        <dynamics>
		<damping>0.31</damping>
	</dynamics>
      </axis>
    </joint>
    <link name='r_ankle_1'>
      <pose>-6.30695e-06 0.0680993 -0.5565 3.04185 -1.57078 0.0997515</pose>
      <inertial>
        <pose>-0.0054 0.00163 -0.0172 0 -0 0</pose>
        <mass>0.746</mass>
        <inertia>
          <ixx>0.01</ixx>
          <ixy>-1.69407e-21</ixy>
          <ixz>1.35525e-20</ixz>
          <iyy>0.01</iyy>
          <iyz>3.38813e-21</iyz>
          <izz>0.01</izz>
        </inertia>
      </inertial>
      <collision name='r_ankle_1_collision'>
        <pose>2.79458e-11 1.60372e-06 3.98983e-06 -1.5708 1.10196e-05 -3.67321e-06</pose>
        <geometry>
          <mesh>
            <scale>1 1 1</scale>
            <uri>model://icub/meshes/collision/icub_simple_collision_r_ankle_1.dae</uri>
          </mesh>
        </geometry>
      </collision>
      <visual name='r_ankle_1_visual'>
        <pose>2.79458e-11 1.60372e-06 3.98983e-06 -1.5708 1.10196e-05 -3.67321e-06</pose>
        <geometry>
          <mesh>
            <scale>1 1 1</scale>
            <uri>model://icub/meshes/visual/icub_r_ankle_1.dae</uri>
          </mesh>
        </geometry>
      </visual>
      <velocity_decay>
        <linear>0</linear>
        <angular>0</angular>
      </velocity_decay>
    </link>
    <joint name='r_ankle_pitch' type='revolute'>
      <child>r_ankle_1</child>
      <parent>r_shank</parent>
      <axis>
        <xyz>6.3268e-06 -1 1.63394e-06</xyz>
        <limit>
            <lower>-0.3490658504</lower>
            <upper>0.7679448709</upper>
          <effort>24</effort>
          <velocity>100</velocity>
        </limit>
        <dynamics/>
      </axis>
    </joint>
    <link name='r_foot'>
      <pose>-6.30695e-06 0.0680993 -0.5565 -0.0997478 -1.57078 0.0997515</pose>
      <inertial>
        <pose>-0.041 0 0 0 -0 0</pose>
        <mass>0.1</mass>
        <inertia>
          <ixx>0.01</ixx>
          <ixy>0</ixy>
          <ixz>0</ixz>
          <iyy>0.01</iyy>
          <iyz>0</iyz>
          <izz>0.01</izz>
        </inertia>
      </inertial>
      <collision name='r_foot_collision'>
        <pose>2.79458e-11 -1.60371e-06 -3.98983e-06 -3.14159 -1.10245e-05 3.67318e-06</pose>
        <geometry>
          <mesh>
            <scale>1 1 1</scale>
            <uri>model://icub/meshes/collision/icub_simple_collision_r_foot.dae</uri>
          </mesh>
        </geometry>
    <surface>
     <contact>
      <ode>
	<soft_erp>
		0.5
	</soft_erp>
       <kp>
        1e+05
       </kp>
       <kd>
        10000
       </kd>
       <max_vel>
        1
       </max_vel>
       <min_depth>
        0
       </min_depth>
      </ode>
     </contact>
     <friction>
      <ode>
       <mu>
        1
       </mu>
       <mu2>
        1
       </mu2>
       <fdir1>
        1 0 0
       </fdir1>
      </ode>
     </friction>
    </surface>
      </collision>
      <visual name='r_foot_visual'>
        <pose>2.79458e-11 -1.60371e-06 -3.98983e-06 -3.14159 -1.10245e-05 3.67318e-06</pose>
        <geometry>
          <mesh>
            <scale>1 1 1</scale>
            <uri>model://icub/meshes/visual/icub_r_foot.dae</uri>
          </mesh>
        </geometry>
      </visual>
      <velocity_decay>
        <linear>0</linear>
        <angular>0</angular>
      </velocity_decay>
    </link>
    <joint name='r_ankle_roll' type='revolute'>
      <child>r_foot</child>
      <parent>r_ankle_1</parent>
      <axis>
        <xyz>1 3.67318e-06 -1.63268e-05</xyz>
        <limit>
          <lower>-0.3839724354</lower>
          <upper>0.3839724354</upper>
          <effort>11</effort>
          <velocity>100</velocity>
        </limit>
        <dynamics/>
      </axis>
    </joint>
    <link name='lap_belt_1'>
      <pose>0 0 0 3.14159 -1.57079 -2.65359e-06</pose>
      <inertial>
        <pose>0 0 0 0 -0 0</pose>
        <mass>0.1</mass>
        <inertia>
          <ixx>0.01</ixx>
          <ixy>-4.263e-05</ixy>
          <ixz>-3.889e-08</ixz>
          <iyy>0.01</iyy>
          <iyz>0</iyz>
          <izz>0.01</izz>
        </inertia>
      </inertial>
      <collision name='lap_belt_1_collision'>
        <pose>0 0 0 -1.57079 3.67321e-06 1.31031e-16</pose>
        <geometry>
          <mesh>
            <scale>1 1 1</scale>
            <uri>model://icub/meshes/collision/icub_simple_collision_lap_belt_1.dae</uri>
          </mesh>
        </geometry>
      </collision>
      <visual name='lap_belt_1_visual'>
        <pose>0 0 0 -1.57079 3.67321e-06 1.31031e-16</pose>
        <geometry>
          <mesh>
            <scale>1 1 1</scale>
            <uri>model://icub/meshes/visual/icub_lap_belt_1.dae</uri>
          </mesh>
        </geometry>
      </visual>
      <velocity_decay>
        <linear>0</linear>
        <angular>0</angular>
      </velocity_decay>
    </link>
    <joint name='torso_pitch' type='revolute'>
      <child>lap_belt_1</child>
      <parent>root_link</parent>
      <axis>
        <xyz>-5.30718e-06 -1 1.67887e-11</xyz>
        <limit>
          <lower>-0.383972</lower>
          <upper>1.46608</upper>
          <effort>36</effort>
          <velocity>100</velocity>
        </limit>
        <dynamics/>
      </axis>
    </joint>
    <link name='lap_belt_2'>
      <pose>2.02457e-07 -5.37239e-13 0.032 -3.14158 3.67322e-06 1.57079</pose>
      <inertial>
        <pose>0 0 0 0 -0 0</pose>
        <mass>0.1</mass>
        <inertia>
          <ixx>0.01</ixx>
          <ixy>-1.923e-06</ixy>
          <ixz>5.095e-05</ixz>
          <iyy>0.01</iyy>
          <iyz>-3.849e-07</iyz>
          <izz>0.01</izz>
        </inertia>
      </inertial>
      <velocity_decay>
        <linear>0</linear>
        <angular>0</angular>
      </velocity_decay>
    </link>
    <joint name='torso_roll' type='revolute'>
      <child>lap_belt_2</child>
      <parent>lap_belt_1</parent>
      <axis>
        <xyz>1 -5.30719e-06 -1e-05</xyz>
        <limit>
          <lower>-0.680678</lower>
          <upper>0.680678</upper>
          <effort>80</effort>
          <velocity>100</velocity>
        </limit>
        <dynamics/>
      </axis>
    </joint>
    <link name='chest'>
      <pose>-0.0054998 2.9189e-08 0.0320001 1.5708 -1e-05 3.14159</pose>
      <inertial>
        <pose>0.00222898 0.075 -1.18362e-17 0 -0 0</pose>
        <mass>4.81</mass>
        <inertia>
          <ixx>0.07472</ixx>
          <ixy>-3.6e-06</ixy>
          <ixz>-4.705e-05</ixz>
          <iyy>0.08145</iyy>
          <iyz>0.004567</iyz>
          <izz>0.01306</izz>
        </inertia>
      </inertial>
      <collision name='chest_collision'>
        <pose>-0.00549988 -5.73437e-13 -2.02022e-08 1.57076 -1.57079 2.26536e-05</pose>
        <geometry>
          <mesh>
            <scale>1 1 1</scale>
            <uri>model://icub/meshes/collision/icub_simple_collision_chest.dae</uri>
          </mesh>
        </geometry>
      </collision>
      <visual name='chest_visual'>
        <pose>-0.00549988 -5.73437e-13 -2.02022e-08 1.57076 -1.57079 2.26536e-05</pose>
        <geometry>
          <mesh>
            <scale>1 1 1</scale>
            <uri>model://icub/meshes/visual/icub_chest.dae</uri>
          </mesh>
        </geometry>
      </visual>
      <velocity_decay>
        <linear>0</linear>
        <angular>0</angular>
      </velocity_decay>
    </link>
    <joint name='torso_yaw' type='revolute'>
      <child>chest</child>
      <parent>lap_belt_2</parent>
      <axis>
        <xyz>-1e-05 3.62833e-11 -1</xyz>
        <limit>
          <lower>-1.02974</lower>
          <upper>1.02974</upper>
          <effort>80</effort>
          <velocity>100</velocity>
        </limit>
        <dynamics/>
      </axis>
    </joint>
    <link name='l_shoulder_1'>
      <pose>-0.0107485 -0.11026 0.1753 -0.261795 -1.57078 -3.09255e-06</pose>
      <inertial>
        <pose>-5e-06 0.0187 -0.00119 0 -0 0</pose>
        <mass>0.189</mass>
        <inertia>
          <ixx>0.01</ixx>
          <ixy>9e-09</ixy>
          <ixz>0</ixz>
          <iyy>0.01</iyy>
          <iyz>-1.7e-08</iyz>
          <izz>0.01</izz>
        </inertia>
      </inertial>
      <collision name='l_shoulder_1_collision'>
        <pose>2.88176e-07 0.109285 -0.00521022 1.20471 1.57078 -0.366086</pose>
        <geometry>
          <mesh>
            <scale>1 1 1</scale>
            <uri>model://icub/meshes/collision/icub_simple_collision_l_shoulder_1.dae</uri>
          </mesh>
        </geometry>
      </collision>
      <visual name='l_shoulder_1_visual'>
        <pose>2.88176e-07 0.109285 -0.00521022 1.20471 1.57078 -0.366086</pose>
        <geometry>
          <mesh>
            <scale>1 1 1</scale>
            <uri>model://icub/meshes/visual/icub_l_shoulder_1.dae</uri>
          </mesh>
        </geometry>
      </visual>
      <velocity_decay>
        <linear>0</linear>
        <angular>0</angular>
      </velocity_decay>
    </link>
    <joint name='l_shoulder_pitch' type='revolute'>
      <child>l_shoulder_1</child>
      <parent>chest</parent>
      <axis>
        <xyz>-0.258818 -0.965926 3.53883e-06</xyz>
        <limit>
          <lower>-1.65806</lower>
          <upper>0.0872665</upper>
          <effort>84</effort>
          <velocity>100</velocity>
        </limit>
        <dynamics/>
      </axis>
    </joint>
    <link name='l_shoulder_2'>
      <pose>-0.0107485 -0.11026 0.1753 3.14158 1.34375e-07 -1.83259</pose>
      <inertial>
        <pose>9.4e-05 -0.00627 0.0166 0 -0 0</pose>
        <mass>0.179</mass>
        <inertia>
          <ixx>0.01</ixx>
          <ixy>4.66e-07</ixy>
          <ixz>3.65e-07</ixz>
          <iyy>0.01</iyy>
          <iyz>-2.0524e-05</iyz>
          <izz>0.01</izz>
        </inertia>
      </inertial>
      <collision name='l_shoulder_2_collision'>
        <pose>-0.00154492 -0.00520978 4.39173e-08 0.117256 1.57079 1.68806</pose>
        <geometry>
          <mesh>
            <scale>1 1 1</scale>
            <uri>model://icub/meshes/collision/icub_simple_collision_l_shoulder_2.dae</uri>
          </mesh>
        </geometry>
      </collision>
      <visual name='l_shoulder_2_visual'>
        <pose>-0.00154492 -0.00520978 4.39173e-08 0.117256 1.57079 1.68806</pose>
        <geometry>
          <mesh>
            <scale>1 1 1</scale>
            <uri>model://icub/meshes/visual/icub_l_shoulder_2.dae</uri>
          </mesh>
        </geometry>
      </visual>
      <velocity_decay>
        <linear>0</linear>
        <angular>0</angular>
      </velocity_decay>
    </link>
    <joint name='l_shoulder_roll' type='revolute'>
      <child>l_shoulder_2</child>
      <parent>l_shoulder_1</parent>
      <axis>
        <xyz>-0.965926 0.258818 9.53413e-06</xyz>
        <limit>
          <lower>0</lower>
          <upper>2.80649</upper>
          <effort>84</effort>
          <velocity>100</velocity>
        </limit>
        <dynamics/>
      </axis>
    </joint>
    <link name='l_upper_arm'>
      <pose>-0.0107485 -0.11026 0.1753 3.14159 -9.17449e-06 3.14159</pose>
      <inertial>
        <pose>0.00559398 9.77357e-05 0.0501346 0 -0 0</pose>
        <mass>0.156157</mass>
        <inertia>
          <ixx>0.01</ixx>
          <ixy>-5.662e-08</ixy>
          <ixz>-4.3618e-06</ixz>
          <iyy>0.01</iyy>
          <iyz>-7.42844e-07</iyz>
          <izz>0.01</izz>
        </inertia>
      </inertial>
      <velocity_decay>
        <linear>0</linear>
        <angular>0</angular>
      </velocity_decay>
    </link>
    <joint name='l_shoulder_yaw' type='revolute'>
      <child>l_upper_arm</child>
      <parent>l_shoulder_2</parent>
      <axis>
        <xyz>-9.17448e-06 2.5974e-06 -1</xyz>
        <limit>
          <lower>-0.645772</lower>
          <upper>1.74533</upper>
          <effort>34</effort>
          <velocity>100</velocity>
        </limit>
        <dynamics/>
      </axis>
    </joint>
    <link name='l_arm'>
      <pose>-0.0257499 -0.11026 0.0230202 1.57079 -9.17449e-06 3.14159</pose>
      <inertial>
        <pose>-0.000156 0.05448 -9.87e-05 0 -0 0</pose>
        <mass>0.727843</mass>
        <inertia>
          <ixx>0.01</ixx>
          <ixy>2.29e-06</ixy>
          <ixz>-1.08e-06</ixz>
          <iyy>0.01</iyy>
          <iyz>-3.57e-06</iyz>
          <izz>0.01</izz>
        </inertia>
      </inertial>
      <collision name='l_arm_collision'>
        <pose>-0.0204321 0.15228 0.000144467 1.57082 1.309 1.68812e-05</pose>
        <geometry>
          <mesh>
            <scale>1 1 1</scale>
            <uri>model://icub/meshes/collision/icub_simple_collision_l_arm.dae</uri>
          </mesh>
        </geometry>
      </collision>
      <visual name='l_arm_visual'>
        <pose>-0.0204321 0.15228 0.000144467 1.57082 1.309 1.68812e-05</pose>
        <geometry>
          <mesh>
            <scale>1 1 1</scale>
            <uri>model://icub/meshes/visual/icub_l_arm.dae</uri>
          </mesh>
        </geometry>
      </visual>
      <velocity_decay>
        <linear>0</linear>
        <angular>0</angular>
      </velocity_decay>
    </link>
    <joint name='l_arm_ft_sensor' type='revolute'>
      <child>l_arm</child>
      <parent>l_upper_arm</parent>
      <axis>
        <xyz>0 0 0</xyz>
        <limit>
          <lower>0</lower>
          <upper>0</upper>
          <effort>0</effort>
          <velocity>0</velocity>
        </limit>
        <dynamics/>
      </axis>
      <!-- check pose of the wrench returned by the simulated sensor -->
      <sensor name="left_arm_ft" type="force_torque">
        <always_on>true</always_on>
        <visualize>true</visualize>
        <update_rate>100</update_rate>
        <pose>0 0 0 0 0 0</pose>
        <plugin filename="libgazebo_yarp_forcetorque.so" name="left_arm_ft_plugin">
          <yarpConfigurationFile>model://icub/conf/FT/gazebo_icub_left_arm_ft.ini</yarpConfigurationFile>
        </plugin>
      </sensor>
    </joint>
    <link name='l_elbow_1'>
      <pose>-0.0257499 -0.11026 0.0230202 3.14159 -9.17449e-06 3.14159</pose>
      <inertial>
        <pose>-0.0013 0.00371 -0.00105 0 -0 0</pose>
        <mass>0.1</mass>
        <inertia>
          <ixx>0.01</ixx>
          <ixy>-5.15e-07</ixy>
          <ixz>-4.08e-07</ixz>
          <iyy>0.01</iyy>
          <iyz>-3.71e-07</iyz>
          <izz>0.01</izz>
        </inertia>
      </inertial>
      <velocity_decay>
        <linear>0</linear>
        <angular>0</angular>
      </velocity_decay>
    </link>
    <joint name='l_elbow' type='revolute'>
      <child>l_elbow_1</child>
      <parent>l_arm</parent>
      <axis>
        <xyz>1.63402e-06 1 2.59738e-06</xyz>
        <limit>
          <lower>0.0959931</lower>
          <upper>1.85005</upper>
          <effort>20</effort>
          <velocity>100</velocity>
        </limit>
        <dynamics/>
      </axis>
    </joint>
    <link name='l_forearm'>
      <pose>-0.0107499 -0.11026 0.0230201 -1.5708 2.59742e-06 -1.57079</pose>
      <inertial>
        <pose>0.000347 0.066 0.00476 0 -0 0</pose>
        <mass>0.525</mass>
        <inertia>
          <ixx>0.01</ixx>
          <ixy>4.337e-06</ixy>
          <ixz>2.39e-07</ixz>
          <iyy>0.01</iyy>
          <iyz>1.9381e-05</iyz>
          <izz>0.01</izz>
        </inertia>
      </inertial>
      <collision name='l_forearm_collision'>
        <pose>-0.000143422 2.11549e-08 0.0204331 1.02538 1.57079 2.59617</pose>
        <geometry>
          <mesh>
            <scale>1 1 1</scale>
            <uri>model://icub/meshes/collision/icub_simple_collision_l_forearm.dae</uri>
          </mesh>
        </geometry>
      </collision>
      <visual name='l_forearm_visual'>
        <pose>-0.000143422 2.11549e-08 0.0204331 1.02538 1.57079 2.59617</pose>
        <geometry>
          <mesh>
            <scale>1 1 1</scale>
            <uri>model://icub/meshes/visual/icub_l_forearm.dae</uri>
          </mesh>
        </geometry>
      </visual>
      <velocity_decay>
        <linear>0</linear>
        <angular>0</angular>
      </velocity_decay>
    </link>
    <joint name='l_wrist_prosup' type='revolute'>
      <child>l_forearm</child>
      <parent>l_elbow_1</parent>
      <axis>
        <xyz>-5.50128e-06 2.5974e-06 -1</xyz>
        <limit>
          <lower>-0.872665</lower>
          <upper>0.872665</upper>
          <effort>0.45</effort>
          <velocity>100</velocity>
        </limit>
        <dynamics/>
      </axis>
    </joint>
    <link name='l_wrist_1'>
      <pose>-0.0107507 -0.110259 -0.11428 -2.42145 1.57079 2.29093</pose>
      <inertial>
        <pose>0 0 0 0 -0 0</pose>
        <mass>0.1</mass>
        <inertia>
          <ixx>0.01</ixx>
          <ixy>0</ixy>
          <ixz>0</ixz>
          <iyy>0.01</iyy>
          <iyz>0</iyz>
          <izz>0.01</izz>
        </inertia>
      </inertial>
      <velocity_decay>
        <linear>0</linear>
        <angular>0</angular>
      </velocity_decay>
    </link>
    <joint name='l_wrist_pitch' type='revolute'>
      <child>l_wrist_1</child>
      <parent>l_forearm</parent>
      <axis>
        <xyz>1 -1.63401e-06 -5.5013e-06</xyz>
        <limit>
          <lower>-1.13446</lower>
          <upper>0.174533</upper>
          <effort>0.65</effort>
          <velocity>100</velocity>
        </limit>
        <dynamics/>
      </axis>
    </joint>
    <link name='l_hand'>
      <pose>-0.0107507 -0.110259 -0.11428 -2.42145 1.57079 2.29093</pose>
      <inertial>
        <pose>0.07023 -0.00805 -0.007 0 -0 0</pose>
        <mass>0.213</mass>
        <inertia>
          <ixx>0.01</ixx>
          <ixy>1.278e-05</ixy>
          <ixz>4.823e-06</ixz>
          <iyy>0.01</iyy>
          <iyz>-1.8188e-05</iyz>
          <izz>0.01</izz>
        </inertia>
      </inertial>
      <collision name='l_hand_collision'>
        <pose>2.16794e-08 0.0204335 -0.00014314 1.01957e-06 -6.27061e-06 2.84772e-06</pose>
        <geometry>
          <mesh>
            <scale>1 1 1</scale>
            <uri>model://icub/meshes/collision/icub_simple_collision_l_hand.dae</uri>
          </mesh>
        </geometry>
      </collision>
      <visual name='l_hand_visual'>
        <pose>2.16794e-08 0.0204335 -0.00014314 1.01957e-06 -6.27061e-06 2.84772e-06</pose>
        <geometry>
          <mesh>
            <scale>1 1 1</scale>
            <uri>model://icub/meshes/visual/icub_l_hand.dae</uri>
          </mesh>
        </geometry>
      </visual>
      <velocity_decay>
        <linear>0</linear>
        <angular>0</angular>
      </velocity_decay>
    </link>
    <joint name='l_wrist_yaw' type='revolute'>
      <child>l_hand</child>
      <parent>l_wrist_1</parent>
      <axis>
        <xyz>-1.63404e-06 -1 -6.2706e-06</xyz>
        <limit>
          <lower>-0.436332</lower>
          <upper>0.436332</upper>
          <effort>0.65</effort>
          <velocity>100</velocity>
        </limit>
        <dynamics/>
      </axis>
    </joint>
    <link name='neck_1'>
      <pose>-0.00780786 3.29565e-08 0.2253 5.13177e-06 -1.57078 -3.09255e-06</pose>
      <inertial>
        <pose>0.00246408 -2.13821e-50 -0.000235713 0 -0 0</pose>
        <mass>0.270176</mass>
        <inertia>
          <ixx>0.01</ixx>
          <ixy>-1.77658e-07</ixy>
          <ixz>4.49143e-07</ixz>
          <iyy>0.01</iyy>
          <iyz>-1.26829e-07</iyz>
          <izz>0.01</izz>
        </inertia>
      </inertial>
      <collision name='neck_1_collision'>
        <pose>3.22095e-09 -3.80377e-08 -0.00549846 1.97339 -1.57078 2.739</pose>
        <geometry>
          <mesh>
            <scale>1 1 1</scale>
            <uri>model://icub/meshes/collision/icub_simple_collision_neck_1.dae</uri>
          </mesh>
        </geometry>
      </collision>
      <visual name='neck_1_visual'>
        <pose>3.22095e-09 -3.80377e-08 -0.00549846 1.97339 -1.57078 2.739</pose>
        <geometry>
          <mesh>
            <scale>1 1 1</scale>
            <uri>model://icub/meshes/visual/icub_neck_1.dae</uri>
          </mesh>
        </geometry>
      </visual>
      <velocity_decay>
        <linear>0</linear>
        <angular>0</angular>
      </velocity_decay>
    </link>
    <joint name='neck_pitch' type='revolute'>
      <child>neck_1</child>
      <parent>chest</parent>
      <axis>
        <xyz>-2.03922e-06 1 7.01678e-11</xyz>
        <limit>
          <lower>-0.698132</lower>
          <upper>0.523599</upper>
          <effort>20</effort>
          <velocity>100</velocity>
        </limit>
        <dynamics/>
      </axis>
    </joint>
    <link name='neck_2'>
      <pose>-0.00780741 3.29551e-08 0.2583 -1.73464e-05 3.67328e-06 -1.57079</pose>
      <inertial>
        <pose>0 0.00337529 0.00545442 0 -0 0</pose>
        <mass>0.272306</mass>
        <inertia>
          <ixx>0.01</ixx>
          <ixy>-5.92615e-09</ixy>
          <ixz>-2.20067e-09</ixz>
          <iyy>0.01</iyy>
          <iyz>-9.13211e-06</iyz>
          <izz>0.01</izz>
        </inertia>
      </inertial>
      <collision name='neck_2_collision'>
        <pose>3.80355e-08 0.0054981 2.34147e-08 -2.89661 -1.57078 -1.81578</pose>
        <geometry>
          <mesh>
            <scale>1 1 1</scale>
            <uri>model://icub/meshes/collision/icub_simple_collision_neck_2.dae</uri>
          </mesh>
        </geometry>
      </collision>
      <visual name='neck_2_visual'>
        <pose>3.80355e-08 0.0054981 2.34147e-08 -2.89661 -1.57078 -1.81578</pose>
        <geometry>
          <mesh>
            <scale>1 1 1</scale>
            <uri>model://icub/meshes/visual/icub_neck_2.dae</uri>
          </mesh>
        </geometry>
      </visual>
      <velocity_decay>
        <linear>0</linear>
        <angular>0</angular>
      </velocity_decay>
    </link>
    <joint name='neck_roll' type='revolute'>
      <child>neck_2</child>
      <parent>neck_1</parent>
      <axis>
        <xyz>-1 -2.03923e-06 1.73464e-05</xyz>
        <limit>
          <lower>-1.22173</lower>
          <upper>1.0472</upper>
          <effort>20</effort>
          <velocity>100</velocity>
        </limit>
        <dynamics/>
      </axis>
    </joint>
    <link name='head'>
      <pose>-0.00880741 3.09159e-08 0.2583 -1.5708 1.73464e-05 5.71244e-06</pose>
      <inertial>
        <pose>0.0225 -0.1005 6.15385e-18 0 -0 0</pose>
        <mass>1.33687</mass>
        <inertia>
          <ixx>0.01</ixx>
          <ixy>0</ixy>
          <ixz>0</ixz>
          <iyy>0.01</iyy>
          <iyz>0</iyz>
          <izz>0.01</izz>
        </inertia>
      </inertial>
      <collision name='head_collision'>
        <pose>0.0054981 -8.72169e-09 -5.35384e-08 -1.57078 1.57079 3.14159</pose>
        <geometry>
          <mesh>
            <scale>1 1 1</scale>
            <uri>model://icub/meshes/collision/icub_simple_collision_head.dae</uri>
          </mesh>
        </geometry>
      </collision>
      <visual name='head_visual'>
        <pose>0.0054981 -8.72169e-09 -5.35384e-08 -1.57078 1.57079 3.14159</pose>
        <geometry>
          <mesh>
            <scale>1 1 1</scale>
            <uri>model://icub/meshes/visual/icub_head.dae</uri>
          </mesh>
        </geometry>
      </visual>
      <velocity_decay>
        <linear>0</linear>
        <angular>0</angular>
      </velocity_decay>
       

    
    <sensor name="imu_sensor" type="imu">
        <always_on>1</always_on>
        <update_rate>100</update_rate>
        <visualize>1</visualize>
      <imu/>
    <plugin filename="libgazebo_yarp_imu.so" name="iCub_yarp_gazebo_plugin_IMU">
        <yarpConfigurationFile>model://icub/conf/gazebo_icub_inertial.ini</yarpConfigurationFile>
    </plugin>
    <pose>0.0185 -0.1108 0.0066 1.5708 -0 0</pose>
   </sensor>
    </link>
    <joint name='neck_yaw' type='revolute'>
      <child>head</child>
      <parent>neck_2</parent>
      <axis>
        <xyz>1.73464e-05 -3.47947e-11 1</xyz>
        <limit>
          <lower>-0.959931</lower>
          <upper>0.959931</upper>
          <effort>20</effort>
          <velocity>100</velocity>
        </limit>
        <dynamics/>
      </axis>
    </joint>
    <link name='r_shoulder_1'>
      <pose>-0.0107482 0.11026 0.1753 -2.87979 -1.57078 -3.09257e-06</pose>
      <inertial>
        <pose>5e-06 0.0187 0.00119 0 -0 0</pose>
        <mass>0.189</mass>
        <inertia>
          <ixx>0.01</ixx>
          <ixy>2.1e-08</ixy>
          <ixz>-1e-09</ixz>
          <iyy>0.01</iyy>
          <iyz>4.22e-06</iyz>
          <izz>0.01</izz>
        </inertia>
      </inertial>
      <collision name='r_shoulder_1_collision'>
        <pose>2.88175e-07 0.109285 0.00521021 1.38131 1.57079 2.9521</pose>
        <geometry>
          <mesh>
            <scale>1 1 1</scale>
            <uri>model://icub/meshes/collision/icub_simple_collision_r_shoulder_1.dae</uri>
          </mesh>
        </geometry>
      </collision>
      <visual name='r_shoulder_1_visual'>
        <pose>2.88175e-07 0.109285 0.00521021 1.38131 1.57079 2.9521</pose>
        <geometry>
          <mesh>
            <scale>1 1 1</scale>
            <uri>model://icub/meshes/visual/icub_r_shoulder_1.dae</uri>
          </mesh>
        </geometry>
      </visual>
      <velocity_decay>
        <linear>0</linear>
        <angular>0</angular>
      </velocity_decay>
    </link>
    <joint name='r_shoulder_pitch' type='revolute'>
      <child>r_shoulder_1</child>
      <parent>chest</parent>
      <axis>
        <xyz>0.258815 -0.965927 -3.53887e-06</xyz>
        <limit>
          <lower>-1.65806</lower>
          <upper>0.0872665</upper>
          <effort>84</effort>
          <velocity>100</velocity>
        </limit>
        <dynamics/>
      </axis>
    </joint>
    <link name='r_shoulder_2'>
      <pose>-0.0107482 0.11026 0.1753 9.53412e-06 1.34337e-07 1.83259</pose>
      <inertial>
        <pose>-9.4e-05 -0.00627 -0.0166 0 -0 0</pose>
        <mass>0.179</mass>
        <inertia>
          <ixx>0.01</ixx>
          <ixy>-4.53e-07</ixy>
          <ixz>2.03e-07</ixz>
          <iyy>0.01</iyy>
          <iyz>2.07e-05</iyz>
          <izz>0.01</izz>
        </inertia>
      </inertial>
      <collision name='r_shoulder_2_collision'>
        <pose>-0.00154501 -0.00520999 -4.39241e-08 -0.117248 -1.57079 1.68805</pose>
        <geometry>
          <mesh>
            <scale>1 1 1</scale>
            <uri>model://icub/meshes/collision/icub_simple_collision_r_shoulder_2.dae</uri>
          </mesh>
        </geometry>
      </collision>
      <visual name='r_shoulder_2_visual'>
        <pose>-0.00154501 -0.00520999 -4.39241e-08 -0.117248 -1.57079 1.68805</pose>
        <geometry>
          <mesh>
            <scale>1 1 1</scale>
            <uri>model://icub/meshes/visual/icub_r_shoulder_2.dae</uri>
          </mesh>
        </geometry>
      </visual>
      <velocity_decay>
        <linear>0</linear>
        <angular>0</angular>
      </velocity_decay>
    </link>
    <joint name='r_shoulder_roll' type='revolute'>
      <child>r_shoulder_2</child>
      <parent>r_shoulder_1</parent>
      <axis>
        <xyz>0.965927 0.258815 -9.53412e-06</xyz>
        <limit>
          <lower>0</lower>
          <upper>2.80649</upper>
          <effort>84</effort>
          <velocity>100</velocity>
        </limit>
        <dynamics/>
      </axis>
    </joint>
    <link name='r_upper_arm'>
      <pose>-0.0107482 0.11026 0.1753 3.14159 -9.17449e-06 3.14159</pose>
      <inertial>
        <pose>0.00553932 -2.47652e-05 0.0493895 0 -0 0</pose>
        <mass>0.155</mass>
        <inertia>
          <ixx>0.01</ixx>
          <ixy>3.56977e-07</ixy>
          <ixz>-3.95372e-06</ixz>
          <iyy>0.01</iyy>
          <iyz>-6.5128e-06</iyz>
          <izz>0.01</izz>
        </inertia>
      </inertial>
      <velocity_decay>
        <linear>0</linear>
        <angular>0</angular>
      </velocity_decay>
    </link>
    <joint name='r_shoulder_yaw' type='revolute'>
      <child>r_upper_arm</child>
      <parent>r_shoulder_2</parent>
      <axis>
        <xyz>9.17449e-06 -5.62627e-08 1</xyz>
        <limit>
          <lower>-0.645772</lower>
          <upper>1.74533</upper>
          <effort>34</effort>
          <velocity>100</velocity>
        </limit>
        <dynamics/>
      </axis>
    </joint>
    <link name='r_arm'>
      <pose>-0.0257496 0.11026 0.0230202 -1.57079 9.17449e-06 1.01961e-06</pose>
      <inertial>
        <pose>0.00015906 -0.0543972 8.28733e-05 0 -0 0</pose>
        <mass>0.729</mass>
        <inertia>
          <ixx>0.01</ixx>
          <ixy>2.29e-06</ixy>
          <ixz>1.08e-06</ixz>
          <iyy>0.01</iyy>
          <iyz>3.57e-06</iyz>
          <izz>0.01</izz>
        </inertia>
      </inertial>
      <collision name='r_arm_collision'>
        <pose>0.0204323 -0.15228 -0.000143432 -1.57078 -1.309 3.14157</pose>
        <geometry>
          <mesh>
            <scale>1 1 1</scale>
            <uri>model://icub/meshes/collision/icub_simple_collision_r_arm.dae</uri>
          </mesh>
        </geometry>
      </collision>
      <visual name='r_arm_visual'>
        <pose>0.0204323 -0.15228 -0.000143432 -1.57078 -1.309 3.14157</pose>
        <geometry>
          <mesh>
            <scale>1 1 1</scale>
            <uri>model://icub/meshes/visual/icub_r_arm.dae</uri>
          </mesh>
        </geometry>
      </visual>
      <velocity_decay>
        <linear>0</linear>
        <angular>0</angular>
      </velocity_decay>
    </link>
    <joint name='r_arm_ft_sensor' type='revolute'>
      <child>r_arm</child>
      <parent>r_upper_arm</parent>
      <axis>
        <xyz>0 -0 0</xyz>
        <limit>
          <lower>0</lower>
          <upper>0</upper>
          <effort>0</effort>
          <velocity>0</velocity>
        </limit>
        <dynamics/>
      </axis>
      <!-- check pose of the wrench returned by the simulated sensor -->
      <sensor name="right_arm_ft" type="force_torque">
        <always_on>true</always_on>
        <visualize>true</visualize>
        <update_rate>100</update_rate>
        <pose>0 0 0 0 0 0</pose>
        <plugin filename="libgazebo_yarp_forcetorque.so" name="right_arm_ft_plugin">
          <yarpConfigurationFile>model://icub/conf/FT/gazebo_icub_right_arm_ft.ini</yarpConfigurationFile>
        </plugin>
      </sensor>
    </joint>
    <link name='r_elbow_1'>
      <pose>-0.0257496 0.11026 0.0230202 7.40268e-06 9.17449e-06 1.01961e-06</pose>
      <inertial>
        <pose>0.0013 -0.00371 0.00105 0 -0 0</pose>
        <mass>0.1</mass>
        <inertia>
          <ixx>0.01</ixx>
          <ixy>-5.02e-07</ixy>
          <ixz>-3.99e-07</ixz>
          <iyy>0.01</iyy>
          <iyz>-3.71e-07</iyz>
          <izz>0.01</izz>
        </inertia>
      </inertial>
      <velocity_decay>
        <linear>0</linear>
        <angular>0</angular>
      </velocity_decay>
    </link>
    <joint name='r_elbow' type='revolute'>
      <child>r_elbow_1</child>
      <parent>r_arm</parent>
      <axis>
        <xyz>-1.01955e-06 1 7.40268e-06</xyz>
        <limit>
          <lower>0.0959931</lower>
          <upper>1.85005</upper>
          <effort>20</effort>
          <velocity>100</velocity>
        </limit>
        <dynamics/>
      </axis>
    </joint>
    <link name='r_forearm'>
      <pose>-0.0107496 0.11026 0.0230201 1.57079 7.40265e-06 -1.5708</pose>
      <inertial>
        <pose>-0.000347 -0.066 -0.00476 0 -0 0</pose>
        <mass>0.525</mass>
        <inertia>
          <ixx>0.01</ixx>
          <ixy>5.66e-06</ixy>
          <ixz>1.4e-06</ixz>
          <iyy>0.01</iyy>
          <iyz>1.82e-05</iyz>
          <izz>0.01</izz>
        </inertia>
      </inertial>
      <collision name='r_forearm_collision'>
        <pose>0.00014398 -1.97229e-08 -0.0204333 1.52422e-05 1.57079 1.57082</pose>
        <geometry>
          <mesh>
            <scale>1 1 1</scale>
            <uri>model://icub/meshes/collision/icub_simple_collision_r_forearm.dae</uri>
          </mesh>
        </geometry>
      </collision>
      <visual name='r_forearm_visual'>
        <pose>0.00014398 -1.97229e-08 -0.0204333 1.52422e-05 1.57079 1.57082</pose>
        <geometry>
          <mesh>
            <scale>1 1 1</scale>
            <uri>model://icub/meshes/visual/icub_r_forearm.dae</uri>
          </mesh>
        </geometry>
      </visual>
      <velocity_decay>
        <linear>0</linear>
        <angular>0</angular>
      </velocity_decay>
    </link>
    <joint name='r_wrist_prosup' type='revolute'>
      <child>r_forearm</child>
      <parent>r_elbow_1</parent>
      <axis>
        <xyz>5.50129e-06 -7.40266e-06 1</xyz>
        <limit>
          <lower>-0.872665</lower>
          <upper>0.872665</upper>
          <effort>0.45</effort>
          <velocity>100</velocity>
        </limit>
        <dynamics/>
      </axis>
    </joint>
    <link name='r_wrist_1'>
      <pose>-0.0107503 0.110261 -0.11428 2.16655 -1.57079 -0.595755</pose>
      <inertial>
        <pose>0 0 0 0 -0 0</pose>
        <mass>0.1</mass>
        <inertia>
          <ixx>0.01</ixx>
          <ixy>0</ixy>
          <ixz>0</ixz>
          <iyy>0.01</iyy>
          <iyz>0</iyz>
          <izz>0.01</izz>
        </inertia>
      </inertial>
      <velocity_decay>
        <linear>0</linear>
        <angular>0</angular>
      </velocity_decay>
    </link>
    <joint name='r_wrist_pitch' type='revolute'>
      <child>r_wrist_1</child>
      <parent>r_forearm</parent>
      <axis>
        <xyz>-1 -1.01959e-06 5.5013e-06</xyz>
        <limit>
          <lower>-1.13446</lower>
          <upper>0.174533</upper>
          <effort>0.65</effort>
          <velocity>100</velocity>
        </limit>
        <dynamics/>
      </axis>
    </joint>
    <link name='r_hand'>
      <pose>-0.0107503 0.110261 -0.11428 -1.99973 1.57079 2.71266</pose>
      <inertial>
        <pose>0.07023 -0.00805 0.007 0 -0 0</pose>
        <mass>0.213</mass>
        <inertia>
          <ixx>0.01</ixx>
          <ixy>1.26e-05</ixy>
          <ixz>-6.08e-06</ixz>
          <iyy>0.01</iyy>
          <iyz>1.76e-05</iyz>
          <izz>0.01</izz>
        </inertia>
      </inertial>
      <collision name='r_hand_collision'>
        <pose>-3.39715e-08 0.0204337 0.000145071 -3.67314e-06 3.72954e-06 -3.14159</pose>
        <geometry>
          <mesh>
            <scale>1 1 1</scale>
            <uri>model://icub/meshes/collision/icub_simple_collision_r_hand.dae</uri>
          </mesh>
        </geometry>
      </collision>
      <visual name='r_hand_visual'>
        <pose>-3.39715e-08 0.0204337 0.000145071 -3.67314e-06 3.72954e-06 -3.14159</pose>
        <geometry>
          <mesh>
            <scale>1 1 1</scale>
            <uri>model://icub/meshes/visual/icub_r_hand.dae</uri>
          </mesh>
        </geometry>
      </visual>
      <velocity_decay>
        <linear>0</linear>
        <angular>0</angular>
      </velocity_decay>
    </link>
    <joint name='r_wrist_yaw' type='revolute'>
      <child>r_hand</child>
      <parent>r_wrist_1</parent>
      <axis>
        <xyz>1.01957e-06 -1 -3.72946e-06</xyz>
        <limit>
          <lower>-0.436332</lower>
          <upper>0.436332</upper>
          <effort>0.65</effort>
          <velocity>100</velocity>
        </limit>
        <dynamics/>
      </axis>
    </joint>
    
        <!-- Configuration file for fake control boards -->
    <plugin name="controlboard_torso" filename="libgazebo_yarp_controlboard.so">
        <yarpConfigurationFile>model://icub/conf/gazebo_icub_torso.ini</yarpConfigurationFile>
    </plugin>
    <plugin name="controlboard_head" filename="libgazebo_yarp_controlboard.so">
        <yarpConfigurationFile>model://icub/conf/gazebo_icub_head.ini</yarpConfigurationFile>
    </plugin>
    <plugin name="controlboard_right_arm" filename="libgazebo_yarp_controlboard.so">
        <yarpConfigurationFile>model://icub/conf/gazebo_icub_right_arm.ini</yarpConfigurationFile>
        <initialConfiguration>-0.52 0.52 0 0.785 0 0 0.698</initialConfiguration>
    </plugin>
    <plugin name="controlboard_left_arm" filename="libgazebo_yarp_controlboard.so">
        <yarpConfigurationFile>model://icub/conf/gazebo_icub_left_arm.ini</yarpConfigurationFile>
        <initialConfiguration>-0.52 0.52 0 0.785 0 0 0.698</initialConfiguration>
    </plugin>
    <plugin name="controlboard_right_leg" filename="libgazebo_yarp_controlboard.so">
        <yarpConfigurationFile>model://icub/conf/gazebo_icub_right_leg.ini</yarpConfigurationFile>
    </plugin>
    <plugin name="controlboard_left_leg" filename="libgazebo_yarp_controlboard.so">
        <yarpConfigurationFile>model://icub/conf/gazebo_icub_left_leg.ini</yarpConfigurationFile>
    </plugin>

    <!-- Spawing pose -->
    <pose>0 0 0.70 0 0 0 </pose>
    
    
  </model>
</sdf>
