<sdf version='1.4'>
  <model name='icub'>
    <link name='root_link'>
      <pose>0 0 0 0 -0 0</pose>
      <inertial>
        <pose>0 0 0 0 -0 0</pose>
        <mass>0.2</mass>
        <inertia>
          <ixx>0.1</ixx>
          <ixy>0</ixy>
          <ixz>0</ixz>
          <iyy>0.1</iyy>
          <iyz>0</iyz>
          <izz>0.1</izz>
        </inertia>
      </inertial>
      <collision name='root_link_collision'>
        <pose>0 0 0 0 -0 0</pose>
        <geometry>
          <mesh>
            <scale>1 1 1</scale>
            <uri>model://icub/meshes/collision/icub_simple_collision_root_link.dae</uri>
          </mesh>
        </geometry>
      </collision>
      <visual name='root_link_visual'>
        <pose>0 0 0 0 -0 0</pose>
        <geometry>
          <mesh>
            <scale>1 1 1</scale>
            <uri>model://icub/meshes/collision/icub_simple_collision_root_link.dae</uri>
          </mesh>
        </geometry>
      </visual>
      <velocity_decay>
        <linear>0</linear>
        <angular>0</angular>
      </velocity_decay>
    </link>
    <link name='l_hip_1'>
      <pose>0 -0.0681 -0.1199 3.14159 1.57079 -3.14159</pose>
      <inertial>
        <pose>0 0 0 0 -0 0</pose>
        <mass>0.695</mass>
        <inertia>
          <ixx>0.00447053</ixx>
          <ixy>-2.2209e-05</ixy>
          <ixz>1.39712e-05</ixz>
          <iyy>0.00325085</iyy>
          <iyz>4.77629e-05</iyz>
          <izz>0.00490487</izz>
        </inertia>
      </inertial>
      <collision name='l_hip_1_collision'>
        <pose>0 0 0 1.5708 -1.57079 3.14159</pose>
        <geometry>
          <mesh>
            <scale>1 1 1</scale>
            <uri>model://icub/meshes/collision/icub_simple_collision_l_hip_1.dae</uri>
          </mesh>
        </geometry>
      </collision>
      <visual name='l_hip_1_visual'>
        <pose>0 0 0 1.5708 -1.57079 3.14159</pose>
        <geometry>
          <mesh>
            <scale>1 1 1</scale>
            <uri>model://icub/meshes/collision/icub_simple_collision_l_hip_1.dae</uri>
          </mesh>
        </geometry>
      </visual>
      <velocity_decay>
        <linear>0</linear>
        <angular>0</angular>
      </velocity_decay>
    </link>
    <joint name='l_hip_pitch' type='revolute'>
      <child>l_hip_1</child>
      <parent>root_link</parent>
      <axis>
        <xyz>-5.30718e-06 1 1.67887e-11</xyz>
        <limit>
          <lower>-1e+16</lower>
          <upper>1e+16</upper>
        </limit>
        <dynamics/>
      </axis>
    </joint>
    <link name='l_hip_2'>
      <pose>0 -0.0681 -0.1199 -1.65821e-11 6.65517e-17 -3.14159</pose>
      <inertial>
        <pose>0 0 0.0665 0 -0 0</pose>
        <mass>0.982</mass>
        <inertia>
          <ixx>0.0253646</ixx>
          <ixy>1.2116e-06</ixy>
          <ixz>0.000491081</ixz>
          <iyy>0.0272714</iyy>
          <iyz>1.15713e-05</iyz>
          <izz>0.0041739</izz>
        </inertia>
      </inertial>
      <collision name='l_hip_2_collision'>
        <pose>0 0 0 -1.57079 1.57079 -1.57079</pose>
        <geometry>
          <mesh>
            <scale>1 1 1</scale>
            <uri>model://icub/meshes/collision/icub_simple_collision_l_hip_2.dae</uri>
          </mesh>
        </geometry>
      </collision>
      <visual name='l_hip_2_visual'>
        <pose>0 0 0 -1.57079 1.57079 -1.57079</pose>
        <geometry>
          <mesh>
            <scale>1 1 1</scale>
            <uri>model://icub/meshes/collision/icub_simple_collision_l_hip_2.dae</uri>
          </mesh>
        </geometry>
      </visual>
      <velocity_decay>
        <linear>0</linear>
        <angular>0</angular>
      </velocity_decay>
    </link>
    <joint name='l_hip_roll' type='revolute'>
      <child>l_hip_2</child>
      <parent>l_hip_1</parent>
      <axis>
        <xyz>1 5.3072e-06 5.31936e-18</xyz>
        <limit>
          <lower>-1e+16</lower>
          <upper>1e+16</upper>
        </limit>
        <dynamics/>
      </axis>
    </joint>
    <link name='l_upper_thigh'>
      <pose>0 -0.0681 -0.1199 3.14159 -1.65821e-11 1.5708</pose>
      <inertial>
        <pose>0 0 0 0 -0 0</pose>
        <mass>0.2</mass>
        <inertia>
          <ixx>0</ixx>
          <ixy>0</ixy>
          <ixz>0</ixz>
          <iyy>0</iyy>
          <iyz>0</iyz>
          <izz>0</izz>
        </inertia>
      </inertial>
      <velocity_decay>
        <linear>0</linear>
        <angular>0</angular>
      </velocity_decay>
    </link>
    <joint name='l_leg_ft_sensor' type='revolute'>
      <child>l_upper_thigh</child>
      <parent>l_hip_2</parent>
      <axis>
        <xyz>2.65359e-06 2.09181e-11 -1</xyz>
        <limit>
          <lower>0</lower>
          <upper>0</upper>
        </limit>
        <dynamics/>
      </axis>
    </joint>
    <link name='l_thigh'>
      <pose>-2.75359e-40 -0.0681 -0.1199 1.57079 2.65359e-06 -3.14159</pose>
      <inertial>
        <pose>-0.0009175 -0.234545 1.43617e-17 0 -0 0</pose>
        <mass>1.522</mass>
        <inertia>
          <ixx>0.0454917</ixx>
          <ixy>-0.000940971</ixy>
          <ixz>5.37405e-05</ixz>
          <iyy>0.01004</iyy>
          <iyz>0.001203</iyz>
          <izz>0.0458255</izz>
        </inertia>
      </inertial>
      <collision name='l_thigh_collision'>
        <pose>0 0 0 3.14158 1.57079 -1.57081</pose>
        <geometry>
          <mesh>
            <scale>1 1 1</scale>
            <uri>model://icub/meshes/collision/icub_simple_collision_l_thigh.dae</uri>
          </mesh>
        </geometry>
      </collision>
      <visual name='l_thigh_visual'>
        <pose>0 0 0 3.14158 1.57079 -1.57081</pose>
        <geometry>
          <mesh>
            <scale>1 1 1</scale>
            <uri>model://icub/meshes/collision/icub_simple_collision_l_thigh.dae</uri>
          </mesh>
        </geometry>
      </visual>
      <velocity_decay>
        <linear>0</linear>
        <angular>0</angular>
      </velocity_decay>
    </link>
    <joint name='l_hip_yaw' type='revolute'>
      <child>l_thigh</child>
      <parent>l_upper_thigh</parent>
      <axis>
        <xyz>2.65357e-06 3.67323e-06 -1</xyz>
        <limit>
          <lower>-1e+16</lower>
          <upper>1e+16</upper>
        </limit>
        <dynamics/>
      </axis>
    </joint>
    <link name='l_shank'>
      <pose>0.000918122 -0.0680991 -0.354445 2.87083 -1.57079 -1.30003</pose>
      <inertial>
        <pose>-0.2005 0 0 0 -0 0</pose>
        <mass>2.032</mass>
        <inertia>
          <ixx>0.0154559</ixx>
          <ixy>-0.0013903</ixy>
          <ixz>-0.0039454</ixz>
          <iyy>0.070277</iyy>
          <iyz>0.00071995</iyz>
          <izz>0.0659645</izz>
        </inertia>
      </inertial>
      <collision name='l_shank_collision'>
        <pose>0.010945 0.000918134 2.30422e-07 -3.14159 -2.65357e-06 1.5708</pose>
        <geometry>
          <mesh>
            <scale>1 1 1</scale>
            <uri>model://icub/meshes/collision/icub_simple_collision_l_shank.dae</uri>
          </mesh>
        </geometry>
      </collision>
      <visual name='l_shank_visual'>
        <pose>0.010945 0.000918134 2.30422e-07 -3.14159 -2.65357e-06 1.5708</pose>
        <geometry>
          <mesh>
            <scale>1 1 1</scale>
            <uri>model://icub/meshes/collision/icub_simple_collision_l_shank.dae</uri>
          </mesh>
        </geometry>
      </visual>
      <velocity_decay>
        <linear>0</linear>
        <angular>0</angular>
      </velocity_decay>
    </link>
    <joint name='l_knee' type='revolute'>
      <child>l_shank</child>
      <parent>l_thigh</parent>
      <axis>
        <xyz>-2.65362e-06 1 3.67321e-06</xyz>
        <limit>
          <lower>-1e+16</lower>
          <upper>1e+16</upper>
        </limit>
        <dynamics/>
      </axis>
    </joint>
    <link name='l_ankle_1'>
      <pose>0.000917918 -0.0680984 -0.554945 -1.84156 -1.57079 -1.30003</pose>
      <inertial>
        <pose>0 0 0 0 -0 0</pose>
        <mass>0.643</mass>
        <inertia>
          <ixx>4.76593</ixx>
          <ixy>9.7426e-06</ixy>
          <ixz>2.68085e-05</ixz>
          <iyy>0.0040935</iyy>
          <iyz>-0.000353796</iyz>
          <izz>0.0036688</izz>
        </inertia>
      </inertial>
      <collision name='l_ankle_1_collision'>
        <pose>-0.001555 4.44229e-07 -0.000917916 -1.5708 1.0196e-06 -1.01962e-06</pose>
        <geometry>
          <mesh>
            <scale>1 1 1</scale>
            <uri>model://icub/meshes/collision/icub_simple_collision_l_ankle_1.dae</uri>
          </mesh>
        </geometry>
      </collision>
      <visual name='l_ankle_1_visual'>
        <pose>-0.001555 4.44229e-07 -0.000917916 -1.5708 1.0196e-06 -1.01962e-06</pose>
        <geometry>
          <mesh>
            <scale>1 1 1</scale>
            <uri>model://icub/meshes/collision/icub_simple_collision_l_ankle_1.dae</uri>
          </mesh>
        </geometry>
      </visual>
      <velocity_decay>
        <linear>0</linear>
        <angular>0</angular>
      </velocity_decay>
    </link>
    <joint name='l_ankle_pitch' type='revolute'>
      <child>l_ankle_1</child>
      <parent>l_shank</parent>
      <axis>
        <xyz>6.32682e-06 -1 -3.67321e-06</xyz>
        <limit>
          <lower>-1e+16</lower>
          <upper>1e+16</upper>
        </limit>
        <dynamics/>
      </axis>
    </joint>
    <link name='l_foot'>
      <pose>0.000917918 -0.0680984 -0.554945 1.30003 -1.57079 -1.30003</pose>
      <inertial>
        <pose>-0.0685 4.28626e-19 -0.0035 0 -0 0</pose>
        <mass>0.861</mass>
        <inertia>
          <ixx>0.00158466</ixx>
          <ixy>-1.43579e-05</ixy>
          <ixz>2.10795e-05</ixz>
          <iyy>0.0020147</iyy>
          <iyz>-1.72417e-05</iyz>
          <izz>0.000977226</izz>
        </inertia>
      </inertial>
      <collision name='l_foot_collision'>
        <pose>-0.001555 -4.46665e-07 0.000917916 1.63396e-06 -1.0196e-06 1.01962e-06</pose>
        <geometry>
          <mesh>
            <scale>1 1 1</scale>
            <uri>model://icub/meshes/collision/icub_simple_collision_l_foot.dae</uri>
          </mesh>
        </geometry>
      </collision>
      <visual name='l_foot_visual'>
        <pose>-0.001555 -4.46665e-07 0.000917916 1.63396e-06 -1.0196e-06 1.01962e-06</pose>
        <geometry>
          <mesh>
            <scale>1 1 1</scale>
            <uri>model://icub/meshes/collision/icub_simple_collision_l_foot.dae</uri>
          </mesh>
        </geometry>
      </visual>
      <velocity_decay>
        <linear>0</linear>
        <angular>0</angular>
      </velocity_decay>
    </link>
    <joint name='l_ankle_roll' type='revolute'>
      <child>l_foot</child>
      <parent>l_ankle_1</parent>
      <axis>
        <xyz>1 3.67324e-06 -1.01962e-06</xyz>
        <limit>
          <lower>-1e+16</lower>
          <upper>1e+16</upper>
        </limit>
        <dynamics/>
      </axis>
    </joint>
    <link name='r_hip_1'>
      <pose>0 0.0681 -0.1199 3.14159 1.57079 -3.14159</pose>
      <inertial>
        <pose>0 0 0 0 -0 0</pose>
        <mass>0.695</mass>
        <inertia>
          <ixx>0.00447053</ixx>
          <ixy>-2.2209e-05</ixy>
          <ixz>-1.39712e-05</ixz>
          <iyy>0.00325085</iyy>
          <iyz>-4.77629e-05</iyz>
          <izz>0.00490487</izz>
        </inertia>
      </inertial>
      <collision name='r_hip_1_collision'>
        <pose>0 0 0 1.5708 -1.57079 3.14159</pose>
        <geometry>
          <mesh>
            <scale>1 1 1</scale>
            <uri>model://icub/meshes/collision/icub_simple_collision_r_hip_1.dae</uri>
          </mesh>
        </geometry>
      </collision>
      <visual name='r_hip_1_visual'>
        <pose>0 0 0 1.5708 -1.57079 3.14159</pose>
        <geometry>
          <mesh>
            <scale>1 1 1</scale>
            <uri>model://icub/meshes/collision/icub_simple_collision_r_hip_1.dae</uri>
          </mesh>
        </geometry>
      </visual>
      <velocity_decay>
        <linear>0</linear>
        <angular>0</angular>
      </velocity_decay>
    </link>
    <joint name='r_hip_pitch' type='revolute'>
      <child>r_hip_1</child>
      <parent>root_link</parent>
      <axis>
        <xyz>-5.30718e-06 1 1.67887e-11</xyz>
        <limit>
          <lower>-1e+16</lower>
          <upper>1e+16</upper>
        </limit>
        <dynamics/>
      </axis>
    </joint>
    <link name='r_hip_2'>
      <pose>0 0.0681 -0.1199 -3.14159 -1.26536e-05 -3.14159</pose>
      <inertial>
        <pose>0 0 0.0665 0 -0 0</pose>
        <mass>0.982</mass>
        <inertia>
          <ixx>0.0253646</ixx>
          <ixy>1.2116e-06</ixy>
          <ixz>0.000491081</ixz>
          <iyy>0.0272714</iyy>
          <iyz>1.15713e-05</iyz>
          <izz>0.0041739</izz>
        </inertia>
      </inertial>
      <collision name='r_hip_2_collision'>
        <pose>0 0 0 3.14159 -1.57079 -3.14159</pose>
        <geometry>
          <mesh>
            <scale>1 1 1</scale>
            <uri>model://icub/meshes/collision/icub_simple_collision_r_hip_2.dae</uri>
          </mesh>
        </geometry>
      </collision>
      <visual name='r_hip_2_visual'>
        <pose>0 0 0 3.14159 -1.57079 -3.14159</pose>
        <geometry>
          <mesh>
            <scale>1 1 1</scale>
            <uri>model://icub/meshes/collision/icub_simple_collision_r_hip_2.dae</uri>
          </mesh>
        </geometry>
      </visual>
      <velocity_decay>
        <linear>0</linear>
        <angular>0</angular>
      </velocity_decay>
    </link>
    <joint name='r_hip_roll' type='revolute'>
      <child>r_hip_2</child>
      <parent>r_hip_1</parent>
      <axis>
        <xyz>1 5.30716e-06 -1.26536e-05</xyz>
        <limit>
          <lower>-1e+16</lower>
          <upper>1e+16</upper>
        </limit>
        <dynamics/>
      </axis>
    </joint>
    <link name='r_upper_thigh'>
      <pose>0 0.0681 -0.1199 -3.14158 5.30721e-06 1.5708</pose>
      <inertial>
        <pose>0 0 0 0 -0 0</pose>
        <mass>0.01</mass>
        <inertia>
          <ixx>0.001</ixx>
          <ixy>0</ixy>
          <ixz>0</ixz>
          <iyy>0.001</iyy>
          <iyz>0</iyz>
          <izz>0.001</izz>
        </inertia>
      </inertial>
      <velocity_decay>
        <linear>0</linear>
        <angular>0</angular>
      </velocity_decay>
    </link>
    <joint name='r_leg_ft_sensor' type='revolute'>
      <child>r_upper_thigh</child>
      <parent>r_hip_2</parent>
      <axis>
        <xyz>-1.26536e-05 -5.30723e-06 -1</xyz>
        <limit>
          <lower>0</lower>
          <upper>0</upper>
        </limit>
        <dynamics/>
      </axis>
    </joint>
    <link name='r_thigh'>
      <pose>-2.75364e-40 0.0681 -0.1199 1.5708 -1.26536e-05 -3.14159</pose>
      <inertial>
        <pose>-0.0009175 -0.234545 1.43617e-17 0 -0 0</pose>
        <mass>1.522</mass>
        <inertia>
          <ixx>0.0454917</ixx>
          <ixy>-0.000940971</ixy>
          <ixz>-5.37405e-05</ixz>
          <iyy>0.01004</iyy>
          <iyz>-0.001203</iyz>
          <izz>0.0458255</izz>
        </inertia>
      </inertial>
      <collision name='r_thigh_collision'>
        <pose>0 0 0 3.14159 -1.57079 -1.5708</pose>
        <geometry>
          <mesh>
            <scale>1 1 1</scale>
            <uri>model://icub/meshes/collision/icub_simple_collision_r_thigh.dae</uri>
          </mesh>
        </geometry>
      </collision>
      <visual name='r_thigh_visual'>
        <pose>0 0 0 3.14159 -1.57079 -1.5708</pose>
        <geometry>
          <mesh>
            <scale>1 1 1</scale>
            <uri>model://icub/meshes/collision/icub_simple_collision_r_thigh.dae</uri>
          </mesh>
        </geometry>
      </visual>
      <velocity_decay>
        <linear>0</linear>
        <angular>0</angular>
      </velocity_decay>
    </link>
    <joint name='r_hip_yaw' type='revolute'>
      <child>r_thigh</child>
      <parent>r_upper_thigh</parent>
      <axis>
        <xyz>-1.26536e-05 -1.63402e-06 -1</xyz>
        <limit>
          <lower>-1e+16</lower>
          <upper>1e+16</upper>
        </limit>
        <dynamics/>
      </axis>
    </joint>
    <link name='r_shank'>
      <pose>0.000914532 0.0680996 -0.354445 1.47105 -1.57078 0.0997515</pose>
      <inertial>
        <pose>-0.2005 0 0 0 -0 0</pose>
        <mass>2.032</mass>
        <inertia>
          <ixx>0.0154559</ixx>
          <ixy>-0.0013903</ixy>
          <ixz>0.0039454</ixz>
          <iyy>0.070277</iyy>
          <iyz>-0.00071995</iyz>
          <izz>0.0659645</izz>
        </inertia>
      </inertial>
      <collision name='r_shank_collision'>
        <pose>0.010945 0.000915898 8.23759e-07 -3.14159 -2.65362e-06 1.57081</pose>
        <geometry>
          <mesh>
            <scale>1 1 1</scale>
            <uri>model://icub/meshes/collision/icub_simple_collision_r_shank.dae</uri>
          </mesh>
        </geometry>
      </collision>
      <visual name='r_shank_visual'>
        <pose>0.010945 0.000915898 8.23759e-07 -3.14159 -2.65362e-06 1.57081</pose>
        <geometry>
          <mesh>
            <scale>1 1 1</scale>
            <uri>model://icub/meshes/collision/icub_simple_collision_r_shank.dae</uri>
          </mesh>
        </geometry>
      </visual>
      <velocity_decay>
        <linear>0</linear>
        <angular>0</angular>
      </velocity_decay>
    </link>
    <joint name='r_knee' type='revolute'>
      <child>r_shank</child>
      <parent>r_thigh</parent>
      <axis>
        <xyz>-2.65359e-06 1 -1.634e-06</xyz>
        <limit>
          <lower>-1e+16</lower>
          <upper>1e+16</upper>
        </limit>
        <dynamics/>
      </axis>
    </joint>
    <link name='r_ankle_1'>
      <pose>0.000911259 0.0680993 -0.554945 3.04185 -1.57078 0.0997515</pose>
      <inertial>
        <pose>0 0 0 0 -0 0</pose>
        <mass>0.643</mass>
        <inertia>
          <ixx>4.76593</ixx>
          <ixy>9.7426e-06</ixy>
          <ixz>-2.68085e-05</ixz>
          <iyy>0.0040935</iyy>
          <iyz>0.000353796</iyz>
          <izz>0.0036688</izz>
        </inertia>
      </inertial>
      <collision name='r_ankle_1_collision'>
        <pose>-0.001555 1.60279e-06 -0.00091355 -1.5708 1.10196e-05 -3.67321e-06</pose>
        <geometry>
          <mesh>
            <scale>1 1 1</scale>
            <uri>model://icub/meshes/collision/icub_simple_collision_r_ankle_1.dae</uri>
          </mesh>
        </geometry>
      </collision>
      <visual name='r_ankle_1_visual'>
        <pose>-0.001555 1.60279e-06 -0.00091355 -1.5708 1.10196e-05 -3.67321e-06</pose>
        <geometry>
          <mesh>
            <scale>1 1 1</scale>
            <uri>model://icub/meshes/collision/icub_simple_collision_r_ankle_1.dae</uri>
          </mesh>
        </geometry>
      </visual>
      <velocity_decay>
        <linear>0</linear>
        <angular>0</angular>
      </velocity_decay>
    </link>
    <joint name='r_ankle_pitch' type='revolute'>
      <child>r_ankle_1</child>
      <parent>r_shank</parent>
      <axis>
        <xyz>6.3268e-06 -1 1.63394e-06</xyz>
        <limit>
          <lower>-1e+16</lower>
          <upper>1e+16</upper>
        </limit>
        <dynamics/>
      </axis>
    </joint>
    <link name='r_foot'>
      <pose>0.000911259 0.0680993 -0.554945 -0.0997478 -1.57078 0.0997515</pose>
      <inertial>
        <pose>-0.0685 4.28626e-19 -0.0035 0 -0 0</pose>
        <mass>0.861</mass>
        <inertia>
          <ixx>0.00158466</ixx>
          <ixy>1.43577e-05</ixy>
          <ixz>2.10795e-05</ixz>
          <iyy>0.0020147</iyy>
          <iyz>1.72417e-05</iyz>
          <izz>0.000977226</izz>
        </inertia>
      </inertial>
      <collision name='r_foot_collision'>
        <pose>-0.001555 -1.60521e-06 0.00091355 -3.14159 -1.10196e-05 3.67318e-06</pose>
        <geometry>
          <mesh>
            <scale>1 1 1</scale>
            <uri>model://icub/meshes/collision/icub_simple_collision_r_foot.dae</uri>
          </mesh>
        </geometry>
      </collision>
      <visual name='r_foot_visual'>
        <pose>-0.001555 -1.60521e-06 0.00091355 -3.14159 -1.10196e-05 3.67318e-06</pose>
        <geometry>
          <mesh>
            <scale>1 1 1</scale>
            <uri>model://icub/meshes/collision/icub_simple_collision_r_foot.dae</uri>
          </mesh>
        </geometry>
      </visual>
      <velocity_decay>
        <linear>0</linear>
        <angular>0</angular>
      </velocity_decay>
    </link>
    <joint name='r_ankle_roll' type='revolute'>
      <child>r_foot</child>
      <parent>r_ankle_1</parent>
      <axis>
        <xyz>1 3.67318e-06 -1.63268e-05</xyz>
        <limit>
          <lower>-1e+16</lower>
          <upper>1e+16</upper>
        </limit>
        <dynamics/>
      </axis>
    </joint>
    <link name='lap_belt_1'>
      <pose>0 0 0 -2.65359e-06 -1.57079 3.14159</pose>
      <inertial>
        <pose>0 0 0 0 -0 0</pose>
        <mass>0.01</mass>
        <inertia>
          <ixx>0.0004544</ixx>
          <ixy>-4.263e-05</ixy>
          <ixz>-3.889e-08</ixz>
          <iyy>0.001141</iyy>
          <iyz>0</iyz>
          <izz>0.001236</izz>
        </inertia>
      </inertial>
      <collision name='lap_belt_1_collision'>
        <pose>0 0 0 -1.57079 -3.6732e-06 -9.74705e-12</pose>
        <geometry>
          <mesh>
            <scale>1 1 1</scale>
            <uri>model://icub/meshes/collision/icub_simple_collision_lap_belt_1.dae</uri>
          </mesh>
        </geometry>
      </collision>
      <visual name='lap_belt_1_visual'>
        <pose>0 0 0 -1.57079 -3.6732e-06 -9.74705e-12</pose>
        <geometry>
          <mesh>
            <scale>1 1 1</scale>
            <uri>model://icub/meshes/collision/icub_simple_collision_lap_belt_1.dae</uri>
          </mesh>
        </geometry>
      </visual>
      <velocity_decay>
        <linear>0</linear>
        <angular>0</angular>
      </velocity_decay>
    </link>
    <joint name='torso_yaw' type='revolute'>
      <child>lap_belt_1</child>
      <parent>root_link</parent>
      <axis>
        <xyz>-5.30718e-06 -1 -1.67887e-11</xyz>
        <limit>
          <lower>-1e+16</lower>
          <upper>1e+16</upper>
        </limit>
        <dynamics/>
      </axis>
    </joint>
    <link name='lap_belt_2'>
      <pose>-2.02457e-07 5.37239e-13 0.032 3.14159 3.67319e-06 1.57079</pose>
      <inertial>
        <pose>0 0 0 0 -0 0</pose>
        <mass>0.01</mass>
        <inertia>
          <ixx>0.0005308</ixx>
          <ixy>-1.923e-06</ixy>
          <ixz>5.095e-05</ixz>
          <iyy>0.002031</iyy>
          <iyz>-3.849e-07</iyz>
          <izz>0.001803</izz>
        </inertia>
      </inertial>
      <velocity_decay>
        <linear>0</linear>
        <angular>0</angular>
      </velocity_decay>
    </link>
    <joint name='torso_roll' type='revolute'>
      <child>lap_belt_2</child>
      <parent>lap_belt_1</parent>
      <axis>
        <xyz>1 -5.30719e-06 2.65359e-06</xyz>
        <limit>
          <lower>-1e+16</lower>
          <upper>1e+16</upper>
        </limit>
        <dynamics/>
      </axis>
    </joint>
    <link name='chest'>
      <pose>-0.0055002 2.91901e-08 0.032 1.5708 2.65358e-06 3.14159</pose>
      <inertial>
        <pose>0.00231 0.1933 -1.18362e-17 0 -0 0</pose>
        <mass>4.81</mass>
        <inertia>
          <ixx>0.07472</ixx>
          <ixy>-3.6e-06</ixy>
          <ixz>-4.705e-05</ixz>
          <iyy>0.08145</iyy>
          <iyz>0.004567</iyz>
          <izz>0.01306</izz>
        </inertia>
      </inertial>
      <collision name='chest_collision'>
        <pose>-0.00550012 2.9008e-13 -2.02027e-08 1.57078 -1.57079 1.26536e-05</pose>
        <geometry>
          <mesh>
            <scale>1 1 1</scale>
            <uri>model://icub/meshes/collision/icub_simple_collision_chest.dae</uri>
          </mesh>
        </geometry>
      </collision>
      <visual name='chest_visual'>
        <pose>-0.00550012 2.9008e-13 -2.02027e-08 1.57078 -1.57079 1.26536e-05</pose>
        <geometry>
          <mesh>
            <scale>1 1 1</scale>
            <uri>model://icub/meshes/collision/icub_simple_collision_chest.dae</uri>
          </mesh>
        </geometry>
      </visual>
      <velocity_decay>
        <linear>0</linear>
        <angular>0</angular>
      </velocity_decay>
    </link>
    <joint name='torso_pitch' type='revolute'>
      <child>chest</child>
      <parent>lap_belt_2</parent>
      <axis>
        <xyz>2.65358e-06 2.70567e-12 -1</xyz>
        <limit>
          <lower>-1e+16</lower>
          <upper>1e+16</upper>
        </limit>
        <dynamics/>
      </axis>
    </joint>
    <link name='l_shoulder_1'>
      <pose>-0.0107508 -0.11026 0.1753 2.8798 -1.57079 3.14158</pose>
      <inertial>
        <pose>0 0 0 0 -0 0</pose>
        <mass>0.189</mass>
        <inertia>
          <ixx>5.4421e-05</ixx>
          <ixy>9e-09</ixy>
          <ixz>0</ixz>
          <iyy>9.331e-06</iyy>
          <iyz>-1.7e-08</iyz>
          <izz>5.4862e-05</izz>
        </inertia>
      </inertial>
      <collision name='l_shoulder_1_collision'>
        <pose>1.22387e-07 0.109285 -0.00521147 0.715704 1.57079 -0.855093</pose>
        <geometry>
          <mesh>
            <scale>1 1 1</scale>
            <uri>model://icub/meshes/collision/icub_simple_collision_l_shoulder_1.dae</uri>
          </mesh>
        </geometry>
      </collision>
      <visual name='l_shoulder_1_visual'>
        <pose>1.22387e-07 0.109285 -0.00521147 0.715704 1.57079 -0.855093</pose>
        <geometry>
          <mesh>
            <scale>1 1 1</scale>
            <uri>model://icub/meshes/collision/icub_simple_collision_l_shoulder_1.dae</uri>
          </mesh>
        </geometry>
      </visual>
      <velocity_decay>
        <linear>0</linear>
        <angular>0</angular>
      </velocity_decay>
    </link>
    <joint name='l_shoulder_pitch' type='revolute'>
      <child>l_shoulder_1</child>
      <parent>chest</parent>
      <axis>
        <xyz>-0.258818 -0.965926 2.6389e-07</xyz>
        <limit>
          <lower>-1e+16</lower>
          <upper>1e+16</upper>
        </limit>
        <dynamics/>
      </axis>
    </joint>
    <link name='l_shoulder_2'>
      <pose>-0.0107508 -0.11026 0.1753 -3.14159 3.40932e-06 -1.83259</pose>
      <inertial>
        <pose>0 0 0 0 -0 0</pose>
        <mass>0.179</mass>
        <inertia>
          <ixx>0.0001372</ixx>
          <ixy>4.66e-07</ixy>
          <ixz>3.65e-07</ixz>
          <iyy>8.2927e-05</iyy>
          <iyz>-2.0524e-05</iyz>
          <izz>9.9274e-05</izz>
        </inertia>
      </inertial>
      <collision name='l_shoulder_2_collision'>
        <pose>-0.00154526 -0.00521103 4.8568e-09 1.61672 1.57079 -3.09566</pose>
        <geometry>
          <mesh>
            <scale>1 1 1</scale>
            <uri>model://icub/meshes/collision/icub_simple_collision_l_shoulder_2.dae</uri>
          </mesh>
        </geometry>
      </collision>
      <visual name='l_shoulder_2_visual'>
        <pose>-0.00154526 -0.00521103 4.8568e-09 1.61672 1.57079 -3.09566</pose>
        <geometry>
          <mesh>
            <scale>1 1 1</scale>
            <uri>model://icub/meshes/collision/icub_simple_collision_l_shoulder_2.dae</uri>
          </mesh>
        </geometry>
      </visual>
      <velocity_decay>
        <linear>0</linear>
        <angular>0</angular>
      </velocity_decay>
    </link>
    <joint name='l_shoulder_roll' type='revolute'>
      <child>l_shoulder_2</child>
      <parent>l_shoulder_1</parent>
      <axis>
        <xyz>-0.965926 0.258818 -2.68832e-06</xyz>
        <limit>
          <lower>-1e+16</lower>
          <upper>1e+16</upper>
        </limit>
        <dynamics/>
      </axis>
    </joint>
    <link name='l_upper_arm'>
      <pose>-0.0107508 -0.11026 0.1753 3.14159 3.4791e-06 3.14159</pose>
      <inertial>
        <pose>0.015 9.36797e-18 0.068 0 -0 0</pose>
        <mass>0.156157</mass>
        <inertia>
          <ixx>4.84118e-05</ixx>
          <ixy>-5.662e-08</ixy>
          <ixz>-4.3618e-06</ixz>
          <iyy>5.79067e-05</iyy>
          <iyz>-7.42844e-07</iyz>
          <izz>6.7103e-05</izz>
        </inertia>
      </inertial>
      <velocity_decay>
        <linear>0</linear>
        <angular>0</angular>
      </velocity_decay>
    </link>
    <joint name='l_shoulder_yaw' type='revolute'>
      <child>l_upper_arm</child>
      <parent>l_shoulder_2</parent>
      <axis>
        <xyz>3.47911e-06 2.59736e-06 -1</xyz>
        <limit>
          <lower>-1e+16</lower>
          <upper>1e+16</upper>
        </limit>
        <dynamics/>
      </axis>
    </joint>
    <link name='l_arm'>
      <pose>-0.0257502 -0.11026 0.0230199 1.57079 3.4791e-06 3.14159</pose>
      <inertial>
        <pose>0 0 0 0 -0 0</pose>
        <mass>0.727843</mass>
        <inertia>
          <ixx>0.000408</ixx>
          <ixy>2.29e-06</ixy>
          <ixz>-1.08e-06</ixz>
          <iyy>0.00026</iyy>
          <iyz>-3.57e-06</iyz>
          <izz>0.00038</izz>
        </inertia>
      </inertial>
      <collision name='l_arm_collision'>
        <pose>-0.0204334 0.15228 0.000144467 1.57082 1.309 2.42275e-05</pose>
        <geometry>
          <mesh>
            <scale>1 1 1</scale>
            <uri>model://icub/meshes/collision/icub_simple_collision_l_arm.dae</uri>
          </mesh>
        </geometry>
      </collision>
      <visual name='l_arm_visual'>
        <pose>-0.0204334 0.15228 0.000144467 1.57082 1.309 2.42275e-05</pose>
        <geometry>
          <mesh>
            <scale>1 1 1</scale>
            <uri>model://icub/meshes/collision/icub_simple_collision_l_arm.dae</uri>
          </mesh>
        </geometry>
      </visual>
      <velocity_decay>
        <linear>0</linear>
        <angular>0</angular>
      </velocity_decay>
    </link>
    <joint name='l_arm_ft_sensor' type='revolute'>
      <child>l_arm</child>
      <parent>l_upper_arm</parent>
      <axis>
        <xyz>1.63398e-06 1 6.27057e-06</xyz>
        <limit>
          <lower>0</lower>
          <upper>0</upper>
        </limit>
        <dynamics/>
      </axis>
    </joint>
    <link name='l_elbow_1'>
      <pose>-0.0257502 -0.11026 0.0230199 3.14159 3.4791e-06 3.14159</pose>
      <inertial>
        <pose>-0.015 0 0 0 -0 0</pose>
        <mass>0.074</mass>
        <inertia>
          <ixx>2.8389e-05</ixx>
          <ixy>-5.15e-07</ixy>
          <ixz>-4.08e-07</ixz>
          <iyy>9.244e-06</iyy>
          <iyz>-3.71e-07</iyz>
          <izz>2.9968e-05</izz>
        </inertia>
      </inertial>
  
      <velocity_decay>
        <linear>0</linear>
        <angular>0</angular>
      </velocity_decay>
    </link>
    <joint name='l_elbow' type='revolute'>
      <child>l_elbow_1</child>
      <parent>l_arm</parent>
      <axis>
        <xyz>1.63399e-06 1 2.59737e-06</xyz>
        <limit>
          <lower>-1e+16</lower>
          <upper>1e+16</upper>
        </limit>
        <dynamics/>
      </axis>
    </joint>
    <link name='l_forearm'>
      <pose>-0.0107502 -0.11026 0.02302 -1.57079 2.59736e-06 -1.57079</pose>
      <inertial>
        <pose>0 0.1373 8.4072e-18 0 -0 0</pose>
        <mass>0.525</mass>
        <inertia>
          <ixx>0.000765393</ixx>
          <ixy>4.337e-06</ixy>
          <ixz>2.39e-07</ixz>
          <iyy>0.000164578</iyy>
          <iyz>1.9381e-05</iyz>
          <izz>0.00069806</izz>
        </inertia>
      </inertial>
      <collision name='l_forearm_collision'>
        <pose>-0.000143422 9.22944e-08 0.0204333 2.33508 1.57079 -2.37731</pose>
        <geometry>
          <mesh>
            <scale>1 1 1</scale>
            <uri>model://icub/meshes/collision/icub_simple_collision_l_forearm.dae</uri>
          </mesh>
        </geometry>
      </collision>
      <visual name='l_forearm_visual'>
        <pose>-0.000143422 9.22944e-08 0.0204333 2.33508 1.57079 -2.37731</pose>
        <geometry>
          <mesh>
            <scale>1 1 1</scale>
            <uri>model://icub/meshes/collision/icub_simple_collision_l_forearm.dae</uri>
          </mesh>
        </geometry>
      </visual>
      <velocity_decay>
        <linear>0</linear>
        <angular>0</angular>
      </velocity_decay>
    </link>
    <joint name='l_wrist_prosup' type='revolute'>
      <child>l_forearm</child>
      <parent>l_elbow_1</parent>
      <axis>
        <xyz>7.15231e-06 2.59737e-06 -1</xyz>
        <limit>
          <lower>-1e+16</lower>
          <upper>1e+16</upper>
        </limit>
        <dynamics/>
      </axis>
    </joint>
    <link name='l_wrist_1'>
      <pose>-0.0107493 -0.110259 -0.11428 2.2906 1.57079 0.719804</pose>
      <inertial>
        <pose>0 0 0 0 -0 0</pose>
        <mass>0.1</mass>
        <inertia>
          <ixx>0</ixx>
          <ixy>0</ixy>
          <ixz>0</ixz>
          <iyy>0</iyy>
          <iyz>0</iyz>
          <izz>0</izz>
        </inertia>
      </inertial>
      <velocity_decay>
        <linear>0</linear>
        <angular>0</angular>
      </velocity_decay>
    </link>
    <joint name='l_wrist_pitch' type='revolute'>
      <child>l_wrist_1</child>
      <parent>l_forearm</parent>
      <axis>
        <xyz>1 -1.63401e-06 7.15229e-06</xyz>
        <limit>
          <lower>-1e+16</lower>
          <upper>1e+16</upper>
        </limit>
        <dynamics/>
      </axis>
    </joint>
    <link name='l_hand'>
      <pose>-0.0107493 -0.110259 -0.11428 2.2906 1.57079 0.719804</pose>
      <inertial>
        <pose>0.0625 0 -0.016 0 -0 0</pose>
        <mass>0.213</mass>
        <inertia>
          <ixx>0.000157143</ixx>
          <ixy>1.278e-05</ixy>
          <ixz>4.823e-06</ixz>
          <iyy>0.000247995</iyy>
          <iyz>-1.8188e-05</iyz>
          <izz>0.000380535</izz>
        </inertia>
      </inertial>
      <collision name='l_hand_collision'>
        <pose>9.2818e-08 0.0204327 -0.00014314 1.01961e-06 -6.27059e-06 -4.49869e-06</pose>
        <geometry>
          <mesh>
            <scale>1 1 1</scale>
            <uri>model://icub/meshes/collision/icub_simple_collision_l_hand.dae</uri>
          </mesh>
        </geometry>
      </collision>
      <visual name='l_hand_visual'>
        <pose>9.2818e-08 0.0204327 -0.00014314 1.01961e-06 -6.27059e-06 -4.49869e-06</pose>
        <geometry>
          <mesh>
            <scale>1 1 1</scale>
            <uri>model://icub/meshes/collision/icub_simple_collision_l_hand.dae</uri>
          </mesh>
        </geometry>
      </visual>
      <velocity_decay>
        <linear>0</linear>
        <angular>0</angular>
      </velocity_decay>
    </link>
    <joint name='l_wrist_yaw' type='revolute'>
      <child>l_hand</child>
      <parent>l_wrist_1</parent>
      <axis>
        <xyz>-1.63397e-06 -1 -6.27059e-06</xyz>
        <limit>
          <lower>-1e+16</lower>
          <upper>1e+16</upper>
        </limit>
        <dynamics/>
      </axis>
    </joint>
    <link name='neck_1'>
      <pose>-0.00781072 3.29641e-08 0.2253 -3.14158 -1.57079 3.14158</pose>
      <inertial>
        <pose>0 0 0 0 -0 0</pose>
        <mass>0.01</mass>
        <inertia>
          <ixx>0.001</ixx>
          <ixy>0</ixy>
          <ixz>0</ixz>
          <iyy>0.001</iyy>
          <iyz>0</iyz>
          <izz>0.001</izz>
        </inertia>
      </inertial>
      <collision name='neck_1_collision'>
        <pose>2.02033e-08 -3.80477e-08 -0.00550012 2.47747 -1.57079 2.23492</pose>
        <geometry>
          <mesh>
            <scale>1 1 1</scale>
            <uri>model://icub/meshes/collision/icub_simple_collision_neck_1.dae</uri>
          </mesh>
        </geometry>
      </collision>
      <visual name='neck_1_visual'>
        <pose>2.02033e-08 -3.80477e-08 -0.00550012 2.47747 -1.57079 2.23492</pose>
        <geometry>
          <mesh>
            <scale>1 1 1</scale>
            <uri>model://icub/meshes/collision/icub_simple_collision_neck_1.dae</uri>
          </mesh>
        </geometry>
      </visual>
      <velocity_decay>
        <linear>0</linear>
        <angular>0</angular>
      </velocity_decay>
    </link>
    <joint name='neck_pitch' type='revolute'>
      <child>neck_1</child>
      <parent>chest</parent>
      <axis>
        <xyz>-2.03922e-06 1 1.07868e-11</xyz>
        <limit>
          <lower>-1e+16</lower>
          <upper>1e+16</upper>
        </limit>
        <dynamics/>
      </axis>
    </joint>
    <link name='neck_2'>
      <pose>-0.00781071 3.2964e-08 0.2348 -4.69283e-06 3.67322e-06 -1.57079</pose>
      <inertial>
        <pose>0 0 0 0 -0 0</pose>
        <mass>0.1</mass>
        <inertia>
          <ixx>0.01</ixx>
          <ixy>0</ixy>
          <ixz>0</ixz>
          <iyy>0.01</iyy>
          <iyz>0.01</iyz>
          <izz>0.01</izz>
        </inertia>
      </inertial>
      <collision name='neck_2_collision'>
        <pose>-4.82735e-08 0.00549991 0.0235 -2.67795 -1.57079 -2.03445</pose>
        <geometry>
          <mesh>
            <scale>1 1 1</scale>
            <uri>model://icub/meshes/collision/icub_simple_collision_neck_2.dae</uri>
          </mesh>
        </geometry>
      </collision>
      <visual name='neck_2_visual'>
        <pose>-4.82735e-08 0.00549991 0.0235 -2.67795 -1.57079 -2.03445</pose>
        <geometry>
          <mesh>
            <scale>1 1 1</scale>
            <uri>model://icub/meshes/collision/icub_simple_collision_neck_2.dae</uri>
          </mesh>
        </geometry>
      </visual>
      <velocity_decay>
        <linear>0</linear>
        <angular>0</angular>
      </velocity_decay>
    </link>
    <joint name='neck_roll' type='revolute'>
      <child>neck_2</child>
      <parent>neck_1</parent>
      <axis>
        <xyz>-1 -2.03923e-06 4.69283e-06</xyz>
        <limit>
          <lower>-1e+16</lower>
          <upper>1e+16</upper>
        </limit>
        <dynamics/>
      </axis>
    </joint>
    <link name='head'>
      <pose>-0.00781071 3.2964e-08 0.2348 -1.5708 4.69282e-06 5.71244e-06</pose>
      <inertial>
        <pose>0.0185 -0.1108 6.78454e-18 0 -0 0</pose>
        <mass>1.33687</mass>
        <inertia>
          <ixx>0</ixx>
          <ixy>0</ixy>
          <ixz>2.40741e-35</ixz>
          <iyy>0</iyy>
          <iyz>0</iyz>
          <izz>0</izz>
        </inertia>
      </inertial>
      <collision name='head_collision'>
        <pose>0.00449991 -0.0235 -4.98833e-08 -1.57079 1.57079 3.14159</pose>
        <geometry>
          <mesh>
            <scale>1 1 1</scale>
            <uri>model://icub/meshes/collision/icub_simple_collision_head.dae</uri>
          </mesh>
        </geometry>
      </collision>
      <visual name='head_visual'>
        <pose>0.00449991 -0.0235 -4.98833e-08 -1.57079 1.57079 3.14159</pose>
        <geometry>
          <mesh>
            <scale>1 1 1</scale>
            <uri>model://icub/meshes/collision/icub_simple_collision_head.dae</uri>
          </mesh>
        </geometry>
      </visual>
      <velocity_decay>
        <linear>0</linear>
        <angular>0</angular>
      </velocity_decay>
    </link>
    <joint name='neck_yaw' type='revolute'>
      <child>head</child>
      <parent>neck_2</parent>
      <axis>
        <xyz>4.69282e-06 -1.21714e-12 1</xyz>
        <limit>
          <lower>-1e+16</lower>
          <upper>1e+16</upper>
        </limit>
        <dynamics/>
      </axis>
    </joint>
    <link name='r_shoulder_1'>
      <pose>-0.0107504 0.11026 0.1753 0.261803 -1.57079 3.14158</pose>
      <inertial>
        <pose>0 0 0 0 -0 0</pose>
        <mass>0.189</mass>
        <inertia>
          <ixx>0.000123</ixx>
          <ixy>2.1e-08</ixy>
          <ixz>-1e-09</ixz>
          <iyy>2.44e-05</iyy>
          <iyz>4.22e-06</iyz>
          <izz>0.000113</izz>
        </inertia>
      </inertial>
      <collision name='r_shoulder_1_collision'>
        <pose>1.22387e-07 0.109285 0.00521146 1.04869 1.57079 2.61949</pose>
        <geometry>
          <mesh>
            <scale>1 1 1</scale>
            <uri>model://icub/meshes/collision/icub_simple_collision_r_shoulder_1.dae</uri>
          </mesh>
        </geometry>
      </collision>
      <visual name='r_shoulder_1_visual'>
        <pose>1.22387e-07 0.109285 0.00521146 1.04869 1.57079 2.61949</pose>
        <geometry>
          <mesh>
            <scale>1 1 1</scale>
            <uri>model://icub/meshes/collision/icub_simple_collision_r_shoulder_1.dae</uri>
          </mesh>
        </geometry>
      </visual>
      <velocity_decay>
        <linear>0</linear>
        <angular>0</angular>
      </velocity_decay>
    </link>
    <joint name='r_shoulder_pitch' type='revolute'>
      <child>r_shoulder_1</child>
      <parent>chest</parent>
      <axis>
        <xyz>0.258815 -0.965927 -2.63903e-07</xyz>
        <limit>
          <lower>-1e+16</lower>
          <upper>1e+16</upper>
        </limit>
        <dynamics/>
      </axis>
    </joint>
    <link name='r_shoulder_2'>
      <pose>-0.0107504 0.11026 0.1753 -2.68832e-06 3.4093e-06 1.83259</pose>
      <inertial>
        <pose>0 0 0 0 -0 0</pose>
        <mass>0.179</mass>
        <inertia>
          <ixx>0.000137</ixx>
          <ixy>-4.53e-07</ixy>
          <ixz>2.03e-07</ixz>
          <iyy>8.3e-05</iyy>
          <iyz>2.07e-05</iyz>
          <izz>9.93e-05</izz>
        </inertia>
      </inertial>
      <collision name='r_shoulder_2_collision'>
        <pose>-0.00154534 -0.00521124 -4.86143e-09 -1.61673 -1.57079 -3.09565</pose>
        <geometry>
          <mesh>
            <scale>1 1 1</scale>
            <uri>model://icub/meshes/collision/icub_simple_collision_r_shoulder_2.dae</uri>
          </mesh>
        </geometry>
      </collision>
      <visual name='r_shoulder_2_visual'>
        <pose>-0.00154534 -0.00521124 -4.86143e-09 -1.61673 -1.57079 -3.09565</pose>
        <geometry>
          <mesh>
            <scale>1 1 1</scale>
            <uri>model://icub/meshes/collision/icub_simple_collision_r_shoulder_2.dae</uri>
          </mesh>
        </geometry>
      </visual>
      <velocity_decay>
        <linear>0</linear>
        <angular>0</angular>
      </velocity_decay>
    </link>
    <joint name='r_shoulder_roll' type='revolute'>
      <child>r_shoulder_2</child>
      <parent>r_shoulder_1</parent>
      <axis>
        <xyz>0.965927 0.258815 2.68832e-06</xyz>
        <limit>
          <lower>-1e+16</lower>
          <upper>1e+16</upper>
        </limit>
        <dynamics/>
      </axis>
    </joint>
    <link name='r_upper_arm'>
      <pose>-0.0107504 0.11026 0.1753 3.14159 3.4791e-06 3.14159</pose>
      <inertial>
        <pose>0.015 -8.93429e-18 0.068 0 -0 0</pose>
        <mass>0.155</mass>
        <inertia>
          <ixx>3.44122e-05</ixx>
          <ixy>3.56977e-07</ixy>
          <ixz>-3.95372e-06</ixz>
          <iyy>4.33544e-05</iyy>
          <iyz>-6.5128e-06</iyz>
          <izz>6.49393e-05</izz>
        </inertia>
      </inertial>
      <velocity_decay>
        <linear>0</linear>
        <angular>0</angular>
      </velocity_decay>
    </link>
    <joint name='r_shoulder_yaw' type='revolute'>
      <child>r_upper_arm</child>
      <parent>r_shoulder_2</parent>
      <axis>
        <xyz>-3.4791e-06 -5.62291e-08 1</xyz>
        <limit>
          <lower>-1e+16</lower>
          <upper>1e+16</upper>
        </limit>
        <dynamics/>
      </axis>
    </joint>
    <link name='r_arm'>
      <pose>-0.0257499 0.11026 0.0230199 -1.57079 -3.4791e-06 1.01961e-06</pose>
      <inertial>
        <pose>0 0 0 0 -0 0</pose>
        <mass>0.729</mass>
        <inertia>
          <ixx>0.000408</ixx>
          <ixy>2.29e-06</ixy>
          <ixz>1.08e-06</ixz>
          <iyy>0.00026</iyy>
          <iyz>3.57e-06</iyz>
          <izz>0.00038</izz>
        </inertia>
      </inertial>
      <collision name='r_arm_collision'>
        <pose>0.0204336 -0.15228 -0.000143432 -1.57078 -1.309 3.14158</pose>
        <geometry>
          <mesh>
            <scale>1 1 1</scale>
            <uri>model://icub/meshes/collision/icub_simple_collision_r_arm.dae</uri>
          </mesh>
        </geometry>
      </collision>
      <visual name='r_arm_visual'>
        <pose>0.0204336 -0.15228 -0.000143432 -1.57078 -1.309 3.14158</pose>
        <geometry>
          <mesh>
            <scale>1 1 1</scale>
            <uri>model://icub/meshes/collision/icub_simple_collision_r_arm.dae</uri>
          </mesh>
        </geometry>
      </visual>
      <velocity_decay>
        <linear>0</linear>
        <angular>0</angular>
      </velocity_decay>
    </link>
    <joint name='r_arm_ft_sensor' type='revolute'>
      <child>r_arm</child>
      <parent>r_upper_arm</parent>
      <axis>
        <xyz>-1.01963e-06 1 3.72943e-06</xyz>
        <limit>
          <lower>0</lower>
          <upper>0</upper>
        </limit>
        <dynamics/>
      </axis>
    </joint>
    <link name='r_elbow_1'>
      <pose>-0.0257499 0.11026 0.0230199 7.40264e-06 -3.4791e-06 1.01961e-06</pose>
      <inertial>
        <pose>0.015 0 0 0 -0 0</pose>
        <mass>0.074</mass>
        <inertia>
          <ixx>2.84e-05</ixx>
          <ixy>-5.02e-07</ixy>
          <ixz>-3.99e-07</ixz>
          <iyy>9.24e-06</iyy>
          <iyz>-3.71e-07</iyz>
          <izz>2.99e-05</izz>
        </inertia>
      </inertial>
      <velocity_decay>
        <linear>0</linear>
        <angular>0</angular>
      </velocity_decay>
    </link>
    <joint name='r_elbow' type='revolute'>
      <child>r_elbow_1</child>
      <parent>r_arm</parent>
      <axis>
        <xyz>-1.01964e-06 1 7.40264e-06</xyz>
        <limit>
          <lower>-1e+16</lower>
          <upper>1e+16</upper>
        </limit>
        <dynamics/>
      </axis>
    </joint>
    <link name='r_forearm'>
      <pose>-0.0107499 0.11026 0.02302 1.5708 7.40265e-06 -1.5708</pose>
      <inertial>
        <pose>0 -0.1373 -8.4072e-18 0 -0 0</pose>
        <mass>0.525</mass>
        <inertia>
          <ixx>0.000766</ixx>
          <ixy>5.66e-06</ixy>
          <ixz>1.4e-06</ixz>
          <iyy>0.000164</iyy>
          <iyz>1.82e-05</iyz>
          <izz>0.000699</izz>
        </inertia>
      </inertial>
      <collision name='r_forearm_collision'>
        <pose>0.00014398 -9.08603e-08 -0.0204335 3.14158 1.57079 -1.5708</pose>
        <geometry>
          <mesh>
            <scale>1 1 1</scale>
            <uri>model://icub/meshes/collision/icub_simple_collision_r_forearm.dae</uri>
          </mesh>
        </geometry>
      </collision>
      <visual name='r_forearm_visual'>
        <pose>0.00014398 -9.08603e-08 -0.0204335 3.14158 1.57079 -1.5708</pose>
        <geometry>
          <mesh>
            <scale>1 1 1</scale>
            <uri>model://icub/meshes/collision/icub_simple_collision_r_forearm.dae</uri>
          </mesh>
        </geometry>
      </visual>
      <velocity_decay>
        <linear>0</linear>
        <angular>0</angular>
      </velocity_decay>
    </link>
    <joint name='r_wrist_prosup' type='revolute'>
      <child>r_forearm</child>
      <parent>r_elbow_1</parent>
      <axis>
        <xyz>-7.1523e-06 -7.40263e-06 1</xyz>
        <limit>
          <lower>-1e+16</lower>
          <upper>1e+16</upper>
        </limit>
        <dynamics/>
      </axis>
    </joint>
    <link name='r_wrist_1'>
      <pose>-0.0107489 0.110261 -0.11428 -2.05144 -1.57079 -2.66095</pose>
      <inertial>
        <pose>0 0 0 0 -0 0</pose>
        <mass>0.01</mass>
        <inertia>
          <ixx>0.001</ixx>
          <ixy>0</ixy>
          <ixz>0</ixz>
          <iyy>0.001</iyy>
          <iyz>0</iyz>
          <izz>0.001</izz>
        </inertia>
      </inertial>
      <velocity_decay>
        <linear>0</linear>
        <angular>0</angular>
      </velocity_decay>
    </link>
    <joint name='r_wrist_pitch' type='revolute'>
      <child>r_wrist_1</child>
      <parent>r_forearm</parent>
      <axis>
        <xyz>-1 -1.01959e-06 -7.15229e-06</xyz>
        <limit>
          <lower>-1e+16</lower>
          <upper>1e+16</upper>
        </limit>
        <dynamics/>
      </axis>
    </joint>
    <link name='r_hand'>
      <pose>-0.0107489 0.110261 -0.11428 2.26297 1.57079 0.692175</pose>
      <inertial>
        <pose>0.0625 0 0.016 0 -0 0</pose>
        <mass>0.213</mass>
        <inertia>
          <ixx>0.000154</ixx>
          <ixy>1.26e-05</ixy>
          <ixz>-6.08e-06</ixz>
          <iyy>0.00025</iyy>
          <iyz>1.76e-05</iyz>
          <izz>0.000378</izz>
        </inertia>
      </inertial>
      <collision name='r_hand_collision'>
        <pose>3.71672e-08 0.0204329 0.000145071 -3.67318e-06 3.72945e-06 3.14159</pose>
        <geometry>
          <mesh>
            <scale>1 1 1</scale>
            <uri>model://icub/meshes/collision/icub_simple_collision_r_hand.dae</uri>
          </mesh>
        </geometry>
      </collision>
      <visual name='r_hand_visual'>
        <pose>3.71672e-08 0.0204329 0.000145071 -3.67318e-06 3.72945e-06 3.14159</pose>
        <geometry>
          <mesh>
            <scale>1 1 1</scale>
            <uri>model://icub/meshes/collision/icub_simple_collision_r_hand.dae</uri>
          </mesh>
        </geometry>
      </visual>
      <velocity_decay>
        <linear>0</linear>
        <angular>0</angular>
      </velocity_decay>
    </link>
    <joint name='r_wrist_yaw' type='revolute'>
      <child>r_hand</child>
      <parent>r_wrist_1</parent>
      <axis>
        <xyz>1.01961e-06 -1 -3.72942e-06</xyz>
        <limit>
          <lower>-1e+16</lower>
          <upper>1e+16</upper>
        </limit>
        <dynamics/>
      </axis>
    </joint>
    
    
    <!-- Configuration file for fake control boards -->
    <plugin name="controlboard_torso" filename="libgazebo_yarp_controlboard.so">
        <yarpConfigurationFile>model://icub/conf/gazebo_icub_torso.ini</yarpConfigurationFile>
    </plugin>
    <plugin name="controlboard_head" filename="libgazebo_yarp_controlboard.so">
        <yarpConfigurationFile>model://icub/conf/gazebo_icub_head.ini</yarpConfigurationFile>
    </plugin>
    <plugin name="controlboard_right_arm" filename="libgazebo_yarp_controlboard.so">
        <yarpConfigurationFile>model://icub/conf/gazebo_icub_right_arm.ini</yarpConfigurationFile>
    </plugin>
    <plugin name="controlboard_left_arm" filename="libgazebo_yarp_controlboard.so">
        <yarpConfigurationFile>model://icub/conf/gazebo_icub_left_arm.ini</yarpConfigurationFile>
    </plugin>
    <plugin name="controlboard_right_leg" filename="libgazebo_yarp_controlboard.so">
        <yarpConfigurationFile>model://icub/conf/gazebo_icub_right_leg.ini</yarpConfigurationFile>
    </plugin>
    <plugin name="controlboard_left_leg" filename="libgazebo_yarp_controlboard.so">
        <yarpConfigurationFile>model://icub/conf/gazebo_icub_left_leg.ini</yarpConfigurationFile>
    </plugin>

    <!-- Spawing pose -->
    <pose>0 0 0.70 0 0 0 </pose>
    
  </model>
</sdf>
