<sdf version='1.6'>
  <model name='iCub'>
    <link name='root_link'>
      <pose frame=''>0 0 0 0 -0 0</pose>
      <inertial>
        <pose frame=''>0 0 0 0 -0 0</pose>
        <mass>4.72</mass>
        <inertia>
          <ixx>0.01</ixx>
          <ixy>0</ixy>
          <ixz>0</ixz>
          <iyy>0.01</iyy>
          <iyz>0</iyz>
          <izz>0.01</izz>
        </inertia>
      </inertial>
      <collision name='root_link_collision'>
        <pose frame=''>0 0 0 0 -0 0</pose>
        <geometry>
          <mesh>
            <scale>1 1 1</scale>
            <uri>model://icub/meshes/collision/icub_simple_collision_root_link.dae</uri>
          </mesh>
        </geometry>
        <surface>
          <contact>
            <ode/>
          </contact>
          <friction>
            <ode/>
          </friction>
        </surface>
      </collision>
      <visual name='root_link_visual'>
        <pose frame=''>0 0 0 0 -0 0</pose>
        <geometry>
          <mesh>
            <scale>1 1 1</scale>
            <uri>model://icub/meshes/visual/icub_root_link.dae</uri>
          </mesh>
        </geometry>
        <material>
          <script>
            <uri>__default__</uri>
            <name>__default__</name>
          </script>
        </material>
      </visual>
      <velocity_decay/>
      <sensor name='root_link_ems_acc_eb5' type='imu'>
        <always_on>1</always_on>
        <update_rate>100</update_rate>
        <pose frame=''>0.049331 -0.012577 -0.115691 3.14159 1.29154 -3.14159</pose>
        <plugin name='iCub_yarp_gazebo_plugin_ACC' filename='libgazebo_yarp_inertialmtb.so'/>
      </sensor>
      <gravity>1</gravity>
      <velocity_decay/>
      <sensor name='root_link_ems_gyro_eb5' type='imu'>
        <always_on>1</always_on>
        <update_rate>100</update_rate>
        <pose frame=''>0.049331 -0.012577 -0.115691 3.14159 1.29154 -3.14159</pose>
      </sensor>
    </link>
    <link name='l_hip_1'>
      <pose frame=''>0 -0.0681 -0.1199 3e-06 1.57079 -3.14159</pose>
      <inertial>
        <pose frame=''>0 -0.0782 0 0 -0 0</pose>
        <mass>0.754</mass>
        <inertia>
          <ixx>0.01</ixx>
          <ixy>2.059e-06</ixy>
          <ixz>1.451e-06</ixz>
          <iyy>0.01</iyy>
          <iyz>1.545e-06</iyz>
          <izz>0.01</izz>
        </inertia>
      </inertial>
      <collision name='l_hip_1_collision'>
        <pose frame=''>0 0 0 -0.785403 1.57079 -2.35619</pose>
        <geometry>
          <mesh>
            <scale>1 1 1</scale>
            <uri>model://icub/meshes/collision/icub_simple_collision_l_hip_1.dae</uri>
          </mesh>
        </geometry>
      </collision>
      <visual name='l_hip_1_visual'>
        <pose frame=''>0 0 0 -0.785403 1.57079 -2.35619</pose>
        <geometry>
          <mesh>
            <scale>1 1 1</scale>
            <uri>model://icub/meshes/visual/icub_l_hip_1.dae</uri>
          </mesh>
        </geometry>
      </visual>
    </link>
    <joint name='l_hip_pitch' type='revolute'>
      <child>l_hip_1</child>
      <parent>root_link</parent>
      <axis>
        <xyz>3e-06 1 -0</xyz>
        <limit>
          <lower>-0.767945</lower>
          <upper>2.30383</upper>
          <effort>84</effort>
          <velocity>100</velocity>
        </limit>
        <dynamics>
          <damping>1</damping>
          <friction>0</friction>
          <spring_reference>0</spring_reference>
          <spring_stiffness>0</spring_stiffness>
        </dynamics>
        <use_parent_model_frame>1</use_parent_model_frame>
      </axis>
    </joint>
    <link name='l_hip_2'>
      <pose frame=''>0 -0.0681 -0.1199 3.14159 -7e-06 3.14159</pose>
      <inertial>
        <pose frame=''>0 0 0.03045 0 -0 0</pose>
        <mass>0.526</mass>
        <inertia>
          <ixx>0.01</ixx>
          <ixy>-7.4e-08</ixy>
          <ixz>1.0835e-05</ixz>
          <iyy>0.01</iyy>
          <iyz>-6.2e-08</iyz>
          <izz>0.01</izz>
        </inertia>
      </inertial>
      <collision name='l_hip_2_collision'>
        <pose frame=''>0 0 0 0.785363 -1.57079 2.35623</pose>
        <geometry>
          <mesh>
            <scale>1 1 1</scale>
            <uri>model://icub/meshes/collision/icub_simple_collision_l_hip_2.dae</uri>
          </mesh>
        </geometry>
      </collision>
      <visual name='l_hip_2_visual'>
        <pose frame=''>0 0 0 0.785363 -1.57079 2.35623</pose>
        <geometry>
          <mesh>
            <scale>1 1 1</scale>
            <uri>model://icub/meshes/visual/icub_l_hip_2.dae</uri>
          </mesh>
        </geometry>
      </visual>
    </link>
    <joint name='l_hip_roll' type='revolute'>
      <child>l_hip_2</child>
      <parent>l_hip_1</parent>
      <axis>
        <xyz>-1 3e-06 7e-06</xyz>
        <limit>
          <lower>0</lower>
          <upper>1.5708</upper>
          <effort>84</effort>
          <velocity>100</velocity>
        </limit>
        <dynamics>
          <damping>1</damping>
          <friction>0</friction>
          <spring_reference>0</spring_reference>
          <spring_stiffness>0</spring_stiffness>
        </dynamics>
        <use_parent_model_frame>1</use_parent_model_frame>
      </axis>
    </joint>
    <link name='l_hip_3'>
      <pose frame=''>-0 -0.0681 -0.1864 3.14159 -7e-06 3.14159</pose>
      <inertial>
        <pose frame=''>0 0 0 0 -0 0</pose>
        <mass>0.1</mass>
        <inertia>
          <ixx>0.01</ixx>
          <ixy>0</ixy>
          <ixz>0</ixz>
          <iyy>0.01</iyy>
          <iyz>0</iyz>
          <izz>0.01</izz>
        </inertia>
      </inertial>
    </link>
    <joint name='l_leg_ft_sensor' type='revolute'>
      <child>l_hip_3</child>
      <parent>l_hip_2</parent>
      <axis>
        <limit>
          <lower>0</lower>
          <upper>0</upper>
        </limit>
        <dynamics>
          <damping>0</damping>
          <friction>0</friction>
          <spring_reference>0</spring_reference>
          <spring_stiffness>0</spring_stiffness>
        </dynamics>
        <use_parent_model_frame>1</use_parent_model_frame>
        <xyz>0 0 1</xyz>
      </axis>
      <physics>
        <ode>
          <limit>
            <cfm>0</cfm>
            <erp>0.2</erp>
          </limit>
        </ode>
      </physics>
      <sensor name='l_leg_ft_sensor' type='force_torque'>
        <always_on>1</always_on>
        <update_rate>100</update_rate>
        <force_torque>
          <frame>child</frame>
          <measure_direction>child_to_parent</measure_direction>
        </force_torque>
      </sensor>
    </joint>
    <link name='l_upper_leg'>
      <pose frame=''>0 -0.0681 -0.1199 1.57079 -7e-06 3.14159</pose>
      <inertial>
        <pose frame=''>0.00144 -0.15943 -0.00039 0 -0 0</pose>
        <mass>2.175</mass>
        <inertia>
          <ixx>0.01</ixx>
          <ixy>-6.726e-05</ixy>
          <ixz>2.267e-06</ixz>
          <iyy>0.01</iyy>
          <iyz>3.63726e-05</iyz>
          <izz>0.01</izz>
        </inertia>
      </inertial>
      <collision name='l_upper_leg_collision'>
        <pose frame=''>0 0 0 -2.67797 1.57079 -1.10716</pose>
        <geometry>
          <mesh>
            <scale>1 1 1</scale>
            <uri>model://icub/meshes/collision/icub_simple_collision_l_thigh.dae</uri>
          </mesh>
        </geometry>
        <surface>
          <contact>
            <ode/>
          </contact>
          <friction>
            <ode/>
          </friction>
        </surface>
      </collision>
      <visual name='l_upper_leg_visual'>
        <pose frame=''>0 0 0 -2.67797 1.57079 -1.10716</pose>
        <geometry>
          <mesh>
            <scale>1 1 1</scale>
            <uri>model://icub/meshes/visual/icub_l_thigh.dae</uri>
          </mesh>
        </geometry>
        <material>
          <script>
            <uri>__default__</uri>
            <name>__default__</name>
          </script>
        </material>
      </visual>
      <velocity_decay/>
      <sensor name='l_upper_leg_ems_acc_eb6' type='imu'>
        <always_on>1</always_on>
        <update_rate>100</update_rate>
        <pose frame=''>-0.040407 -0.083207 -0.012577 1.5708 0 -1.5708</pose>
        <plugin name='iCub_yarp_gazebo_plugin_ACC' filename='libgazebo_yarp_inertialmtb.so'/>
      </sensor>
      <velocity_decay/>
      <sensor name='l_upper_leg_ems_acc_eb10' type='imu'>
        <always_on>1</always_on>
        <update_rate>100</update_rate>
        <pose frame=''>0.040407 -0.040027 -0.012575 1.5708 -0 1.5708</pose>
        <plugin name='iCub_yarp_gazebo_plugin_ACC' filename='libgazebo_yarp_inertialmtb.so'/>
      </sensor>
      <velocity_decay/>
      <sensor name='l_upper_leg_ems_gyro_eb6' type='imu'>
        <always_on>1</always_on>
        <update_rate>100</update_rate>
        <pose frame=''>-0.040407 -0.087779 -0.013081 1.5708 0 -1.5708</pose>
      </sensor>
      <velocity_decay/>
      <sensor name='l_upper_leg_ems_gyro_eb10' type='imu'>
        <always_on>1</always_on>
        <update_rate>100</update_rate>
        <pose frame=''>0.040407 -0.035455 -0.013079 1.5708 -0 1.5708</pose>
      </sensor>
      <velocity_decay/>
      <sensor name='l_upper_leg_mtb_acc_10b1' type='imu'>
        <always_on>1</always_on>
        <update_rate>100</update_rate>
        <pose frame=''>0.031565 0.049332 0.042002 0.837758 -8.6e-05 1.57087</pose>
        <plugin name='iCub_yarp_gazebo_plugin_ACC' filename='libgazebo_yarp_inertialmtb.so'/>
      </sensor>
      <velocity_decay/>
      <sensor name='l_upper_leg_mtb_acc_10b2' type='imu'>
        <always_on>1</always_on>
        <update_rate>100</update_rate>
        <pose frame=''>0.008384 0.039452 0.053355 0.261799 -3e-05 1.57091</pose>
        <plugin name='iCub_yarp_gazebo_plugin_ACC' filename='libgazebo_yarp_inertialmtb.so'/>
      </sensor>
      <velocity_decay/>
      <sensor name='l_upper_leg_mtb_acc_10b3' type='imu'>
        <always_on>1</always_on>
        <update_rate>100</update_rate>
        <pose frame=''>0.015071 0.004382 0.053785 0 -0 1.5708</pose>
        <plugin name='iCub_yarp_gazebo_plugin_ACC' filename='libgazebo_yarp_inertialmtb.so'/>
      </sensor>
      <velocity_decay/>
      <sensor name='l_upper_leg_mtb_acc_10b4' type='imu'>
        <always_on>1</always_on>
        <update_rate>100</update_rate>
        <pose frame=''>-0.014429 0.004382 0.053785 0 -0 1.5708</pose>
        <plugin name='iCub_yarp_gazebo_plugin_ACC' filename='libgazebo_yarp_inertialmtb.so'/>
      </sensor>
      <velocity_decay/>
      <sensor name='l_upper_leg_mtb_acc_10b5' type='imu'>
        <always_on>1</always_on>
        <update_rate>100</update_rate>
        <pose frame=''>-0.0415 -0.004658 0.034129 -1.18682 -0 1.5708</pose>
        <plugin name='iCub_yarp_gazebo_plugin_ACC' filename='libgazebo_yarp_inertialmtb.so'/>
      </sensor>
      <velocity_decay/>
      <sensor name='l_upper_leg_mtb_acc_10b6' type='imu'>
        <always_on>1</always_on>
        <update_rate>100</update_rate>
        <pose frame=''>0.017809 -0.026212 -0.043785 -3.14159 -0 -1.57091</pose>
        <plugin name='iCub_yarp_gazebo_plugin_ACC' filename='libgazebo_yarp_inertialmtb.so'/>
      </sensor>
      <gravity>1</gravity>
      <velocity_decay/>
      <sensor name='l_upper_leg_mtb_acc_10b7' type='imu'>
        <always_on>1</always_on>
        <update_rate>100</update_rate>
        <pose frame=''>-0.014192 -0.026211 -0.043785 -3.14159 0 -1.57095</pose>
        <plugin name='iCub_yarp_gazebo_plugin_ACC' filename='libgazebo_yarp_inertialmtb.so'/>
      </sensor>
    </link>
    <joint name='l_hip_yaw' type='revolute'>
      <child>l_upper_leg</child>
      <parent>l_hip_3</parent>
      <axis>
        <xyz>7e-06 -6e-06 1</xyz>
        <limit>
          <lower>-1.37881</lower>
          <upper>1.37881</upper>
          <effort>40</effort>
          <velocity>100</velocity>
        </limit>
        <dynamics>
          <damping>1</damping>
          <friction>0</friction>
          <spring_reference>0</spring_reference>
          <spring_stiffness>0</spring_stiffness>
        </dynamics>
        <use_parent_model_frame>1</use_parent_model_frame>
      </axis>
    </joint>
    <link name='l_lower_leg'>
      <pose frame=''>-2e-06 -0.068099 -0.3435 2.09198 -1.57078 -0.521189</pose>
      <inertial>
        <pose frame=''>-0.1071 0.00182 0.00211 0 -0 0</pose>
        <mass>1.264</mass>
        <inertia>
          <ixx>0.01</ixx>
          <ixy>-0.000185699</ixy>
          <ixz>-6.3147e-05</ixz>
          <iyy>0.01</iyy>
          <iyz>7.86e-07</iyz>
          <izz>0.01</izz>
        </inertia>
      </inertial>
      <collision name='l_lower_leg_collision'>
        <pose frame=''>0 0 0 -3.14159 -0 1.5708</pose>
        <geometry>
          <mesh>
            <scale>1 1 1</scale>
            <uri>model://icub/meshes/collision/icub_simple_collision_l_shank.dae</uri>
          </mesh>
        </geometry>
        <surface>
          <contact>
            <ode/>
          </contact>
          <friction>
            <ode/>
          </friction>
        </surface>
      </collision>
      <visual name='l_lower_leg_visual'>
        <pose frame=''>0 0 0 -3.14159 -0 1.5708</pose>
        <geometry>
          <mesh>
            <scale>1 1 1</scale>
            <uri>model://icub/meshes/visual/icub_l_shank.dae</uri>
          </mesh>
        </geometry>
        <material>
          <script>
            <uri>__default__</uri>
            <name>__default__</name>
          </script>
        </material>
      </visual>
      <velocity_decay/>
      <sensor name='l_lower_leg_ems_acc_eb7' type='imu'>
        <always_on>1</always_on>
        <update_rate>100</update_rate>
        <pose frame=''>0.0249 -0.092765 0.043514 -0 -0.218167 1.5708</pose>
        <plugin name='iCub_yarp_gazebo_plugin_ACC' filename='libgazebo_yarp_inertialmtb.so'/>
      </sensor>
      <velocity_decay/>
      <sensor name='l_lower_leg_ems_gyro_eb7' type='imu'>
        <always_on>1</always_on>
        <update_rate>100</update_rate>
        <pose frame=''>0.025404 -0.088301 0.044503 -0 -0.218167 1.5708</pose>
      </sensor>
      <velocity_decay/>
      <sensor name='l_lower_leg_mtb_acc_10b8' type='imu'>
        <always_on>1</always_on>
        <update_rate>100</update_rate>
        <pose frame=''>0.03077 -0.004318 0.053133 0.244346 -0 1.5708</pose>
        <plugin name='iCub_yarp_gazebo_plugin_ACC' filename='libgazebo_yarp_inertialmtb.so'/>
      </sensor>
      <velocity_decay/>
      <sensor name='l_lower_leg_mtb_acc_10b9' type='imu'>
        <always_on>1</always_on>
        <update_rate>100</update_rate>
        <pose frame=''>-0.000214 -0.004318 0.054452 -0.349066 4e-05 1.5709</pose>
        <plugin name='iCub_yarp_gazebo_plugin_ACC' filename='libgazebo_yarp_inertialmtb.so'/>
      </sensor>
      <velocity_decay/>
      <sensor name='l_lower_leg_mtb_acc_10b10' type='imu'>
        <always_on>1</always_on>
        <update_rate>100</update_rate>
        <pose frame=''>0.05633 -0.043468 0.025915 1.309 -0.000112 1.57083</pose>
        <plugin name='iCub_yarp_gazebo_plugin_ACC' filename='libgazebo_yarp_inertialmtb.so'/>
      </sensor>
      <gravity>1</gravity>
      <velocity_decay/>
      <sensor name='l_lower_leg_mtb_acc_10b11' type='imu'>
        <always_on>1</always_on>
        <update_rate>100</update_rate>
        <pose frame=''>-0.028133 -0.092958 0.018459 -1.309 -2.5e-05 1.57079</pose>
        <plugin name='iCub_yarp_gazebo_plugin_ACC' filename='libgazebo_yarp_inertialmtb.so'/>
      </sensor>
    </link>
    <joint name='l_knee' type='revolute'>
      <child>l_lower_leg</child>
      <parent>l_upper_leg</parent>
      <axis>
        <xyz>5e-06 1 6e-06</xyz>
        <limit>
          <lower>-2.18166</lower>
          <upper>0.401426</upper>
          <effort>30</effort>
          <velocity>100</velocity>
        </limit>
        <dynamics>
          <damping>1</damping>
          <friction>0</friction>
          <spring_reference>0</spring_reference>
          <spring_stiffness>0</spring_stiffness>
        </dynamics>
        <use_parent_model_frame>1</use_parent_model_frame>
      </axis>
    </joint>
    <link name='l_ankle_1'>
      <pose frame=''>-4e-06 -0.068097 -0.5565 0.52118 -1.57078 -0.521189</pose>
      <inertial>
        <pose frame=''>-0.0054 0.00163 0.0172 0 -0 0</pose>
        <mass>0.746</mass>
        <inertia>
          <ixx>0.01</ixx>
          <ixy>-7.081e-06</ixy>
          <ixz>4.1421e-05</ixz>
          <iyy>0.01</iyy>
          <iyz>2.0817e-05</iyz>
          <izz>0.01</izz>
        </inertia>
      </inertial>
      <collision name='l_ankle_1_collision'>
        <pose frame=''>0 -0 0 1.5708 0 0</pose>
        <geometry>
          <mesh>
            <scale>1 1 1</scale>
            <uri>model://icub/meshes/collision/icub_simple_collision_l_ankle_1.dae</uri>
          </mesh>
        </geometry>
      </collision>
      <visual name='l_ankle_1_visual'>
        <pose frame=''>0 -0 0 1.5708 0 0</pose>
        <geometry>
          <mesh>
            <scale>1 1 1</scale>
            <uri>model://icub/meshes/visual/icub_l_ankle_1.dae</uri>
          </mesh>
        </geometry>
      </visual>
    </link>
    <joint name='l_ankle_pitch' type='revolute'>
      <child>l_ankle_1</child>
      <parent>l_lower_leg</parent>
      <axis>
        <xyz>-9e-06 -1 -6e-06</xyz>
        <limit>
          <lower>-0.733038</lower>
          <upper>0.366519</upper>
          <effort>24</effort>
          <velocity>100</velocity>
        </limit>
        <dynamics>
          <damping>1</damping>
          <friction>0</friction>
          <spring_reference>0</spring_reference>
          <spring_stiffness>0</spring_stiffness>
        </dynamics>
        <use_parent_model_frame>1</use_parent_model_frame>
      </axis>
    </joint>
    <link name='l_ankle_2'>
      <pose frame=''>-4e-06 -0.068097 -0.5565 3.14159 -7e-06 3.14158</pose>
      <inertial>
        <pose frame=''>0 0 0.037 0 -0 0</pose>
        <mass>0.2675</mass>
        <inertia>
          <ixx>0.01</ixx>
          <ixy>0</ixy>
          <ixz>0</ixz>
          <iyy>0.01</iyy>
          <iyz>0</iyz>
          <izz>0.01</izz>
        </inertia>
      </inertial>
    </link>
    <joint name='l_ankle_roll' type='revolute'>
      <child>l_ankle_2</child>
      <parent>l_ankle_1</parent>
      <axis>
        <xyz>-1 9e-06 7e-06</xyz>
        <limit>
          <lower>-0.418879</lower>
          <upper>0.418879</upper>
          <effort>11</effort>
          <velocity>100</velocity>
        </limit>
        <dynamics>
          <damping>1</damping>
          <friction>0</friction>
          <spring_reference>0</spring_reference>
          <spring_stiffness>0</spring_stiffness>
        </dynamics>
        <use_parent_model_frame>1</use_parent_model_frame>
      </axis>
    </joint>
    <link name='l_foot'>
      <pose frame=''>-4e-06 -0.068097 -0.5935 3.14159 -7e-06 3.14158</pose>
      <inertial>
        <pose frame=''>0.024069 -0.000614 -0.028415 0 -0 0</pose>
        <mass>0.5935</mass>
        <inertia>
          <ixx>0.01</ixx>
          <ixy>-4.51893e-06</ixy>
          <ixz>0.000567785</ixz>
          <iyy>0.01</iyy>
          <iyz>-6.62361e-07</iyz>
          <izz>0.01</izz>
        </inertia>
      </inertial>
      <collision name='l_foot_collision'>
        <pose frame=''>0 -0 -0.037 -0.785403 1.57079 -0.785403</pose>
        <geometry>
          <mesh>
            <scale>1 1 1</scale>
            <uri>model://icub/meshes/collision/icub_simple_collision_l_foot.dae</uri>
          </mesh>
        </geometry>
        <surface>
          <contact>
            <ode/>
          </contact>
          <friction>
            <ode/>
          </friction>
        </surface>
      </collision>
      <visual name='l_foot_visual'>
        <pose frame=''>0 -0 -0.037 -0.785403 1.57079 -0.785403</pose>
        <geometry>
          <mesh>
            <scale>1 1 1</scale>
            <uri>model://icub/meshes/visual/icub_l_foot.dae</uri>
          </mesh>
        </geometry>
        <material>
          <script>
            <uri>__default__</uri>
            <name>__default__</name>
          </script>
        </material>
      </visual>
      <velocity_decay/>
      <sensor name='l_foot_mtb_acc_10b12' type='imu'>
        <always_on>1</always_on>
        <update_rate>100</update_rate>
        <pose frame=''>0.105522 0.000807 -0.001215 0 -0 1.5708</pose>
        <plugin name='iCub_yarp_gazebo_plugin_ACC' filename='libgazebo_yarp_inertialmtb.so'/>
      </sensor>
      <gravity>1</gravity>
      <velocity_decay/>
      <sensor name='l_foot_mtb_acc_10b13' type='imu'>
        <always_on>1</always_on>
        <update_rate>100</update_rate>
        <pose frame=''>0.080522 0.011807 -0.001215 0 -0 1.5708</pose>
        <plugin name='iCub_yarp_gazebo_plugin_ACC' filename='libgazebo_yarp_inertialmtb.so'/>
      </sensor>
    </link>
    <joint name='l_foot_ft_sensor' type='revolute'>
      <child>l_foot</child>
      <parent>l_ankle_2</parent>
      <axis>
        <limit>
          <lower>0</lower>
          <upper>0</upper>
        </limit>
        <dynamics>
          <damping>0</damping>
          <friction>0</friction>
          <spring_reference>0</spring_reference>
          <spring_stiffness>0</spring_stiffness>
        </dynamics>
        <use_parent_model_frame>1</use_parent_model_frame>
        <xyz>0 0 1</xyz>
      </axis>
      <physics>
        <ode>
          <limit>
            <cfm>0</cfm>
            <erp>0.2</erp>
          </limit>
        </ode>
      </physics>
      <sensor name='l_foot_ft_sensor' type='force_torque'>
        <always_on>1</always_on>
        <update_rate>100</update_rate>
        <force_torque>
          <frame>child</frame>
          <measure_direction>child_to_parent</measure_direction>
        </force_torque>
      </sensor>
    </joint>
    <link name='r_hip_1'>
      <pose frame=''>0 0.0681 -0.1199 3.14159 1.57079 -3.14159</pose>
      <inertial>
        <pose frame=''>0 -0.0782 0 0 -0 0</pose>
        <mass>0.754</mass>
        <inertia>
          <ixx>0.01</ixx>
          <ixy>0</ixy>
          <ixz>0</ixz>
          <iyy>0.01</iyy>
          <iyz>0</iyz>
          <izz>0.01</izz>
        </inertia>
      </inertial>
      <collision name='r_hip_1_collision'>
        <pose frame=''>0 0 0 1.76819 -1.57079 2.76109</pose>
        <geometry>
          <mesh>
            <scale>1 1 1</scale>
            <uri>model://icub/meshes/collision/icub_simple_collision_r_hip_1.dae</uri>
          </mesh>
        </geometry>
      </collision>
      <visual name='r_hip_1_visual'>
        <pose frame=''>0 0 0 1.76819 -1.57079 2.76109</pose>
        <geometry>
          <mesh>
            <scale>1 1 1</scale>
            <uri>model://icub/meshes/visual/icub_r_hip_1.dae</uri>
          </mesh>
        </geometry>
      </visual>
    </link>
    <joint name='r_hip_pitch' type='revolute'>
      <child>r_hip_1</child>
      <parent>root_link</parent>
      <axis>
        <xyz>0 1 -0</xyz>
        <limit>
          <lower>-0.767945</lower>
          <upper>2.30383</upper>
          <effort>84</effort>
          <velocity>100</velocity>
        </limit>
        <dynamics>
          <damping>1</damping>
          <friction>0</friction>
          <spring_reference>0</spring_reference>
          <spring_stiffness>0</spring_stiffness>
        </dynamics>
        <use_parent_model_frame>1</use_parent_model_frame>
      </axis>
    </joint>
    <link name='r_hip_2'>
      <pose frame=''>0 0.0681 -0.1199 -3.14159 -7e-06 -3.14159</pose>
      <inertial>
        <pose frame=''>0 0 0.03045 0 -0 0</pose>
        <mass>0.526</mass>
        <inertia>
          <ixx>0.01</ixx>
          <ixy>0</ixy>
          <ixz>0</ixz>
          <iyy>0.01</iyy>
          <iyz>0</iyz>
          <izz>0.01</izz>
        </inertia>
      </inertial>
      <collision name='r_hip_2_collision'>
        <pose frame=''>0 0 0 -2.35627 -1.57079 2.35627</pose>
        <geometry>
          <mesh>
            <scale>1 1 1</scale>
            <uri>model://icub/meshes/collision/icub_simple_collision_r_hip_2.dae</uri>
          </mesh>
        </geometry>
      </collision>
      <visual name='r_hip_2_visual'>
        <pose frame=''>0 0 0 -2.35627 -1.57079 2.35627</pose>
        <geometry>
          <mesh>
            <scale>1 1 1</scale>
            <uri>model://icub/meshes/visual/icub_r_hip_2.dae</uri>
          </mesh>
        </geometry>
      </visual>
    </link>
    <joint name='r_hip_roll' type='revolute'>
      <child>r_hip_2</child>
      <parent>r_hip_1</parent>
      <axis>
        <xyz>1 0 -7e-06</xyz>
        <limit>
          <lower>0</lower>
          <upper>1.5708</upper>
          <effort>84</effort>
          <velocity>100</velocity>
        </limit>
        <dynamics>
          <damping>1</damping>
          <friction>0</friction>
          <spring_reference>0</spring_reference>
          <spring_stiffness>0</spring_stiffness>
        </dynamics>
        <use_parent_model_frame>1</use_parent_model_frame>
      </axis>
    </joint>
    <link name='r_hip_3'>
      <pose frame=''>-0 0.0681 -0.1864 -3.14159 -7e-06 -3.14159</pose>
      <inertial>
        <pose frame=''>0 0 0 0 -0 0</pose>
        <mass>0.1</mass>
        <inertia>
          <ixx>0.01</ixx>
          <ixy>0</ixy>
          <ixz>0</ixz>
          <iyy>0.01</iyy>
          <iyz>0</iyz>
          <izz>0.01</izz>
        </inertia>
      </inertial>
    </link>
    <joint name='r_leg_ft_sensor' type='revolute'>
      <child>r_hip_3</child>
      <parent>r_hip_2</parent>
      <axis>
        <limit>
          <lower>0</lower>
          <upper>0</upper>
        </limit>
        <dynamics>
          <damping>0</damping>
          <friction>0</friction>
          <spring_reference>0</spring_reference>
          <spring_stiffness>0</spring_stiffness>
        </dynamics>
        <use_parent_model_frame>1</use_parent_model_frame>
        <xyz>0 0 1</xyz>
      </axis>
      <physics>
        <ode>
          <limit>
            <cfm>0</cfm>
            <erp>0.2</erp>
          </limit>
        </ode>
      </physics>
      <sensor name='r_leg_ft_sensor' type='force_torque'>
        <always_on>1</always_on>
        <update_rate>100</update_rate>
        <force_torque>
          <frame>child</frame>
          <measure_direction>child_to_parent</measure_direction>
        </force_torque>
      </sensor>
    </joint>
    <link name='r_upper_leg'>
      <pose frame=''>0 0.0681 -0.1199 1.57079 -7e-06 3.14159</pose>
      <inertial>
        <pose frame=''>0.00144 -0.15943 0.00039 0 -0 0</pose>
        <mass>2.175</mass>
        <inertia>
          <ixx>0.01</ixx>
          <ixy>0</ixy>
          <ixz>0</ixz>
          <iyy>0.01</iyy>
          <iyz>-2.71051e-20</iyz>
          <izz>0.01</izz>
        </inertia>
      </inertial>
      <collision name='r_upper_leg_collision'>
        <pose frame=''>0 0 0 1.57087 -1.57079 -7.3e-05</pose>
        <geometry>
          <mesh>
            <scale>1 1 1</scale>
            <uri>model://icub/meshes/collision/icub_simple_collision_r_thigh.dae</uri>
          </mesh>
        </geometry>
        <surface>
          <contact>
            <ode/>
          </contact>
          <friction>
            <ode/>
          </friction>
        </surface>
      </collision>
      <visual name='r_upper_leg_visual'>
        <pose frame=''>0 0 0 1.57087 -1.57079 -7.3e-05</pose>
        <geometry>
          <mesh>
            <scale>1 1 1</scale>
            <uri>model://icub/meshes/visual/icub_r_thigh.dae</uri>
          </mesh>
        </geometry>
        <material>
          <script>
            <uri>__default__</uri>
            <name>__default__</name>
          </script>
        </material>
      </visual>
      <velocity_decay/>
      <sensor name='r_upper_leg_ems_acc_eb8' type='imu'>
        <always_on>1</always_on>
        <update_rate>100</update_rate>
        <pose frame=''>0.040407 -0.040027 -0.012575 1.5708 0 -1.5708</pose>
        <plugin name='iCub_yarp_gazebo_plugin_ACC' filename='libgazebo_yarp_inertialmtb.so'/>
      </sensor>
      <velocity_decay/>
      <sensor name='r_upper_leg_ems_acc_eb11' type='imu'>
        <always_on>1</always_on>
        <update_rate>100</update_rate>
        <pose frame=''>-0.040407 -0.083207 -0.012577 1.5708 0 -1.5708</pose>
        <plugin name='iCub_yarp_gazebo_plugin_ACC' filename='libgazebo_yarp_inertialmtb.so'/>
      </sensor>
      <velocity_decay/>
      <sensor name='r_upper_leg_ems_gyro_eb8' type='imu'>
        <always_on>1</always_on>
        <update_rate>100</update_rate>
        <pose frame=''>0.040407 -0.035455 -0.013079 1.5708 0 -1.5708</pose>
      </sensor>
      <velocity_decay/>
      <sensor name='r_upper_leg_ems_gyro_eb11' type='imu'>
        <always_on>1</always_on>
        <update_rate>100</update_rate>
        <pose frame=''>-0.040407 -0.087779 -0.013081 1.5708 0 -1.5708</pose>
      </sensor>
      <velocity_decay/>
      <sensor name='r_upper_leg_mtb_acc_11b1' type='imu'>
        <always_on>1</always_on>
        <update_rate>100</update_rate>
        <pose frame=''>-0.030195 0.04914 0.043589 -0.837758 -0.000343 1.57087</pose>
        <plugin name='iCub_yarp_gazebo_plugin_ACC' filename='libgazebo_yarp_inertialmtb.so'/>
      </sensor>
      <velocity_decay/>
      <sensor name='r_upper_leg_mtb_acc_11b2' type='imu'>
        <always_on>1</always_on>
        <update_rate>100</update_rate>
        <pose frame=''>-0.006407 0.039256 0.053947 -0.261799 -0.000399 1.57091</pose>
        <plugin name='iCub_yarp_gazebo_plugin_ACC' filename='libgazebo_yarp_inertialmtb.so'/>
      </sensor>
      <velocity_decay/>
      <sensor name='r_upper_leg_mtb_acc_11b3' type='imu'>
        <always_on>1</always_on>
        <update_rate>100</update_rate>
        <pose frame=''>-0.013021 0.004186 0.053831 -0 -0.000429 1.57091</pose>
        <plugin name='iCub_yarp_gazebo_plugin_ACC' filename='libgazebo_yarp_inertialmtb.so'/>
      </sensor>
      <velocity_decay/>
      <sensor name='r_upper_leg_mtb_acc_11b4' type='imu'>
        <always_on>1</always_on>
        <update_rate>100</update_rate>
        <pose frame=''>0.042268 -0.004845 0.032272 1.18682 -0.000537 1.57084</pose>
        <plugin name='iCub_yarp_gazebo_plugin_ACC' filename='libgazebo_yarp_inertialmtb.so'/>
      </sensor>
      <velocity_decay/>
      <sensor name='r_upper_leg_mtb_acc_11b5' type='imu'>
        <always_on>1</always_on>
        <update_rate>100</update_rate>
        <pose frame=''>0.016479 0.004186 0.053831 -0 -0.000429 1.57091</pose>
        <plugin name='iCub_yarp_gazebo_plugin_ACC' filename='libgazebo_yarp_inertialmtb.so'/>
      </sensor>
      <velocity_decay/>
      <sensor name='r_upper_leg_mtb_acc_11b6' type='imu'>
        <always_on>1</always_on>
        <update_rate>100</update_rate>
        <pose frame=''>-0.015759 -0.026365 -0.043752 -3.14159 0.000429 -1.5708</pose>
        <plugin name='iCub_yarp_gazebo_plugin_ACC' filename='libgazebo_yarp_inertialmtb.so'/>
      </sensor>
      <gravity>1</gravity>
      <velocity_decay/>
      <sensor name='r_upper_leg_mtb_acc_11b7' type='imu'>
        <always_on>1</always_on>
        <update_rate>100</update_rate>
        <pose frame=''>0.016239 -0.026366 -0.043752 3.14159 0.000429 -1.57091</pose>
        <plugin name='iCub_yarp_gazebo_plugin_ACC' filename='libgazebo_yarp_inertialmtb.so'/>
      </sensor>
    </link>
    <joint name='r_hip_yaw' type='revolute'>
      <child>r_upper_leg</child>
      <parent>r_hip_3</parent>
      <axis>
        <xyz>-7e-06 4e-06 -1</xyz>
        <limit>
          <lower>-1.37881</lower>
          <upper>1.37881</upper>
          <effort>40</effort>
          <velocity>100</velocity>
        </limit>
        <dynamics>
          <damping>1</damping>
          <friction>0</friction>
          <spring_reference>0</spring_reference>
          <spring_stiffness>0</spring_stiffness>
        </dynamics>
        <use_parent_model_frame>1</use_parent_model_frame>
      </axis>
    </joint>
    <link name='r_lower_leg'>
      <pose frame=''>-2e-06 0.068101 -0.3435 1.89254 -1.57078 -0.321751</pose>
      <inertial>
        <pose frame=''>-0.1071 0.00182 -0.00211 0 -0 0</pose>
        <mass>1.264</mass>
        <inertia>
          <ixx>0.01</ixx>
          <ixy>5.42101e-20</ixy>
          <ixz>-5.42101e-20</ixz>
          <iyy>0.01</iyy>
          <iyz>8.47033e-22</iyz>
          <izz>0.01</izz>
        </inertia>
      </inertial>
      <collision name='r_lower_leg_collision'>
        <pose frame=''>0 0 -0 3.14159 -0 1.5708</pose>
        <geometry>
          <mesh>
            <scale>1 1 1</scale>
            <uri>model://icub/meshes/collision/icub_simple_collision_r_shank.dae</uri>
          </mesh>
        </geometry>
        <surface>
          <contact>
            <ode/>
          </contact>
          <friction>
            <ode/>
          </friction>
        </surface>
      </collision>
      <visual name='r_lower_leg_visual'>
        <pose frame=''>0 0 -0 3.14159 -0 1.5708</pose>
        <geometry>
          <mesh>
            <scale>1 1 1</scale>
            <uri>model://icub/meshes/visual/icub_r_shank.dae</uri>
          </mesh>
        </geometry>
        <material>
          <script>
            <uri>__default__</uri>
            <name>__default__</name>
          </script>
        </material>
      </visual>
      <velocity_decay/>
      <sensor name='r_lower_leg_ems_acc_eb9' type='imu'>
        <always_on>1</always_on>
        <update_rate>100</update_rate>
        <pose frame=''>0.023507 -0.092765 0.043514 -0 -0.218167 1.5708</pose>
        <plugin name='iCub_yarp_gazebo_plugin_ACC' filename='libgazebo_yarp_inertialmtb.so'/>
      </sensor>
      <velocity_decay/>
      <sensor name='r_lower_leg_ems_gyro_eb9' type='imu'>
        <always_on>1</always_on>
        <update_rate>100</update_rate>
        <pose frame=''>0.024011 -0.088301 0.044503 -0 -0.218167 1.5708</pose>
      </sensor>
      <velocity_decay/>
      <sensor name='r_lower_leg_mtb_acc_11b8' type='imu'>
        <always_on>1</always_on>
        <update_rate>100</update_rate>
        <pose frame=''>-0.005528 -0.004318 0.053629 -0.244346 2.8e-05 1.57091</pose>
        <plugin name='iCub_yarp_gazebo_plugin_ACC' filename='libgazebo_yarp_inertialmtb.so'/>
      </sensor>
      <velocity_decay/>
      <sensor name='r_lower_leg_mtb_acc_11b9' type='imu'>
        <always_on>1</always_on>
        <update_rate>100</update_rate>
        <pose frame=''>0.02539 -0.004318 0.053752 0.349066 -4e-05 1.5709</pose>
        <plugin name='iCub_yarp_gazebo_plugin_ACC' filename='libgazebo_yarp_inertialmtb.so'/>
      </sensor>
      <velocity_decay/>
      <sensor name='r_lower_leg_mtb_acc_11b10' type='imu'>
        <always_on>1</always_on>
        <update_rate>100</update_rate>
        <pose frame=''>-0.032547 -0.043468 0.027895 -1.309 0 1.5708</pose>
        <plugin name='iCub_yarp_gazebo_plugin_ACC' filename='libgazebo_yarp_inertialmtb.so'/>
      </sensor>
      <gravity>1</gravity>
      <velocity_decay/>
      <sensor name='r_lower_leg_mtb_acc_11b11' type='imu'>
        <always_on>1</always_on>
        <update_rate>100</update_rate>
        <pose frame=''>0.051917 -0.092958 0.01648 1.309 -0.000112 1.57083</pose>
        <plugin name='iCub_yarp_gazebo_plugin_ACC' filename='libgazebo_yarp_inertialmtb.so'/>
      </sensor>
    </link>
    <joint name='r_knee' type='revolute'>
      <child>r_lower_leg</child>
      <parent>r_upper_leg</parent>
      <axis>
        <xyz>3e-06 1 4e-06</xyz>
        <limit>
          <lower>-2.18166</lower>
          <upper>0.401426</upper>
          <effort>30</effort>
          <velocity>100</velocity>
        </limit>
        <dynamics>
          <damping>1</damping>
          <friction>0</friction>
          <spring_reference>0</spring_reference>
          <spring_stiffness>0</spring_stiffness>
        </dynamics>
        <use_parent_model_frame>1</use_parent_model_frame>
      </axis>
    </joint>
    <link name='r_ankle_1'>
      <pose frame=''>-4e-06 0.068102 -0.5565 -2.81984 -1.57078 -0.321751</pose>
      <inertial>
        <pose frame=''>-0.0054 0.00163 -0.0172 0 -0 0</pose>
        <mass>0.746</mass>
        <inertia>
          <ixx>0.01</ixx>
          <ixy>-1.69407e-21</ixy>
          <ixz>1.35525e-20</ixz>
          <iyy>0.01</iyy>
          <iyz>3.38813e-21</iyz>
          <izz>0.01</izz>
        </inertia>
      </inertial>
      <collision name='r_ankle_1_collision'>
        <pose frame=''>0 -0 -0 -1.5708 -0 0</pose>
        <geometry>
          <mesh>
            <scale>1 1 1</scale>
            <uri>model://icub/meshes/collision/icub_simple_collision_r_ankle_1.dae</uri>
          </mesh>
        </geometry>
      </collision>
      <visual name='r_ankle_1_visual'>
        <pose frame=''>0 -0 -0 -1.5708 -0 0</pose>
        <geometry>
          <mesh>
            <scale>1 1 1</scale>
            <uri>model://icub/meshes/visual/icub_r_ankle_1.dae</uri>
          </mesh>
        </geometry>
      </visual>
    </link>
    <joint name='r_ankle_pitch' type='revolute'>
      <child>r_ankle_1</child>
      <parent>r_lower_leg</parent>
      <axis>
        <xyz>1e-06 -1 -4e-06</xyz>
        <limit>
          <lower>-0.733038</lower>
          <upper>0.366519</upper>
          <effort>24</effort>
          <velocity>100</velocity>
        </limit>
        <dynamics>
          <damping>1</damping>
          <friction>0</friction>
          <spring_reference>0</spring_reference>
          <spring_stiffness>0</spring_stiffness>
        </dynamics>
        <use_parent_model_frame>1</use_parent_model_frame>
      </axis>
    </joint>
    <link name='r_ankle_2'>
      <pose frame=''>-4e-06 0.068102 -0.5565 3.14159 -1.4e-05 -3.14159</pose>
      <inertial>
        <pose frame=''>0 0 0.037 0 -0 0</pose>
        <mass>0.2675</mass>
        <inertia>
          <ixx>0.01</ixx>
          <ixy>0</ixy>
          <ixz>0</ixz>
          <iyy>0.01</iyy>
          <iyz>0</iyz>
          <izz>0.01</izz>
        </inertia>
      </inertial>
    </link>
    <joint name='r_ankle_roll' type='revolute'>
      <child>r_ankle_2</child>
      <parent>r_ankle_1</parent>
      <axis>
        <xyz>1 3e-06 -1.4e-05</xyz>
        <limit>
          <lower>-0.418879</lower>
          <upper>0.418879</upper>
          <effort>11</effort>
          <velocity>100</velocity>
        </limit>
        <dynamics>
          <damping>1</damping>
          <friction>0</friction>
          <spring_reference>0</spring_reference>
          <spring_stiffness>0</spring_stiffness>
        </dynamics>
        <use_parent_model_frame>1</use_parent_model_frame>
      </axis>
    </joint>
    <link name='r_foot'>
      <pose frame=''>-5e-06 0.068102 -0.5935 3.14159 -1.4e-05 -3.14159</pose>
      <inertial>
        <pose frame=''>0.024069 0.000614 -0.028415 0 -0 0</pose>
        <mass>0.5935</mass>
        <inertia>
          <ixx>0.01</ixx>
          <ixy>4.51893e-06</ixy>
          <ixz>0.000567784</ixz>
          <iyy>0.01</iyy>
          <iyz>6.62535e-07</iyz>
          <izz>0.01</izz>
        </inertia>
      </inertial>
      <collision name='r_foot_collision'>
        <pose frame=''>0 0 -0.037 -2.81983 1.57079 0.321763</pose>
        <geometry>
          <mesh>
            <scale>1 1 1</scale>
            <uri>model://icub/meshes/collision/icub_simple_collision_r_foot.dae</uri>
          </mesh>
        </geometry>
        <surface>
          <contact>
            <ode/>
          </contact>
          <friction>
            <ode/>
          </friction>
        </surface>
      </collision>
      <visual name='r_foot_visual'>
        <pose frame=''>0 0 -0.037 -2.81983 1.57079 0.321763</pose>
        <geometry>
          <mesh>
            <scale>1 1 1</scale>
            <uri>model://icub/meshes/visual/icub_r_foot.dae</uri>
          </mesh>
        </geometry>
        <material>
          <script>
            <uri>__default__</uri>
            <name>__default__</name>
          </script>
        </material>
      </visual>
      <velocity_decay/>
      <sensor name='r_foot_mtb_acc_11b12' type='imu'>
        <always_on>1</always_on>
        <update_rate>100</update_rate>
        <pose frame=''>0.103474 -0.000807 -0.001215 0 0 -1.5708</pose>
        <plugin name='iCub_yarp_gazebo_plugin_ACC' filename='libgazebo_yarp_inertialmtb.so'/>
      </sensor>
      <gravity>1</gravity>
      <velocity_decay/>
      <sensor name='r_foot_mtb_acc_11b13' type='imu'>
        <always_on>1</always_on>
        <update_rate>100</update_rate>
        <pose frame=''>0.078474 -0.011807 -0.001215 0 0 -1.5708</pose>
        <plugin name='iCub_yarp_gazebo_plugin_ACC' filename='libgazebo_yarp_inertialmtb.so'/>
      </sensor>
    </link>
    <joint name='r_foot_ft_sensor' type='revolute'>
      <child>r_foot</child>
      <parent>r_ankle_2</parent>
      <axis>
        <limit>
          <lower>0</lower>
          <upper>0</upper>
        </limit>
        <dynamics>
          <damping>0</damping>
          <friction>0</friction>
          <spring_reference>0</spring_reference>
          <spring_stiffness>0</spring_stiffness>
        </dynamics>
        <use_parent_model_frame>1</use_parent_model_frame>
        <xyz>0 0 1</xyz>
      </axis>
      <physics>
        <ode>
          <limit>
            <cfm>0</cfm>
            <erp>0.2</erp>
          </limit>
        </ode>
      </physics>
      <sensor name='r_foot_ft_sensor' type='force_torque'>
        <always_on>1</always_on>
        <update_rate>100</update_rate>
        <force_torque>
          <frame>child</frame>
          <measure_direction>child_to_parent</measure_direction>
        </force_torque>
      </sensor>
    </joint>
    <link name='torso_1'>
      <pose frame=''>0 0 0 -3.14159 -1.57079 -3e-06</pose>
      <inertial>
        <pose frame=''>0 0 0 0 -0 0</pose>
        <mass>0.1</mass>
        <inertia>
          <ixx>0.01</ixx>
          <ixy>-4.263e-05</ixy>
          <ixz>-3.889e-08</ixz>
          <iyy>0.01</iyy>
          <iyz>0</iyz>
          <izz>0.01</izz>
        </inertia>
      </inertial>
      <collision name='torso_1_collision'>
        <pose frame=''>0 0 0 -1.5708 0 0</pose>
        <geometry>
          <mesh>
            <scale>1 1 1</scale>
            <uri>model://icub/meshes/collision/icub_simple_collision_lap_belt_1.dae</uri>
          </mesh>
        </geometry>
      </collision>
      <visual name='torso_1_visual'>
        <pose frame=''>0 0 0 -1.5708 0 0</pose>
        <geometry>
          <mesh>
            <scale>1 1 1</scale>
            <uri>model://icub/meshes/visual/icub_lap_belt_1.dae</uri>
          </mesh>
        </geometry>
      </visual>
    </link>
    <joint name='torso_pitch' type='revolute'>
      <child>torso_1</child>
      <parent>root_link</parent>
      <axis>
        <xyz>-3e-06 -1 -0</xyz>
        <limit>
          <lower>-0.383972</lower>
          <upper>1.46608</upper>
          <effort>36</effort>
          <velocity>100</velocity>
        </limit>
        <dynamics>
          <damping>1</damping>
          <friction>0</friction>
          <spring_reference>0</spring_reference>
          <spring_stiffness>0</spring_stiffness>
        </dynamics>
        <use_parent_model_frame>1</use_parent_model_frame>
      </axis>
    </joint>
    <link name='torso_2'>
      <pose frame=''>0 -0 0.032 -3.14159 4e-06 1.57079</pose>
      <inertial>
        <pose frame=''>0 0 0 0 -0 0</pose>
        <mass>0.1</mass>
        <inertia>
          <ixx>0.01</ixx>
          <ixy>-1.923e-06</ixy>
          <ixz>5.095e-05</ixz>
          <iyy>0.01</iyy>
          <iyz>-3.849e-07</iyz>
          <izz>0.01</izz>
        </inertia>
      </inertial>
    </link>
    <joint name='torso_roll' type='revolute'>
      <child>torso_2</child>
      <parent>torso_1</parent>
      <axis>
        <xyz>1 -3e-06 -7e-06</xyz>
        <limit>
          <lower>-0.680678</lower>
          <upper>0.680678</upper>
          <effort>80</effort>
          <velocity>100</velocity>
        </limit>
        <dynamics>
          <damping>1</damping>
          <friction>0</friction>
          <spring_reference>0</spring_reference>
          <spring_stiffness>0</spring_stiffness>
        </dynamics>
        <use_parent_model_frame>1</use_parent_model_frame>
      </axis>
    </joint>
    <link name='chest'>
      <pose frame=''>-0.0055 0 0.032 1.5708 -7e-06 -3.14159</pose>
      <inertial>
        <pose frame=''>0.002229 0.075 -0 0 -0 0</pose>
        <mass>4.81</mass>
        <inertia>
          <ixx>0.07472</ixx>
          <ixy>-3.6e-06</ixy>
          <ixz>-4.705e-05</ixz>
          <iyy>0.08145</iyy>
          <iyz>0.004567</iyz>
          <izz>0.01306</izz>
        </inertia>
      </inertial>
      <collision name='chest_collision'>
        <pose frame=''>-0.0055 -0 -0 -1.10717 -1.57079 2.67798</pose>
        <geometry>
          <mesh>
            <scale>1 1 1</scale>
            <uri>model://icub/meshes/collision/icub_simple_collision_chest.dae</uri>
          </mesh>
        </geometry>
        <surface>
          <contact>
            <ode/>
          </contact>
          <friction>
            <ode/>
          </friction>
        </surface>
      </collision>
      <visual name='chest_visual'>
        <pose frame=''>-0.0055 -0 -0 -1.10717 -1.57079 2.67798</pose>
        <geometry>
          <mesh>
            <scale>1 1 1</scale>
            <uri>model://icub/meshes/visual/icub_chest.dae</uri>
          </mesh>
        </geometry>
        <material>
          <script>
            <uri>__default__</uri>
            <name>__default__</name>
          </script>
        </material>
      </visual>
      <velocity_decay/>
      <sensor name='chest_ems_acc_eb1' type='imu'>
        <always_on>1</always_on>
        <update_rate>100</update_rate>
        <pose frame=''>0.064786 0.064043 -0.064709 3.14152 -0.261799 0.000293</pose>
        <plugin name='iCub_yarp_gazebo_plugin_ACC' filename='libgazebo_yarp_inertialmtb.so'/>
      </sensor>
      <velocity_decay/>
      <sensor name='chest_ems_gyro_eb1' type='imu'>
        <always_on>1</always_on>
        <update_rate>100</update_rate>
        <pose frame=''>0.069202 0.064548 -0.063526 3.14152 -0.261799 0.000293</pose>
      </sensor>
      <velocity_decay/>
      <sensor name='chest_ems_acc_eb2' type='imu'>
        <always_on>1</always_on>
        <update_rate>100</update_rate>
        <pose frame=''>0.020453 0.088063 -0.064165 3.14159 0.261799 3.14158</pose>
        <plugin name='iCub_yarp_gazebo_plugin_ACC' filename='libgazebo_yarp_inertialmtb.so'/>
      </sensor>
      <velocity_decay/>
      <sensor name='chest_ems_gyro_eb2' type='imu'>
        <always_on>1</always_on>
        <update_rate>100</update_rate>
        <pose frame=''>0.016037 0.087559 -0.065348 3.14159 0.261799 3.14158</pose>
      </sensor>
      <velocity_decay/>
      <sensor name='chest_ems_acc_eb3' type='imu'>
        <always_on>1</always_on>
        <update_rate>100</update_rate>
        <pose frame=''>-0.023059 0.064019 -0.075899 3.14111 0.261101 -0.000309</pose>
        <plugin name='iCub_yarp_gazebo_plugin_ACC' filename='libgazebo_yarp_inertialmtb.so'/>
      </sensor>
      <velocity_decay/>
      <sensor name='chest_ems_gyro_eb3' type='imu'>
        <always_on>1</always_on>
        <update_rate>100</update_rate>
        <pose frame=''>-0.018642 0.064521 -0.077079 3.14111 0.261101 -0.000309</pose>
      </sensor>
      <velocity_decay/>
      <sensor name='chest_ems_acc_eb4' type='imu'>
        <always_on>1</always_on>
        <update_rate>100</update_rate>
        <pose frame=''>-0.062162 0.088063 -0.052989 -3.14159 -0.261799 3.14158</pose>
        <plugin name='iCub_yarp_gazebo_plugin_ACC' filename='libgazebo_yarp_inertialmtb.so'/>
      </sensor>
      <velocity_decay/>
      <sensor name='chest_ems_gyro_eb4' type='imu'>
        <always_on>1</always_on>
        <update_rate>100</update_rate>
        <pose frame=''>-0.066578 0.087559 -0.051805 -3.14159 -0.261799 3.14158</pose>
      </sensor>
      <velocity_decay/>
      <sensor name='chest_mtb_acc_0b7' type='imu'>
        <always_on>1</always_on>
        <update_rate>100</update_rate>
        <pose frame=''>-0.060754 -0.001784 0.044234 0.875168 0.116364 -1.48597</pose>
        <plugin name='iCub_yarp_gazebo_plugin_ACC' filename='libgazebo_yarp_inertialmtb.so'/>
      </sensor>
      <velocity_decay/>
      <sensor name='chest_mtb_acc_0b8' type='imu'>
        <always_on>1</always_on>
        <update_rate>100</update_rate>
        <pose frame=''>-0.045705 -0.001846 0.056743 0.50096 0.107314 -1.47783</pose>
        <plugin name='iCub_yarp_gazebo_plugin_ACC' filename='libgazebo_yarp_inertialmtb.so'/>
      </sensor>
      <velocity_decay/>
      <sensor name='chest_mtb_acc_0b9' type='imu'>
        <always_on>1</always_on>
        <update_rate>100</update_rate>
        <pose frame=''>0.043904 -0.001784 0.057722 -0.50096 0.107315 -1.66376</pose>
        <plugin name='iCub_yarp_gazebo_plugin_ACC' filename='libgazebo_yarp_inertialmtb.so'/>
      </sensor>
      <gravity>1</gravity>
      <velocity_decay/>
      <sensor name='chest_mtb_acc_0b10' type='imu'>
        <always_on>1</always_on>
        <update_rate>100</update_rate>
        <pose frame=''>0.059429 -0.001854 0.045798 -0.875168 0.116362 -1.65562</pose>
        <plugin name='iCub_yarp_gazebo_plugin_ACC' filename='libgazebo_yarp_inertialmtb.so'/>
      </sensor>
    </link>
    <joint name='torso_yaw' type='revolute'>
      <child>chest</child>
      <parent>torso_2</parent>
      <axis>
        <xyz>-7e-06 0 -1</xyz>
        <limit>
          <lower>-1.02974</lower>
          <upper>1.02974</upper>
          <effort>80</effort>
          <velocity>100</velocity>
        </limit>
        <dynamics>
          <damping>1</damping>
          <friction>0</friction>
          <spring_reference>0</spring_reference>
          <spring_stiffness>0</spring_stiffness>
        </dynamics>
        <use_parent_model_frame>1</use_parent_model_frame>
      </axis>
    </joint>
    <link name='l_shoulder_1'>
      <pose frame=''>-0.010749 -0.11026 0.1753 -0.261794 -1.57079 -1e-06</pose>
      <inertial>
        <pose frame=''>-5e-06 0.0187 -0.00119 0 -0 0</pose>
        <mass>0.189</mass>
        <inertia>
          <ixx>0.01</ixx>
          <ixy>9e-09</ixy>
          <ixz>0</ixz>
          <iyy>0.01</iyy>
          <iyz>-1.7e-08</iyz>
          <izz>0.01</izz>
        </inertia>
      </inertial>
      <collision name='l_shoulder_1_collision'>
        <pose frame=''>0 0.109285 -0.005211 -0.301063 1.57079 -1.87186</pose>
        <geometry>
          <mesh>
            <scale>1 1 1</scale>
            <uri>model://icub/meshes/collision/icub_simple_collision_l_shoulder_1.dae</uri>
          </mesh>
        </geometry>
      </collision>
      <visual name='l_shoulder_1_visual'>
        <pose frame=''>0 0.109285 -0.005211 -0.301063 1.57079 -1.87186</pose>
        <geometry>
          <mesh>
            <scale>1 1 1</scale>
            <uri>model://icub/meshes/visual/icub_l_shoulder_1.dae</uri>
          </mesh>
        </geometry>
      </visual>
    </link>
    <joint name='l_shoulder_pitch' type='revolute'>
      <child>l_shoulder_1</child>
      <parent>chest</parent>
      <axis>
        <xyz>-0.258815 -0.965927 3e-06</xyz>
        <limit>
          <lower>-1.65806</lower>
          <upper>0.0872665</upper>
          <effort>84</effort>
          <velocity>100</velocity>
        </limit>
        <dynamics>
          <damping>1</damping>
          <friction>0</friction>
          <spring_reference>0</spring_reference>
          <spring_stiffness>0</spring_stiffness>
        </dynamics>
        <use_parent_model_frame>1</use_parent_model_frame>
      </axis>
    </joint>
    <link name='l_shoulder_2'>
      <pose frame=''>-0.010749 -0.11026 0.1753 3.14159 1e-06 -1.83259</pose>
      <inertial>
        <pose frame=''>9.4e-05 -0.00627 0.0166 0 -0 0</pose>
        <mass>0.179</mass>
        <inertia>
          <ixx>0.01</ixx>
          <ixy>4.66e-07</ixy>
          <ixz>3.65e-07</ixz>
          <iyy>0.01</iyy>
          <iyz>-2.0524e-05</iyz>
          <izz>0.01</izz>
        </inertia>
      </inertial>
      <collision name='l_shoulder_2_collision'>
        <pose frame=''>-0.001545 -0.005211 -0 -2.14033 1.57079 -0.569533</pose>
        <geometry>
          <mesh>
            <scale>1 1 1</scale>
            <uri>model://icub/meshes/collision/icub_simple_collision_l_shoulder_2.dae</uri>
          </mesh>
        </geometry>
      </collision>
      <visual name='l_shoulder_2_visual'>
        <pose frame=''>-0.001545 -0.005211 -0 -2.14033 1.57079 -0.569533</pose>
        <geometry>
          <mesh>
            <scale>1 1 1</scale>
            <uri>model://icub/meshes/visual/icub_l_shoulder_2.dae</uri>
          </mesh>
        </geometry>
      </visual>
    </link>
    <joint name='l_shoulder_roll' type='revolute'>
      <child>l_shoulder_2</child>
      <parent>l_shoulder_1</parent>
      <axis>
        <xyz>-0.965927 0.258815 7e-06</xyz>
        <limit>
          <lower>0</lower>
          <upper>2.80649</upper>
          <effort>84</effort>
          <velocity>100</velocity>
        </limit>
        <dynamics>
          <damping>1</damping>
          <friction>0</friction>
          <spring_reference>0</spring_reference>
          <spring_stiffness>0</spring_stiffness>
        </dynamics>
        <use_parent_model_frame>1</use_parent_model_frame>
      </axis>
    </joint>
    <link name='l_shoulder_3'>
      <pose frame=''>-0.010749 -0.11026 0.1753 3.14159 -7e-06 -3.14159</pose>
      <inertial>
        <pose frame=''>0.005594 9.8e-05 0.050135 0 -0 0</pose>
        <mass>0.156157</mass>
        <inertia>
          <ixx>0.01</ixx>
          <ixy>-5.662e-08</ixy>
          <ixz>-4.3618e-06</ixz>
          <iyy>0.01</iyy>
          <iyz>-7.42844e-07</iyz>
          <izz>0.01</izz>
        </inertia>
      </inertial>
    </link>
    <joint name='l_shoulder_yaw' type='revolute'>
      <child>l_shoulder_3</child>
      <parent>l_shoulder_2</parent>
      <axis>
        <xyz>-7e-06 3e-06 -1</xyz>
        <limit>
          <lower>-0.645772</lower>
          <upper>1.74533</upper>
          <effort>34</effort>
          <velocity>100</velocity>
        </limit>
        <dynamics>
          <damping>1</damping>
          <friction>0</friction>
          <spring_reference>0</spring_reference>
          <spring_stiffness>0</spring_stiffness>
        </dynamics>
        <use_parent_model_frame>1</use_parent_model_frame>
      </axis>
    </joint>
    <link name='l_upper_arm'>
      <pose frame=''>-0.025749 -0.11026 0.1073 3.14159 -7e-06 -3.14159</pose>
      <inertial>
        <pose frame=''>-0.000156 -9.9e-05 0.0298 0 -0 0</pose>
        <mass>0.727843</mass>
        <inertia>
          <ixx>0.01</ixx>
          <ixy>-1.08e-06</ixy>
          <ixz>-2.29e-06</ixz>
          <iyy>0.01</iyy>
          <iyz>3.57e-06</iyz>
          <izz>0.01</izz>
        </inertia>
      </inertial>
      <collision name='l_upper_arm_collision'>
        <pose frame=''>-0.020433 0.000144 -0.068 0 0 -1.309</pose>
        <geometry>
          <mesh>
            <scale>1 1 1</scale>
            <uri>model://icub/meshes/collision/icub_simple_collision_l_arm.dae</uri>
          </mesh>
        </geometry>
        <surface>
          <contact>
            <ode/>
          </contact>
          <friction>
            <ode/>
          </friction>
        </surface>
      </collision>
      <visual name='l_upper_arm_visual'>
        <pose frame=''>-0.020433 0.000144 -0.068 0 0 -1.309</pose>
        <geometry>
          <mesh>
            <scale>1 1 1</scale>
            <uri>model://icub/meshes/visual/icub_l_arm.dae</uri>
          </mesh>
        </geometry>
        <material>
          <script>
            <uri>__default__</uri>
            <name>__default__</name>
          </script>
        </material>
      </visual>
      <velocity_decay/>
      <sensor name='l_upper_arm_mtb_acc_1b10' type='imu'>
        <always_on>1</always_on>
        <update_rate>100</update_rate>
        <pose frame=''>-0.043055 -0.028681 0.029528 -1.5708 -1.5705 2.68257</pose>
        <plugin name='iCub_yarp_gazebo_plugin_ACC' filename='libgazebo_yarp_inertialmtb.so'/>
      </sensor>
      <velocity_decay/>
      <sensor name='l_upper_arm_mtb_acc_1b11' type='imu'>
        <always_on>1</always_on>
        <update_rate>100</update_rate>
        <pose frame=''>-0.041218 -0.029589 0.07606 -1.5708 -1.5705 2.68257</pose>
        <plugin name='iCub_yarp_gazebo_plugin_ACC' filename='libgazebo_yarp_inertialmtb.so'/>
      </sensor>
      <velocity_decay/>
      <sensor name='l_upper_arm_mtb_acc_1b12' type='imu'>
        <always_on>1</always_on>
        <update_rate>100</update_rate>
        <pose frame=''>-0.04122 -0.029588 0.004992 -1.5708 -1.57078 2.68257</pose>
        <plugin name='iCub_yarp_gazebo_plugin_ACC' filename='libgazebo_yarp_inertialmtb.so'/>
      </sensor>
      <gravity>1</gravity>
      <velocity_decay/>
      <sensor name='l_upper_arm_mtb_acc_1b13' type='imu'>
        <always_on>1</always_on>
        <update_rate>100</update_rate>
        <pose frame=''>0.010593 -0.028351 -0.008691 -1.5708 0.000215 -2.47804</pose>
        <plugin name='iCub_yarp_gazebo_plugin_ACC' filename='libgazebo_yarp_inertialmtb.so'/>
      </sensor>
    </link>
    <joint name='l_arm_ft_sensor' type='revolute'>
      <child>l_upper_arm</child>
      <parent>l_shoulder_3</parent>
      <axis>
        <limit>
          <lower>0</lower>
          <upper>0</upper>
        </limit>
        <dynamics>
          <damping>0</damping>
          <friction>0</friction>
          <spring_reference>0</spring_reference>
          <spring_stiffness>0</spring_stiffness>
        </dynamics>
        <use_parent_model_frame>1</use_parent_model_frame>
        <xyz>0 0 1</xyz>
      </axis>
      <physics>
        <ode>
          <limit>
            <cfm>0</cfm>
            <erp>0.2</erp>
          </limit>
        </ode>
      </physics>
      <sensor name='l_arm_ft_sensor' type='force_torque'>
        <always_on>1</always_on>
        <update_rate>100</update_rate>
        <force_torque>
          <frame>child</frame>
          <measure_direction>child_to_parent</measure_direction>
        </force_torque>
      </sensor>
    </joint>
    <link name='l_elbow_1'>
      <pose frame=''>-0.02575 -0.11026 0.02302 3.14159 -7e-06 -3.14159</pose>
      <inertial>
        <pose frame=''>-0.0013 0.00371 -0.00105 0 -0 0</pose>
        <mass>0.1</mass>
        <inertia>
          <ixx>0.01</ixx>
          <ixy>-5.15e-07</ixy>
          <ixz>-4.08e-07</ixz>
          <iyy>0.01</iyy>
          <iyz>-3.71e-07</iyz>
          <izz>0.01</izz>
        </inertia>
      </inertial>
    </link>
    <joint name='l_elbow' type='revolute'>
      <child>l_elbow_1</child>
      <parent>l_upper_arm</parent>
      <axis>
        <xyz>-1e-06 1 3e-06</xyz>
        <limit>
          <lower>0.0959931</lower>
          <upper>1.85005</upper>
          <effort>20</effort>
          <velocity>100</velocity>
        </limit>
        <dynamics>
          <damping>1</damping>
          <friction>0</friction>
          <spring_reference>0</spring_reference>
          <spring_stiffness>0</spring_stiffness>
        </dynamics>
        <use_parent_model_frame>1</use_parent_model_frame>
      </axis>
    </joint>
    <link name='l_forearm'>
      <pose frame=''>-0.01075 -0.11026 0.02302 -1.5708 3e-06 -1.57079</pose>
      <inertial>
        <pose frame=''>0.000347 0.066 0.00476 0 -0 0</pose>
        <mass>0.525</mass>
        <inertia>
          <ixx>0.01</ixx>
          <ixy>4.337e-06</ixy>
          <ixz>2.39e-07</ixz>
          <iyy>0.01</iyy>
          <iyz>1.9381e-05</iyz>
          <izz>0.01</izz>
        </inertia>
      </inertial>
      <collision name='l_forearm_collision'>
        <pose frame=''>-0.000144 -0 0.020433 -2.66395 1.57079 -1.09315</pose>
        <geometry>
          <mesh>
            <scale>1 1 1</scale>
            <uri>model://icub/meshes/collision/icub_simple_collision_l_forearm.dae</uri>
          </mesh>
        </geometry>
        <surface>
          <contact>
            <ode/>
          </contact>
          <friction>
            <ode/>
          </friction>
        </surface>
      </collision>
      <visual name='l_forearm_visual'>
        <pose frame=''>-0.000144 -0 0.020433 -2.66395 1.57079 -1.09315</pose>
        <geometry>
          <mesh>
            <scale>1 1 1</scale>
            <uri>model://icub/meshes/visual/icub_l_forearm.dae</uri>
          </mesh>
        </geometry>
        <material>
          <script>
            <uri>__default__</uri>
            <name>__default__</name>
          </script>
        </material>
      </visual>
      <velocity_decay/>
      <sensor name='l_forearm_mtb_acc_1b7' type='imu'>
        <always_on>1</always_on>
        <update_rate>100</update_rate>
        <pose frame=''>0.076873 -0.005483 -0.011048 0.261799 0.00037 -1.57033</pose>
        <plugin name='iCub_yarp_gazebo_plugin_ACC' filename='libgazebo_yarp_inertialmtb.so'/>
      </sensor>
      <velocity_decay/>
      <sensor name='l_forearm_mtb_acc_1b8' type='imu'>
        <always_on>1</always_on>
        <update_rate>100</update_rate>
        <pose frame=''>0.051424 -0.018028 0.040751 -0.661144 0.147825 -3.04952</pose>
        <plugin name='iCub_yarp_gazebo_plugin_ACC' filename='libgazebo_yarp_inertialmtb.so'/>
      </sensor>
      <gravity>1</gravity>
      <velocity_decay/>
      <sensor name='l_forearm_mtb_acc_1b9' type='imu'>
        <always_on>1</always_on>
        <update_rate>100</update_rate>
        <pose frame=''>0.022099 0.025657 -0.015118 1.76682 0.2611 3.08752</pose>
        <plugin name='iCub_yarp_gazebo_plugin_ACC' filename='libgazebo_yarp_inertialmtb.so'/>
      </sensor>
    </link>
    <joint name='l_wrist_prosup' type='revolute'>
      <child>l_forearm</child>
      <parent>l_elbow_1</parent>
      <axis>
        <xyz>-3e-06 3e-06 -1</xyz>
        <limit>
          <lower>-0.872665</lower>
          <upper>0.872665</upper>
          <effort>0.45</effort>
          <velocity>100</velocity>
        </limit>
        <dynamics>
          <damping>1</damping>
          <friction>0</friction>
          <spring_reference>0</spring_reference>
          <spring_stiffness>0</spring_stiffness>
        </dynamics>
        <use_parent_model_frame>1</use_parent_model_frame>
      </axis>
    </joint>
    <link name='l_wrist_1'>
      <pose frame=''>-0.01075 -0.110259 -0.11428 -2.7153 1.57079 1.99709</pose>
      <inertial>
        <pose frame=''>0 0 0 0 -0 0</pose>
        <mass>0.1</mass>
        <inertia>
          <ixx>0.01</ixx>
          <ixy>0</ixy>
          <ixz>0</ixz>
          <iyy>0.01</iyy>
          <iyz>0</iyz>
          <izz>0.01</izz>
        </inertia>
      </inertial>
    </link>
    <joint name='l_wrist_pitch' type='revolute'>
      <child>l_wrist_1</child>
      <parent>l_forearm</parent>
      <axis>
        <xyz>1 1e-06 -3e-06</xyz>
        <limit>
          <lower>-1.13446</lower>
          <upper>0.174533</upper>
          <effort>0.65</effort>
          <velocity>100</velocity>
        </limit>
        <dynamics>
          <damping>1</damping>
          <friction>0</friction>
          <spring_reference>0</spring_reference>
          <spring_stiffness>0</spring_stiffness>
        </dynamics>
        <use_parent_model_frame>1</use_parent_model_frame>
      </axis>
    </joint>
    <link name='l_hand'>
      <pose frame=''>-0.01075 -0.110259 -0.11428 -2.7153 1.57079 1.99709</pose>
      <inertial>
        <pose frame=''>0.07023 -0.00805 -0.007 0 -0 0</pose>
        <mass>0.213</mass>
        <inertia>
          <ixx>0.01</ixx>
          <ixy>1.278e-05</ixy>
          <ixz>4.823e-06</ixz>
          <iyy>0.01</iyy>
          <iyz>-1.8188e-05</iyz>
          <izz>0.01</izz>
        </inertia>
      </inertial>
      <collision name='l_hand_collision'>
        <pose frame=''>-0 0.020433 -0.000144 0 -0 0</pose>
        <geometry>
          <mesh>
            <scale>1 1 1</scale>
            <uri>model://icub/meshes/collision/icub_simple_collision_l_hand.dae</uri>
          </mesh>
        </geometry>
      </collision>
      <visual name='l_hand_visual'>
        <pose frame=''>-0 0.020433 -0.000144 0 -0 0</pose>
        <geometry>
          <mesh>
            <scale>1 1 1</scale>
            <uri>model://icub/meshes/visual/icub_l_hand.dae</uri>
          </mesh>
        </geometry>
      </visual>
    </link>
    <joint name='l_wrist_yaw' type='revolute'>
      <child>l_hand</child>
      <parent>l_wrist_1</parent>
      <axis>
        <xyz>1e-06 -1 -6e-06</xyz>
        <limit>
          <lower>-0.436332</lower>
          <upper>0.436332</upper>
          <effort>0.65</effort>
          <velocity>100</velocity>
        </limit>
        <dynamics>
          <damping>1</damping>
          <friction>0</friction>
          <spring_reference>0</spring_reference>
          <spring_stiffness>0</spring_stiffness>
        </dynamics>
        <use_parent_model_frame>1</use_parent_model_frame>
      </axis>
    </joint>
    <link name='neck_1'>
      <pose frame=''>-0.007808 0 0.2253 6e-06 -1.57079 -1e-06</pose>
      <inertial>
        <pose frame=''>0 0 0 0 -0 0</pose>
        <mass>0.1</mass>
        <inertia>
          <ixx>0.01</ixx>
          <ixy>0</ixy>
          <ixz>0</ixz>
          <iyy>0.01</iyy>
          <iyz>0</iyz>
          <izz>0.01</izz>
        </inertia>
      </inertial>
      <collision name='neck_1_collision'>
        <pose frame=''>-0 0 -0.0055 3.14159 -1.57079 1.5708</pose>
        <geometry>
          <mesh>
            <scale>1 1 1</scale>
            <uri>model://icub/meshes/collision/icub_simple_collision_neck_1.dae</uri>
          </mesh>
        </geometry>
      </collision>
      <visual name='neck_1_visual'>
        <pose frame=''>-0 0 -0.0055 3.14159 -1.57079 1.5708</pose>
        <geometry>
          <mesh>
            <scale>1 1 1</scale>
            <uri>model://icub/meshes/visual/icub_neck_1.dae</uri>
          </mesh>
        </geometry>
      </visual>
    </link>
    <joint name='neck_pitch' type='revolute'>
      <child>neck_1</child>
      <parent>chest</parent>
      <axis>
        <xyz>-5e-06 1 0</xyz>
        <limit>
          <lower>-0.698132</lower>
          <upper>0.523599</upper>
          <effort>20</effort>
          <velocity>100</velocity>
        </limit>
        <dynamics>
          <damping>1</damping>
          <friction>0</friction>
          <spring_reference>0</spring_reference>
          <spring_stiffness>0</spring_stiffness>
        </dynamics>
        <use_parent_model_frame>1</use_parent_model_frame>
      </axis>
    </joint>
    <link name='neck_2'>
      <pose frame=''>-0.007808 0 0.2348 -1.5e-05 4e-06 -1.57079</pose>
      <inertial>
        <pose frame=''>0 0 0 0 -0 0</pose>
        <mass>0.1</mass>
        <inertia>
          <ixx>0.01</ixx>
          <ixy>0</ixy>
          <ixz>0</ixz>
          <iyy>0.01</iyy>
          <iyz>0</iyz>
          <izz>0.01</izz>
        </inertia>
      </inertial>
      <collision name='neck_2_collision'>
        <pose frame=''>-0 0.0055 0.0235 -3.14157 -1.57079 -1.57082</pose>
        <geometry>
          <mesh>
            <scale>1 1 1</scale>
            <uri>model://icub/meshes/collision/icub_simple_collision_neck_2.dae</uri>
          </mesh>
        </geometry>
      </collision>
      <visual name='neck_2_visual'>
        <pose frame=''>-0 0.0055 0.0235 -3.14157 -1.57079 -1.57082</pose>
        <geometry>
          <mesh>
            <scale>1 1 1</scale>
            <uri>model://icub/meshes/visual/icub_neck_2.dae</uri>
          </mesh>
        </geometry>
      </visual>
    </link>
    <joint name='neck_roll' type='revolute'>
      <child>neck_2</child>
      <parent>neck_1</parent>
      <axis>
        <xyz>-1 -5e-06 1.5e-05</xyz>
        <limit>
          <lower>-1.22173</lower>
          <upper>1.0472</upper>
          <effort>20</effort>
          <velocity>100</velocity>
        </limit>
        <dynamics>
          <damping>1</damping>
          <friction>0</friction>
          <spring_reference>0</spring_reference>
          <spring_stiffness>0</spring_stiffness>
        </dynamics>
        <use_parent_model_frame>1</use_parent_model_frame>
      </axis>
    </joint>
    <link name='head'>
      <pose frame=''>-0.007808 0 0.2348 -1.5708 1.5e-05 8e-06</pose>
      <inertial>
        <pose frame=''>0.0185 -0.1108 0 0 -0 0</pose>
        <mass>3</mass>
        <inertia>
          <ixx>0.01</ixx>
          <ixy>1.73472e-18</ixy>
          <ixz>-4.81482e-35</ixz>
          <iyy>0.01</iyy>
          <iyz>3.85186e-34</iyz>
          <izz>0.01</izz>
        </inertia>
      </inertial>
      <collision name='head_collision'>
        <pose frame=''>0.0045 -0.0235 0 -1.32582 1.57079 -2.89662</pose>
        <geometry>
          <mesh>
            <scale>1 1 1</scale>
            <uri>model://icub/meshes/collision/icub_simple_collision_head.dae</uri>
          </mesh>
        </geometry>
      </collision>
      <visual name='head_visual'>
        <pose frame=''>0.0045 -0.0235 0 -1.32582 1.57079 -2.89662</pose>
        <geometry>
          <mesh>
            <scale>1 1 1</scale>
            <uri>model://icub/meshes/visual/icub_head.dae</uri>
          </mesh>
        </geometry>
      </visual>
    </link>
    <joint name='neck_yaw' type='revolute'>
      <child>head</child>
      <parent>neck_2</parent>
      <axis>
        <xyz>1.5e-05 0 1</xyz>
        <limit>
          <lower>-0.959931</lower>
          <upper>0.959931</upper>
          <effort>20</effort>
          <velocity>100</velocity>
        </limit>
        <dynamics>
          <damping>1</damping>
          <friction>0</friction>
          <spring_reference>0</spring_reference>
          <spring_stiffness>0</spring_stiffness>
        </dynamics>
        <use_parent_model_frame>1</use_parent_model_frame>
      </axis>
    </joint>
    <link name='r_shoulder_1'>
      <pose frame=''>-0.010749 0.11026 0.1753 -2.87979 -1.57079 -1e-06</pose>
      <inertial>
        <pose frame=''>5e-06 0.0187 0.00119 0 -0 0</pose>
        <mass>0.189</mass>
        <inertia>
          <ixx>0.01</ixx>
          <ixy>2.1e-08</ixy>
          <ixz>-1e-09</ixz>
          <iyy>0.01</iyy>
          <iyz>4.22e-06</iyz>
          <izz>0.01</izz>
        </inertia>
      </inertial>
      <collision name='r_shoulder_1_collision'>
        <pose frame=''>-0 0.109285 0.005211 3.06003 1.57079 -1.65235</pose>
        <geometry>
          <mesh>
            <scale>1 1 1</scale>
            <uri>model://icub/meshes/collision/icub_simple_collision_r_shoulder_1.dae</uri>
          </mesh>
        </geometry>
      </collision>
      <visual name='r_shoulder_1_visual'>
        <pose frame=''>-0 0.109285 0.005211 3.06003 1.57079 -1.65235</pose>
        <geometry>
          <mesh>
            <scale>1 1 1</scale>
            <uri>model://icub/meshes/visual/icub_r_shoulder_1.dae</uri>
          </mesh>
        </geometry>
      </visual>
    </link>
    <joint name='r_shoulder_pitch' type='revolute'>
      <child>r_shoulder_1</child>
      <parent>chest</parent>
      <axis>
        <xyz>0.258817 -0.965926 -3e-06</xyz>
        <limit>
          <lower>-1.65806</lower>
          <upper>0.0872665</upper>
          <effort>84</effort>
          <velocity>100</velocity>
        </limit>
        <dynamics>
          <damping>1</damping>
          <friction>0</friction>
          <spring_reference>0</spring_reference>
          <spring_stiffness>0</spring_stiffness>
        </dynamics>
        <use_parent_model_frame>1</use_parent_model_frame>
      </axis>
    </joint>
    <link name='r_shoulder_2'>
      <pose frame=''>-0.010749 0.11026 0.1753 7e-06 1e-06 1.83259</pose>
      <inertial>
        <pose frame=''>-9.4e-05 -0.00627 -0.0166 0 -0 0</pose>
        <mass>0.179</mass>
        <inertia>
          <ixx>0.01</ixx>
          <ixy>-4.53e-07</ixy>
          <ixz>2.03e-07</ixz>
          <iyy>0.01</iyy>
          <iyz>2.07e-05</iyz>
          <izz>0.01</izz>
        </inertia>
      </inertial>
      <collision name='r_shoulder_2_collision'>
        <pose frame=''>-0.001545 -0.005211 -0 -1.00125 -1.57079 2.57205</pose>
        <geometry>
          <mesh>
            <scale>1 1 1</scale>
            <uri>model://icub/meshes/collision/icub_simple_collision_r_shoulder_2.dae</uri>
          </mesh>
        </geometry>
      </collision>
      <visual name='r_shoulder_2_visual'>
        <pose frame=''>-0.001545 -0.005211 -0 -1.00125 -1.57079 2.57205</pose>
        <geometry>
          <mesh>
            <scale>1 1 1</scale>
            <uri>model://icub/meshes/visual/icub_r_shoulder_2.dae</uri>
          </mesh>
        </geometry>
      </visual>
    </link>
    <joint name='r_shoulder_roll' type='revolute'>
      <child>r_shoulder_2</child>
      <parent>r_shoulder_1</parent>
      <axis>
        <xyz>0.965926 0.258817 -7e-06</xyz>
        <limit>
          <lower>0</lower>
          <upper>2.80649</upper>
          <effort>84</effort>
          <velocity>100</velocity>
        </limit>
        <dynamics>
          <damping>1</damping>
          <friction>0</friction>
          <spring_reference>0</spring_reference>
          <spring_stiffness>0</spring_stiffness>
        </dynamics>
        <use_parent_model_frame>1</use_parent_model_frame>
      </axis>
    </joint>
    <link name='r_shoulder_3'>
      <pose frame=''>-0.010749 0.11026 0.1753 3.14159 -7e-06 -3.14159</pose>
      <inertial>
        <pose frame=''>0.005539 -2.5e-05 0.04939 0 -0 0</pose>
        <mass>0.155</mass>
        <inertia>
          <ixx>0.01</ixx>
          <ixy>3.56977e-07</ixy>
          <ixz>-3.95372e-06</ixz>
          <iyy>0.01</iyy>
          <iyz>-6.5128e-06</iyz>
          <izz>0.01</izz>
        </inertia>
      </inertial>
    </link>
    <joint name='r_shoulder_yaw' type='revolute'>
      <child>r_shoulder_3</child>
      <parent>r_shoulder_2</parent>
      <axis>
        <xyz>7e-06 -0 1</xyz>
        <limit>
          <lower>-0.645772</lower>
          <upper>1.74533</upper>
          <effort>34</effort>
          <velocity>100</velocity>
        </limit>
        <dynamics>
          <damping>1</damping>
          <friction>0</friction>
          <spring_reference>0</spring_reference>
          <spring_stiffness>0</spring_stiffness>
        </dynamics>
        <use_parent_model_frame>1</use_parent_model_frame>
      </axis>
    </joint>
    <link name='r_upper_arm'>
      <pose frame=''>-0.025749 0.11026 0.1073 3.14159 -7e-06 -3.14159</pose>
      <inertial>
        <pose frame=''>-0.000159 8.3e-05 0.029883 0 -0 0</pose>
        <mass>0.729</mass>
        <inertia>
          <ixx>0.01</ixx>
          <ixy>-1.08e-06</ixy>
          <ixz>-2.29e-06</ixz>
          <iyy>0.01</iyy>
          <iyz>3.57e-06</iyz>
          <izz>0.01</izz>
        </inertia>
      </inertial>
      <collision name='r_upper_arm_collision'>
        <pose frame=''>-0.020433 -0.000144 -0.068 -3.14159 -0 1.309</pose>
        <geometry>
          <mesh>
            <scale>1 1 1</scale>
            <uri>model://icub/meshes/collision/icub_simple_collision_r_arm.dae</uri>
          </mesh>
        </geometry>
        <surface>
          <contact>
            <ode/>
          </contact>
          <friction>
            <ode/>
          </friction>
        </surface>
      </collision>
      <visual name='r_upper_arm_visual'>
        <pose frame=''>-0.020433 -0.000144 -0.068 -3.14159 -0 1.309</pose>
        <geometry>
          <mesh>
            <scale>1 1 1</scale>
            <uri>model://icub/meshes/visual/icub_r_arm.dae</uri>
          </mesh>
        </geometry>
        <material>
          <script>
            <uri>__default__</uri>
            <name>__default__</name>
          </script>
        </material>
      </visual>
      <velocity_decay/>
      <sensor name='r_upper_arm_mtb_acc_2b10' type='imu'>
        <always_on>1</always_on>
        <update_rate>100</update_rate>
        <pose frame=''>-0.04122 0.029588 0.029528 1.57079 1.57078 -2.68257</pose>
        <plugin name='iCub_yarp_gazebo_plugin_ACC' filename='libgazebo_yarp_inertialmtb.so'/>
      </sensor>
      <velocity_decay/>
      <sensor name='r_upper_arm_mtb_acc_2b11' type='imu'>
        <always_on>1</always_on>
        <update_rate>100</update_rate>
        <pose frame=''>-0.043057 0.02868 0.07606 -1.5708 -1.5705 0.459022</pose>
        <plugin name='iCub_yarp_gazebo_plugin_ACC' filename='libgazebo_yarp_inertialmtb.so'/>
      </sensor>
      <velocity_decay/>
      <sensor name='r_upper_arm_mtb_acc_2b12' type='imu'>
        <always_on>1</always_on>
        <update_rate>100</update_rate>
        <pose frame=''>-0.043056 0.028681 0.004992 -1.11179 -1.5708 1.1e-05</pose>
        <plugin name='iCub_yarp_gazebo_plugin_ACC' filename='libgazebo_yarp_inertialmtb.so'/>
      </sensor>
      <gravity>1</gravity>
      <velocity_decay/>
      <sensor name='r_upper_arm_mtb_acc_2b13' type='imu'>
        <always_on>1</always_on>
        <update_rate>100</update_rate>
        <pose frame=''>0.010593 0.02835 -0.010738 1.5708 -0.000215 2.47804</pose>
        <plugin name='iCub_yarp_gazebo_plugin_ACC' filename='libgazebo_yarp_inertialmtb.so'/>
      </sensor>
    </link>
    <joint name='r_arm_ft_sensor' type='revolute'>
      <child>r_upper_arm</child>
      <parent>r_shoulder_3</parent>
      <axis>
        <limit>
          <lower>0</lower>
          <upper>0</upper>
        </limit>
        <dynamics>
          <damping>0</damping>
          <friction>0</friction>
          <spring_reference>0</spring_reference>
          <spring_stiffness>0</spring_stiffness>
        </dynamics>
        <use_parent_model_frame>1</use_parent_model_frame>
        <xyz>0 0 1</xyz>
      </axis>
      <physics>
        <ode>
          <limit>
            <cfm>0</cfm>
            <erp>0.2</erp>
          </limit>
        </ode>
      </physics>
      <sensor name='r_arm_ft_sensor' type='force_torque'>
        <always_on>1</always_on>
        <update_rate>100</update_rate>
        <force_torque>
          <frame>child</frame>
          <measure_direction>child_to_parent</measure_direction>
        </force_torque>
      </sensor>
    </joint>
    <link name='r_elbow_1'>
      <pose frame=''>-0.02575 0.11026 0.02302 -3e-06 7e-06 4e-06</pose>
      <inertial>
        <pose frame=''>0.0013 -0.00371 0.00105 0 -0 0</pose>
        <mass>0.1</mass>
        <inertia>
          <ixx>0.01</ixx>
          <ixy>-5.02e-07</ixy>
          <ixz>-3.99e-07</ixz>
          <iyy>0.01</iyy>
          <iyz>-3.71e-07</iyz>
          <izz>0.01</izz>
        </inertia>
      </inertial>
    </link>
    <joint name='r_elbow' type='revolute'>
      <child>r_elbow_1</child>
      <parent>r_upper_arm</parent>
      <axis>
        <xyz>-4e-06 1 -3e-06</xyz>
        <limit>
          <lower>0.0959931</lower>
          <upper>1.85005</upper>
          <effort>20</effort>
          <velocity>100</velocity>
        </limit>
        <dynamics>
          <damping>1</damping>
          <friction>0</friction>
          <spring_reference>0</spring_reference>
          <spring_stiffness>0</spring_stiffness>
        </dynamics>
        <use_parent_model_frame>1</use_parent_model_frame>
      </axis>
    </joint>
    <link name='r_forearm'>
      <pose frame=''>-0.01075 0.11026 0.02302 1.57079 -3e-06 -1.5708</pose>
      <inertial>
        <pose frame=''>-0.000347 -0.066 -0.00476 0 -0 0</pose>
        <mass>0.525</mass>
        <inertia>
          <ixx>0.01</ixx>
          <ixy>5.66e-06</ixy>
          <ixz>1.4e-06</ixz>
          <iyy>0.01</iyy>
          <iyz>1.82e-05</iyz>
          <izz>0.01</izz>
        </inertia>
      </inertial>
      <collision name='r_forearm_collision'>
        <pose frame=''>0.000144 -0 -0.020433 -1.74165 1.57079 -0.170863</pose>
        <geometry>
          <mesh>
            <scale>1 1 1</scale>
            <uri>model://icub/meshes/collision/icub_simple_collision_r_forearm.dae</uri>
          </mesh>
        </geometry>
        <surface>
          <contact>
            <ode/>
          </contact>
          <friction>
            <ode/>
          </friction>
        </surface>
      </collision>
      <visual name='r_forearm_visual'>
        <pose frame=''>0.000144 -0 -0.020433 -1.74165 1.57079 -0.170863</pose>
        <geometry>
          <mesh>
            <scale>1 1 1</scale>
            <uri>model://icub/meshes/visual/icub_r_forearm.dae</uri>
          </mesh>
        </geometry>
        <material>
          <script>
            <uri>__default__</uri>
            <name>__default__</name>
          </script>
        </material>
      </visual>
      <velocity_decay/>
      <sensor name='r_forearm_mtb_acc_2b7' type='imu'>
        <always_on>1</always_on>
        <update_rate>100</update_rate>
        <pose frame=''>-0.076873 0.005497 -0.011048 0.261799 0.00037 1.57126</pose>
        <plugin name='iCub_yarp_gazebo_plugin_ACC' filename='libgazebo_yarp_inertialmtb.so'/>
      </sensor>
      <velocity_decay/>
      <sensor name='r_forearm_mtb_acc_2b8' type='imu'>
        <always_on>1</always_on>
        <update_rate>100</update_rate>
        <pose frame=''>-0.051419 0.015786 0.040752 -0.661144 0.147825 0.09207</pose>
        <plugin name='iCub_yarp_gazebo_plugin_ACC' filename='libgazebo_yarp_inertialmtb.so'/>
      </sensor>
      <gravity>1</gravity>
      <velocity_decay/>
      <sensor name='r_forearm_mtb_acc_2b9' type='imu'>
        <always_on>1</always_on>
        <update_rate>100</update_rate>
        <pose frame=''>-0.021638 0.027924 -0.013249 -1.76683 0.261191 0.054048</pose>
        <plugin name='iCub_yarp_gazebo_plugin_ACC' filename='libgazebo_yarp_inertialmtb.so'/>
      </sensor>
    </link>
    <joint name='r_wrist_prosup' type='revolute'>
      <child>r_forearm</child>
      <parent>r_elbow_1</parent>
      <axis>
        <xyz>3e-06 3e-06 1</xyz>
        <limit>
          <lower>-0.872665</lower>
          <upper>0.872665</upper>
          <effort>0.45</effort>
          <velocity>100</velocity>
        </limit>
        <dynamics>
          <damping>1</damping>
          <friction>0</friction>
          <spring_reference>0</spring_reference>
          <spring_stiffness>0</spring_stiffness>
        </dynamics>
        <use_parent_model_frame>1</use_parent_model_frame>
      </axis>
    </joint>
    <link name='r_wrist_1'>
      <pose frame=''>-0.01075 0.11026 -0.11428 0.426292 -1.57079 1.14451</pose>
      <inertial>
        <pose frame=''>0 0 0 0 -0 0</pose>
        <mass>0.1</mass>
        <inertia>
          <ixx>0.01</ixx>
          <ixy>0</ixy>
          <ixz>0</ixz>
          <iyy>0.01</iyy>
          <iyz>0</iyz>
          <izz>0.01</izz>
        </inertia>
      </inertial>
    </link>
    <joint name='r_wrist_pitch' type='revolute'>
      <child>r_wrist_1</child>
      <parent>r_forearm</parent>
      <axis>
        <xyz>-1 -4e-06 3e-06</xyz>
        <limit>
          <lower>-1.13446</lower>
          <upper>0.174533</upper>
          <effort>0.65</effort>
          <velocity>100</velocity>
        </limit>
        <dynamics>
          <damping>1</damping>
          <friction>0</friction>
          <spring_reference>0</spring_reference>
          <spring_stiffness>0</spring_stiffness>
        </dynamics>
        <use_parent_model_frame>1</use_parent_model_frame>
      </axis>
    </joint>
    <link name='r_hand'>
      <pose frame=''>-0.01075 0.11026 -0.11428 -0.720145 1.57079 -2.29094</pose>
      <inertial>
        <pose frame=''>0.07023 -0.00805 0.007 0 -0 0</pose>
        <mass>0.213</mass>
        <inertia>
          <ixx>0.01</ixx>
          <ixy>1.26e-05</ixy>
          <ixz>-6.08e-06</ixz>
          <iyy>0.01</iyy>
          <iyz>1.76e-05</iyz>
          <izz>0.01</izz>
        </inertia>
      </inertial>
      <collision name='r_hand_collision'>
        <pose frame=''>0 0.020433 0.000144 0 0 -3.14159</pose>
        <geometry>
          <mesh>
            <scale>1 1 1</scale>
            <uri>model://icub/meshes/collision/icub_simple_collision_r_hand.dae</uri>
          </mesh>
        </geometry>
      </collision>
      <visual name='r_hand_visual'>
        <pose frame=''>0 0.020433 0.000144 0 0 -3.14159</pose>
        <geometry>
          <mesh>
            <scale>1 1 1</scale>
            <uri>model://icub/meshes/visual/icub_r_hand.dae</uri>
          </mesh>
        </geometry>
      </visual>
    </link>
    <joint name='r_wrist_yaw' type='revolute'>
      <child>r_hand</child>
      <parent>r_wrist_1</parent>
      <axis>
        <xyz>4e-06 -1 6e-06</xyz>
        <limit>
          <lower>-0.436332</lower>
          <upper>0.436332</upper>
          <effort>0.65</effort>
          <velocity>100</velocity>
        </limit>
        <dynamics>
          <damping>1</damping>
          <friction>0</friction>
          <spring_reference>0</spring_reference>
          <spring_stiffness>0</spring_stiffness>
        </dynamics>
        <use_parent_model_frame>1</use_parent_model_frame>
      </axis>
    </joint>
    <static>0</static>
    <plugin name='iCub_yarp_gazebo_plugin_ACC_left_arm' filename='libgazebo_yarp_inertialmtbPart.so'>
      <yarpConfigurationFile>model://icub/conf/MTB/gazebo_icub_left_arm_mtb.ini</yarpConfigurationFile>
    </plugin>
    <plugin name='iCub_yarp_gazebo_plugin_ACC_right_arm' filename='libgazebo_yarp_inertialmtbPart.so'>
      <yarpConfigurationFile>model://icub/conf/MTB/gazebo_icub_right_arm_mtb.ini</yarpConfigurationFile>
    </plugin>
    <plugin name='iCub_yarp_gazebo_plugin_ACC_left_leg' filename='libgazebo_yarp_inertialmtbPart.so'>
      <yarpConfigurationFile>model://icub/conf/MTB/gazebo_icub_left_leg_mtb.ini</yarpConfigurationFile>
    </plugin>
    <plugin name='iCub_yarp_gazebo_plugin_ACC_right_leg' filename='libgazebo_yarp_inertialmtbPart.so'>
      <yarpConfigurationFile>model://icub/conf/MTB/gazebo_icub_right_leg_mtb.ini</yarpConfigurationFile>
    </plugin>
    <plugin name='controlboard_torso' filename='libgazebo_yarp_controlboard.so'>
      <yarpConfigurationFile>model://icub/conf/gazebo_icub_torso.ini</yarpConfigurationFile>
    </plugin>
    <plugin name='controlboard_head' filename='libgazebo_yarp_controlboard.so'>
      <yarpConfigurationFile>model://icub/conf/gazebo_icub_head_without_eyes.ini</yarpConfigurationFile>
    </plugin>
    <plugin name='controlboard_left_arm' filename='libgazebo_yarp_controlboard.so'>
      <yarpConfigurationFile>model://icub/conf/gazebo_icub_left_arm_no_hand_for_no_hand_model.ini</yarpConfigurationFile>
      <initialConfiguration>-0.52 0.52 0 0.785 0 0 0.698</initialConfiguration>
    </plugin>
    <plugin name='controlboard_right_arm' filename='libgazebo_yarp_controlboard.so'>
      <yarpConfigurationFile>model://icub/conf/gazebo_icub_right_arm_no_hand_for_no_hand_model.ini</yarpConfigurationFile>
      <initialConfiguration>-0.52 0.52 0 0.785 0 0 0.698</initialConfiguration>
    </plugin>
    <plugin name='controlboard_right_leg' filename='libgazebo_yarp_controlboard.so'>
      <yarpConfigurationFile>model://icub/conf/gazebo_icub_right_leg.ini</yarpConfigurationFile>
    </plugin>
    <plugin name='controlboard_left_leg' filename='libgazebo_yarp_controlboard.so'>
      <yarpConfigurationFile>model://icub/conf/gazebo_icub_left_leg.ini</yarpConfigurationFile>
    </plugin>
    <plugin name='apply_external_wrench' filename='libgazebo_yarp_externalwrench.so'>
      <robotNamefromConfigFile>model://icub/conf/gazebo_icub_robotname.ini</robotNamefromConfigFile>
    </plugin>
  </model>
</sdf>
